Workbook
Name \a: #REF!
Name \a: #REF!
Name \a: #REF!
Name \b: #REF!
Name \b: #REF!
Name \b: #REF!
Name \c: #REF!
Name \c: #REF!
Name \d: #REF!
Name \d: #REF!
Name \e: #REF!
Name \e: #REF!
Name \f: #REF!
Name \f: #REF!
Name \g: #REF!
Name \g: #REF!
Name \h: #REF!
Name \h: #REF!
Name \i: #REF!
Name \i: #REF!
Name \j: #REF!
Name \j: #REF!
Name \m: #REF!
Name \m: #REF!
Name \s: #REF!
Name \s: #REF!
Name _____1.2: [1]BOQ!#REF!
Name _____1.2: [1]BOQ!#REF!
Name _____1.3: [1]BOQ!#REF!
Name _____1.3: [1]BOQ!#REF!
Name _____1.4: [1]BOQ!#REF!
Name _____1.4: [1]BOQ!#REF!
Name _____5A.1: [1]BOQ!#REF!
Name _____5A.1: [1]BOQ!#REF!
Name _____5A.2: [1]BOQ!#REF!
Name _____5A.2: [1]BOQ!#REF!
Name _____5A.3: [1]BOQ!#REF!
Name _____5A.3: [1]BOQ!#REF!
Name _____5B.1: [1]BOQ!#REF!
Name _____5B.1: [1]BOQ!#REF!
Name _____5B.2: [1]BOQ!#REF!
Name _____5B.2: [1]BOQ!#REF!
Name _____5B.3: [1]BOQ!#REF!
Name _____5B.3: [1]BOQ!#REF!
Name _____5B.4: [1]BOQ!#REF!
Name _____5B.4: [1]BOQ!#REF!
Name _____6.2: [1]BOQ!#REF!
Name _____6.2: [1]BOQ!#REF!
Name _____6.3: [1]BOQ!#REF!
Name _____6.3: [1]BOQ!#REF!
Name _____6.4: [1]BOQ!#REF!
Name _____6.4: [1]BOQ!#REF!
Name ____1.2: [1]BOQ!#REF!
Name ____1.2: [1]BOQ!#REF!
Name ____1.3: [1]BOQ!#REF!
Name ____1.3: [1]BOQ!#REF!
Name ____1.4: [1]BOQ!#REF!
Name ____1.4: [1]BOQ!#REF!
Name ____5A.1: [1]BOQ!#REF!
Name ____5A.1: [1]BOQ!#REF!

Sheet Machinery 
A1: Vehicle Running Summary - January 2026
A3: No | B3: Vehicle No | C3: Type | D3: actual days/machine hours | E3: Days/machine hours consider for costing | F3: Distance (Km) | G3: Fuel | H3: rate | I3: Rate Unit | J3: Actual Work Done | K3: Consumption | L3: RATE HOUR /DAY | M3: Amount without Idling | N3: Amount with Idling | O3: Owner | P3: Package | Q3: Remarks
A4: 1 | B4: LA-1359 | C4: Diesel bowser | H4: =IF(COUNTIF(Sheet1!$C$13:$C$530,Table44[[#This Row],[Vehicle No]])>0,_xlfn.XLOOKUP(Table44[[#This Row],[Vehicle No]],Sheet1!$C$13:$C$530,Sheet1!$K$13:$K$530,"",0),_xlfn.XLOOKUP(Table44[[#This Row],[Vehicle No]],Sheet1!$B$13:$B$530,Sheet1!$K$13:$K$530,"",0)) -> 5 | I4: =IF(COUNTIF(Sheet1!$C$13:$C$530,Table44[[#This Row],[Vehicle No]])>0,_xlfn.XLOOKUP(Table44[[#This Row],[Vehicle No]],Sheet1!$C$13:$C$530,Sheet1!$J$13:$J$530,"-",0),_xlfn.XLOOKUP(Table44[[#This Row],[Vehicle No]],Sheet1!$B$13:$B$530,Sheet1!$J$13:$J$530,"-",0)) -> L/hr | J4: =IF(Table44[[#This Row],[rate]]=0,"-",IF(Table44[[#This Row],[Rate Unit]]="L/hr",IF(Table44[[#This Row],[Fuel]]=0,"-",Table44[[#This Row],[Fuel]]/Table44[[#This Row],[rate]]),IF(Table44[[#This Row],[Fuel]]=0,"-",Table44[[#This Row],[Fuel]]*Table44[[#This Row],[rate]]))) -> - | K4: =Table44[[#This Row],[Distance (Km)]]/Table44[[#This Row],[Fuel]] -> #DIV/0! | L4: =IF(COUNTIF(Sheet1!$C$13:$C$530,Table44[[#This Row],[Vehicle No]])>0,_xlfn.XLOOKUP(Table44[[#This Row],[Vehicle No]],Sheet1!$C$13:$C$530,Sheet1!$O$13:$O$530,"",0),_xlfn.XLOOKUP(Table44[[#This Row],[Vehicle No]],Sheet1!$B$13:$B$530,Sheet1!$O$13:$O$530,"",0)) -> 2808.25 | M4: =Table44[[#This Row],[RATE HOUR /DAY]]*Table44[[#This Row],[actual days/machine hours]] -> 0 | N4: =Table44[[#This Row],[RATE HOUR /DAY]]*Table44[[#This Row],[Days/machine hours consider for costing]] -> 0 | O4: E & C
A5: 2 | B5: LL-0920 | C5: 01 Cube | D5: 24 | E5: 24 | G5: 460 | H5: =IF(COUNTIF(Sheet1!$C$13:$C$530,Table44[[#This Row],[Vehicle No]])>0,_xlfn.XLOOKUP(Table44[[#This Row],[Vehicle No]],Sheet1!$C$13:$C$530,Sheet1!$K$13:$K$530,"",0),_xlfn.XLOOKUP(Table44[[#This Row],[Vehicle No]],Sheet1!$B$13:$B$530,Sheet1!$K$13:$K$530,"",0)) -> 6.4 | I5: =IF(COUNTIF(Sheet1!$C$13:$C$530,Table44[[#This Row],[Vehicle No]])>0,_xlfn.XLOOKUP(Table44[[#This Row],[Vehicle No]],Sheet1!$C$13:$C$530,Sheet1!$J$13:$J$530,"-",0),_xlfn.XLOOKUP(Table44[[#This Row],[Vehicle No]],Sheet1!$B$13:$B$530,Sheet1!$J$13:$J$530,"-",0)) -> km/L | J5: =IF(Table44[[#This Row],[rate]]=0,"-",IF(Table44[[#This Row],[Rate Unit]]="L/hr",IF(Table44[[#This Row],[Fuel]]=0,"-",Table44[[#This Row],[Fuel]]/Table44[[#This Row],[rate]]),IF(Table44[[#This Row],[Fuel]]=0,"-",Table44[[#This Row],[Fuel]]*Table44[[#This Row],[rate]]))) -> 2944 | L5: =IF(COUNTIF(Sheet1!$C$13:$C$530,Table44[[#This Row],[Vehicle No]])>0,_xlfn.XLOOKUP(Table44[[#This Row],[Vehicle No]],Sheet1!$C$13:$C$530,Sheet1!$O$13:$O$530,"",0),_xlfn.XLOOKUP(Table44[[#This Row],[Vehicle No]],Sheet1!$B$13:$B$530,Sheet1!$O$13:$O$530,"",0)) -> 81.484062 | M5: =Table44[[#This Row],[RATE HOUR /DAY]]*Table44[[#This Row],[actual days/machine hours]] -> 1955.6175 | N5: =Table44[[#This Row],[RATE HOUR /DAY]]*Table44[[#This Row],[Days/machine hours consider for costing]] -> 1955.6175 | O5: E & C
A6: 3 | B6: LP-1573 | C6: 3 Cube | D6: 21 | E6: 21 | F6: 2356 | G6: 869 | H6: =IF(COUNTIF(Sheet1!$C$13:$C$530,Table44[[#This Row],[Vehicle No]])>0,_xlfn.XLOOKUP(Table44[[#This Row],[Vehicle No]],Sheet1!$C$13:$C$530,Sheet1!$K$13:$K$530,"",0),_xlfn.XLOOKUP(Table44[[#This Row],[Vehicle No]],Sheet1!$B$13:$B$530,Sheet1!$K$13:$K$530,"",0)) -> 3.8 | I6: =IF(COUNTIF(Sheet1!$C$13:$C$530,Table44[[#This Row],[Vehicle No]])>0,_xlfn.XLOOKUP(Table44[[#This Row],[Vehicle No]],Sheet1!$C$13:$C$530,Sheet1!$J$13:$J$530,"-",0),_xlfn.XLOOKUP(Table44[[#This Row],[Vehicle No]],Sheet1!$B$13:$B$530,Sheet1!$J$13:$J$530,"-",0)) -> km/L | J6: =IF(Table44[[#This Row],[rate]]=0,"-",IF(Table44[[#This Row],[Rate Unit]]="L/hr",IF(Table44[[#This Row],[Fuel]]=0,"-",Table44[[#This Row],[Fuel]]/Table44[[#This Row],[rate]]),IF(Table44[[#This Row],[Fuel]]=0,"-",Table44[[#This Row],[Fuel]]*Table44[[#This Row],[rate]]))) -> 3302.2 | K6: =F6/G6 -> 2.7111623 | L6: =IF(COUNTIF(Sheet1!$C$13:$C$530,Table44[[#This Row],[Vehicle No]])>0,_xlfn.XLOOKUP(Table44[[#This Row],[Vehicle No]],Sheet1!$C$13:$C$530,Sheet1!$O$13:$O$530,"",0),_xlfn.XLOOKUP(Table44[[#This Row],[Vehicle No]],Sheet1!$B$13:$B$530,Sheet1!$O$13:$O$530,"",0)) -> 130.19211 | M6: =Table44[[#This Row],[RATE HOUR /DAY]]*Table44[[#This Row],[actual days/machine hours]] -> 2734.0342 | N6: =Table44[[#This Row],[RATE HOUR /DAY]]*Table44[[#This Row],[Days/machine hours consider for costing]] -> 2734.0342 | O6: E & C
A7: 4 | B7: LP-1577 | C7: 3 Cube | D7: 19 | E7: 19 | F7: 1807 | G7: 710 | H7: =IF(COUNTIF(Sheet1!$C$13:$C$530,Table44[[#This Row],[Vehicle No]])>0,_xlfn.XLOOKUP(Table44[[#This Row],[Vehicle No]],Sheet1!$C$13:$C$530,Sheet1!$K$13:$K$530,"",0),_xlfn.XLOOKUP(Table44[[#This Row],[Vehicle No]],Sheet1!$B$13:$B$530,Sheet1!$K$13:$K$530,"",0)) -> 3.8 | I7: =IF(COUNTIF(Sheet1!$C$13:$C$530,Table44[[#This Row],[Vehicle No]])>0,_xlfn.XLOOKUP(Table44[[#This Row],[Vehicle No]],Sheet1!$C$13:$C$530,Sheet1!$J$13:$J$530,"-",0),_xlfn.XLOOKUP(Table44[[#This Row],[Vehicle No]],Sheet1!$B$13:$B$530,Sheet1!$J$13:$J$530,"-",0)) -> km/L | J7: =IF(Table44[[#This Row],[rate]]=0,"-",IF(Table44[[#This Row],[Rate Unit]]="L/hr",IF(Table44[[#This Row],[Fuel]]=0,"-",Table44[[#This Row],[Fuel]]/Table44[[#This Row],[rate]]),IF(Table44[[#This Row],[Fuel]]=0,"-",Table44[[#This Row],[Fuel]]*Table44[[#This Row],[rate]]))) -> 2698 | K7: =F7/G7 -> 2.5450704 | L7: =IF(COUNTIF(Sheet1!$C$13:$C$530,Table44[[#This Row],[Vehicle No]])>0,_xlfn.XLOOKUP(Table44[[#This Row],[Vehicle No]],Sheet1!$C$13:$C$530,Sheet1!$O$13:$O$530,"",0),_xlfn.XLOOKUP(Table44[[#This Row],[Vehicle No]],Sheet1!$B$13:$B$530,Sheet1!$O$13:$O$530,"",0)) -> 130.19211 | M7: =Table44[[#This Row],[RATE HOUR /DAY]]*Table44[[#This Row],[actual days/machine hours]] -> 2473.65 | N7: =Table44[[#This Row],[RATE HOUR /DAY]]*Table44[[#This Row],[Days/machine hours consider for costing]] -> 2473.65 | O7: E & C
A8: 5 | B8: LM-5719 | C8: 3 Cube | D8: 8 | E8: 8 | G8: 210 | H8: =IF(COUNTIF(Sheet1!$C$13:$C$530,Table44[[#This Row],[Vehicle No]])>0,_xlfn.XLOOKUP(Table44[[#This Row],[Vehicle No]],Sheet1!$C$13:$C$530,Sheet1!$K$13:$K$530,"",0),_xlfn.XLOOKUP(Table44[[#This Row],[Vehicle No]],Sheet1!$B$13:$B$530,Sheet1!$K$13:$K$530,"",0)) -> 3.8 | I8: =IF(COUNTIF(Sheet1!$C$13:$C$530,Table44[[#This Row],[Vehicle No]])>0,_xlfn.XLOOKUP(Table44[[#This Row],[Vehicle No]],Sheet1!$C$13:$C$530,Sheet1!$J$13:$J$530,"-",0),_xlfn.XLOOKUP(Table44[[#This Row],[Vehicle No]],Sheet1!$B$13:$B$530,Sheet1!$J$13:$J$530,"-",0)) -> km/L | J8: =IF(Table44[[#This Row],[rate]]=0,"-",IF(Table44[[#This Row],[Rate Unit]]="L/hr",IF(Table44[[#This Row],[Fuel]]=0,"-",Table44[[#This Row],[Fuel]]/Table44[[#This Row],[rate]]),IF(Table44[[#This Row],[Fuel]]=0,"-",Table44[[#This Row],[Fuel]]*Table44[[#This Row],[rate]]))) -> 798 | K8: =F8/G8 -> 0 | L8: =IF(COUNTIF(Sheet1!$C$13:$C$530,Table44[[#This Row],[Vehicle No]])>0,_xlfn.XLOOKUP(Table44[[#This Row],[Vehicle No]],Sheet1!$C$13:$C$530,Sheet1!$O$13:$O$530,"",0),_xlfn.XLOOKUP(Table44[[#This Row],[Vehicle No]],Sheet1!$B$13:$B$530,Sheet1!$O$13:$O$530,"",0)) -> 134.59474 | M8: =Table44[[#This Row],[RATE HOUR /DAY]]*Table44[[#This Row],[actual days/machine hours]] -> 1076.7579 | N8: =Table44[[#This Row],[RATE HOUR /DAY]]*Table44[[#This Row],[Days/machine hours consider for costing]] -> 1076.7579 | O8: E & C
A9: 6 | B9: LM-7940 | C9: 3 Cube | H9: =IF(COUNTIF(Sheet1!$C$13:$C$530,Table44[[#This Row],[Vehicle No]])>0,_xlfn.XLOOKUP(Table44[[#This Row],[Vehicle No]],Sheet1!$C$13:$C$530,Sheet1!$K$13:$K$530,"",0),_xlfn.XLOOKUP(Table44[[#This Row],[Vehicle No]],Sheet1!$B$13:$B$530,Sheet1!$K$13:$K$530,"",0)) -> 3.8 | I9: =IF(COUNTIF(Sheet1!$C$13:$C$530,Table44[[#This Row],[Vehicle No]])>0,_xlfn.XLOOKUP(Table44[[#This Row],[Vehicle No]],Sheet1!$C$13:$C$530,Sheet1!$J$13:$J$530,"-",0),_xlfn.XLOOKUP(Table44[[#This Row],[Vehicle No]],Sheet1!$B$13:$B$530,Sheet1!$J$13:$J$530,"-",0)) -> km/L | J9: =IF(Table44[[#This Row],[rate]]=0,"-",IF(Table44[[#This Row],[Rate Unit]]="L/hr",IF(Table44[[#This Row],[Fuel]]=0,"-",Table44[[#This Row],[Fuel]]/Table44[[#This Row],[rate]]),IF(Table44[[#This Row],[Fuel]]=0,"-",Table44[[#This Row],[Fuel]]*Table44[[#This Row],[rate]]))) -> - | K9: =F9/G9 -> #DIV/0! | L9: =IF(COUNTIF(Sheet1!$C$13:$C$530,Table44[[#This Row],[Vehicle No]])>0,_xlfn.XLOOKUP(Table44[[#This Row],[Vehicle No]],Sheet1!$C$13:$C$530,Sheet1!$O$13:$O$530,"",0),_xlfn.XLOOKUP(Table44[[#This Row],[Vehicle No]],Sheet1!$B$13:$B$530,Sheet1!$O$13:$O$530,"",0)) -> 134.59474 | M9: =Table44[[#This Row],[RATE HOUR /DAY]]*Table44[[#This Row],[actual days/machine hours]] -> 0 | N9: =Table44[[#This Row],[RATE HOUR /DAY]]*Table44[[#This Row],[Days/machine hours consider for costing]] -> 0 | O9: E & C
A10: 7 | B10: LM-7948 | C10: 3 Cube | D10: 5 | E10: 5 | G10: 50 | H10: =IF(COUNTIF(Sheet1!$C$13:$C$530,Table44[[#This Row],[Vehicle No]])>0,_xlfn.XLOOKUP(Table44[[#This Row],[Vehicle No]],Sheet1!$C$13:$C$530,Sheet1!$K$13:$K$530,"",0),_xlfn.XLOOKUP(Table44[[#This Row],[Vehicle No]],Sheet1!$B$13:$B$530,Sheet1!$K$13:$K$530,"",0)) -> 3.8 | I10: =IF(COUNTIF(Sheet1!$C$13:$C$530,Table44[[#This Row],[Vehicle No]])>0,_xlfn.XLOOKUP(Table44[[#This Row],[Vehicle No]],Sheet1!$C$13:$C$530,Sheet1!$J$13:$J$530,"-",0),_xlfn.XLOOKUP(Table44[[#This Row],[Vehicle No]],Sheet1!$B$13:$B$530,Sheet1!$J$13:$J$530,"-",0)) -> km/L | J10: =IF(Table44[[#This Row],[rate]]=0,"-",IF(Table44[[#This Row],[Rate Unit]]="L/hr",IF(Table44[[#This Row],[Fuel]]=0,"-",Table44[[#This Row],[Fuel]]/Table44[[#This Row],[rate]]),IF(Table44[[#This Row],[Fuel]]=0,"-",Table44[[#This Row],[Fuel]]*Table44[[#This Row],[rate]]))) -> 190 | K10: =F10/G10 -> 0 | L10: =IF(COUNTIF(Sheet1!$C$13:$C$530,Table44[[#This Row],[Vehicle No]])>0,_xlfn.XLOOKUP(Table44[[#This Row],[Vehicle No]],Sheet1!$C$13:$C$530,Sheet1!$O$13:$O$530,"",0),_xlfn.XLOOKUP(Table44[[#This Row],[Vehicle No]],Sheet1!$B$13:$B$530,Sheet1!$O$13:$O$530,"",0)) -> 134.59474 | M10: =Table44[[#This Row],[RATE HOUR /DAY]]*Table44[[#This Row],[actual days/machine hours]] -> 672.97368 | N10: =Table44[[#This Row],[RATE HOUR /DAY]]*Table44[[#This Row],[Days/machine hours consider for costing]] -> 672.97368 | O10: E & C
A11: 8 | B11: LO-5983 | C11: 3 Cube | D11: 23 | E11: 23 | G11: 605 | H11: =IF(COUNTIF(Sheet1!$C$13:$C$530,Table44[[#This Row],[Vehicle No]])>0,_xlfn.XLOOKUP(Table44[[#This Row],[Vehicle No]],Sheet1!$C$13:$C$530,Sheet1!$K$13:$K$530,"",0),_xlfn.XLOOKUP(Table44[[#This Row],[Vehicle No]],Sheet1!$B$13:$B$530,Sheet1!$K$13:$K$530,"",0)) -> 3.8 | I11: =IF(COUNTIF(Sheet1!$C$13:$C$530,Table44[[#This Row],[Vehicle No]])>0,_xlfn.XLOOKUP(Table44[[#This Row],[Vehicle No]],Sheet1!$C$13:$C$530,Sheet1!$J$13:$J$530,"-",0),_xlfn.XLOOKUP(Table44[[#This Row],[Vehicle No]],Sheet1!$B$13:$B$530,Sheet1!$J$13:$J$530,"-",0)) -> km/L | J11: =IF(Table44[[#This Row],[rate]]=0,"-",IF(Table44[[#This Row],[Rate Unit]]="L/hr",IF(Table44[[#This Row],[Fuel]]=0,"-",Table44[[#This Row],[Fuel]]/Table44[[#This Row],[rate]]),IF(Table44[[#This Row],[Fuel]]=0,"-",Table44[[#This Row],[Fuel]]*Table44[[#This Row],[rate]]))) -> 2299 | K11: =F11/G11 -> 0 | L11: =IF(COUNTIF(Sheet1!$C$13:$C$530,Table44[[#This Row],[Vehicle No]])>0,_xlfn.XLOOKUP(Table44[[#This Row],[Vehicle No]],Sheet1!$C$13:$C$530,Sheet1!$O$13:$O$530,"",0),_xlfn.XLOOKUP(Table44[[#This Row],[Vehicle No]],Sheet1!$B$13:$B$530,Sheet1!$O$13:$O$530,"",0)) -> 134.59474 | M11: =Table44[[#This Row],[RATE HOUR /DAY]]*Table44[[#This Row],[actual days/machine hours]] -> 3095.6789 | N11: =Table44[[#This Row],[RATE HOUR /DAY]]*Table44[[#This Row],[Days/machine hours consider for costing]] -> 3095.6789 | O11: E & C
A12: 9 | B12: LO-7182 | C12: 3 Cube | D12: 26 | E12: 26 | G12: 810 | H12: =IF(COUNTIF(Sheet1!$C$13:$C$530,Table44[[#This Row],[Vehicle No]])>0,_xlfn.XLOOKUP(Table44[[#This Row],[Vehicle No]],Sheet1!$C$13:$C$530,Sheet1!$K$13:$K$530,"",0),_xlfn.XLOOKUP(Table44[[#This Row],[Vehicle No]],Sheet1!$B$13:$B$530,Sheet1!$K$13:$K$530,"",0)) -> 3.8 | I12: =IF(COUNTIF(Sheet1!$C$13:$C$530,Table44[[#This Row],[Vehicle No]])>0,_xlfn.XLOOKUP(Table44[[#This Row],[Vehicle No]],Sheet1!$C$13:$C$530,Sheet1!$J$13:$J$530,"-",0),_xlfn.XLOOKUP(Table44[[#This Row],[Vehicle No]],Sheet1!$B$13:$B$530,Sheet1!$J$13:$J$530,"-",0)) -> km/L | J12: =IF(Table44[[#This Row],[rate]]=0,"-",IF(Table44[[#This Row],[Rate Unit]]="L/hr",IF(Table44[[#This Row],[Fuel]]=0,"-",Table44[[#This Row],[Fuel]]/Table44[[#This Row],[rate]]),IF(Table44[[#This Row],[Fuel]]=0,"-",Table44[[#This Row],[Fuel]]*Table44[[#This Row],[rate]]))) -> 3078 | K12: =F12/G12 -> 0 | L12: =IF(COUNTIF(Sheet1!$C$13:$C$530,Table44[[#This Row],[Vehicle No]])>0,_xlfn.XLOOKUP(Table44[[#This Row],[Vehicle No]],Sheet1!$C$13:$C$530,Sheet1!$O$13:$O$530,"",0),_xlfn.XLOOKUP(Table44[[#This Row],[Vehicle No]],Sheet1!$B$13:$B$530,Sheet1!$O$13:$O$530,"",0)) -> 132.83368 | M12: =Table44[[#This Row],[RATE HOUR /DAY]]*Table44[[#This Row],[actual days/machine hours]] -> 3453.6758 | N12: =Table44[[#This Row],[RATE HOUR /DAY]]*Table44[[#This Row],[Days/machine hours consider for costing]] -> 3453.6758 | O12: E & C
A13: 10 | B13: LO-7183 | C13: 3 Cube | H13: =IF(COUNTIF(Sheet1!$C$13:$C$530,Table44[[#This Row],[Vehicle No]])>0,_xlfn.XLOOKUP(Table44[[#This Row],[Vehicle No]],Sheet1!$C$13:$C$530,Sheet1!$K$13:$K$530,"",0),_xlfn.XLOOKUP(Table44[[#This Row],[Vehicle No]],Sheet1!$B$13:$B$530,Sheet1!$K$13:$K$530,"",0)) -> 3.8 | I13: =IF(COUNTIF(Sheet1!$C$13:$C$530,Table44[[#This Row],[Vehicle No]])>0,_xlfn.XLOOKUP(Table44[[#This Row],[Vehicle No]],Sheet1!$C$13:$C$530,Sheet1!$J$13:$J$530,"-",0),_xlfn.XLOOKUP(Table44[[#This Row],[Vehicle No]],Sheet1!$B$13:$B$530,Sheet1!$J$13:$J$530,"-",0)) -> km/L | J13: =IF(Table44[[#This Row],[rate]]=0,"-",IF(Table44[[#This Row],[Rate Unit]]="L/hr",IF(Table44[[#This Row],[Fuel]]=0,"-",Table44[[#This Row],[Fuel]]/Table44[[#This Row],[rate]]),IF(Table44[[#This Row],[Fuel]]=0,"-",Table44[[#This Row],[Fuel]]*Table44[[#This Row],[rate]]))) -> - | L13: =IF(COUNTIF(Sheet1!$C$13:$C$530,Table44[[#This Row],[Vehicle No]])>0,_xlfn.XLOOKUP(Table44[[#This Row],[Vehicle No]],Sheet1!$C$13:$C$530,Sheet1!$O$13:$O$530,"",0),_xlfn.XLOOKUP(Table44[[#This Row],[Vehicle No]],Sheet1!$B$13:$B$530,Sheet1!$O$13:$O$530,"",0)) -> 132.83368 | M13: =Table44[[#This Row],[RATE HOUR /DAY]]*Table44[[#This Row],[actual days/machine hours]] -> 0 | N13: =Table44[[#This Row],[RATE HOUR /DAY]]*Table44[[#This Row],[Days/machine hours consider for costing]] -> 0
A14: 11 | B14: LN-8277 | C14: Boom Truck | D14: 20 | E14: 20 | F14: 2041 | G14: 830 | H14: =IF(COUNTIF(Sheet1!$C$13:$C$530,Table44[[#This Row],[Vehicle No]])>0,_xlfn.XLOOKUP(Table44[[#This Row],[Vehicle No]],Sheet1!$C$13:$C$530,Sheet1!$K$13:$K$530,"",0),_xlfn.XLOOKUP(Table44[[#This Row],[Vehicle No]],Sheet1!$B$13:$B$530,Sheet1!$K$13:$K$530,"",0)) -> 7.2 | I14: =IF(COUNTIF(Sheet1!$C$13:$C$530,Table44[[#This Row],[Vehicle No]])>0,_xlfn.XLOOKUP(Table44[[#This Row],[Vehicle No]],Sheet1!$C$13:$C$530,Sheet1!$J$13:$J$530,"-",0),_xlfn.XLOOKUP(Table44[[#This Row],[Vehicle No]],Sheet1!$B$13:$B$530,Sheet1!$J$13:$J$530,"-",0)) -> L/hr | J14: =IF(Table44[[#This Row],[rate]]=0,"-",IF(Table44[[#This Row],[Rate Unit]]="L/hr",IF(Table44[[#This Row],[Fuel]]=0,"-",Table44[[#This Row],[Fuel]]/Table44[[#This Row],[rate]]),IF(Table44[[#This Row],[Fuel]]=0,"-",Table44[[#This Row],[Fuel]]*Table44[[#This Row],[rate]]))) -> 115.27778 | K14: =F14/G14 -> 2.4590361 | L14: =IF(COUNTIF(Sheet1!$C$13:$C$530,Table44[[#This Row],[Vehicle No]])>0,_xlfn.XLOOKUP(Table44[[#This Row],[Vehicle No]],Sheet1!$C$13:$C$530,Sheet1!$O$13:$O$530,"",0),_xlfn.XLOOKUP(Table44[[#This Row],[Vehicle No]],Sheet1!$B$13:$B$530,Sheet1!$O$13:$O$530,"",0)) -> 3947.5152 | M14: =Table44[[#This Row],[RATE HOUR /DAY]]*Table44[[#This Row],[actual days/machine hours]] -> 78950.304 | N14: =Table44[[#This Row],[RATE HOUR /DAY]]*Table44[[#This Row],[Days/machine hours consider for costing]] -> 78950.304 | O14: E & C
A15: 12 | B15: HEX-01 | C15: Volvo 220 | D15: 95.8 | E15: 95.8 | G15: 1145 | H15: =IF(COUNTIF(Sheet1!$C$13:$C$530,Table44[[#This Row],[Vehicle No]])>0,_xlfn.XLOOKUP(Table44[[#This Row],[Vehicle No]],Sheet1!$C$13:$C$530,Sheet1!$K$13:$K$530,"",0),_xlfn.XLOOKUP(Table44[[#This Row],[Vehicle No]],Sheet1!$B$13:$B$530,Sheet1!$K$13:$K$530,"",0)) -> 11.5 | I15: =IF(COUNTIF(Sheet1!$C$13:$C$530,Table44[[#This Row],[Vehicle No]])>0,_xlfn.XLOOKUP(Table44[[#This Row],[Vehicle No]],Sheet1!$C$13:$C$530,Sheet1!$J$13:$J$530,"-",0),_xlfn.XLOOKUP(Table44[[#This Row],[Vehicle No]],Sheet1!$B$13:$B$530,Sheet1!$J$13:$J$530,"-",0)) -> L/hr | J15: =IF(Table44[[#This Row],[rate]]=0,"-",IF(Table44[[#This Row],[Rate Unit]]="L/hr",IF(Table44[[#This Row],[Fuel]]=0,"-",Table44[[#This Row],[Fuel]]/Table44[[#This Row],[rate]]),IF(Table44[[#This Row],[Fuel]]=0,"-",Table44[[#This Row],[Fuel]]*Table44[[#This Row],[rate]]))) -> 99.565217 | K15: =Table44[[#This Row],[Fuel]]/Table44[[#This Row],[actual days/machine hours]] -> 11.951983 | L15: =IF(COUNTIF(Sheet1!$C$13:$C$530,Table44[[#This Row],[Vehicle No]])>0,_xlfn.XLOOKUP(Table44[[#This Row],[Vehicle No]],Sheet1!$C$13:$C$530,Sheet1!$O$13:$O$530,"",0),_xlfn.XLOOKUP(Table44[[#This Row],[Vehicle No]],Sheet1!$B$13:$B$530,Sheet1!$O$13:$O$530,"",0)) -> 5997.227 | M15: =Table44[[#This Row],[RATE HOUR /DAY]]*Table44[[#This Row],[actual days/machine hours]] -> 574534.35 | N15: =Table44[[#This Row],[RATE HOUR /DAY]]*Table44[[#This Row],[Days/machine hours consider for costing]] -> 574534.35 | O15: E & C
A16: 13 | B16: HEX-19 | C16: Komatsu 120 | D16: 126.9 | E16: 126.9 | G16: 855 | H16: =IF(COUNTIF(Sheet1!$C$13:$C$530,Table44[[#This Row],[Vehicle No]])>0,_xlfn.XLOOKUP(Table44[[#This Row],[Vehicle No]],Sheet1!$C$13:$C$530,Sheet1!$K$13:$K$530,"",0),_xlfn.XLOOKUP(Table44[[#This Row],[Vehicle No]],Sheet1!$B$13:$B$530,Sheet1!$K$13:$K$530,"",0)) -> 7.2 | I16: =IF(COUNTIF(Sheet1!$C$13:$C$530,Table44[[#This Row],[Vehicle No]])>0,_xlfn.XLOOKUP(Table44[[#This Row],[Vehicle No]],Sheet1!$C$13:$C$530,Sheet1!$J$13:$J$530,"-",0),_xlfn.XLOOKUP(Table44[[#This Row],[Vehicle No]],Sheet1!$B$13:$B$530,Sheet1!$J$13:$J$530,"-",0)) -> L/hr | J16: =IF(Table44[[#This Row],[rate]]=0,"-",IF(Table44[[#This Row],[Rate Unit]]="L/hr",IF(Table44[[#This Row],[Fuel]]=0,"-",Table44[[#This Row],[Fuel]]/Table44[[#This Row],[rate]]),IF(Table44[[#This Row],[Fuel]]=0,"-",Table44[[#This Row],[Fuel]]*Table44[[#This Row],[rate]]))) -> 118.75 | K16: =Table44[[#This Row],[Fuel]]/Table44[[#This Row],[actual days/machine hours]] -> 6.7375887 | L16: =IF(COUNTIF(Sheet1!$C$13:$C$530,Table44[[#This Row],[Vehicle No]])>0,_xlfn.XLOOKUP(Table44[[#This Row],[Vehicle No]],Sheet1!$C$13:$C$530,Sheet1!$O$13:$O$530,"",0),_xlfn.XLOOKUP(Table44[[#This Row],[Vehicle No]],Sheet1!$B$13:$B$530,Sheet1!$O$13:$O$530,"",0)) -> 3851.1504 | M16: =Table44[[#This Row],[RATE HOUR /DAY]]*Table44[[#This Row],[actual days/machine hours]] -> 488710.99 | N16: =Table44[[#This Row],[RATE HOUR /DAY]]*Table44[[#This Row],[Days/machine hours consider for costing]] -> 488710.99 | O16: E & C
B17: HEX-42 | C17: Case 220 | D17: 43.9 | E17: 43.9 | G17: 570 | H17: =IF(COUNTIF(Sheet1!$C$13:$C$530,Table44[[#This Row],[Vehicle No]])>0,_xlfn.XLOOKUP(Table44[[#This Row],[Vehicle No]],Sheet1!$C$13:$C$530,Sheet1!$K$13:$K$530,"",0),_xlfn.XLOOKUP(Table44[[#This Row],[Vehicle No]],Sheet1!$B$13:$B$530,Sheet1!$K$13:$K$530,"",0)) -> 11.5 | I17: =IF(COUNTIF(Sheet1!$C$13:$C$530,Table44[[#This Row],[Vehicle No]])>0,_xlfn.XLOOKUP(Table44[[#This Row],[Vehicle No]],Sheet1!$C$13:$C$530,Sheet1!$J$13:$J$530,"-",0),_xlfn.XLOOKUP(Table44[[#This Row],[Vehicle No]],Sheet1!$B$13:$B$530,Sheet1!$J$13:$J$530,"-",0)) -> L/hr | J17: =IF(Table44[[#This Row],[rate]]=0,"-",IF(Table44[[#This Row],[Rate Unit]]="L/hr",IF(Table44[[#This Row],[Fuel]]=0,"-",Table44[[#This Row],[Fuel]]/Table44[[#This Row],[rate]]),IF(Table44[[#This Row],[Fuel]]=0,"-",Table44[[#This Row],[Fuel]]*Table44[[#This Row],[rate]]))) -> 49.565217 | K17: =Table44[[#This Row],[Fuel]]/Table44[[#This Row],[actual days/machine hours]] -> 12.984055 | L17: =IF(COUNTIF(Sheet1!$C$13:$C$530,Table44[[#This Row],[Vehicle No]])>0,_xlfn.XLOOKUP(Table44[[#This Row],[Vehicle No]],Sheet1!$C$13:$C$530,Sheet1!$O$13:$O$530,"",0),_xlfn.XLOOKUP(Table44[[#This Row],[Vehicle No]],Sheet1!$B$13:$B$530,Sheet1!$O$13:$O$530,"",0)) -> 5689.395 | M17: =Table44[[#This Row],[RATE HOUR /DAY]]*Table44[[#This Row],[actual days/machine hours]] -> 249764.44 | N17: =Table44[[#This Row],[RATE HOUR /DAY]]*Table44[[#This Row],[Days/machine hours consider for costing]] -> 249764.44
A18: 14 | B18: 51-8083 | C18: D/Cab | D18: 23 | E18: 23 | G18: 616 | H18: =IF(COUNTIF(Sheet1!$C$13:$C$530,Table44[[#This Row],[Vehicle No]])>0,_xlfn.XLOOKUP(Table44[[#This Row],[Vehicle No]],Sheet1!$C$13:$C$530,Sheet1!$K$13:$K$530,"",0),_xlfn.XLOOKUP(Table44[[#This Row],[Vehicle No]],Sheet1!$B$13:$B$530,Sheet1!$K$13:$K$530,"",0)) -> 12.8 | I18: =IF(COUNTIF(Sheet1!$C$13:$C$530,Table44[[#This Row],[Vehicle No]])>0,_xlfn.XLOOKUP(Table44[[#This Row],[Vehicle No]],Sheet1!$C$13:$C$530,Sheet1!$J$13:$J$530,"-",0),_xlfn.XLOOKUP(Table44[[#This Row],[Vehicle No]],Sheet1!$B$13:$B$530,Sheet1!$J$13:$J$530,"-",0)) -> km/L | J18: =IF(Table44[[#This Row],[rate]]=0,"-",IF(Table44[[#This Row],[Rate Unit]]="L/hr",IF(Table44[[#This Row],[Fuel]]=0,"-",Table44[[#This Row],[Fuel]]/Table44[[#This Row],[rate]]),IF(Table44[[#This Row],[Fuel]]=0,"-",Table44[[#This Row],[Fuel]]*Table44[[#This Row],[rate]]))) -> 7884.8 | K18: =F18/G18 -> 0 | L18: =IF(COUNTIF(Sheet1!$C$13:$C$530,Table44[[#This Row],[Vehicle No]])>0,_xlfn.XLOOKUP(Table44[[#This Row],[Vehicle No]],Sheet1!$C$13:$C$530,Sheet1!$O$13:$O$530,"",0),_xlfn.XLOOKUP(Table44[[#This Row],[Vehicle No]],Sheet1!$B$13:$B$530,Sheet1!$O$13:$O$530,"",0)) -> 37.34375 | M18: =Table44[[#This Row],[RATE HOUR /DAY]]*Table44[[#This Row],[actual days/machine hours]] -> 858.90625 | N18: =Table44[[#This Row],[RATE HOUR /DAY]]*Table44[[#This Row],[Days/machine hours consider for costing]] -> 858.90625 | O18: E & C
B19: DAH-2230 | C19: S/Cab | D19: 8 | E19: 8 | F19: 859 | G19: 114 | H19: =IF(COUNTIF(Sheet1!$C$13:$C$530,Table44[[#This Row],[Vehicle No]])>0,_xlfn.XLOOKUP(Table44[[#This Row],[Vehicle No]],Sheet1!$C$13:$C$530,Sheet1!$K$13:$K$530,"",0),_xlfn.XLOOKUP(Table44[[#This Row],[Vehicle No]],Sheet1!$B$13:$B$530,Sheet1!$K$13:$K$530,"",0)) -> 14.1 | I19: =IF(COUNTIF(Sheet1!$C$13:$C$530,Table44[[#This Row],[Vehicle No]])>0,_xlfn.XLOOKUP(Table44[[#This Row],[Vehicle No]],Sheet1!$C$13:$C$530,Sheet1!$J$13:$J$530,"-",0),_xlfn.XLOOKUP(Table44[[#This Row],[Vehicle No]],Sheet1!$B$13:$B$530,Sheet1!$J$13:$J$530,"-",0)) -> km/L | J19: =IF(Table44[[#This Row],[rate]]=0,"-",IF(Table44[[#This Row],[Rate Unit]]="L/hr",IF(Table44[[#This Row],[Fuel]]=0,"-",Table44[[#This Row],[Fuel]]/Table44[[#This Row],[rate]]),IF(Table44[[#This Row],[Fuel]]=0,"-",Table44[[#This Row],[Fuel]]*Table44[[#This Row],[rate]]))) -> 1607.4 | L19: =IF(COUNTIF(Sheet1!$C$13:$C$530,Table44[[#This Row],[Vehicle No]])>0,_xlfn.XLOOKUP(Table44[[#This Row],[Vehicle No]],Sheet1!$C$13:$C$530,Sheet1!$O$13:$O$530,"",0),_xlfn.XLOOKUP(Table44[[#This Row],[Vehicle No]],Sheet1!$B$13:$B$530,Sheet1!$O$13:$O$530,"",0)) -> 35.561844 | M19: =Table44[[#This Row],[RATE HOUR /DAY]]*Table44[[#This Row],[actual days/machine hours]] -> 284.49475 | N19: =Table44[[#This Row],[RATE HOUR /DAY]]*Table44[[#This Row],[Days/machine hours consider for costing]] -> 284.49475
A20: 15 | B20: PT-1569 | C20: S/Cab | D20: 10 | E20: 10 | G20: 144 | H20: =IF(COUNTIF(Sheet1!$C$13:$C$530,Table44[[#This Row],[Vehicle No]])>0,_xlfn.XLOOKUP(Table44[[#This Row],[Vehicle No]],Sheet1!$C$13:$C$530,Sheet1!$K$13:$K$530,"",0),_xlfn.XLOOKUP(Table44[[#This Row],[Vehicle No]],Sheet1!$B$13:$B$530,Sheet1!$K$13:$K$530,"",0)) -> 14.1 | I20: =IF(COUNTIF(Sheet1!$C$13:$C$530,Table44[[#This Row],[Vehicle No]])>0,_xlfn.XLOOKUP(Table44[[#This Row],[Vehicle No]],Sheet1!$C$13:$C$530,Sheet1!$J$13:$J$530,"-",0),_xlfn.XLOOKUP(Table44[[#This Row],[Vehicle No]],Sheet1!$B$13:$B$530,Sheet1!$J$13:$J$530,"-",0)) -> km/L | J20: =IF(Table44[[#This Row],[rate]]=0,"-",IF(Table44[[#This Row],[Rate Unit]]="L/hr",IF(Table44[[#This Row],[Fuel]]=0,"-",Table44[[#This Row],[Fuel]]/Table44[[#This Row],[rate]]),IF(Table44[[#This Row],[Fuel]]=0,"-",Table44[[#This Row],[Fuel]]*Table44[[#This Row],[rate]]))) -> 2030.4 | L20: =IF(COUNTIF(Sheet1!$C$13:$C$530,Table44[[#This Row],[Vehicle No]])>0,_xlfn.XLOOKUP(Table44[[#This Row],[Vehicle No]],Sheet1!$C$13:$C$530,Sheet1!$O$13:$O$530,"",0),_xlfn.XLOOKUP(Table44[[#This Row],[Vehicle No]],Sheet1!$B$13:$B$530,Sheet1!$O$13:$O$530,"",0)) -> 37.222979 | M20: =Table44[[#This Row],[RATE HOUR /DAY]]*Table44[[#This Row],[actual days/machine hours]] -> 372.22979 | N20: =Table44[[#This Row],[RATE HOUR /DAY]]*Table44[[#This Row],[Days/machine hours consider for costing]] -> 372.22979
A21: 16 | B21: PH-6742 | C21: C/Cab | H21: =IF(COUNTIF(Sheet1!$C$13:$C$530,Table44[[#This Row],[Vehicle No]])>0,_xlfn.XLOOKUP(Table44[[#This Row],[Vehicle No]],Sheet1!$C$13:$C$530,Sheet1!$K$13:$K$530,"",0),_xlfn.XLOOKUP(Table44[[#This Row],[Vehicle No]],Sheet1!$B$13:$B$530,Sheet1!$K$13:$K$530,"",0)) -> 12.8 | I21: =IF(COUNTIF(Sheet1!$C$13:$C$530,Table44[[#This Row],[Vehicle No]])>0,_xlfn.XLOOKUP(Table44[[#This Row],[Vehicle No]],Sheet1!$C$13:$C$530,Sheet1!$J$13:$J$530,"-",0),_xlfn.XLOOKUP(Table44[[#This Row],[Vehicle No]],Sheet1!$B$13:$B$530,Sheet1!$J$13:$J$530,"-",0)) -> km/L | J21: =IF(Table44[[#This Row],[rate]]=0,"-",IF(Table44[[#This Row],[Rate Unit]]="L/hr",IF(Table44[[#This Row],[Fuel]]=0,"-",Table44[[#This Row],[Fuel]]/Table44[[#This Row],[rate]]),IF(Table44[[#This Row],[Fuel]]=0,"-",Table44[[#This Row],[Fuel]]*Table44[[#This Row],[rate]]))) -> - | K21: =F21/G21 -> #DIV/0! | L21: =IF(COUNTIF(Sheet1!$C$13:$C$530,Table44[[#This Row],[Vehicle No]])>0,_xlfn.XLOOKUP(Table44[[#This Row],[Vehicle No]],Sheet1!$C$13:$C$530,Sheet1!$O$13:$O$530,"",0),_xlfn.XLOOKUP(Table44[[#This Row],[Vehicle No]],Sheet1!$B$13:$B$530,Sheet1!$O$13:$O$530,"",0)) -> 39.957813 | M21: =Table44[[#This Row],[RATE HOUR /DAY]]*Table44[[#This Row],[actual days/machine hours]] -> 0 | N21: =Table44[[#This Row],[RATE HOUR /DAY]]*Table44[[#This Row],[Days/machine hours consider for costing]] -> 0 | O21: E & C
A22: 17 | B22: 325-3448 | C22: C/Cab | H22: =IF(COUNTIF(Sheet1!$C$13:$C$530,Table44[[#This Row],[Vehicle No]])>0,_xlfn.XLOOKUP(Table44[[#This Row],[Vehicle No]],Sheet1!$C$13:$C$530,Sheet1!$K$13:$K$530,"",0),_xlfn.XLOOKUP(Table44[[#This Row],[Vehicle No]],Sheet1!$B$13:$B$530,Sheet1!$K$13:$K$530,"",0)) -> 12.8 | I22: =IF(COUNTIF(Sheet1!$C$13:$C$530,Table44[[#This Row],[Vehicle No]])>0,_xlfn.XLOOKUP(Table44[[#This Row],[Vehicle No]],Sheet1!$C$13:$C$530,Sheet1!$J$13:$J$530,"-",0),_xlfn.XLOOKUP(Table44[[#This Row],[Vehicle No]],Sheet1!$B$13:$B$530,Sheet1!$J$13:$J$530,"-",0)) -> km/L | J22: =IF(Table44[[#This Row],[rate]]=0,"-",IF(Table44[[#This Row],[Rate Unit]]="L/hr",IF(Table44[[#This Row],[Fuel]]=0,"-",Table44[[#This Row],[Fuel]]/Table44[[#This Row],[rate]]),IF(Table44[[#This Row],[Fuel]]=0,"-",Table44[[#This Row],[Fuel]]*Table44[[#This Row],[rate]]))) -> - | K22: =F22/G22 -> #DIV/0! | L22: =IF(COUNTIF(Sheet1!$C$13:$C$530,Table44[[#This Row],[Vehicle No]])>0,_xlfn.XLOOKUP(Table44[[#This Row],[Vehicle No]],Sheet1!$C$13:$C$530,Sheet1!$O$13:$O$530,"",0),_xlfn.XLOOKUP(Table44[[#This Row],[Vehicle No]],Sheet1!$B$13:$B$530,Sheet1!$O$13:$O$530,"",0)) -> 43.878906 | M22: =Table44[[#This Row],[RATE HOUR /DAY]]*Table44[[#This Row],[actual days/machine hours]] -> 0 | N22: =Table44[[#This Row],[RATE HOUR /DAY]]*Table44[[#This Row],[Days/machine hours consider for costing]] -> 0 | O22: E & C
A23: 18 | B23: PD-6917 | C23: D/Cab | H23: =IF(COUNTIF(Sheet1!$C$13:$C$530,Table44[[#This Row],[Vehicle No]])>0,_xlfn.XLOOKUP(Table44[[#This Row],[Vehicle No]],Sheet1!$C$13:$C$530,Sheet1!$K$13:$K$530,"",0),_xlfn.XLOOKUP(Table44[[#This Row],[Vehicle No]],Sheet1!$B$13:$B$530,Sheet1!$K$13:$K$530,"",0)) -> 12.8 | I23: =IF(COUNTIF(Sheet1!$C$13:$C$530,Table44[[#This Row],[Vehicle No]])>0,_xlfn.XLOOKUP(Table44[[#This Row],[Vehicle No]],Sheet1!$C$13:$C$530,Sheet1!$J$13:$J$530,"-",0),_xlfn.XLOOKUP(Table44[[#This Row],[Vehicle No]],Sheet1!$B$13:$B$530,Sheet1!$J$13:$J$530,"-",0)) -> km/L | J23: =IF(Table44[[#This Row],[rate]]=0,"-",IF(Table44[[#This Row],[Rate Unit]]="L/hr",IF(Table44[[#This Row],[Fuel]]=0,"-",Table44[[#This Row],[Fuel]]/Table44[[#This Row],[rate]]),IF(Table44[[#This Row],[Fuel]]=0,"-",Table44[[#This Row],[Fuel]]*Table44[[#This Row],[rate]]))) -> - | K23: =F23/G23 -> #DIV/0! | L23: =IF(COUNTIF(Sheet1!$C$13:$C$530,Table44[[#This Row],[Vehicle No]])>0,_xlfn.XLOOKUP(Table44[[#This Row],[Vehicle No]],Sheet1!$C$13:$C$530,Sheet1!$O$13:$O$530,"",0),_xlfn.XLOOKUP(Table44[[#This Row],[Vehicle No]],Sheet1!$B$13:$B$530,Sheet1!$O$13:$O$530,"",0)) -> 41.264844 | M23: =Table44[[#This Row],[RATE HOUR /DAY]]*Table44[[#This Row],[actual days/machine hours]] -> 0 | N23: =Table44[[#This Row],[RATE HOUR /DAY]]*Table44[[#This Row],[Days/machine hours consider for costing]] -> 0 | O23: E & C
A24: 19 | B24: MG-06 | C24: Motor Grader | D24: 87.8 | E24: 87.8 | G24: 830 | H24: =IF(COUNTIF(Sheet1!$C$13:$C$530,Table44[[#This Row],[Vehicle No]])>0,_xlfn.XLOOKUP(Table44[[#This Row],[Vehicle No]],Sheet1!$C$13:$C$530,Sheet1!$K$13:$K$530,"",0),_xlfn.XLOOKUP(Table44[[#This Row],[Vehicle No]],Sheet1!$B$13:$B$530,Sheet1!$K$13:$K$530,"",0)) -> 13 | I24: =IF(COUNTIF(Sheet1!$C$13:$C$530,Table44[[#This Row],[Vehicle No]])>0,_xlfn.XLOOKUP(Table44[[#This Row],[Vehicle No]],Sheet1!$C$13:$C$530,Sheet1!$J$13:$J$530,"-",0),_xlfn.XLOOKUP(Table44[[#This Row],[Vehicle No]],Sheet1!$B$13:$B$530,Sheet1!$J$13:$J$530,"-",0)) -> L/hr | J24: =IF(Table44[[#This Row],[rate]]=0,"-",IF(Table44[[#This Row],[Rate Unit]]="L/hr",IF(Table44[[#This Row],[Fuel]]=0,"-",Table44[[#This Row],[Fuel]]/Table44[[#This Row],[rate]]),IF(Table44[[#This Row],[Fuel]]=0,"-",Table44[[#This Row],[Fuel]]*Table44[[#This Row],[rate]]))) -> 63.846154 | K24: =Table44[[#This Row],[Fuel]]/Table44[[#This Row],[actual days/machine hours]] -> 9.453303 | L24: =IF(COUNTIF(Sheet1!$C$13:$C$530,Table44[[#This Row],[Vehicle No]])>0,_xlfn.XLOOKUP(Table44[[#This Row],[Vehicle No]],Sheet1!$C$13:$C$530,Sheet1!$O$13:$O$530,"",0),_xlfn.XLOOKUP(Table44[[#This Row],[Vehicle No]],Sheet1!$B$13:$B$530,Sheet1!$O$13:$O$530,"",0)) -> 6214 | M24: =Table44[[#This Row],[RATE HOUR /DAY]]*Table44[[#This Row],[actual days/machine hours]] -> 545589.2 | N24: =Table44[[#This Row],[RATE HOUR /DAY]]*Table44[[#This Row],[Days/machine hours consider for costing]] -> 545589.2 | O24: E & C
A25: 20 | B25: MG-12 | C25: Motor Grader | D25: 16.5 | E25: 16.5 | G25: 200 | H25: =IF(COUNTIF(Sheet1!$C$13:$C$530,Table44[[#This Row],[Vehicle No]])>0,_xlfn.XLOOKUP(Table44[[#This Row],[Vehicle No]],Sheet1!$C$13:$C$530,Sheet1!$K$13:$K$530,"",0),_xlfn.XLOOKUP(Table44[[#This Row],[Vehicle No]],Sheet1!$B$13:$B$530,Sheet1!$K$13:$K$530,"",0)) -> 13 | I25: =IF(COUNTIF(Sheet1!$C$13:$C$530,Table44[[#This Row],[Vehicle No]])>0,_xlfn.XLOOKUP(Table44[[#This Row],[Vehicle No]],Sheet1!$C$13:$C$530,Sheet1!$J$13:$J$530,"-",0),_xlfn.XLOOKUP(Table44[[#This Row],[Vehicle No]],Sheet1!$B$13:$B$530,Sheet1!$J$13:$J$530,"-",0)) -> L/hr | J25: =IF(Table44[[#This Row],[rate]]=0,"-",IF(Table44[[#This Row],[Rate Unit]]="L/hr",IF(Table44[[#This Row],[Fuel]]=0,"-",Table44[[#This Row],[Fuel]]/Table44[[#This Row],[rate]]),IF(Table44[[#This Row],[Fuel]]=0,"-",Table44[[#This Row],[Fuel]]*Table44[[#This Row],[rate]]))) -> 15.384615 | K25: =Table44[[#This Row],[Fuel]]/Table44[[#This Row],[actual days/machine hours]] -> 12.121212 | L25: =IF(COUNTIF(Sheet1!$C$13:$C$530,Table44[[#This Row],[Vehicle No]])>0,_xlfn.XLOOKUP(Table44[[#This Row],[Vehicle No]],Sheet1!$C$13:$C$530,Sheet1!$O$13:$O$530,"",0),_xlfn.XLOOKUP(Table44[[#This Row],[Vehicle No]],Sheet1!$B$13:$B$530,Sheet1!$O$13:$O$530,"",0)) -> 6431.49 | M25: =Table44[[#This Row],[RATE HOUR /DAY]]*Table44[[#This Row],[actual days/machine hours]] -> 106119.58 | N25: =Table44[[#This Row],[RATE HOUR /DAY]]*Table44[[#This Row],[Days/machine hours consider for costing]] -> 106119.58
A26: 21 | B26: ZA-8395 | C26: Crane | H26: =IF(COUNTIF(Sheet1!$C$13:$C$530,Table44[[#This Row],[Vehicle No]])>0,_xlfn.XLOOKUP(Table44[[#This Row],[Vehicle No]],Sheet1!$C$13:$C$530,Sheet1!$K$13:$K$530,"",0),_xlfn.XLOOKUP(Table44[[#This Row],[Vehicle No]],Sheet1!$B$13:$B$530,Sheet1!$K$13:$K$530,"",0)) -> 10.8 | I26: =IF(COUNTIF(Sheet1!$C$13:$C$530,Table44[[#This Row],[Vehicle No]])>0,_xlfn.XLOOKUP(Table44[[#This Row],[Vehicle No]],Sheet1!$C$13:$C$530,Sheet1!$J$13:$J$530,"-",0),_xlfn.XLOOKUP(Table44[[#This Row],[Vehicle No]],Sheet1!$B$13:$B$530,Sheet1!$J$13:$J$530,"-",0)) -> L/hr | J26: =IF(Table44[[#This Row],[rate]]=0,"-",IF(Table44[[#This Row],[Rate Unit]]="L/hr",IF(Table44[[#This Row],[Fuel]]=0,"-",Table44[[#This Row],[Fuel]]/Table44[[#This Row],[rate]]),IF(Table44[[#This Row],[Fuel]]=0,"-",Table44[[#This Row],[Fuel]]*Table44[[#This Row],[rate]]))) -> - | K26: =Table44[[#This Row],[Fuel]]/Table44[[#This Row],[actual days/machine hours]] -> #DIV/0! | L26: =IF(COUNTIF(Sheet1!$C$13:$C$530,Table44[[#This Row],[Vehicle No]])>0,_xlfn.XLOOKUP(Table44[[#This Row],[Vehicle No]],Sheet1!$C$13:$C$530,Sheet1!$O$13:$O$530,"",0),_xlfn.XLOOKUP(Table44[[#This Row],[Vehicle No]],Sheet1!$B$13:$B$530,Sheet1!$O$13:$O$530,"",0)) -> 6065.82 | M26: =Table44[[#This Row],[RATE HOUR /DAY]]*Table44[[#This Row],[actual days/machine hours]] -> 0 | N26: =Table44[[#This Row],[RATE HOUR /DAY]]*Table44[[#This Row],[Days/machine hours consider for costing]] -> 0 | O26: E & C
A27: 22 | B27: ZA-8373 | C27: Pump Car | H27: =IF(COUNTIF(Sheet1!$C$13:$C$530,Table44[[#This Row],[Vehicle No]])>0,_xlfn.XLOOKUP(Table44[[#This Row],[Vehicle No]],Sheet1!$C$13:$C$530,Sheet1!$K$13:$K$530,"",0),_xlfn.XLOOKUP(Table44[[#This Row],[Vehicle No]],Sheet1!$B$13:$B$530,Sheet1!$K$13:$K$530,"",0)) -> 13 | I27: =IF(COUNTIF(Sheet1!$C$13:$C$530,Table44[[#This Row],[Vehicle No]])>0,_xlfn.XLOOKUP(Table44[[#This Row],[Vehicle No]],Sheet1!$C$13:$C$530,Sheet1!$J$13:$J$530,"-",0),_xlfn.XLOOKUP(Table44[[#This Row],[Vehicle No]],Sheet1!$B$13:$B$530,Sheet1!$J$13:$J$530,"-",0)) -> L/hr | J27: =IF(Table44[[#This Row],[rate]]=0,"-",IF(Table44[[#This Row],[Rate Unit]]="L/hr",IF(Table44[[#This Row],[Fuel]]=0,"-",Table44[[#This Row],[Fuel]]/Table44[[#This Row],[rate]]),IF(Table44[[#This Row],[Fuel]]=0,"-",Table44[[#This Row],[Fuel]]*Table44[[#This Row],[rate]]))) -> - | K27: =Table44[[#This Row],[Fuel]]/Table44[[#This Row],[actual days/machine hours]] -> #DIV/0! | L27: =IF(COUNTIF(Sheet1!$C$13:$C$530,Table44[[#This Row],[Vehicle No]])>0,_xlfn.XLOOKUP(Table44[[#This Row],[Vehicle No]],Sheet1!$C$13:$C$530,Sheet1!$O$13:$O$530,"",0),_xlfn.XLOOKUP(Table44[[#This Row],[Vehicle No]],Sheet1!$B$13:$B$530,Sheet1!$O$13:$O$530,"",0)) -> 6996.964 | O27: E & C
A28: 23 | B28: SR-19 | C28: 10 ton roller | D28: 61.9 | E28: 61.9 | G28: 630 | H28: =IF(COUNTIF(Sheet1!$C$13:$C$530,Table44[[#This Row],[Vehicle No]])>0,_xlfn.XLOOKUP(Table44[[#This Row],[Vehicle No]],Sheet1!$C$13:$C$530,Sheet1!$K$13:$K$530,"",0),_xlfn.XLOOKUP(Table44[[#This Row],[Vehicle No]],Sheet1!$B$13:$B$530,Sheet1!$K$13:$K$530,"",0)) -> 4.3 | I28: =IF(COUNTIF(Sheet1!$C$13:$C$530,Table44[[#This Row],[Vehicle No]])>0,_xlfn.XLOOKUP(Table44[[#This Row],[Vehicle No]],Sheet1!$C$13:$C$530,Sheet1!$J$13:$J$530,"-",0),_xlfn.XLOOKUP(Table44[[#This Row],[Vehicle No]],Sheet1!$B$13:$B$530,Sheet1!$J$13:$J$530,"-",0)) -> L/hr | J28: =IF(Table44[[#This Row],[rate]]=0,"-",IF(Table44[[#This Row],[Rate Unit]]="L/hr",IF(Table44[[#This Row],[Fuel]]=0,"-",Table44[[#This Row],[Fuel]]/Table44[[#This Row],[rate]]),IF(Table44[[#This Row],[Fuel]]=0,"-",Table44[[#This Row],[Fuel]]*Table44[[#This Row],[rate]]))) -> 146.51163 | K28: =Table44[[#This Row],[Fuel]]/Table44[[#This Row],[actual days/machine hours]] -> 10.177706 | L28: =IF(COUNTIF(Sheet1!$C$13:$C$530,Table44[[#This Row],[Vehicle No]])>0,_xlfn.XLOOKUP(Table44[[#This Row],[Vehicle No]],Sheet1!$C$13:$C$530,Sheet1!$O$13:$O$530,"",0),_xlfn.XLOOKUP(Table44[[#This Row],[Vehicle No]],Sheet1!$B$13:$B$530,Sheet1!$O$13:$O$530,"",0)) -> 2127.339 | M28: =Table44[[#This Row],[RATE HOUR /DAY]]*Table44[[#This Row],[actual days/machine hours]] -> 131682.28 | N28: =Table44[[#This Row],[RATE HOUR /DAY]]*Table44[[#This Row],[Days/machine hours consider for costing]] -> 131682.28
A29: 24 | B29: VR-65 | C29: 4 ton roller | D29: 79 | E29: 79 | G29: 425 | H29: =IF(COUNTIF(Sheet1!$C$13:$C$530,Table44[[#This Row],[Vehicle No]])>0,_xlfn.XLOOKUP(Table44[[#This Row],[Vehicle No]],Sheet1!$C$13:$C$530,Sheet1!$K$13:$K$530,"",0),_xlfn.XLOOKUP(Table44[[#This Row],[Vehicle No]],Sheet1!$B$13:$B$530,Sheet1!$K$13:$K$530,"",0)) -> 7.2 | I29: =IF(COUNTIF(Sheet1!$C$13:$C$530,Table44[[#This Row],[Vehicle No]])>0,_xlfn.XLOOKUP(Table44[[#This Row],[Vehicle No]],Sheet1!$C$13:$C$530,Sheet1!$J$13:$J$530,"-",0),_xlfn.XLOOKUP(Table44[[#This Row],[Vehicle No]],Sheet1!$B$13:$B$530,Sheet1!$J$13:$J$530,"-",0)) -> L/hr | J29: =IF(Table44[[#This Row],[rate]]=0,"-",IF(Table44[[#This Row],[Rate Unit]]="L/hr",IF(Table44[[#This Row],[Fuel]]=0,"-",Table44[[#This Row],[Fuel]]/Table44[[#This Row],[rate]]),IF(Table44[[#This Row],[Fuel]]=0,"-",Table44[[#This Row],[Fuel]]*Table44[[#This Row],[rate]]))) -> 59.027778 | K29: =Table44[[#This Row],[Fuel]]/Table44[[#This Row],[actual days/machine hours]] -> 5.3797468 | L29: =IF(COUNTIF(Sheet1!$C$13:$C$530,Table44[[#This Row],[Vehicle No]])>0,_xlfn.XLOOKUP(Table44[[#This Row],[Vehicle No]],Sheet1!$C$13:$C$530,Sheet1!$O$13:$O$530,"",0),_xlfn.XLOOKUP(Table44[[#This Row],[Vehicle No]],Sheet1!$B$13:$B$530,Sheet1!$O$13:$O$530,"",0)) -> 3441.6 | M29: =Table44[[#This Row],[RATE HOUR /DAY]]*Table44[[#This Row],[actual days/machine hours]] -> 271886.4 | N29: =Table44[[#This Row],[RATE HOUR /DAY]]*Table44[[#This Row],[Days/machine hours consider for costing]] -> 271886.4 | O29: E & C
A30: 25 | B30: ZA-6069 | C30: JCB | D30: 131.9 | E30: 131.9 | G30: 640 | H30: =IF(COUNTIF(Sheet1!$C$13:$C$530,Table44[[#This Row],[Vehicle No]])>0,_xlfn.XLOOKUP(Table44[[#This Row],[Vehicle No]],Sheet1!$C$13:$C$530,Sheet1!$K$13:$K$530,"",0),_xlfn.XLOOKUP(Table44[[#This Row],[Vehicle No]],Sheet1!$B$13:$B$530,Sheet1!$K$13:$K$530,"",0)) -> 5 | I30: =IF(COUNTIF(Sheet1!$C$13:$C$530,Table44[[#This Row],[Vehicle No]])>0,_xlfn.XLOOKUP(Table44[[#This Row],[Vehicle No]],Sheet1!$C$13:$C$530,Sheet1!$J$13:$J$530,"-",0),_xlfn.XLOOKUP(Table44[[#This Row],[Vehicle No]],Sheet1!$B$13:$B$530,Sheet1!$J$13:$J$530,"-",0)) -> L/hr | J30: =IF(Table44[[#This Row],[rate]]=0,"-",IF(Table44[[#This Row],[Rate Unit]]="L/hr",IF(Table44[[#This Row],[Fuel]]=0,"-",Table44[[#This Row],[Fuel]]/Table44[[#This Row],[rate]]),IF(Table44[[#This Row],[Fuel]]=0,"-",Table44[[#This Row],[Fuel]]*Table44[[#This Row],[rate]]))) -> 128 | K30: =Table44[[#This Row],[Fuel]]/Table44[[#This Row],[actual days/machine hours]] -> 4.8521607 | L30: =IF(COUNTIF(Sheet1!$C$13:$C$530,Table44[[#This Row],[Vehicle No]])>0,_xlfn.XLOOKUP(Table44[[#This Row],[Vehicle No]],Sheet1!$C$13:$C$530,Sheet1!$O$13:$O$530,"",0),_xlfn.XLOOKUP(Table44[[#This Row],[Vehicle No]],Sheet1!$B$13:$B$530,Sheet1!$O$13:$O$530,"",0)) -> 2574.03 | M30: =Table44[[#This Row],[RATE HOUR /DAY]]*Table44[[#This Row],[actual days/machine hours]] -> 339514.56 | N30: =Table44[[#This Row],[RATE HOUR /DAY]]*Table44[[#This Row],[Days/machine hours consider for costing]] -> 339514.56 | O30: E & C
A31: 26 | B31: ZB-1546 | C31: JCB | H31: =IF(COUNTIF(Sheet1!$C$13:$C$530,Table44[[#This Row],[Vehicle No]])>0,_xlfn.XLOOKUP(Table44[[#This Row],[Vehicle No]],Sheet1!$C$13:$C$530,Sheet1!$K$13:$K$530,"",0),_xlfn.XLOOKUP(Table44[[#This Row],[Vehicle No]],Sheet1!$B$13:$B$530,Sheet1!$K$13:$K$530,"",0)) -> 5 | I31: =IF(COUNTIF(Sheet1!$C$13:$C$530,Table44[[#This Row],[Vehicle No]])>0,_xlfn.XLOOKUP(Table44[[#This Row],[Vehicle No]],Sheet1!$C$13:$C$530,Sheet1!$J$13:$J$530,"-",0),_xlfn.XLOOKUP(Table44[[#This Row],[Vehicle No]],Sheet1!$B$13:$B$530,Sheet1!$J$13:$J$530,"-",0)) -> L/hr | J31: =IF(Table44[[#This Row],[rate]]=0,"-",IF(Table44[[#This Row],[Rate Unit]]="L/hr",IF(Table44[[#This Row],[Fuel]]=0,"-",Table44[[#This Row],[Fuel]]/Table44[[#This Row],[rate]]),IF(Table44[[#This Row],[Fuel]]=0,"-",Table44[[#This Row],[Fuel]]*Table44[[#This Row],[rate]]))) -> - | K31: =Table44[[#This Row],[Fuel]]/Table44[[#This Row],[actual days/machine hours]] -> #DIV/0! | L31: =IF(COUNTIF(Sheet1!$C$13:$C$530,Table44[[#This Row],[Vehicle No]])>0,_xlfn.XLOOKUP(Table44[[#This Row],[Vehicle No]],Sheet1!$C$13:$C$530,Sheet1!$O$13:$O$530,"",0),_xlfn.XLOOKUP(Table44[[#This Row],[Vehicle No]],Sheet1!$B$13:$B$530,Sheet1!$O$13:$O$530,"",0)) -> 2490.38 | M31: =Table44[[#This Row],[RATE HOUR /DAY]]*Table44[[#This Row],[actual days/machine hours]] -> 0 | N31: =Table44[[#This Row],[RATE HOUR /DAY]]*Table44[[#This Row],[Days/machine hours consider for costing]] -> 0 | O31: E & C
A32: 27 | B32: SL-14 | C32: Skid Loader | D32: 108.5 | E32: 108.5 | G32: 495 | H32: =IF(COUNTIF(Sheet1!$C$13:$C$530,Table44[[#This Row],[Vehicle No]])>0,_xlfn.XLOOKUP(Table44[[#This Row],[Vehicle No]],Sheet1!$C$13:$C$530,Sheet1!$K$13:$K$530,"",0),_xlfn.XLOOKUP(Table44[[#This Row],[Vehicle No]],Sheet1!$B$13:$B$530,Sheet1!$K$13:$K$530,"",0)) -> 3.2 | I32: =IF(COUNTIF(Sheet1!$C$13:$C$530,Table44[[#This Row],[Vehicle No]])>0,_xlfn.XLOOKUP(Table44[[#This Row],[Vehicle No]],Sheet1!$C$13:$C$530,Sheet1!$J$13:$J$530,"-",0),_xlfn.XLOOKUP(Table44[[#This Row],[Vehicle No]],Sheet1!$B$13:$B$530,Sheet1!$J$13:$J$530,"-",0)) -> L/hr | J32: =IF(Table44[[#This Row],[rate]]=0,"-",IF(Table44[[#This Row],[Rate Unit]]="L/hr",IF(Table44[[#This Row],[Fuel]]=0,"-",Table44[[#This Row],[Fuel]]/Table44[[#This Row],[rate]]),IF(Table44[[#This Row],[Fuel]]=0,"-",Table44[[#This Row],[Fuel]]*Table44[[#This Row],[rate]]))) -> 154.6875 | K32: =Table44[[#This Row],[Fuel]]/Table44[[#This Row],[actual days/machine hours]] -> 4.562212 | L32: =IF(COUNTIF(Sheet1!$C$13:$C$530,Table44[[#This Row],[Vehicle No]])>0,_xlfn.XLOOKUP(Table44[[#This Row],[Vehicle No]],Sheet1!$C$13:$C$530,Sheet1!$O$13:$O$530,"",0),_xlfn.XLOOKUP(Table44[[#This Row],[Vehicle No]],Sheet1!$B$13:$B$530,Sheet1!$O$13:$O$530,"",0)) -> 1636.672 | M32: =Table44[[#This Row],[RATE HOUR /DAY]]*Table44[[#This Row],[actual days/machine hours]] -> 177578.91 | N32: =Table44[[#This Row],[RATE HOUR /DAY]]*Table44[[#This Row],[Days/machine hours consider for costing]] -> 177578.91 | O32: E & C
M34: =SUM(M4:M33) -> 2981309 | N34: =SUM(N4:N33) -> 2981309

Sheet Plant expenses
B1: Vehicle Running Summary -January
A3: No | B3: Vehicle No | C3: Type | D3: actual days/machine hours | E3: Days/machine hours consider for costing | F3: Cons Econ | G3: Fuel Rate Unit | H3: Distance | I3: Fuel | J3: Actual Work Done | K3: RATE HOUR /DAY | L3: Actual amount | M3: Amount (idling included) | N3: Owner | O3: Remarks
A4: 1 | B4: ZA-7290 | C4: Truck Mixer | F4: =IF(COUNTIF(Sheet1!$C$13:$C$530,Table443[[#This Row],[Vehicle No]])>0,_xlfn.XLOOKUP(Table443[[#This Row],[Vehicle No]],Sheet1!$C$13:$C$530,Sheet1!$K$13:$K$530,"-",0),_xlfn.XLOOKUP(Table443[[#This Row],[Vehicle No]],Sheet1!$B$13:$B$530,Sheet1!$K$13:$K$530,"-",0)) -> 7.9 | G4: =IF(COUNTIF(Sheet1!$C$13:$C$530,Table443[[#This Row],[Vehicle No]])>0,_xlfn.XLOOKUP(Table443[[#This Row],[Vehicle No]],Sheet1!$C$13:$C$530,Sheet1!$J$13:$J$530,"-",0),_xlfn.XLOOKUP(Table443[[#This Row],[Vehicle No]],Sheet1!$B$13:$B$530,Sheet1!$J$13:$J$530,"-",0)) -> L/hr | J4: =IF(Table443[[#This Row],[Cons Econ]]="-","-",IF(Table443[[#This Row],[Fuel Rate Unit]]="KM/L",IF(Table443[[#This Row],[Fuel]]=0,"-",Table443[[#This Row],[Fuel]]*Table443[[#This Row],[Cons Econ]]),IF(Table443[[#This Row],[Fuel]]=0,"-",Table443[[#This Row],[Fuel]]/Table443[[#This Row],[Cons Econ]]))) -> - | K4: =IF(COUNTIF(Sheet1!$C$13:$C$530,Table443[[#This Row],[Vehicle No]])>0,_xlfn.XLOOKUP(Table443[[#This Row],[Vehicle No]],Sheet1!$C$13:$C$530,Sheet1!$O$13:$O$530,"",0),_xlfn.XLOOKUP(Table443[[#This Row],[Vehicle No]],Sheet1!$B$13:$B$530,Sheet1!$O$13:$O$530,"",0)) -> 4040.534 | L4: =Table443[[#This Row],[RATE HOUR /DAY]]*Table443[[#This Row],[actual days/machine hours]] -> 0 | M4: =Table443[[#This Row],[RATE HOUR /DAY]]*Table443[[#This Row],[Days/machine hours consider for costing]] -> 0 | N4: E & C
A5: 2 | B5: ZA-7291 | C5: Truck Mixer | F5: =IF(COUNTIF(Sheet1!$C$13:$C$530,Table443[[#This Row],[Vehicle No]])>0,_xlfn.XLOOKUP(Table443[[#This Row],[Vehicle No]],Sheet1!$C$13:$C$530,Sheet1!$K$13:$K$530,"-",0),_xlfn.XLOOKUP(Table443[[#This Row],[Vehicle No]],Sheet1!$B$13:$B$530,Sheet1!$K$13:$K$530,"-",0)) -> 7.9 | G5: =IF(COUNTIF(Sheet1!$C$13:$C$530,Table443[[#This Row],[Vehicle No]])>0,_xlfn.XLOOKUP(Table443[[#This Row],[Vehicle No]],Sheet1!$C$13:$C$530,Sheet1!$J$13:$J$530,"-",0),_xlfn.XLOOKUP(Table443[[#This Row],[Vehicle No]],Sheet1!$B$13:$B$530,Sheet1!$J$13:$J$530,"-",0)) -> L/hr | J5: =IF(Table443[[#This Row],[Cons Econ]]="-","-",IF(Table443[[#This Row],[Fuel Rate Unit]]="KM/L",IF(Table443[[#This Row],[Fuel]]=0,"-",Table443[[#This Row],[Fuel]]*Table443[[#This Row],[Cons Econ]]),IF(Table443[[#This Row],[Fuel]]=0,"-",Table443[[#This Row],[Fuel]]/Table443[[#This Row],[Cons Econ]]))) -> - | K5: =IF(COUNTIF(Sheet1!$C$13:$C$530,Table443[[#This Row],[Vehicle No]])>0,_xlfn.XLOOKUP(Table443[[#This Row],[Vehicle No]],Sheet1!$C$13:$C$530,Sheet1!$O$13:$O$530,"",0),_xlfn.XLOOKUP(Table443[[#This Row],[Vehicle No]],Sheet1!$B$13:$B$530,Sheet1!$O$13:$O$530,"",0)) -> 4040.534 | L5: =Table443[[#This Row],[RATE HOUR /DAY]]*Table443[[#This Row],[actual days/machine hours]] -> 0 | M5: =Table443[[#This Row],[RATE HOUR /DAY]]*Table443[[#This Row],[Days/machine hours consider for costing]] -> 0
A6: 3 | B6: ZA-8511 | C6: Truck Mixer | D6: 16 | E6: 16 | F6: =IF(COUNTIF(Sheet1!$C$13:$C$530,Table443[[#This Row],[Vehicle No]])>0,_xlfn.XLOOKUP(Table443[[#This Row],[Vehicle No]],Sheet1!$C$13:$C$530,Sheet1!$K$13:$K$530,"-",0),_xlfn.XLOOKUP(Table443[[#This Row],[Vehicle No]],Sheet1!$B$13:$B$530,Sheet1!$K$13:$K$530,"-",0)) -> 7.9 | G6: =IF(COUNTIF(Sheet1!$C$13:$C$530,Table443[[#This Row],[Vehicle No]])>0,_xlfn.XLOOKUP(Table443[[#This Row],[Vehicle No]],Sheet1!$C$13:$C$530,Sheet1!$J$13:$J$530,"-",0),_xlfn.XLOOKUP(Table443[[#This Row],[Vehicle No]],Sheet1!$B$13:$B$530,Sheet1!$J$13:$J$530,"-",0)) -> L/hr | I6: 555 | J6: =IF(Table443[[#This Row],[Cons Econ]]="-","-",IF(Table443[[#This Row],[Fuel Rate Unit]]="KM/L",IF(Table443[[#This Row],[Fuel]]=0,"-",Table443[[#This Row],[Fuel]]*Table443[[#This Row],[Cons Econ]]),IF(Table443[[#This Row],[Fuel]]=0,"-",Table443[[#This Row],[Fuel]]/Table443[[#This Row],[Cons Econ]]))) -> 70.253165 | K6: =IF(COUNTIF(Sheet1!$C$13:$C$530,Table443[[#This Row],[Vehicle No]])>0,_xlfn.XLOOKUP(Table443[[#This Row],[Vehicle No]],Sheet1!$C$13:$C$530,Sheet1!$O$13:$O$530,"",0),_xlfn.XLOOKUP(Table443[[#This Row],[Vehicle No]],Sheet1!$B$13:$B$530,Sheet1!$O$13:$O$530,"",0)) -> 4014.1006 | L6: =Table443[[#This Row],[RATE HOUR /DAY]]*Table443[[#This Row],[actual days/machine hours]] -> 64225.61 | M6: =Table443[[#This Row],[RATE HOUR /DAY]]*Table443[[#This Row],[Days/machine hours consider for costing]] -> 64225.61
A7: 4 | B7: ZA-7810 | C7: Truck Mixer | F7: =IF(COUNTIF(Sheet1!$C$13:$C$530,Table443[[#This Row],[Vehicle No]])>0,_xlfn.XLOOKUP(Table443[[#This Row],[Vehicle No]],Sheet1!$C$13:$C$530,Sheet1!$K$13:$K$530,"-",0),_xlfn.XLOOKUP(Table443[[#This Row],[Vehicle No]],Sheet1!$B$13:$B$530,Sheet1!$K$13:$K$530,"-",0)) -> 9.4 | G7: =IF(COUNTIF(Sheet1!$C$13:$C$530,Table443[[#This Row],[Vehicle No]])>0,_xlfn.XLOOKUP(Table443[[#This Row],[Vehicle No]],Sheet1!$C$13:$C$530,Sheet1!$J$13:$J$530,"-",0),_xlfn.XLOOKUP(Table443[[#This Row],[Vehicle No]],Sheet1!$B$13:$B$530,Sheet1!$J$13:$J$530,"-",0)) -> L/hr | J7: =IF(Table443[[#This Row],[Cons Econ]]="-","-",IF(Table443[[#This Row],[Fuel Rate Unit]]="KM/L",IF(Table443[[#This Row],[Fuel]]=0,"-",Table443[[#This Row],[Fuel]]*Table443[[#This Row],[Cons Econ]]),IF(Table443[[#This Row],[Fuel]]=0,"-",Table443[[#This Row],[Fuel]]/Table443[[#This Row],[Cons Econ]]))) -> - | K7: =IF(COUNTIF(Sheet1!$C$13:$C$530,Table443[[#This Row],[Vehicle No]])>0,_xlfn.XLOOKUP(Table443[[#This Row],[Vehicle No]],Sheet1!$C$13:$C$530,Sheet1!$O$13:$O$530,"",0),_xlfn.XLOOKUP(Table443[[#This Row],[Vehicle No]],Sheet1!$B$13:$B$530,Sheet1!$O$13:$O$530,"",0)) -> 4807.724 | L7: =Table443[[#This Row],[RATE HOUR /DAY]]*Table443[[#This Row],[actual days/machine hours]] -> 0 | M7: =Table443[[#This Row],[RATE HOUR /DAY]]*Table443[[#This Row],[Days/machine hours consider for costing]] -> 0 | N7: E & C
A8: 5 | B8: LD-09 | C8: Loader | D8: 190 | E8: 190 | F8: =IF(COUNTIF(Sheet1!$C$13:$C$530,Table443[[#This Row],[Vehicle No]])>0,_xlfn.XLOOKUP(Table443[[#This Row],[Vehicle No]],Sheet1!$C$13:$C$530,Sheet1!$K$13:$K$530,"-",0),_xlfn.XLOOKUP(Table443[[#This Row],[Vehicle No]],Sheet1!$B$13:$B$530,Sheet1!$K$13:$K$530,"-",0)) -> 10.8 | G8: =IF(COUNTIF(Sheet1!$C$13:$C$530,Table443[[#This Row],[Vehicle No]])>0,_xlfn.XLOOKUP(Table443[[#This Row],[Vehicle No]],Sheet1!$C$13:$C$530,Sheet1!$J$13:$J$530,"-",0),_xlfn.XLOOKUP(Table443[[#This Row],[Vehicle No]],Sheet1!$B$13:$B$530,Sheet1!$J$13:$J$530,"-",0)) -> L/hr | I8: 1719 | J8: =IF(Table443[[#This Row],[Cons Econ]]="-","-",IF(Table443[[#This Row],[Fuel Rate Unit]]="KM/L",IF(Table443[[#This Row],[Fuel]]=0,"-",Table443[[#This Row],[Fuel]]*Table443[[#This Row],[Cons Econ]]),IF(Table443[[#This Row],[Fuel]]=0,"-",Table443[[#This Row],[Fuel]]/Table443[[#This Row],[Cons Econ]]))) -> 159.16667 | K8: =IF(COUNTIF(Sheet1!$C$13:$C$530,Table443[[#This Row],[Vehicle No]])>0,_xlfn.XLOOKUP(Table443[[#This Row],[Vehicle No]],Sheet1!$C$13:$C$530,Sheet1!$O$13:$O$530,"",0),_xlfn.XLOOKUP(Table443[[#This Row],[Vehicle No]],Sheet1!$B$13:$B$530,Sheet1!$O$13:$O$530,"",0)) -> 5379.2208 | L8: =Table443[[#This Row],[RATE HOUR /DAY]]*Table443[[#This Row],[actual days/machine hours]] -> 1022052 | M8: =Table443[[#This Row],[RATE HOUR /DAY]]*Table443[[#This Row],[Days/machine hours consider for costing]] -> 1022052 | N8: E & C | O8: Meter broken
A9: 6 | B9: ZA-8373 | C9: Truck Mixer | F9: =IF(COUNTIF(Sheet1!$C$13:$C$530,Table443[[#This Row],[Vehicle No]])>0,_xlfn.XLOOKUP(Table443[[#This Row],[Vehicle No]],Sheet1!$C$13:$C$530,Sheet1!$K$13:$K$530,"-",0),_xlfn.XLOOKUP(Table443[[#This Row],[Vehicle No]],Sheet1!$B$13:$B$530,Sheet1!$K$13:$K$530,"-",0)) -> 13 | G9: =IF(COUNTIF(Sheet1!$C$13:$C$530,Table443[[#This Row],[Vehicle No]])>0,_xlfn.XLOOKUP(Table443[[#This Row],[Vehicle No]],Sheet1!$C$13:$C$530,Sheet1!$J$13:$J$530,"-",0),_xlfn.XLOOKUP(Table443[[#This Row],[Vehicle No]],Sheet1!$B$13:$B$530,Sheet1!$J$13:$J$530,"-",0)) -> L/hr | J9: =IF(Table443[[#This Row],[Cons Econ]]="-","-",IF(Table443[[#This Row],[Fuel Rate Unit]]="KM/L",IF(Table443[[#This Row],[Fuel]]=0,"-",Table443[[#This Row],[Fuel]]*Table443[[#This Row],[Cons Econ]]),IF(Table443[[#This Row],[Fuel]]=0,"-",Table443[[#This Row],[Fuel]]/Table443[[#This Row],[Cons Econ]]))) -> - | K9: =IF(COUNTIF(Sheet1!$C$13:$C$530,Table443[[#This Row],[Vehicle No]])>0,_xlfn.XLOOKUP(Table443[[#This Row],[Vehicle No]],Sheet1!$C$13:$C$530,Sheet1!$O$13:$O$530,"",0),_xlfn.XLOOKUP(Table443[[#This Row],[Vehicle No]],Sheet1!$B$13:$B$530,Sheet1!$O$13:$O$530,"",0)) -> 6996.964 | L9: =Table443[[#This Row],[RATE HOUR /DAY]]*Table443[[#This Row],[actual days/machine hours]] -> 0 | M9: =Table443[[#This Row],[RATE HOUR /DAY]]*Table443[[#This Row],[Days/machine hours consider for costing]] -> 0 | N9: E & C
A10: 7 | B10: ZB-1496 | C10: Truck Mixer | D10: 21 | E10: 21 | F10: =IF(COUNTIF(Sheet1!$C$13:$C$530,Table443[[#This Row],[Vehicle No]])>0,_xlfn.XLOOKUP(Table443[[#This Row],[Vehicle No]],Sheet1!$C$13:$C$530,Sheet1!$K$13:$K$530,"-",0),_xlfn.XLOOKUP(Table443[[#This Row],[Vehicle No]],Sheet1!$B$13:$B$530,Sheet1!$K$13:$K$530,"-",0)) -> 13 | G10: =IF(COUNTIF(Sheet1!$C$13:$C$530,Table443[[#This Row],[Vehicle No]])>0,_xlfn.XLOOKUP(Table443[[#This Row],[Vehicle No]],Sheet1!$C$13:$C$530,Sheet1!$J$13:$J$530,"-",0),_xlfn.XLOOKUP(Table443[[#This Row],[Vehicle No]],Sheet1!$B$13:$B$530,Sheet1!$J$13:$J$530,"-",0)) -> L/hr | I10: 1290 | J10: =IF(Table443[[#This Row],[Cons Econ]]="-","-",IF(Table443[[#This Row],[Fuel Rate Unit]]="KM/L",IF(Table443[[#This Row],[Fuel]]=0,"-",Table443[[#This Row],[Fuel]]*Table443[[#This Row],[Cons Econ]]),IF(Table443[[#This Row],[Fuel]]=0,"-",Table443[[#This Row],[Fuel]]/Table443[[#This Row],[Cons Econ]]))) -> 99.230769 | K10: =IF(COUNTIF(Sheet1!$C$13:$C$530,Table443[[#This Row],[Vehicle No]])>0,_xlfn.XLOOKUP(Table443[[#This Row],[Vehicle No]],Sheet1!$C$13:$C$530,Sheet1!$O$13:$O$530,"",0),_xlfn.XLOOKUP(Table443[[#This Row],[Vehicle No]],Sheet1!$B$13:$B$530,Sheet1!$O$13:$O$530,"",0)) -> 6518.486 | L10: =Table443[[#This Row],[RATE HOUR /DAY]]*Table443[[#This Row],[actual days/machine hours]] -> 136888.21 | M10: =Table443[[#This Row],[RATE HOUR /DAY]]*Table443[[#This Row],[Days/machine hours consider for costing]] -> 136888.21 | N10: E & C
A11: 8 | B11: HEX-19 | C11: Komatsu 120 | F11: =IF(COUNTIF(Sheet1!$C$13:$C$530,Table443[[#This Row],[Vehicle No]])>0,_xlfn.XLOOKUP(Table443[[#This Row],[Vehicle No]],Sheet1!$C$13:$C$530,Sheet1!$K$13:$K$530,"-",0),_xlfn.XLOOKUP(Table443[[#This Row],[Vehicle No]],Sheet1!$B$13:$B$530,Sheet1!$K$13:$K$530,"-",0)) -> 7.2 | G11: =IF(COUNTIF(Sheet1!$C$13:$C$530,Table443[[#This Row],[Vehicle No]])>0,_xlfn.XLOOKUP(Table443[[#This Row],[Vehicle No]],Sheet1!$C$13:$C$530,Sheet1!$J$13:$J$530,"-",0),_xlfn.XLOOKUP(Table443[[#This Row],[Vehicle No]],Sheet1!$B$13:$B$530,Sheet1!$J$13:$J$530,"-",0)) -> L/hr | J11: =IF(Table443[[#This Row],[Cons Econ]]="-","-",IF(Table443[[#This Row],[Fuel Rate Unit]]="KM/L",IF(Table443[[#This Row],[Fuel]]=0,"-",Table443[[#This Row],[Fuel]]*Table443[[#This Row],[Cons Econ]]),IF(Table443[[#This Row],[Fuel]]=0,"-",Table443[[#This Row],[Fuel]]/Table443[[#This Row],[Cons Econ]]))) -> - | K11: =IF(COUNTIF(Sheet1!$C$13:$C$530,Table443[[#This Row],[Vehicle No]])>0,_xlfn.XLOOKUP(Table443[[#This Row],[Vehicle No]],Sheet1!$C$13:$C$530,Sheet1!$O$13:$O$530,"",0),_xlfn.XLOOKUP(Table443[[#This Row],[Vehicle No]],Sheet1!$B$13:$B$530,Sheet1!$O$13:$O$530,"",0)) -> 3851.1504 | L11: =Table443[[#This Row],[RATE HOUR /DAY]]*Table443[[#This Row],[actual days/machine hours]] -> 0 | M11: =Table443[[#This Row],[RATE HOUR /DAY]]*Table443[[#This Row],[Days/machine hours consider for costing]] -> 0 | N11: E & C | O11: Crusher Plant
A12: 9 | B12: ZA-0050 | C12: Truck Mixer | D12: 18 | E12: 18 | F12: =IF(COUNTIF(Sheet1!$C$13:$C$530,Table443[[#This Row],[Vehicle No]])>0,_xlfn.XLOOKUP(Table443[[#This Row],[Vehicle No]],Sheet1!$C$13:$C$530,Sheet1!$K$13:$K$530,"-",0),_xlfn.XLOOKUP(Table443[[#This Row],[Vehicle No]],Sheet1!$B$13:$B$530,Sheet1!$K$13:$K$530,"-",0)) -> 9.4 | G12: =IF(COUNTIF(Sheet1!$C$13:$C$530,Table443[[#This Row],[Vehicle No]])>0,_xlfn.XLOOKUP(Table443[[#This Row],[Vehicle No]],Sheet1!$C$13:$C$530,Sheet1!$J$13:$J$530,"-",0),_xlfn.XLOOKUP(Table443[[#This Row],[Vehicle No]],Sheet1!$B$13:$B$530,Sheet1!$J$13:$J$530,"-",0)) -> L/hr | I12: 1095 | J12: =IF(Table443[[#This Row],[Cons Econ]]="-","-",IF(Table443[[#This Row],[Fuel Rate Unit]]="KM/L",IF(Table443[[#This Row],[Fuel]]=0,"-",Table443[[#This Row],[Fuel]]*Table443[[#This Row],[Cons Econ]]),IF(Table443[[#This Row],[Fuel]]=0,"-",Table443[[#This Row],[Fuel]]/Table443[[#This Row],[Cons Econ]]))) -> 116.48936 | K12: =IF(COUNTIF(Sheet1!$C$13:$C$530,Table443[[#This Row],[Vehicle No]])>0,_xlfn.XLOOKUP(Table443[[#This Row],[Vehicle No]],Sheet1!$C$13:$C$530,Sheet1!$O$13:$O$530,0,0),_xlfn.XLOOKUP(Table443[[#This Row],[Vehicle No]],Sheet1!$B$13:$B$530,Sheet1!$O$13:$O$530,0,0)) -> 4776.2716 | L12: =Table443[[#This Row],[RATE HOUR /DAY]]*Table443[[#This Row],[actual days/machine hours]] -> 85972.889 | M12: =Table443[[#This Row],[RATE HOUR /DAY]]*Table443[[#This Row],[Days/machine hours consider for costing]] -> 85972.889 | N12: E & C
L14: =SUM(L4:L13) -> 1309138.7 | M14: =SUM(M4:M13) -> 1309138.7

Sheet Sheet2
A1: Vehicle Running Summary - April 2026 (Package E)
A3: No | B3: Vehicle No | C3: 58 | D3: Actual working days/machine hours | E3: Days/hours consider for costing | F3: 6 | G3: Fuel | H3: Actual Consumption Rate | I3: Column2 | J3: Actual Consumption | K3: Consumption | L3: RATE HOUR /DAY | M3: Total Amount with idling | N3: Total amount without idling | O3: Owner | P3: Remarks
A4: 1 | B4: LH-5586 | C4: 5 Cube | D4: 1 | E4: 1 | F4: 26 | G4: 20 | H4: =IFERROR(_xlfn.XLOOKUP(B4,[20]Sheet1!$C:$C,[20]Sheet1!$K:$K,_xlfn.XLOOKUP(B4,[20]Sheet1!$B:$B,[20]Sheet1!$K:$K,"")),"") -> 2.9 | I4: =IFERROR(_xlfn.XLOOKUP(B4,[20]Sheet1!$C:$C,[20]Sheet1!$J:$J,_xlfn.XLOOKUP(B4,[20]Sheet1!$B:$B,[20]Sheet1!$J:$J,"")),"") -> km/L | J4: =IF(OR(H4="",H4=0),"",IF(ISNUMBER(SEARCH("hr",I4)),G4/H4,H4*G4)) -> 58 | K4: =F4/G4 -> 1.3 | L4: 7000 | M4: =Table4434[[#This Row],[RATE HOUR /DAY]]*Table4434[[#This Row],[Days/hours consider for costing]] -> 7000 | N4: =Table4434[[#This Row],[Actual working days/machine hours ]]*Table4434[[#This Row],[RATE HOUR /DAY]] -> 7000 | O4: E & C
A5: 2 | B5: LI-7618 | C5: 3 Cube | D5: 14 | E5: 14 | G5: 60 | H5: =IFERROR(_xlfn.XLOOKUP(B5,[20]Sheet1!$C:$C,[20]Sheet1!$K:$K,_xlfn.XLOOKUP(B5,[20]Sheet1!$B:$B,[20]Sheet1!$K:$K,"")),"") -> 3.8 | I5: =IFERROR(_xlfn.XLOOKUP(B5,[20]Sheet1!$C:$C,[20]Sheet1!$J:$J,_xlfn.XLOOKUP(B5,[20]Sheet1!$B:$B,[20]Sheet1!$J:$J,"")),"") -> km/L | J5: =IF(OR(H5="",H5=0),"",IF(ISNUMBER(SEARCH("hr",I5)),G5/H5,H5*G5)) -> 228 | K5: =F5/G5 -> 0 | L5: 6440 | M5: =Table4434[[#This Row],[RATE HOUR /DAY]]*Table4434[[#This Row],[Days/hours consider for costing]] -> 90160 | N5: =Table4434[[#This Row],[Actual working days/machine hours ]]*Table4434[[#This Row],[RATE HOUR /DAY]] -> 90160 | O5: E & C
A6: 3 | B6: LP-1713 | C6: 3 Cube | D6: 5 | E6: 5 | F6: 126 | G6: 60 | H6: =IFERROR(_xlfn.XLOOKUP(B6,[20]Sheet1!$C:$C,[20]Sheet1!$K:$K,_xlfn.XLOOKUP(B6,[20]Sheet1!$B:$B,[20]Sheet1!$K:$K,"")),"") -> 3.8 | I6: =IFERROR(_xlfn.XLOOKUP(B6,[20]Sheet1!$C:$C,[20]Sheet1!$J:$J,_xlfn.XLOOKUP(B6,[20]Sheet1!$B:$B,[20]Sheet1!$J:$J,"")),"") -> km/L | J6: =IF(OR(H6="",H6=0),"",IF(ISNUMBER(SEARCH("hr",I6)),G6/H6,H6*G6)) -> 228 | L6: 6440 | M6: =Table4434[[#This Row],[RATE HOUR /DAY]]*Table4434[[#This Row],[Days/hours consider for costing]] -> 32200 | N6: =Table4434[[#This Row],[Actual working days/machine hours ]]*Table4434[[#This Row],[RATE HOUR /DAY]] -> 32200
