Workbook

Sheet Cover & Legend
B2: EDWARD & CHRISTIE GROUP (PVT) LTD
B3: FLEET HIRE RATE CARD · 2026
B4: Badalgama Workshop · Negombo · Sri Lanka All rates in Sri Lankan Rupees (LKR), exclusive of SSCL & VAT unless stated.
B6: RATE BASIS — WHAT EACH PRICE INCLUDES
B7: Tier | C7: Includes | D7: Description
B8: Dry | C8: Machine / vehicle only. | D8: Customer supplies the operator AND the fuel. E&C provides the bare unit.
B9: Wet (Driver only) | C9: Machine + E&C operator / driver. | D9: Customer supplies the fuel only. Labour is included; diesel is billed to / arranged by the customer.
B10: Fully Wet (Driver + Fuel) | C10: Machine + operator + fuel — all-inclusive. | D10: E&C provides everything: the unit, the driver and the fuel. The simplest single rate for the customer.
B12: BILLING BASIS
B13: Hourly | C13: Per machine-hour. Standard for site plant (excavators, loaders, rollers, etc.).
B14: Per Day | C14: Per working day. Used for daily-hire plant and portable equipment.
B15: Per KM | C15: Per kilometre. Applies to road-registered vehicles only (tippers, prime movers, cabs, lorries, bikes). Blank = not applicable.
B17: FLEET AT A GLANCE
B18: Total fleet units | C18: =COUNTIF('Fleet Rate Card'!C8:C525,"?*") -> 518
B19: Equipment categories | C19: =SUMPRODUCT((COUNTIF('Category Summary'!B6:B34,'Category Summary'!B6:B34)>0)*1) -> 29
B20: Road-registered (per-KM) units | C20: =COUNT('Fleet Rate Card'!N8:N525) -> 210
B21: Portable equipment items | C21: =COUNTIF('Portable Equipment'!B6:B200,"?*") -> 41
B23: Generated: | C23: 17 June 2026

Sheet Fleet Rate Card
A1: EDWARD & CHRISTIE — FLEET HIRE RATE CARD 2026 (all rates, excl. SSCL/VAT)
A6: UNIT DETAILS | F6: HOURLY RATE (Rs.) | I6: PER DAY RATE (Rs.) | L6: PER KM RATE (Rs.)
A7: E&C Code | B7: Reg No. | C7: Category | D7: Model | E7: Year | F7: Dry | G7: Wet (Driver) | H7: Fully Wet (Driver+Fuel) | I7: Dry | J7: Wet (Driver) | K7: Fully Wet (Driver+Fuel) | L7: Dry | M7: Wet (Driver) | N7: Fully Wet (Driver+Fuel)
A8: LB-01 | B8: ZA-2609 | C8: Backhoe Loader | D8: JCB 3DX | E8: 2012 | F8: 1640 | G8: 2400 | H8: 3400 | I8: 6200 | J8: 9300 | K8: 12900
A9: LB-02 | B9: ZA-2963 | C9: Backhoe Loader | D9: JCB 3DX | E9: 2012 | F9: 2000 | G9: 2800 | H9: 4150 | I9: 7600 | J9: 10700 | K9: 15800
A10: LB-03 | B10: ZA-2964 | C10: Backhoe Loader | D10: JCB 3DX | E10: 2012 | F10: 2000 | G10: 2800 | H10: 4150 | I10: 7600 | J10: 10700 | K10: 15800
A11: LB-04 | B11: RS-0401 | C11: Backhoe Loader | D11: JCB SLP3CX | E11: 1999 | F11: 1160 | G11: 1950 | H11: 2410 | I11: 4400 | J11: 7500 | K11: 9200
A12: LB-05 | B12: RS-0483 | C12: Backhoe Loader | D12: JCB 3DX | E12: 2006 | F12: 1440 | G12: 2200 | H12: 2990 | I12: 5500 | J12: 8600 | K12: 11400
A13: LB-06 | B13: ZA-0447 | C13: Backhoe Loader | D13: JCB 3CX | E13: 2002 | F13: 1300 | G13: 2100 | H13: 2700 | I13: 4900 | J13: 8000 | K13: 10300
A14: LB-07 | B14: ZA-2608 | C14: Backhoe Loader | D14: JCB JCB 3CX | E14: 2004 | F14: 1300 | G14: 2100 | H14: 2700 | I14: 4900 | J14: 8000 | K14: 10300
A15: LB-08 | B15: ZA-6068 | C15: Backhoe Loader | D15: JCB JCB 3DX | E15: 2015 | F15: 1840 | G15: 2600 | H15: 3820 | I15: 7000 | J15: 10100 | K15: 14500
A16: LB-09 | B16: ZA-6069 | C16: Backhoe Loader | D16: JCB 3DX | E16: 2015 | F16: 2000 | G16: 2800 | H16: 4150 | I16: 7600 | J16: 10700 | K16: 15800
A17: LB-10 | B17: ZA-7034 | C17: Backhoe Loader | D17: JCB JCB 3DX | E17: 2016 | F17: 1840 | G17: 2600 | H17: 3820 | I17: 7000 | J17: 10100 | K17: 14500
A18: LB-11 | B18: ZA-7092 | C18: Backhoe Loader | D18: JCB 3DX | E18: 2016 | F18: 2000 | G18: 2800 | H18: 4150 | I18: 7600 | J18: 10700 | K18: 15800
A19: LB-12 | B19: ZA-8337 | C19: Backhoe Loader | D19: JCB 3DX | E19: 2016 | F19: 1840 | G19: 2600 | H19: 3820 | I19: 7000 | J19: 10100 | K19: 14500
... A222: BM-04 | B222: LN-8278 | C222: Boom Truck | D222: ISUZU KL.FSR34LARFORWARD | E222: 2003 | F222: 1630 | G222: 2400 | H222: 3250 | I222: 6200 | J222: 9300 | K222: 12400
A223: BD-01 | B223: LL-1782 | C223: Prime Mover / Bed | D223: ISUZU GIGA | E223: 1995 | H223: 2810 | I223: 5400 | J223: 8500 | K223: 10700 | L223: 115 | M223: 135 | N223: 285
A224: BD-02 | B224: GL-0019 | C224: Prime Mover / Bed | D224: RENAULT — | E224: 1996 | H224: 2810 | I224: 5400 | J224: 8500 | K224: 10700 | L224: 115 | M224: 135 | N224: 285
A225: BD-03 | B225: LY-1614 | C225: Prime Mover / Bed | D225: TATA LPS4018 | E225: 2011 | H225: 3980 | I225: 7600 | J225: 10700 | K225: 15100 | L225: 115 | M225: 135 | N225: 285
A226: BD-04 | B226: LY-4524 | C226: Prime Mover / Bed | D226: RENAULT PREMIUM | E226: 2012 | H226: 3980 | I226: 7600 | J226: 10700 | K226: 15100 | L226: 115 | M226: 135 | N226: 285
A227: BD-05 | B227: LM-6653 | C227: Prime Mover / Bed | D227: ASHOK LELAND TAURUS 2518 | E227: 2016 | H227: 4460 | I227: 8600 | J227: 11700 | K227: 16900 | L227: 115 | M227: 135 | N227: 285
A228: BD-06 | B228: 325-5120 | C228: Prime Mover / Bed | D228: ASHOK LELAND CAROO 709 | E228: 1998 | H228: 2810 | I228: 5400 | J228: 8500 | K228: 10700 | L228: 115 | M228: 135 | N228: 285
A229: BD-08 | B229: LN-8279 | C229: Prime Mover / Bed | D229: HINO PROFLA | E229: 2008 | H229: 3490 | I229: 6700 | J229: 9800 | K229: 13300 | L229: 115 | M229: 135 | N229: 285
A230: BM-05 | B230: LK-5041 | C230: Prime Mover / Bed | D230: TATA LPT2516 | E230: 2010 | H230: 3980 | I230: 7600 | J230: 10700 | K230: 15100 | L230: 115 | M230: 135 | N230: 285
A231: PC-01 | B231: ZA-8373 | C231: Pump Truck (Concrete) | D231: HINO FS1EWY | E231: 2008 | F231: 3020 | G231: 3800 | H231: 6730 | I231: 11500 | J231: 14600 | K231: 25600
A232: PC-02 | B232: ZB-1496 | C232: Pump Truck (Concrete) | D232: SANY LZZ1BCKH2KW579978 | E232: 2019 | F232: 3860 | G232: 4650 | H232: 8600 | I232: 14700 | J232: 17800 | K232: 32700
A233: DC-06 | B233: PA-4193 | C233: Double Cab (Pickup) | D233: TOYOTA HILUX | E233: 2005 | H233: 1260 | I233: 2600 | J233: 4800 | K233: 4800 | L233: 45 | M233: 70 | N233: 110
A234: DC-07 | B234: 51-8083 | C234: Double Cab (Pickup) | D234: DATZEN MOTOR PIC-UP | E234: — | H234: 1020 | I234: 2100 | J234: 3900 | K234: 3900 | L234: 45 | M234: 70 | N234: 110
A235: DC-08 | B235: 59-5421 | C235: Double Cab (Pickup) | D235: ISUZU MOTOR PIC-UP | E235: 1997 | H235: 1020 | I235: 2100 | J235: 3900 | K235: 3900 | L235: 45 | M235: 70 | N235: 110
A236: DC-10 | B236: 28-4314 | C236: Double Cab (Pickup) | D236: DATZEN MOTOR PIC-UP | E236: 1985 | H236: 1020 | I236: 2100 | J236: 3900 | K236: 3900 | L236: 45 | M236: 70 | N236: 110
A237: DC-11 | B237: HU-5097 | C237: Double Cab (Pickup) | D237: MITSUBISHI L 200 | E237: 2003 | H237: 1140 | I237: 2400 | J237: 4300 | K237: 4300 | L237: 45 | M237: 70 | N237: 110
A238: DC-12 | B238: 253-2574 | C238: Double Cab (Pickup) | D238: MITSUBISHI MOTOR PIC-UP | E238: 1999 | H238: 1020 | I238: 2100 | J238: 3900 | K238: 3900 | L238: 45 | M238: 70 | N238: 110
A239: DC-14 | B239: PD-6917 | C239: Double Cab (Pickup) | D239: MAHINDRA BOLERO CAMPER GOLD | E239: 2011 | H239: 1440 | I239: 3000 | J239: 5500 | K239: 5500 | L239: 45 | M239: 70 | N239: 110
A240: DC-15 | B240: PE-6582 | C240: Double Cab (Pickup) | D240: MITSUBISHI L 200 | E240: 2008 | H240: 1260 | I240: 2600 | J240: 4800 | K240: 4800 | L240: 45 | M240: 70 | N240: 110
A241: DC-16 | B241: PA-4102 | C241: Double Cab (Pickup) | D241: VOLKSWAGON T5 TRANSPORTER | E241: 2005 | H241: 1260 | I241: 2600 | J241: 4800 | K241: 4800 | L241: 45 | M241: 70 | N241: 110
A242: DC-18 | B242: PE-5879 | C242: Double Cab (Pickup) | D242: TOYOTA HILUX VIGO | E242: 2008 | H242: 1260 | I242: 2600 | J242: 4800 | K242: 4800 | L242: 45 | M242: 70 | N242: 110
A243: DC-19 | B243: PD-8451 | C243: Double Cab (Pickup) | D243: TOYOTA HILUX VIGO | E243: 2007 | H243: 1260 | I243: 2600 | J243: 4800 | K243: 4800 | L243: 45 | M243: 70 | N243: 110
A244: DC-20 | B244: PH-0765 | C244: Double Cab (Pickup) | D244: MAHINDRA BOLERO CAMPER GOLD | E244: 2015 | H244: 1610 | I244: 3300 | J244: 6100 | K244: 6100 | L244: 45 | M244: 70 | N244: 110
... A381: — | B381: LX-1045 | C381: Lorry Trailer | D381: (Unknown) — | E381: — | H381: 1280 | I381: 4600 | J381: 4900 | K381: 4900 | L381: 215 | M381: 225 | N381: 255
A382: DB-01 | B382: LA-9208 | C382: Diesel Bowser | D382: TATA 207 DI | E382: 2005 | F382: 970 | G382: 1750 | H382: 1760 | I382: 3700 | J382: 6700 | K382: 6700
...

Sheet Portable Equipment
B2: PORTABLE EQUIPMENT — PER-DAY HIRE
B5: Category | C5: Capacity / Specification | D5: Day Rate — Wet (Rs.) | E5: Day Rate — Dry (Rs.)
B6: Air Compressor | C6: 10–15 HP (industrial) | D6: 6500 | E6: 4500
B7: Air Compressor | C7: 185 cfm (towable diesel) | D7: 16000 | E7: 11000
B8: Air Compressor | C8: 2–3 HP (portable, electric) | D8: 2200 | E8: 1300
B9: Air Compressor | C9: 375 cfm (towable diesel) | D9: 26000 | E9: 18000
B10: Air Compressor | C10: 5–7 HP (belt-drive, petrol) | D10: 3800 | E10: 2400
B11: Angle Grinder | C11: 4–5" (100–125 mm) | D11: 900 | E11: 550
B12: Angle Grinder | C12: 7–9" (180–230 mm) | D12: 1500 | E12: 950
B13: Circular Saw | C13: 14" cut-off / metal saw | D13: 3800 | E13: 2600
B14: Circular Saw | C14: 7" (185 mm, hand-held) | D14: 1200 | E14: 800
B15: Circular Saw | C15: 9" (235 mm, hand-held) | D15: 1700 | E15: 1100
B16: Concrete Mixer | C16: 10/7 cu.ft drum (diesel, one-bag) | D16: 4500 | E16: 3000
B17: Concrete Mixer | C17: 10/7 cu.ft with hopper / hoist | D17: 6500 | E17: 4500
... B46: Welding Plant | C46: 300 A diesel (engine-driven) | D46: 9500 | E46: 6500

Sheet Category Summary
B2: CATEGORY SUMMARY — UNIT COUNTS & AVERAGE DAY RATES
B3: Live figures pulled from the Fleet Rate Card sheet. Day rates in LKR.
B5: Category | C5: Units | D5: Avg Day Dry | E5: Avg Day Wet | F5: Avg Day Fully Wet | G5: Min Day Fully Wet | H5: Max Day Fully Wet
B6: Backhoe Loader | C6: =COUNTIF('Fleet Rate Card'!$C$8:$C$525,$B6) -> 24 | D6: =AVERAGEIF('Fleet Rate Card'!$C$8:$C$525,$B6,'Fleet Rate Card'!$I$8:$I$525) -> 6779.1667 | E6: =AVERAGEIF('Fleet Rate Card'!$C$8:$C$525,$B6,'Fleet Rate Card'!$J$8:$J$525) -> 9879.1667 | F6: =AVERAGEIF('Fleet Rate Card'!$C$8:$C$525,$B6,'Fleet Rate Card'!$K$8:$K$525) -> 14087.5 | G6: {=MIN(IF('Fleet Rate Card'!$C$8:$C$525=$B6,'Fleet Rate Card'!$K$8:$K$525))} -> 9200 | H6: {=MAX(IF('Fleet Rate Card'!$C$8:$C$525=$B6,'Fleet Rate Card'!$K$8:$K$525))} -> 15800
B7: Wheel Loader | C7: =COUNTIF('Fleet Rate Card'!$C$8:$C$525,$B7) -> 9 | D7: =AVERAGEIF('Fleet Rate Card'!$C$8:$C$525,$B7,'Fleet Rate Card'!$I$8:$I$525) -> 12166.667 | E7: =AVERAGEIF('Fleet Rate Card'!$C$8:$C$525,$B7,'Fleet Rate Card'!$J$8:$J$525) -> 15266.667 | F7: =AVERAGEIF('Fleet Rate Card'!$C$8:$C$525,$B7,'Fleet Rate Card'!$K$8:$K$525) -> 26944.444 | G7: {=MIN(IF('Fleet Rate Card'!$C$8:$C$525=$B7,'Fleet Rate Card'!$K$8:$K$525))} -> 23100 | H7: {=MAX(IF('Fleet Rate Card'!$C$8:$C$525=$B7,'Fleet Rate Card'!$K$8:$K$525))} -> 32100
B8: Truck Mixer | C8: =COUNTIF('Fleet Rate Card'!$C$8:$C$525,$B8) -> 16 | D8: =AVERAGEIF('Fleet Rate Card'!$C$8:$C$525,$B8,'Fleet Rate Card'!$I$8:$I$525) -> 7275 | E8: =AVERAGEIF('Fleet Rate Card'!$C$8:$C$525,$B8,'Fleet Rate Card'!$J$8:$J$525) -> 10375 | F8: =AVERAGEIF('Fleet Rate Card'!$C$8:$C$525,$B8,'Fleet Rate Card'!$K$8:$K$525) -> 14350 | G8: {=MIN(IF('Fleet Rate Card'!$C$8:$C$525=$B8,'Fleet Rate Card'!$K$8:$K$525))} -> 10700 | H8: {=MAX(IF('Fleet Rate Card'!$C$8:$C$525=$B8,'Fleet Rate Card'!$K$8:$K$525))} -> 16900
B9: Self Loader Mixer | C9: =COUNTIF('Fleet Rate Card'!$C$8:$C$525,$B9) -> 3 | D9: =AVERAGEIF('Fleet Rate Card'!$C$8:$C$525,$B9,'Fleet Rate Card'!$I$8:$I$525) -> 9300 | E9: =AVERAGEIF('Fleet Rate Card'!$C$8:$C$525,$B9,'Fleet Rate Card'!$J$8:$J$525) -> 12400 | F9: =AVERAGEIF('Fleet Rate Card'!$C$8:$C$525,$B9,'Fleet Rate Card'!$K$8:$K$525) -> 18500 | G9: {=MIN(IF('Fleet Rate Card'!$C$8:$C$525=$B9,'Fleet Rate Card'!$K$8:$K$525))} -> 18500 | H9: {=MAX(IF('Fleet Rate Card'!$C$8:$C$525=$B9,'Fleet Rate Card'!$K$8:$K$525))} -> 18500
B10: Static Roller | C10: =COUNTIF('Fleet Rate Card'!$C$8:$C$525,$B10) -> 19 | D10: =AVERAGEIF('Fleet Rate Card'!$C$8:$C$525,$B10,'Fleet Rate Card'!$I$8:$I$525) -> 6868.4211 | E10: =AVERAGEIF('Fleet Rate Card'!$C$8:$C$525,$B10,'Fleet Rate Card'!$J$8:$J$525) -> 9968.4211 | F10: =AVERAGEIF('Fleet Rate Card'!$C$8:$C$525,$B10,'Fleet Rate Card'!$K$8:$K$525) -> 13673.684 | G10: {=MIN(IF('Fleet Rate Card'!$C$8:$C$525=$B10,'Fleet Rate Card'!$K$8:$K$525))} -> 10100 | H10: {=MAX(IF('Fleet Rate Card'!$C$8:$C$525=$B10,'Fleet Rate Card'!$K$8:$K$525))} -> 17500
B11: Vibrating Roller | C11: =COUNTIF('Fleet Rate Card'!$C$8:$C$525,$B11) -> 72 | D11: =AVERAGEIF('Fleet Rate Card'!$C$8:$C$525,$B11,'Fleet Rate Card'!$I$8:$I$525) -> 5166.6667 | E11: =AVERAGEIF('Fleet Rate Card'!$C$8:$C$525,$B11,'Fleet Rate Card'!$J$8:$J$525) -> 8266.6667 | F11: =AVERAGEIF('Fleet Rate Card'!$C$8:$C$525,$B11,'Fleet Rate Card'!$K$8:$K$525) -> 10333.333 | G11: {=MIN(IF('Fleet Rate Card'!$C$8:$C$525=$B11,'Fleet Rate Card'!$K$8:$K$525))} -> 8600 | H11: {=MAX(IF('Fleet Rate Card'!$C$8:$C$525=$B11,'Fleet Rate Card'!$K$8:$K$525))} -> 13600
B12: Pneumatic Roller | C12: =COUNTIF('Fleet Rate Card'!$C$8:$C$525,$B12) -> 10 | D12: =AVERAGEIF('Fleet Rate Card'!$C$8:$C$525,$B12,'Fleet Rate Card'!$I$8:$I$525) -> 5710 | E12: =AVERAGEIF('Fleet Rate Card'!$C$8:$C$525,$B12,'Fleet Rate Card'!$J$8:$J$525) -> 8810 | F12: =AVERAGEIF('Fleet Rate Card'!$C$8:$C$525,$B12,'Fleet Rate Card'!$K$8:$K$525) -> 11330 | G12: {=MIN(IF('Fleet Rate Card'!$C$8:$C$525=$B12,'Fleet Rate Card'!$K$8:$K$525))} -> 8700 | H12: {=MAX(IF('Fleet Rate Card'!$C$8:$C$525=$B12,'Fleet Rate Card'!$K$8:$K$525))} -> 12300
B13: Motor Grader | C13: =COUNTIF('Fleet Rate Card'!$C$8:$C$525,$B13) -> 16 | D13: =AVERAGEIF('Fleet Rate Card'!$C$8:$C$525,$B13,'Fleet Rate Card'!$I$8:$I$525) -> 12150 | E13: =AVERAGEIF('Fleet Rate Card'!$C$8:$C$525,$B13,'Fleet Rate Card'!$J$8:$J$525) -> 15250 | F13: =AVERAGEIF('Fleet Rate Card'!$C$8:$C$525,$B13,'Fleet Rate Card'!$K$8:$K$525) -> 26981.25 | G13: {=MIN(IF('Fleet Rate Card'!$C$8:$C$525=$B13,'Fleet Rate Card'!$K$8:$K$525))} -> 21300 | H13: {=MAX(IF('Fleet Rate Card'!$C$8:$C$525=$B13,'Fleet Rate Card'!$K$8:$K$525))} -> 36700
B14: Skid Steer | C14: =COUNTIF('Fleet Rate Card'!$C$8:$C$525,$B14) -> 25 | D14: =AVERAGEIF('Fleet Rate Card'!$C$8:$C$525,$B14,'Fleet Rate Card'!$I$8:$I$525) -> 4716 | E14: =AVERAGEIF('Fleet Rate Card'!$C$8:$C$525,$B14,'Fleet Rate Card'!$J$8:$J$525) -> 7816 | F14: =AVERAGEIF('Fleet Rate Card'!$C$8:$C$525,$B14,'Fleet Rate Card'!$K$8:$K$525) -> 9456 | G14: {=MIN(IF('Fleet Rate Card'!$C$8:$C$525=$B14,'Fleet Rate Card'!$K$8:$K$525))} -> 8400 | H14: {=MAX(IF('Fleet Rate Card'!$C$8:$C$525=$B14,'Fleet Rate Card'!$K$8:$K$525))} -> 10300
B15: Asphalt Paver | C15: =COUNTIF('Fleet Rate Card'!$C$8:$C$525,$B15) -> 11 | D15: =AVERAGEIF('Fleet Rate Card'!$C$8:$C$525,$B15,'Fleet Rate Card'!$I$8:$I$525) -> 10827.273 | E15: =AVERAGEIF('Fleet Rate Card'!$C$8:$C$525,$B15,'Fleet Rate Card'!$J$8:$J$525) -> 13927.273 | F15: =AVERAGEIF('Fleet Rate Card'!$C$8:$C$525,$B15,'Fleet Rate Card'!$K$8:$K$525) -> 24254.545 | G15: {=MIN(IF('Fleet Rate Card'!$C$8:$C$525=$B15,'Fleet Rate Card'!$K$8:$K$525))} -> 17700 | H15: {=MAX(IF('Fleet Rate Card'!$C$8:$C$525=$B15,'Fleet Rate Card'!$K$8:$K$525))} -> 30600
B16: Bitumen Bowser | C16: =COUNTIF('Fleet Rate Card'!$C$8:$C$525,$B16) -> 4 | D16: =AVERAGEIF('Fleet Rate Card'!$C$8:$C$525,$B16,'Fleet Rate Card'!$I$8:$I$525) -> 5250 | E16: =AVERAGEIF('Fleet Rate Card'!$C$8:$C$525,$B16,'Fleet Rate Card'!$J$8:$J$525) -> 8350 | F16: =AVERAGEIF('Fleet Rate Card'!$C$8:$C$525,$B16,'Fleet Rate Card'!$K$8:$K$525) -> 10425 | G16: {=MIN(IF('Fleet Rate Card'!$C$8:$C$525=$B16,'Fleet Rate Card'!$K$8:$K$525))} -> 7700 | H16: {=MAX(IF('Fleet Rate Card'!$C$8:$C$525=$B16,'Fleet Rate Card'!$K$8:$K$525))} -> 12200
B17: Mobile Crane | C17: =COUNTIF('Fleet Rate Card'!$C$8:$C$525,$B17) -> 2 | D17: =AVERAGEIF('Fleet Rate Card'!$C$8:$C$525,$B17,'Fleet Rate Card'!$I$8:$I$525) -> 9700 | E17: =AVERAGEIF('Fleet Rate Card'!$C$8:$C$525,$B17,'Fleet Rate Card'!$J$8:$J$525) -> 12800 | F17: =AVERAGEIF('Fleet Rate Card'!$C$8:$C$525,$B17,'Fleet Rate Card'!$K$8:$K$525) -> 19400 | G17: {=MIN(IF('Fleet Rate Card'!$C$8:$C$525=$B17,'Fleet Rate Card'!$K$8:$K$525))} -> 19400 | H17: {=MAX(IF('Fleet Rate Card'!$C$8:$C$525=$B17,'Fleet Rate Card'!$K$8:$K$525))} -> 19400
... B34: Forklift | C34: =COUNTIF('Fleet Rate Card'!$C$8:$C$525,$B34) -> 3 | D34: =AVERAGEIF('Fleet Rate Card'!$C$8:$C$525,$B34,'Fleet Rate Card'!$I$8:$I$525) -> 3400 | E34: =AVERAGEIF('Fleet Rate Card'!$C$8:$C$525,$B34,'Fleet Rate Card'!$J$8:$J$525) -> 6500 | F34: =AVERAGEIF('Fleet Rate Card'!$C$8:$C$525,$B34,'Fleet Rate Card'!$K$8:$K$525) -> 6700 | G34: {=MIN(IF('Fleet Rate Card'!$C$8:$C$525=$B34,'Fleet Rate Card'!$K$8:$K$525))} -> 6700 | H34: {=MAX(IF('Fleet Rate Card'!$C$8:$C$525=$B34,'Fleet Rate Card'!$K$8:$K$525))} -> 6700
B35: TOTAL / FLEET AVG | C35: =SUM(C6:C34) -> 518 | D35: =AVERAGE('Fleet Rate Card'!$I$8:$I$525) -> 5564.8649 | E35: =AVERAGE('Fleet Rate Card'!$J$8:$J$525) -> 8152.8958 | F35: =AVERAGE('Fleet Rate Card'!$K$8:$K$525) -> 11460.811 | G35: =MIN('Fleet Rate Card'!$K$8:$K$525) -> 1100 | H35: =MAX('Fleet Rate Card'!$K$8:$K$525) -> 39900
