Workbook

Sheet README
A1: FLEET & MACHINERY RENTAL PRICE SHEET — 2026 (3-TIER: DRY / DRY+OPERATOR / WET)
A2: Market: Sri Lanka | Currency: LKR, EXCLUDING 18% VAT | Prepared 04-Jul-2026
A4: RATE DEFINITIONS
A5: DRY — Bare machine/vehicle only. Client supplies fuel, operator/driver, lubricants; tolls, fines, operator food at client cost.
A6: DRY + OPERATOR (dry with driver) — Machine + our trained operator/driver. Fuel & lubricants supplied by client. Fleet: DRY + Rs.800/hr operator charge-out. Machinery: DRY + Rs.3,500/day operator (Rs.5,000/day skilled welder/cutter).
A7: WET (fully wet) — Machine + operator + fuel + routine consumables & normal maintenance. Fleet WET = market-engineered 2026 rate card (validated vs SLLDC & private market). Machinery WET = DRY+OPERATOR + fuel for stated duty hours/day at current CPC price.
A9: FUEL BASIS (edit on 'Fuel & Inputs' — every rate recalculates)
A10: CPC/Ceypetco effective 29-Jun-2026: Auto Diesel Rs.382/L • Petrol 92 Rs.414/L. (Super Diesel Rs.478, Petrol 95 Rs.495, Kerosene Rs.285 — eff. 30-May-2026, reference only.)
A11: 2026 context: Middle-East conflict (Feb-26) + LKR depreciation pushed Auto Diesel from Rs.286 (Jan) to Rs.407 (30-May peak); cut back to Rs.382 on 29-Jun-26. Previous workbook v7 used Rs.478 — that is the SUPER Diesel price; corrected here.
A12: Because Auto Diesel Rs.382 equals the March-2026 engineering basis, the engineering cost floors behind the fleet WET card remain valid at today's pump price.
A14: BILLING RULES
A15: Fleet: hourly card. Daily = hourly x 4 hrs min x 0.95 (5% volume disc). Monthly = hourly x 120 hrs min x 0.85 (15% disc). Extra hours at hourly rate.
... A24: SHEETS: Fuel & Inputs (editable drivers) • Fleet Price Sheet (29 categories x 3 tiers, hourly/daily/monthly) • Machinery Price Sheet (76 items, 5 groups, capacities+efficiency+fuel) • Market Analysis (SL market position & findings).

Sheet Fuel & Inputs
A1: GLOBAL INPUTS — edit BLUE cells; all rates in the workbook recalculate
A3: FUEL PRICES (CPC/Ceypetco pump prices)
A4: Auto Diesel (Rs./litre) | C4: 382 | D4: CPC effective 29-Jun-2026 (cut of Rs.25)
A5: Petrol 92 Octane (Rs./litre) | C5: 414 | D5: CPC effective 29-Jun-2026 (cut of Rs.20)
A6: Super Diesel Euro-4 (Rs./litre) | C6: 478 | D6: Reference — eff. 30-May-2026
A7: Petrol 95 Octane (Rs./litre) | C7: 495 | D7: Reference — eff. 30-May-2026
A8: Kerosene (Rs./litre) | C8: 285 | D8: Reference — eff. 30-May-2026
A10: OPERATOR / DRIVER
A11: Fleet operator/driver cost (Rs./hour) | C11: 650 | D11: Management input, Apr-2026
A12: Loading on operator (EPF/ETF, meals, admin) | C12: 1.23 | D12: 23% loading -> charge-out
A13: Fleet operator charge-out (Rs./hour) | C13: =MROUND(C11*C12,50) -> 800 | D13: cost x loading, rounded to 50
A14: Machinery operator (Rs./day, 8-hr) | C14: 3500 | D14: Semi-skilled plant operator, SL 2026
A15: Skilled welder / gas cutter (Rs./day) | C15: 5000 | D15: For welding plant & gas cutting sets
A17: BILLING FACTORS
A18: Machinery standard working day (hrs) | C18: 8 | D18: Duty hrs per item set on Machinery sheet
A19: Fleet daily minimum (hrs) | C19: 4
A20: Fleet monthly minimum (hrs) | C20: 120
A21: Daily volume factor | C21: 0.95 | D21: 5% discount on hourly x 4
A22: Monthly volume factor | C22: 0.85 | D22: 15% discount on hourly x 120
A23: VAT (add on all rates) | C23: 0.18 | D23: Standard SL rate 2026

Sheet Fleet Price Sheet
A1: FLEET PRICE SHEET 2026 — DRY / DRY + OPERATOR / WET (Rs., excl. 18% VAT)
A2: WET = machine+operator+fuel+maintenance (market-engineered card). DRY+OPERATOR = DRY + operator charge-out (Fuel & Inputs C13). Fuel Rs./hr at CPC Auto Diesel eff. 29-Jun-2026 (motorcycle: Petrol 92). Daily = hourly x 4 x 0.95 • Monthly = hourly x 120 x 0.85. Apply per-unit age factors.
A4: # | B4: Category | C4: Fuel L/hr (typ) | D4: Fuel cost Rs./hr | E4: DRY Rs./hr | F4: DRY+OPERATOR Rs./hr | G4: WET Rs./hr | H4: Fuel recovery in WET (Rs./hr) | I4: Margin check | J4: DRY Rs./day (4h) | K4: DRY+OP Rs./day (4h) | L4: WET Rs./day (4h) | M4: DRY Rs./month (120h) | N4: DRY+OP Rs./month (120h) | O4: WET Rs./month (120h) | P4: Market basis (LOW • HIGH source)
A5: 1 | B5: Backhoe Loader | C5: 5.5 | D5: =MROUND(C5*'Fuel & Inputs'!$C$4,10) -> 2100 | E5: 2000 | F5: =MROUND(E5+'Fuel & Inputs'!$C$13,50) -> 2800 | G5: 4150 | H5: =G5-F5 -> 1350 | I5: =IF(C5=0,"n/a",IF(H5>=D5,"OK","THIN")) -> THIN | J5: =MROUND(E5*'Fuel & Inputs'!$C$19*'Fuel & Inputs'!$C$21,100) -> 7600 | K5: =MROUND(F5*'Fuel & Inputs'!$C$19*'Fuel & Inputs'!$C$21,100) -> 10600 | L5: =MROUND(G5*'Fuel & Inputs'!$C$19*'Fuel & Inputs'!$C$21,100) -> 15800 | M5: =MROUND(E5*'Fuel & Inputs'!$C$20*'Fuel & Inputs'!$C$22,500) -> 204000 | N5: =MROUND(F5*'Fuel & Inputs'!$C$20*'Fuel & Inputs'!$C$22,500) -> 285500 | O5: =MROUND(G5*'Fuel & Inputs'!$C$20*'Fuel & Inputs'!$C$22,500) -> 423500 | P5: LOW: small private/Wedabima • HIGH: SLLDC JCB 3CX
A6: 2 | B6: Wheel Loader | C6: 13 | D6: =MROUND(C6*'Fuel & Inputs'!$C$4,10) -> 4970 | E6: 3800 | F6: =MROUND(E6+'Fuel & Inputs'!$C$13,50) -> 4600 | G6: 8450 | H6: =G6-F6 -> 3850 | I6: =IF(C6=0,"n/a",IF(H6>=D6,"OK","THIN")) -> THIN | J6: =MROUND(E6*'Fuel & Inputs'!$C$19*'Fuel & Inputs'!$C$21,100) -> 14400 | K6: =MROUND(F6*'Fuel & Inputs'!$C$19*'Fuel & Inputs'!$C$21,100) -> 17500 | L6: =MROUND(G6*'Fuel & Inputs'!$C$19*'Fuel & Inputs'!$C$21,100) -> 32100 | M6: =MROUND(E6*'Fuel & Inputs'!$C$20*'Fuel & Inputs'!$C$22,500) -> 387500 | N6: =MROUND(F6*'Fuel & Inputs'!$C$20*'Fuel & Inputs'!$C$22,500) -> 469000 | O6: =MROUND(G6*'Fuel & Inputs'!$C$20*'Fuel & Inputs'!$C$22,500) -> 862000 | P6: LOW: used private • HIGH: SLLDC Doosan Mega 250
A7: 3 | B7: Truck Mixer | C7: 7 | D7: =MROUND(C7*'Fuel & Inputs'!$C$4,10) -> 2670 | E7: 2450 | F7: =MROUND(E7+'Fuel & Inputs'!$C$13,50) -> 3250 | G7: 4850 | H7: =G7-F7 -> 1600 | I7: =IF(C7=0,"n/a",IF(H7>=D7,"OK","THIN")) -> THIN | J7: =MROUND(E7*'Fuel & Inputs'!$C$19*'Fuel & Inputs'!$C$21,100) -> 9300 | K7: =MROUND(F7*'Fuel & Inputs'!$C$19*'Fuel & Inputs'!$C$21,100) -> 12400 | L7: =MROUND(G7*'Fuel & Inputs'!$C$19*'Fuel & Inputs'!$C$21,100) -> 18400 | M7: =MROUND(E7*'Fuel & Inputs'!$C$20*'Fuel & Inputs'!$C$22,500) -> 250000 | N7: =MROUND(F7*'Fuel & Inputs'!$C$20*'Fuel & Inputs'!$C$22,500) -> 331500 | O7: =MROUND(G7*'Fuel & Inputs'!$C$20*'Fuel & Inputs'!$C$22,500) -> 494500 | P7: LOW: TATA mixer private • HIGH: large operators
A8: 4 | B8: Self Loader Mixer | C8: 8 | D8: =MROUND(C8*'Fuel & Inputs'!$C$4,10) -> 3060 | E8: 2650 | F8: =MROUND(E8+'Fuel & Inputs'!$C$13,50) -> 3450 | G8: 5300 | H8: =G8-F8 -> 1850 | I8: =IF(C8=0,"n/a",IF(H8>=D8,"OK","THIN")) -> THIN | J8: =MROUND(E8*'Fuel & Inputs'!$C$19*'Fuel & Inputs'!$C$21,100) -> 10100 | K8: =MROUND(F8*'Fuel & Inputs'!$C$19*'Fuel & Inputs'!$C$21,100) -> 13100 | L8: =MROUND(G8*'Fuel & Inputs'!$C$19*'Fuel & Inputs'!$C$21,100) -> 20100 | M8: =MROUND(E8*'Fuel & Inputs'!$C$20*'Fuel & Inputs'!$C$22,500) -> 270500 | N8: =MROUND(F8*'Fuel & Inputs'!$C$20*'Fuel & Inputs'!$C$22,500) -> 352000 | O8: =MROUND(G8*'Fuel & Inputs'!$C$20*'Fuel & Inputs'!$C$22,500) -> 540500 | P8: LOW: FIORI/Ajax private • HIGH: large operators
A9: 5 | B9: Static Roller | C9: 8 | D9: =MROUND(C9*'Fuel & Inputs'!$C$4,10) -> 3060 | E9: 2300 | F9: =MROUND(E9+'Fuel & Inputs'!$C$13,50) -> 3100 | G9: 4600 | H9: =G9-F9 -> 1500 | I9: =IF(C9=0,"n/a",IF(H9>=D9,"OK","THIN")) -> THIN | J9: =MROUND(E9*'Fuel & Inputs'!$C$19*'Fuel & Inputs'!$C$21,100) -> 8700 | K9: =MROUND(F9*'Fuel & Inputs'!$C$19*'Fuel & Inputs'!$C$21,100) -> 11800 | L9: =MROUND(G9*'Fuel & Inputs'!$C$19*'Fuel & Inputs'!$C$21,100) -> 17500 | M9: =MROUND(E9*'Fuel & Inputs'!$C$20*'Fuel & Inputs'!$C$22,500) -> 234500 | N9: =MROUND(F9*'Fuel & Inputs'!$C$20*'Fuel & Inputs'!$C$22,500) -> 316000 | O9: =MROUND(G9*'Fuel & Inputs'!$C$20*'Fuel & Inputs'!$C$22,500) -> 469000 | P9: LOW: private 10T • HIGH: SLLDC HAMM HD12vv
A10: 6 | B10: Vibrating Roller | C10: 5 | D10: =MROUND(C10*'Fuel & Inputs'!$C$4,10) -> 1910 | E10: 1950 | F10: =MROUND(E10+'Fuel & Inputs'!$C$13,50) -> 2750 | G10: 3900 | H10: =G10-F10 -> 1150 | I10: =IF(C10=0,"n/a",IF(H10>=D10,"OK","THIN")) -> THIN | J10: =MROUND(E10*'Fuel & Inputs'!$C$19*'Fuel & Inputs'!$C$21,100) -> 7400 | K10: =MROUND(F10*'Fuel & Inputs'!$C$19*'Fuel & Inputs'!$C$21,100) -> 10500 | L10: =MROUND(G10*'Fuel & Inputs'!$C$19*'Fuel & Inputs'!$C$21,100) -> 14800 | M10: =MROUND(E10*'Fuel & Inputs'!$C$20*'Fuel & Inputs'!$C$22,500) -> 199000 | N10: =MROUND(F10*'Fuel & Inputs'!$C$20*'Fuel & Inputs'!$C$22,500) -> 280500 | O10: =MROUND(G10*'Fuel & Inputs'!$C$20*'Fuel & Inputs'!$C$22,500) -> 398000 | P10: LOW: BOMAG private • HIGH: large private 10T
A11: 7 | B11: Pneumatic Roller | C11: 7 | D11: =MROUND(C11*'Fuel & Inputs'!$C$4,10) -> 2670 | E11: 2000 | F11: =MROUND(E11+'Fuel & Inputs'!$C$13,50) -> 2800 | G11: 3950 | H11: =G11-F11 -> 1150 | I11: =IF(C11=0,"n/a",IF(H11>=D11,"OK","THIN")) -> THIN | J11: =MROUND(E11*'Fuel & Inputs'!$C$19*'Fuel & Inputs'!$C$21,100) -> 7600 | K11: =MROUND(F11*'Fuel & Inputs'!$C$19*'Fuel & Inputs'!$C$21,100) -> 10600 | L11: =MROUND(G11*'Fuel & Inputs'!$C$19*'Fuel & Inputs'!$C$21,100) -> 15000 | M11: =MROUND(E11*'Fuel & Inputs'!$C$20*'Fuel & Inputs'!$C$22,500) -> 204000 | N11: =MROUND(F11*'Fuel & Inputs'!$C$20*'Fuel & Inputs'!$C$22,500) -> 285500 | O11: =MROUND(G11*'Fuel & Inputs'!$C$20*'Fuel & Inputs'!$C$22,500) -> 403000 | P11: LOW: Sakai/Dynapac private • HIGH: premium
A12: 8 | B12: Motor Grader | C12: 15 | D12: =MROUND(C12*'Fuel & Inputs'!$C$4,10) -> 5730 | E12: 4350 | F12: =MROUND(E12+'Fuel & Inputs'!$C$13,50) -> 5150 | G12: 9650 | H12: =G12-F12 -> 4500 | I12: =IF(C12=0,"n/a",IF(H12>=D12,"OK","THIN")) -> THIN | J12: =MROUND(E12*'Fuel & Inputs'!$C$19*'Fuel & Inputs'!$C$21,100) -> 16500 | K12: =MROUND(F12*'Fuel & Inputs'!$C$19*'Fuel & Inputs'!$C$21,100) -> 19600 | L12: =MROUND(G12*'Fuel & Inputs'!$C$19*'Fuel & Inputs'!$C$21,100) -> 36700 | M12: =MROUND(E12*'Fuel & Inputs'!$C$20*'Fuel & Inputs'!$C$22,500) -> 443500 | N12: =MROUND(F12*'Fuel & Inputs'!$C$20*'Fuel & Inputs'!$C$22,500) -> 525500 | O12: =MROUND(G12*'Fuel & Inputs'!$C$20*'Fuel & Inputs'!$C$22,500) -> 984500 | P12: LOW: used CAT private • HIGH: premium/SLLDC class
A13: 9 | B13: Skid Steer | C13: 4.5 | D13: =MROUND(C13*'Fuel & Inputs'!$C$4,10) -> 1720 | E13: 1350 | F13: =MROUND(E13+'Fuel & Inputs'!$C$13,50) -> 2150 | G13: 2700 | H13: =G13-F13 -> 550 | I13: =IF(C13=0,"n/a",IF(H13>=D13,"OK","THIN")) -> THIN | J13: =MROUND(E13*'Fuel & Inputs'!$C$19*'Fuel & Inputs'!$C$21,100) -> 5100 | K13: =MROUND(F13*'Fuel & Inputs'!$C$19*'Fuel & Inputs'!$C$21,100) -> 8200 | L13: =MROUND(G13*'Fuel & Inputs'!$C$19*'Fuel & Inputs'!$C$21,100) -> 10300 | M13: =MROUND(E13*'Fuel & Inputs'!$C$20*'Fuel & Inputs'!$C$22,500) -> 137500 | N13: =MROUND(F13*'Fuel & Inputs'!$C$20*'Fuel & Inputs'!$C$22,500) -> 219500 | O13: =MROUND(G13*'Fuel & Inputs'!$C$20*'Fuel & Inputs'!$C$22,500) -> 275500 | P13: LOW: small private • HIGH: SLLDC Bobcat
A14: 10 | B14: Asphalt Paver | C14: 12 | D14: =MROUND(C14*'Fuel & Inputs'!$C$4,10) -> 4580 | E14: 3600 | F14: =MROUND(E14+'Fuel & Inputs'!$C$13,50) -> 4400 | G14: 8050 | H14: =G14-F14 -> 3650 | I14: =IF(C14=0,"n/a",IF(H14>=D14,"OK","THIN")) -> THIN | J14: =MROUND(E14*'Fuel & Inputs'!$C$19*'Fuel & Inputs'!$C$21,100) -> 13700 | K14: =MROUND(F14*'Fuel & Inputs'!$C$19*'Fuel & Inputs'!$C$21,100) -> 16700 | L14: =MROUND(G14*'Fuel & Inputs'!$C$19*'Fuel & Inputs'!$C$21,100) -> 30600 | M14: =MROUND(E14*'Fuel & Inputs'!$C$20*'Fuel & Inputs'!$C$22,500) -> 367000 | N14: =MROUND(F14*'Fuel & Inputs'!$C$20*'Fuel & Inputs'!$C$22,500) -> 449000 | O14: =MROUND(G14*'Fuel & Inputs'!$C$20*'Fuel & Inputs'!$C$22,500) -> 821000 | P14: LOW: SUMITOMO private • HIGH: VOLVO premium
A15: 11 | B15: Bitumen Bowser | C15: 6.5 | D15: =MROUND(C15*'Fuel & Inputs'!$C$4,10) -> 2480 | E15: 1750 | F15: =MROUND(E15+'Fuel & Inputs'!$C$13,50) -> 2550 | G15: 3500 | H15: =G15-F15 -> 950 | I15: =IF(C15=0,"n/a",IF(H15>=D15,"OK","THIN")) -> THIN | J15: =MROUND(E15*'Fuel & Inputs'!$C$19*'Fuel & Inputs'!$C$21,100) -> 6700 | K15: =MROUND(F15*'Fuel & Inputs'!$C$19*'Fuel & Inputs'!$C$21,100) -> 9700 | L15: =MROUND(G15*'Fuel & Inputs'!$C$19*'Fuel & Inputs'!$C$21,100) -> 13300 | M15: =MROUND(E15*'Fuel & Inputs'!$C$20*'Fuel & Inputs'!$C$22,500) -> 178500 | N15: =MROUND(F15*'Fuel & Inputs'!$C$20*'Fuel & Inputs'!$C$22,500) -> 260000 | O15: =MROUND(G15*'Fuel & Inputs'!$C$20*'Fuel & Inputs'!$C$22,500) -> 357000 | P15: LOW: private 4-cu • HIGH: large insulated
A16: 12 | B16: Mobile Crane | C16: 10 | D16: =MROUND(C16*'Fuel & Inputs'!$C$4,10) -> 3820 | E16: 4400 | F16: =MROUND(E16+'Fuel & Inputs'!$C$13,50) -> 5200 | G16: 8800 | H16: =G16-F16 -> 3600 | I16: =IF(C16=0,"n/a",IF(H16>=D16,"OK","THIN")) -> THIN | J16: =MROUND(E16*'Fuel & Inputs'!$C$19*'Fuel & Inputs'!$C$21,100) -> 16700 | K16: =MROUND(F16*'Fuel & Inputs'!$C$19*'Fuel & Inputs'!$C$21,100) -> 19800 | L16: =MROUND(G16*'Fuel & Inputs'!$C$19*'Fuel & Inputs'!$C$21,100) -> 33400 | M16: =MROUND(E16*'Fuel & Inputs'!$C$20*'Fuel & Inputs'!$C$22,500) -> 449000 | N16: =MROUND(F16*'Fuel & Inputs'!$C$20*'Fuel & Inputs'!$C$22,500) -> 530500 | O16: =MROUND(G16*'Fuel & Inputs'!$C$20*'Fuel & Inputs'!$C$22,500) -> 897500 | P16: LOW: private 25T • HIGH: SLLDC Kobelco RK250
... A24: 20 | B24: Dump Truck (Tipper) | C24: 7.5 | D24: =MROUND(C24*'Fuel & Inputs'!$C$4,10) -> 2870 | E24: 1550 | F24: =MROUND(E24+'Fuel & Inputs'!$C$13,50) -> 2350 | G24: 3250 | H24: =G24-F24 -> 900 | I24: =IF(C24=0,"n/a",IF(H24>=D24,"OK","THIN")) -> THIN | J24: =MROUND(E24*'Fuel & Inputs'!$C$19*'Fuel & Inputs'!$C$21,100) -> 5900 | K24: =MROUND(F24*'Fuel & Inputs'!$C$19*'Fuel & Inputs'!$C$21,100) -> 8900 | L24: =MROUND(G24*'Fuel & Inputs'!$C$19*'Fuel & Inputs'!$C$21,100) -> 12400 | M24: =MROUND(E24*'Fuel & Inputs'!$C$20*'Fuel & Inputs'!$C$22,500) -> 158000 | N24: =MROUND(F24*'Fuel & Inputs'!$C$20*'Fuel & Inputs'!$C$22,500) -> 239500 | O24: =MROUND(G24*'Fuel & Inputs'!$C$20*'Fuel & Inputs'!$C$22,500) -> 331500 | P24: LOW: ikman monthly • HIGH: premium TATA LPK1618
A25: 21 | B25: Trailer (towed) | C25: 0 | D25: =MROUND(C25*'Fuel & Inputs'!$C$4,10) -> 0 | E25: 1250 | F25: =E25 -> 1250 | G25: 1300 | H25: =G25-F25 -> 50 | I25: =IF(C25=0,"n/a",IF(H25>=D25,"OK","THIN")) -> n/a | J25: =MROUND(E25*'Fuel & Inputs'!$C$19*'Fuel & Inputs'!$C$21,100) -> 4800 | K25: =MROUND(F25*'Fuel & Inputs'!$C$19*'Fuel & Inputs'!$C$21,100) -> 4800 | L25: =MROUND(G25*'Fuel & Inputs'!$C$19*'Fuel & Inputs'!$C$21,100) -> 4900 | M25: =MROUND(E25*'Fuel & Inputs'!$C$20*'Fuel & Inputs'!$C$22,500) -> 127500 | N25: =MROUND(F25*'Fuel & Inputs'!$C$20*'Fuel & Inputs'!$C$22,500) -> 127500 | O25: =MROUND(G25*'Fuel & Inputs'!$C$20*'Fuel & Inputs'!$C$22,500) -> 132500 | P25: LOW: tractor trailer private • HIGH: premium
A26: 22 | B26: Lorry Trailer (towed) | C26: 0 | D26: =MROUND(C26*'Fuel & Inputs'!$C$4,10) -> 0 | E26: 2100 | F26: =E26 -> 2100 | G26: 2200 | H26: =G26-F26 -> 100 | I26: =IF(C26=0,"n/a",IF(H26>=D26,"OK","THIN")) -> n/a | J26: =MROUND(E26*'Fuel & Inputs'!$C$19*'Fuel & Inputs'!$C$21,100) -> 8000 | K26: =MROUND(F26*'Fuel & Inputs'!$C$19*'Fuel & Inputs'!$C$21,100) -> 8000 | L26: =MROUND(G26*'Fuel & Inputs'!$C$19*'Fuel & Inputs'!$C$21,100) -> 8400 | M26: =MROUND(E26*'Fuel & Inputs'!$C$20*'Fuel & Inputs'!$C$22,500) -> 214000 | N26: =MROUND(F26*'Fuel & Inputs'!$C$20*'Fuel & Inputs'!$C$22,500) -> 214000 | O26: =MROUND(G26*'Fuel & Inputs'!$C$20*'Fuel & Inputs'!$C$22,500) -> 224500 | P26: LOW: private Tantri • HIGH: Tantri TFB40
A27: 23 | B27: Diesel Bowser | C27: 3.5 | D27: =MROUND(C27*'Fuel & Inputs'!$C$4,10) -> 1340 | E27: 1350 | F27: =MROUND(E27+'Fuel & Inputs'!$C$13,50) -> 2150 | G27: 2450 | H27: =G27-F27 -> 300 | I27: =IF(C27=0,"n/a",IF(H27>=D27,"OK","THIN")) -> THIN | J27: =MROUND(E27*'Fuel & Inputs'!$C$19*'Fuel & Inputs'!$C$21,100) -> 5100 | K27: =MROUND(F27*'Fuel & Inputs'!$C$19*'Fuel & Inputs'!$C$21,100) -> 8200 | L27: =MROUND(G27*'Fuel & Inputs'!$C$19*'Fuel & Inputs'!$C$21,100) -> 9300 | M27: =MROUND(E27*'Fuel & Inputs'!$C$20*'Fuel & Inputs'!$C$22,500) -> 137500 | N27: =MROUND(F27*'Fuel & Inputs'!$C$20*'Fuel & Inputs'!$C$22,500) -> 219500 | O27: =MROUND(G27*'Fuel & Inputs'!$C$20*'Fuel & Inputs'!$C$22,500) -> 250000 | P27: LOW: private fuel bowser • HIGH: large premium
A28: 24 | B28: Excavator (20T class) | C28: 15 | D28: =MROUND(C28*'Fuel & Inputs'!$C$4,10) -> 5730 | E28: 4300 | F28: =MROUND(E28+'Fuel & Inputs'!$C$13,50) -> 5100 | G28: 9550 | H28: =G28-F28 -> 4450 | I28: =IF(C28=0,"n/a",IF(H28>=D28,"OK","THIN")) -> THIN | J28: =MROUND(E28*'Fuel & Inputs'!$C$19*'Fuel & Inputs'!$C$21,100) -> 16300 | K28: =MROUND(F28*'Fuel & Inputs'!$C$19*'Fuel & Inputs'!$C$21,100) -> 19400 | L28: =MROUND(G28*'Fuel & Inputs'!$C$19*'Fuel & Inputs'!$C$21,100) -> 36300 | M28: =MROUND(E28*'Fuel & Inputs'!$C$20*'Fuel & Inputs'!$C$22,500) -> 438500 | N28: =MROUND(F28*'Fuel & Inputs'!$C$20*'Fuel & Inputs'!$C$22,500) -> 520000 | O28: =MROUND(G28*'Fuel & Inputs'!$C$20*'Fuel & Inputs'!$C$22,500) -> 974000 | P28: LOW: 20T Hyundai private • HIGH: SLLDC Doosan DX200
A29: 25 | B29: Water Bowser | C29: 3.5 | D29: =MROUND(C29*'Fuel & Inputs'!$C$4,10) -> 1340 | E29: 1500 | F29: =MROUND(E29+'Fuel & Inputs'!$C$13,50) -> 2300 | G29: 2950 | H29: =G29-F29 -> 650 | I29: =IF(C29=0,"n/a",IF(H29>=D29,"OK","THIN")) -> THIN | J29: =MROUND(E29*'Fuel & Inputs'!$C$19*'Fuel & Inputs'!$C$21,100) -> 5700 | K29: =MROUND(F29*'Fuel & Inputs'!$C$19*'Fuel & Inputs'!$C$21,100) -> 8700 | L29: =MROUND(G29*'Fuel & Inputs'!$C$19*'Fuel & Inputs'!$C$21,100) -> 11200 | M29: =MROUND(E29*'Fuel & Inputs'!$C$20*'Fuel & Inputs'!$C$22,500) -> 153000 | N29: =MROUND(F29*'Fuel & Inputs'!$C$20*'Fuel & Inputs'!$C$22,500) -> 234500 | O29: =MROUND(G29*'Fuel & Inputs'!$C$20*'Fuel & Inputs'!$C$22,500) -> 301000 | P29: LOW: small private • HIGH: SLLDC 6,000L equiv.
A30: 26 | B30: Farm Tractor | C30: 4 | D30: =MROUND(C30*'Fuel & Inputs'!$C$4,10) -> 1530 | E30: 1150 | F30: =MROUND(E30+'Fuel & Inputs'!$C$13,50) -> 1950 | G30: 2100 | H30: =G30-F30 -> 150 | I30: =IF(C30=0,"n/a",IF(H30>=D30,"OK","THIN")) -> THIN | J30: =MROUND(E30*'Fuel & Inputs'!$C$19*'Fuel & Inputs'!$C$21,100) -> 4400 | K30: =MROUND(F30*'Fuel & Inputs'!$C$19*'Fuel & Inputs'!$C$21,100) -> 7400 | L30: =MROUND(G30*'Fuel & Inputs'!$C$19*'Fuel & Inputs'!$C$21,100) -> 8000 | M30: =MROUND(E30*'Fuel & Inputs'!$C$20*'Fuel & Inputs'!$C$22,500) -> 117500 | N30: =MROUND(F30*'Fuel & Inputs'!$C$20*'Fuel & Inputs'!$C$22,500) -> 199000 | O30: =MROUND(G30*'Fuel & Inputs'!$C$20*'Fuel & Inputs'!$C$22,500) -> 214000 | P30: LOW: MASSEY/TAFE private • HIGH: MAHINDRA premium
A31: 27 | B31: Motor Bicycle (self-ride) | C31: 1.2 | D31: =MROUND(C31*'Fuel & Inputs'!$C$5,10) -> 500 | E31: 300 | F31: =E31 -> 300 | G31: 500 | H31: =G31-F31 -> 200 | I31: =IF(C31=0,"n/a",IF(H31>=D31,"OK","THIN")) -> THIN | J31: =MROUND(E31*'Fuel & Inputs'!$C$19*'Fuel & Inputs'!$C$21,100) -> 1100 | K31: =MROUND(F31*'Fuel & Inputs'!$C$19*'Fuel & Inputs'!$C$21,100) -> 1100 | L31: =MROUND(G31*'Fuel & Inputs'!$C$19*'Fuel & Inputs'!$C$21,100) -> 1900 | M31: =MROUND(E31*'Fuel & Inputs'!$C$20*'Fuel & Inputs'!$C$22,500) -> 30500 | N31: =MROUND(F31*'Fuel & Inputs'!$C$20*'Fuel & Inputs'!$C$22,500) -> 30500 | O31: =MROUND(G31*'Fuel & Inputs'!$C$20*'Fuel & Inputs'!$C$22,500) -> 51000 | P31: LOW: staff rental • HIGH: daily hire
A32: 28 | B32: Tractor Bowser | C32: 4.5 | D32: =MROUND(C32*'Fuel & Inputs'!$C$4,10) -> 1720 | E32: 950 | F32: =MROUND(E32+'Fuel & Inputs'!$C$13,50) -> 1750 | G32: 1750 | H32: =G32-F32 -> 0 | I32: =IF(C32=0,"n/a",IF(H32>=D32,"OK","THIN")) -> THIN | J32: =MROUND(E32*'Fuel & Inputs'!$C$19*'Fuel & Inputs'!$C$21,100) -> 3600 | K32: =MROUND(F32*'Fuel & Inputs'!$C$19*'Fuel & Inputs'!$C$21,100) -> 6700 | L32: =MROUND(G32*'Fuel & Inputs'!$C$19*'Fuel & Inputs'!$C$21,100) -> 6700 | M32: =MROUND(E32*'Fuel & Inputs'!$C$20*'Fuel & Inputs'!$C$22,500) -> 97000 | N32: =MROUND(F32*'Fuel & Inputs'!$C$20*'Fuel & Inputs'!$C$22,500) -> 178500 | O32: =MROUND(G32*'Fuel & Inputs'!$C$20*'Fuel & Inputs'!$C$22,500) -> 178500 | P32: LOW: private combo • HIGH: premium combo
A33: 29 | B33: Forklift (3T) | C33: 3.5 | D33: =MROUND(C33*'Fuel & Inputs'!$C$4,10) -> 1340 | E33: 1550 | F33: =MROUND(E33+'Fuel & Inputs'!$C$13,50) -> 2350 | G33: 3050 | H33: =G33-F33 -> 700 | I33: =IF(C33=0,"n/a",IF(H33>=D33,"OK","THIN")) -> THIN | J33: =MROUND(E33*'Fuel & Inputs'!$C$19*'Fuel & Inputs'!$C$21,100) -> 5900 | K33: =MROUND(F33*'Fuel & Inputs'!$C$19*'Fuel & Inputs'!$C$21,100) -> 8900 | L33: =MROUND(G33*'Fuel & Inputs'!$C$19*'Fuel & Inputs'!$C$21,100) -> 11600 | M33: =MROUND(E33*'Fuel & Inputs'!$C$20*'Fuel & Inputs'!$C$22,500) -> 158000 | N33: =MROUND(F33*'Fuel & Inputs'!$C$20*'Fuel & Inputs'!$C$22,500) -> 239500 | O33: =MROUND(G33*'Fuel & Inputs'!$C$20*'Fuel & Inputs'!$C$22,500) -> 311000 | P33: LOW: private 3T • HIGH: premium/specialist
B35: Notes: trailers are towed (no engine/operator) — DRY+OPERATOR = DRY; motorcycle is self-ride, WET includes Petrol-92 for staff duty use. 'Margin check' = does the WET-vs-DRY+OPERATOR gap cover fuel at today's CPC price? THIN rows: attach the fuel escalation clause (README) and/or bill fuel actuals via the timesheet calculator.

Sheet Fleet — Per Unit
A1: FLEET — UNIT-BY-UNIT PRICE LIST 2026 (518 units) — DRY / DRY + OPERATOR / WET (Rs., excl. 18% VAT)
A2: Per-unit DRY & WET carried over from the engineered Fleet Pricing card (age & size adjusted). DRY+OPERATOR = DRY + operator charge-out (Fuel & Inputs C13; trailers are towed and motorcycles self-ride — no operator added). Per-unit fuel = model-class typical consumption x age factor x CPC price (Auto Diesel Rs.382 / Petrol-92 Rs.414, eff. 29-Jun-2026); road vehicles shown in Rs./km. Daily = hourly x 4 x 0.95 • Monthly = hourly x 120 x 0.85.
A4: # | B4: Category | C4: Brand | D4: Model | E4: Year | F4: E&C No. | G4: Reg No. | H4: Fuel | I4: Cons. (typ) L/hr | km/L | J4: Age factor | K4: Fuel rate | L4: Unit | M4: DRY Rs./hr | N4: DRY+OPERATOR Rs./hr | O4: WET Rs./hr | P4: DRY Rs./day (4h) | Q4: DRY+OP Rs./day (4h) | R4: WET Rs./day (4h) | S4: DRY Rs./mo (120h) | T4: DRY+OP Rs./mo (120h) | U4: WET Rs./mo (120h)
A5: BACKHOE LOADER
A6: 1 | B6: Backhoe Loader | C6: BOB CAT | D6: B760 | E6: 2021 | F6: LB-22 | G6: ZB-2586 | H6: Diesel | I6: 7 | J6: 1.035 | K6: =IF(I6=0,0,IF(L6="Rs./km",MROUND(IF(H6="Petrol",'Fuel & Inputs'!$C$5,'Fuel & Inputs'!$C$4)/I6*J6,1),MROUND(I6*J6*IF(H6="Petrol",'Fuel & Inputs'!$C$5,'Fuel & Inputs'!$C$4),10))) -> 2770 | L6: Rs./hr | M6: 2000 | N6: =MROUND(M6+'Fuel & Inputs'!$C$13,50) -> 2800 | O6: 4150 | P6: =MROUND(M6*'Fuel & Inputs'!$C$19*'Fuel & Inputs'!$C$21,100) -> 7600 | Q6: =MROUND(N6*'Fuel & Inputs'!$C$19*'Fuel & Inputs'!$C$21,100) -> 10600 | R6: =MROUND(O6*'Fuel & Inputs'!$C$19*'Fuel & Inputs'!$C$21,100) -> 15800 | S6: =MROUND(M6*'Fuel & Inputs'!$C$20*'Fuel & Inputs'!$C$22,500) -> 204000 | T6: =MROUND(N6*'Fuel & Inputs'!$C$20*'Fuel & Inputs'!$C$22,500) -> 285500 | U6: =MROUND(O6*'Fuel & Inputs'!$C$20*'Fuel & Inputs'!$C$22,500) -> 423500
A7: 2 | B7: Backhoe Loader | C7: BOB CAT | D7: B760 | E7: 2021 | F7: LB-23 | G7: ZB-2587 | H7: Diesel | I7: 7 | J7: 1.035 | K7: =IF(I7=0,0,IF(L7="Rs./km",MROUND(IF(H7="Petrol",'Fuel & Inputs'!$C$5,'Fuel & Inputs'!$C$4)/I7*J7,1),MROUND(I7*J7*IF(H7="Petrol",'Fuel & Inputs'!$C$5,'Fuel & Inputs'!$C$4),10))) -> 2770 | L7: Rs./hr | M7: 2000 | N7: =MROUND(M7+'Fuel & Inputs'!$C$13,50) -> 2800 | O7: 4150 | P7: =MROUND(M7*'Fuel & Inputs'!$C$19*'Fuel & Inputs'!$C$21,100) -> 7600 | Q7: =MROUND(N7*'Fuel & Inputs'!$C$19*'Fuel & Inputs'!$C$21,100) -> 10600 | R7: =MROUND(O7*'Fuel & Inputs'!$C$19*'Fuel & Inputs'!$C$21,100) -> 15800 | S7: =MROUND(M7*'Fuel & Inputs'!$C$20*'Fuel & Inputs'!$C$22,500) -> 204000 | T7: =MROUND(N7*'Fuel & Inputs'!$C$20*'Fuel & Inputs'!$C$22,500) -> 285500 | U7: =MROUND(O7*'Fuel & Inputs'!$C$20*'Fuel & Inputs'!$C$22,500) -> 423500
A8: 3 | B8: Backhoe Loader | C8: BOB CAT | D8: B760 | E8: 2021 | F8: LB-24 | G8: ZB-2583 | H8: Diesel | I8: 7 | J8: 1.035 | K8: =IF(I8=0,0,IF(L8="Rs./km",MROUND(IF(H8="Petrol",'Fuel & Inputs'!$C$5,'Fuel & Inputs'!$C$4)/I8*J8,1),MROUND(I8*J8*IF(H8="Petrol",'Fuel & Inputs'!$C$5,'Fuel & Inputs'!$C$4),10))) -> 2770 | L8: Rs./hr | M8: 2000 | N8: =MROUND(M8+'Fuel & Inputs'!$C$13,50) -> 2800 | O8: 4150 | P8: =MROUND(M8*'Fuel & Inputs'!$C$19*'Fuel & Inputs'!$C$21,100) -> 7600 | Q8: =MROUND(N8*'Fuel & Inputs'!$C$19*'Fuel & Inputs'!$C$21,100) -> 10600 | R8: =MROUND(O8*'Fuel & Inputs'!$C$19*'Fuel & Inputs'!$C$21,100) -> 15800 | S8: =MROUND(M8*'Fuel & Inputs'!$C$20*'Fuel & Inputs'!$C$22,500) -> 204000 | T8: =MROUND(N8*'Fuel & Inputs'!$C$20*'Fuel & Inputs'!$C$22,500) -> 285500 | U8: =MROUND(O8*'Fuel & Inputs'!$C$20*'Fuel & Inputs'!$C$22,500) -> 423500
A9: 4 | B9: Backhoe Loader | C9: J.C.B | D9: 3DX | E9: 2020 | F9: LB-16 | G9: ZB-1547 | H9: Diesel | I9: 7 | J9: 1.042 | K9: =IF(I9=0,0,IF(L9="Rs./km",MROUND(IF(H9="Petrol",'Fuel & Inputs'!$C$5,'Fuel & Inputs'!$C$4)/I9*J9,1),MROUND(I9*J9*IF(H9="Petrol",'Fuel & Inputs'!$C$5,'Fuel & Inputs'!$C$4),10))) -> 2790 | L9: Rs./hr | M9: 2000 | N9: =MROUND(M9+'Fuel & Inputs'!$C$13,50) -> 2800 | O9: 4150 | P9: =MROUND(M9*'Fuel & Inputs'!$C$19*'Fuel & Inputs'!$C$21,100) -> 7600 | Q9: =MROUND(N9*'Fuel & Inputs'!$C$19*'Fuel & Inputs'!$C$21,100) -> 10600 | R9: =MROUND(O9*'Fuel & Inputs'!$C$19*'Fuel & Inputs'!$C$21,100) -> 15800 | S9: =MROUND(M9*'Fuel & Inputs'!$C$20*'Fuel & Inputs'!$C$22,500) -> 204000 | T9: =MROUND(N9*'Fuel & Inputs'!$C$20*'Fuel & Inputs'!$C$22,500) -> 285500 | U9: =MROUND(O9*'Fuel & Inputs'!$C$20*'Fuel & Inputs'!$C$22,500) -> 423500
A10: 5 | B10: Backhoe Loader | C10: JCB | D10: 3DX | E10: 2012 | F10: LB-02 | G10: ZA-2963 | H10: Diesel | I10: 7 | J10: 1.098 | K10: =IF(I10=0,0,IF(L10="Rs./km",MROUND(IF(H10="Petrol",'Fuel & Inputs'!$C$5,'Fuel & Inputs'!$C$4)/I10*J10,1),MROUND(I10*J10*IF(H10="Petrol",'Fuel & Inputs'!$C$5,'Fuel & Inputs'!$C$4),10))) -> 2940 | L10: Rs./hr | M10: 2000 | N10: =MROUND(M10+'Fuel & Inputs'!$C$13,50) -> 2800 | O10: 4150 | P10: =MROUND(M10*'Fuel & Inputs'!$C$19*'Fuel & Inputs'!$C$21,100) -> 7600 | Q10: =MROUND(N10*'Fuel & Inputs'!$C$19*'Fuel & Inputs'!$C$21,100) -> 10600 | R10: =MROUND(O10*'Fuel & Inputs'!$C$19*'Fuel & Inputs'!$C$21,100) -> 15800 | S10: =MROUND(M10*'Fuel & Inputs'!$C$20*'Fuel & Inputs'!$C$22,500) -> 204000 | T10: =MROUND(N10*'Fuel & Inputs'!$C$20*'Fuel & Inputs'!$C$22,500) -> 285500 | U10: =MROUND(O10*'Fuel & Inputs'!$C$20*'Fuel & Inputs'!$C$22,500) -> 423500
A11: 6 | B11: Backhoe Loader | C11: JCB | D11: 3DX | E11: 2012 | F11: LB-03 | G11: ZA-2964 | H11: Diesel | I11: 7 | J11: 1.098 | K11: =IF(I11=0,0,IF(L11="Rs./km",MROUND(IF(H11="Petrol",'Fuel & Inputs'!$C$5,'Fuel & Inputs'!$C$4)/I11*J11,1),MROUND(I11*J11*IF(H11="Petrol",'Fuel & Inputs'!$C$5,'Fuel & Inputs'!$C$4),10))) -> 2940 | L11: Rs./hr | M11: 2000 | N11: =MROUND(M11+'Fuel & Inputs'!$C$13,50) -> 2800 | O11: 4150 | P11: =MROUND(M11*'Fuel & Inputs'!$C$19*'Fuel & Inputs'!$C$21,100) -> 7600 | Q11: =MROUND(N11*'Fuel & Inputs'!$C$19*'Fuel & Inputs'!$C$21,100) -> 10600 | R11: =MROUND(O11*'Fuel & Inputs'!$C$19*'Fuel & Inputs'!$C$21,100) -> 15800 | S11: =MROUND(M11*'Fuel & Inputs'!$C$20*'Fuel & Inputs'!$C$22,500) -> 204000 | T11: =MROUND(N11*'Fuel & Inputs'!$C$20*'Fuel & Inputs'!$C$22,500) -> 285500 | U11: =MROUND(O11*'Fuel & Inputs'!$C$20*'Fuel & Inputs'!$C$22,500) -> 423500
A12: 7 | B12: Backhoe Loader | C12: JCB | D12: 3DX | E12: 2015 | F12: LB-09 | G12: ZA-6069 | H12: Diesel | I12: 7 | J12: 1.077 | K12: =IF(I12=0,0,IF(L12="Rs./km",MROUND(IF(H12="Petrol",'Fuel & Inputs'!$C$5,'Fuel & Inputs'!$C$4)/I12*J12,1),MROUND(I12*J12*IF(H12="Petrol",'Fuel & Inputs'!$C$5,'Fuel & Inputs'!$C$4),10))) -> 2880 | L12: Rs./hr | M12: 2000 | N12: =MROUND(M12+'Fuel & Inputs'!$C$13,50) -> 2800 | O12: 4150 | P12: =MROUND(M12*'Fuel & Inputs'!$C$19*'Fuel & Inputs'!$C$21,100) -> 7600 | Q12: =MROUND(N12*'Fuel & Inputs'!$C$19*'Fuel & Inputs'!$C$21,100) -> 10600 | R12: =MROUND(O12*'Fuel & Inputs'!$C$19*'Fuel & Inputs'!$C$21,100) -> 15800 | S12: =MROUND(M12*'Fuel & Inputs'!$C$20*'Fuel & Inputs'!$C$22,500) -> 204000 | T12: =MROUND(N12*'Fuel & Inputs'!$C$20*'Fuel & Inputs'!$C$22,500) -> 285500 | U12: =MROUND(O12*'Fuel & Inputs'!$C$20*'Fuel & Inputs'!$C$22,500) -> 423500
A13: 8 | B13: Backhoe Loader | C13: JCB | D13: 3DX | E13: 2016 | F13: LB-11 | G13: ZA-7092 | H13: Diesel | I13: 7 | J13: 1.07 | K13: =IF(I13=0,0,IF(L13="Rs./km",MROUND(IF(H13="Petrol",'Fuel & Inputs'!$C$5,'Fuel & Inputs'!$C$4)/I13*J13,1),MROUND(I13*J13*IF(H13="Petrol",'Fuel & Inputs'!$C$5,'Fuel & Inputs'!$C$4),10))) -> 2860 | L13: Rs./hr | M13: 2000 | N13: =MROUND(M13+'Fuel & Inputs'!$C$13,50) -> 2800 | O13: 4150 | P13: =MROUND(M13*'Fuel & Inputs'!$C$19*'Fuel & Inputs'!$C$21,100) -> 7600 | Q13: =MROUND(N13*'Fuel & Inputs'!$C$19*'Fuel & Inputs'!$C$21,100) -> 10600 | R13: =MROUND(O13*'Fuel & Inputs'!$C$19*'Fuel & Inputs'!$C$21,100) -> 15800 | S13: =MROUND(M13*'Fuel & Inputs'!$C$20*'Fuel & Inputs'!$C$22,500) -> 204000 | T13: =MROUND(N13*'Fuel & Inputs'!$C$20*'Fuel & Inputs'!$C$22,500) -> 285500 | U13: =MROUND(O13*'Fuel & Inputs'!$C$20*'Fuel & Inputs'!$C$22,500) -> 423500
A14: 9 | B14: Backhoe Loader | C14: JCB | D14: 3DX | E14: 2016 | F14: LB-13 | G14: ZA-7965 | H14: Diesel | I14: 7 | J14: 1.07 | K14: =IF(I14=0,0,IF(L14="Rs./km",MROUND(IF(H14="Petrol",'Fuel & Inputs'!$C$5,'Fuel & Inputs'!$C$4)/I14*J14,1),MROUND(I14*J14*IF(H14="Petrol",'Fuel & Inputs'!$C$5,'Fuel & Inputs'!$C$4),10))) -> 2860 | L14: Rs./hr | M14: 2000 | N14: =MROUND(M14+'Fuel & Inputs'!$C$13,50) -> 2800 | O14: 4150 | P14: =MROUND(M14*'Fuel & Inputs'!$C$19*'Fuel & Inputs'!$C$21,100) -> 7600 | Q14: =MROUND(N14*'Fuel & Inputs'!$C$19*'Fuel & Inputs'!$C$21,100) -> 10600 | R14: =MROUND(O14*'Fuel & Inputs'!$C$19*'Fuel & Inputs'!$C$21,100) -> 15800 | S14: =MROUND(M14*'Fuel & Inputs'!$C$20*'Fuel & Inputs'!$C$22,500) -> 204000 | T14: =MROUND(N14*'Fuel & Inputs'!$C$20*'Fuel & Inputs'!$C$22,500) -> 285500 | U14: =MROUND(O14*'Fuel & Inputs'!$C$20*'Fuel & Inputs'!$C$22,500) -> 423500
A15: 10 | B15: Backhoe Loader | C15: J.C.B | D15: 570ST | E15: 2019 | F15: LB-15 | G15: ZB-1047 | H15: Diesel | I15: 7 | J15: 1.049 | K15: =IF(I15=0,0,IF(L15="Rs./km",MROUND(IF(H15="Petrol",'Fuel & Inputs'!$C$5,'Fuel & Inputs'!$C$4)/I15*J15,1),MROUND(I15*J15*IF(H15="Petrol",'Fuel & Inputs'!$C$5,'Fuel & Inputs'!$C$4),10))) -> 2810 | L15: Rs./hr | M15: 1840 | N15: =MROUND(M15+'Fuel & Inputs'!$C$13,50) -> 2650 | O15: 3820 | P15: =MROUND(M15*'Fuel & Inputs'!$C$19*'Fuel & Inputs'!$C$21,100) -> 7000 | Q15: =MROUND(N15*'Fuel & Inputs'!$C$19*'Fuel & Inputs'!$C$21,100) -> 10100 | R15: =MROUND(O15*'Fuel & Inputs'!$C$19*'Fuel & Inputs'!$C$21,100) -> 14500 | S15: =MROUND(M15*'Fuel & Inputs'!$C$20*'Fuel & Inputs'!$C$22,500) -> 187500 | T15: =MROUND(N15*'Fuel & Inputs'!$C$20*'Fuel & Inputs'!$C$22,500) -> 270500 | U15: =MROUND(O15*'Fuel & Inputs'!$C$20*'Fuel & Inputs'!$C$22,500) -> 389500
A16: 11 | B16: Backhoe Loader | C16: JCB | D16: JCB 3DX | E16: 2016 | F16: LB-10 | G16: ZA-7034 | H16: Diesel | I16: 7 | J16: 1.07 | K16: =IF(I16=0,0,IF(L16="Rs./km",MROUND(IF(H16="Petrol",'Fuel & Inputs'!$C$5,'Fuel & Inputs'!$C$4)/I16*J16,1),MROUND(I16*J16*IF(H16="Petrol",'Fuel & Inputs'!$C$5,'Fuel & Inputs'!$C$4),10))) -> 2860 | L16: Rs./hr | M16: 1840 | N16: =MROUND(M16+'Fuel & Inputs'!$C$13,50) -> 2650 | O16: 3820 | P16: =MROUND(M16*'Fuel & Inputs'!$C$19*'Fuel & Inputs'!$C$21,100) -> 7000 | Q16: =MROUND(N16*'Fuel & Inputs'!$C$19*'Fuel & Inputs'!$C$21,100) -> 10100 | R16: =MROUND(O16*'Fuel & Inputs'!$C$19*'Fuel & Inputs'!$C$21,100) -> 14500 | S16: =MROUND(M16*'Fuel & Inputs'!$C$20*'Fuel & Inputs'!$C$22,500) -> 187500 | T16: =MROUND(N16*'Fuel & Inputs'!$C$20*'Fuel & Inputs'!$C$22,500) -> 270500 | U16: =MROUND(O16*'Fuel & Inputs'!$C$20*'Fuel & Inputs'!$C$22,500) -> 389500
A17: 12 | B17: Backhoe Loader | C17: JCB | D17: JCB 3DX | E17: 2016 | F17: LB-14 | G17: ZA-7968 | H17: Diesel | I17: 7 | J17: 1.07 | K17: =IF(I17=0,0,IF(L17="Rs./km",MROUND(IF(H17="Petrol",'Fuel & Inputs'!$C$5,'Fuel & Inputs'!$C$4)/I17*J17,1),MROUND(I17*J17*IF(H17="Petrol",'Fuel & Inputs'!$C$5,'Fuel & Inputs'!$C$4),10))) -> 2860 | L17: Rs./hr | M17: 1840 | N17: =MROUND(M17+'Fuel & Inputs'!$C$13,50) -> 2650 | O17: 3820 | P17: =MROUND(M17*'Fuel & Inputs'!$C$19*'Fuel & Inputs'!$C$21,100) -> 7000 | Q17: =MROUND(N17*'Fuel & Inputs'!$C$19*'Fuel & Inputs'!$C$21,100) -> 10100 | R17: =MROUND(O17*'Fuel & Inputs'!$C$19*'Fuel & Inputs'!$C$21,100) -> 14500 | S17: =MROUND(M17*'Fuel & Inputs'!$C$20*'Fuel & Inputs'!$C$22,500) -> 187500 | T17: =MROUND(N17*'Fuel & Inputs'!$C$20*'Fuel & Inputs'!$C$22,500) -> 270500 | U17: =MROUND(O17*'Fuel & Inputs'!$C$20*'Fuel & Inputs'!$C$22,500) -> 389500
... A29: 24 | B29: Backhoe Loader | C29: JCB | D29: SLP3CX | E29: 1999 | F29: LB-04 | G29: RS-0401 | H29: Diesel | I29: 7 | J29: 1.175 | K29: =IF(I29=0,0,IF(L29="Rs./km",MROUND(IF(H29="Petrol",'Fuel & Inputs'!$C$5,'Fuel & Inputs'!$C$4)/I29*J29,1),MROUND(I29*J29*IF(H29="Petrol",'Fuel & Inputs'!$C$5,'Fuel & Inputs'!$C$4),10))) -> 3140 | L29: Rs./hr | M29: 1160 | N29: =MROUND(M29+'Fuel & Inputs'!$C$13,50) -> 1950 | O29: 2410 | P29: =MROUND(M29*'Fuel & Inputs'!$C$19*'Fuel & Inputs'!$C$21,100) -> 4400 | Q29: =MROUND(N29*'Fuel & Inputs'!$C$19*'Fuel & Inputs'!$C$21,100) -> 7400 | R29: =MROUND(O29*'Fuel & Inputs'!$C$19*'Fuel & Inputs'!$C$21,100) -> 9200 | S29: =MROUND(M29*'Fuel & Inputs'!$C$20*'Fuel & Inputs'!$C$22,500) -> 118500 | T29: =MROUND(N29*'Fuel & Inputs'!$C$20*'Fuel & Inputs'!$C$22,500) -> 199000 | U29: =MROUND(O29*'Fuel & Inputs'!$C$20*'Fuel & Inputs'!$C$22,500) -> 246000
A30: WHEEL LOADER
A31: 25 | B31: Wheel Loader | C31: SHANTUI | D31: SL-50WN | E31: 2020 | F31: LD-09 | G31: — | H31: Diesel | I31: 15 | J31: 1.042 | K31: =IF(I31=0,0,IF(L31="Rs./km",MROUND(IF(H31="Petrol",'Fuel & Inputs'!$C$5,'Fuel & Inputs'!$C$4)/I31*J31,1),MROUND(I31*J31*IF(H31="Petrol",'Fuel & Inputs'!$C$5,'Fuel & Inputs'!$C$4),10))) -> 5970 | L31: Rs./hr | M31: 3800 | N31: =MROUND(M31+'Fuel & Inputs'!$C$13,50) -> 4600 | O31: 8450 | P31: =MROUND(M31*'Fuel & Inputs'!$C$19*'Fuel & Inputs'!$C$21,100) -> 14400 | Q31: =MROUND(N31*'Fuel & Inputs'!$C$19*'Fuel & Inputs'!$C$21,100) -> 17500 | R31: =MROUND(O31*'Fuel & Inputs'!$C$19*'Fuel & Inputs'!$C$21,100) -> 32100 | S31: =MROUND(M31*'Fuel & Inputs'!$C$20*'Fuel & Inputs'!$C$22,500) -> 387500 | T31: =MROUND(N31*'Fuel & Inputs'!$C$20*'Fuel & Inputs'!$C$22,500) -> 469000 | U31: =MROUND(O31*'Fuel & Inputs'!$C$20*'Fuel & Inputs'!$C$22,500) -> 862000
A32: 26 | B32: Wheel Loader | C32: KOMATSU | D32: WA-80SS | E32: 2015 | F32: LD-07 | G32: — | H32: Diesel | I32: 8 | J32: 1.077 | K32: =IF(I32=0,0,IF(L32="Rs./km",MROUND(IF(H32="Petrol",'Fuel & Inputs'!$C$5,'Fuel & Inputs'!$C$4)/I32*J32,1),MROUND(I32*J32*IF(H32="Petrol",'Fuel & Inputs'!$C$5,'Fuel & Inputs'!$C$4),10))) -> 3290 | L32: Rs./hr | M32: 3500 | N32: =MROUND(M32+'Fuel & Inputs'!$C$13,50) -> 4300 | O32: 7770 | P32: =MROUND(M32*'Fuel & Inputs'!$C$19*'Fuel & Inputs'!$C$21,100) -> 13300 | Q32: =MROUND(N32*'Fuel & Inputs'!$C$19*'Fuel & Inputs'!$C$21,100) -> 16300 | R32: =MROUND(O32*'Fuel & Inputs'!$C$19*'Fuel & Inputs'!$C$21,100) -> 29500 | S32: =MROUND(M32*'Fuel & Inputs'!$C$20*'Fuel & Inputs'!$C$22,500) -> 357000 | T32: =MROUND(N32*'Fuel & Inputs'!$C$20*'Fuel & Inputs'!$C$22,500) -> 438500 | U32: =MROUND(O32*'Fuel & Inputs'!$C$20*'Fuel & Inputs'!$C$22,500) -> 792500
A33: 27 | B33: Wheel Loader | C33: KOMATSU | D33: WA150 | E33: 2014 | F33: LD-05 | G33: — | H33: Diesel | I33: 12 | J33: 1.084 | K33: =IF(I33=0,0,IF(L33="Rs./km",MROUND(IF(H33="Petrol",'Fuel & Inputs'!$C$5,'Fuel & Inputs'!$C$4)/I33*J33,1),MROUND(I33*J33*IF(H33="Petrol",'Fuel & Inputs'!$C$5,'Fuel & Inputs'!$C$4),10))) -> 4970 | L33: Rs./hr | M33: 3120 | N33: =MROUND(M33+'Fuel & Inputs'!$C$13,50) -> 3900 | O33: 6930 | P33: =MROUND(M33*'Fuel & Inputs'!$C$19*'Fuel & Inputs'!$C$21,100) -> 11900 | Q33: =MROUND(N33*'Fuel & Inputs'!$C$19*'Fuel & Inputs'!$C$21,100) -> 14800 | R33: =MROUND(O33*'Fuel & Inputs'!$C$19*'Fuel & Inputs'!$C$21,100) -> 26300 | S33: =MROUND(M33*'Fuel & Inputs'!$C$20*'Fuel & Inputs'!$C$22,500) -> 318000 | T33: =MROUND(N33*'Fuel & Inputs'!$C$20*'Fuel & Inputs'!$C$22,500) -> 398000 | U33: =MROUND(O33*'Fuel & Inputs'!$C$20*'Fuel & Inputs'!$C$22,500) -> 707000
A34: 28 | B34: Wheel Loader | C34: SANTUI | D34: SL30W | E34: 2014 | F34: LD-08 | G34: — | H34: Diesel | I34: 9 | J34: 1.084 | K34: =IF(I34=0,0,IF(L34="Rs./km",MROUND(IF(H34="Petrol",'Fuel & Inputs'!$C$5,'Fuel & Inputs'!$C$4)/I34*J34,1),MROUND(I34*J34*IF(H34="Petrol",'Fuel & Inputs'!$C$5,'Fuel & Inputs'!$C$4),10))) -> 3730 | L34: Rs./hr | M34: 3120 | N34: =MROUND(M34+'Fuel & Inputs'!$C$13,50) -> 3900 | O34: 6930 | P34: =MROUND(M34*'Fuel & Inputs'!$C$19*'Fuel & Inputs'!$C$21,100) -> 11900 | Q34: =MROUND(N34*'Fuel & Inputs'!$C$19*'Fuel & Inputs'!$C$21,100) -> 14800 | R34: =MROUND(O34*'Fuel & Inputs'!$C$19*'Fuel & Inputs'!$C$21,100) -> 26300 | S34: =MROUND(M34*'Fuel & Inputs'!$C$20*'Fuel & Inputs'!$C$22,500) -> 318000 | T34: =MROUND(N34*'Fuel & Inputs'!$C$20*'Fuel & Inputs'!$C$22,500) -> 398000 | U34: =MROUND(O34*'Fuel & Inputs'!$C$20*'Fuel & Inputs'!$C$22,500) -> 707000
A35: 29 | B35: Wheel Loader | C35: KOMATSU | D35: 924F | E35: 2013 | F35: LD-04 | G35: — | H35: Diesel | I35: 12 | J35: 1.091 | K35: =IF(I35=0,0,IF(L35="Rs./km",MROUND(IF(H35="Petrol",'Fuel & Inputs'!$C$5,'Fuel & Inputs'!$C$4)/I35*J35,1),MROUND(I35*J35*IF(H35="Petrol",'Fuel & Inputs'!$C$5,'Fuel & Inputs'!$C$4),10))) -> 5000 | L35: Rs./hr | M35: 3120 | N35: =MROUND(M35+'Fuel & Inputs'!$C$13,50) -> 3900 | O35: 6930 | P35: =MROUND(M35*'Fuel & Inputs'!$C$19*'Fuel & Inputs'!$C$21,100) -> 11900 | Q35: =MROUND(N35*'Fuel & Inputs'!$C$19*'Fuel & Inputs'!$C$21,100) -> 14800 | R35: =MROUND(O35*'Fuel & Inputs'!$C$19*'Fuel & Inputs'!$C$21,100) -> 26300 | S35: =MROUND(M35*'Fuel & Inputs'!$C$20*'Fuel & Inputs'!$C$22,500) -> 318000 | T35: =MROUND(N35*'Fuel & Inputs'!$C$20*'Fuel & Inputs'!$C$22,500) -> 398000 | U35: =MROUND(O35*'Fuel & Inputs'!$C$20*'Fuel & Inputs'!$C$22,500) -> 707000
A36: 30 | B36: Wheel Loader | C36: KOMATSU | D36: 510 | E36: 2013 | F36: LD-06 | G36: ZA-3116 | H36: Diesel | I36: 11 | J36: 1.091 | K36: =IF(I36=0,0,IF(L36="Rs./km",MROUND(IF(H36="Petrol",'Fuel & Inputs'!$C$5,'Fuel & Inputs'!$C$4)/I36*J36,1),MROUND(I36*J36*IF(H36="Petrol",'Fuel & Inputs'!$C$5,'Fuel & Inputs'!$C$4),10))) -> 4580 | L36: Rs./hr | M36: 3120 | N36: =MROUND(M36+'Fuel & Inputs'!$C$13,50) -> 3900 | O36: 6930 | P36: =MROUND(M36*'Fuel & Inputs'!$C$19*'Fuel & Inputs'!$C$21,100) -> 11900 | Q36: =MROUND(N36*'Fuel & Inputs'!$C$19*'Fuel & Inputs'!$C$21,100) -> 14800 | R36: =MROUND(O36*'Fuel & Inputs'!$C$19*'Fuel & Inputs'!$C$21,100) -> 26300 | S36: =MROUND(M36*'Fuel & Inputs'!$C$20*'Fuel & Inputs'!$C$22,500) -> 318000 | T36: =MROUND(N36*'Fuel & Inputs'!$C$20*'Fuel & Inputs'!$C$22,500) -> 398000 | U36: =MROUND(O36*'Fuel & Inputs'!$C$20*'Fuel & Inputs'!$C$22,500) -> 707000
A37: 31 | B37: Wheel Loader | C37: KOMATSU | D37: WA100 | E37: 2012 | F37: LD-03 | G37: — | H37: Diesel | I37: 9 | J37: 1.098 | K37: =IF(I37=0,0,IF(L37="Rs./km",MROUND(IF(H37="Petrol",'Fuel & Inputs'!$C$5,'Fuel & Inputs'!$C$4)/I37*J37,1),MROUND(I37*J37*IF(H37="Petrol",'Fuel & Inputs'!$C$5,'Fuel & Inputs'!$C$4),10))) -> 3770 | L37: Rs./hr | M37: 3120 | N37: =MROUND(M37+'Fuel & Inputs'!$C$13,50) -> 3900 | O37: 6930 | P37: =MROUND(M37*'Fuel & Inputs'!$C$19*'Fuel & Inputs'!$C$21,100) -> 11900 | Q37: =MROUND(N37*'Fuel & Inputs'!$C$19*'Fuel & Inputs'!$C$21,100) -> 14800 | R37: =MROUND(O37*'Fuel & Inputs'!$C$19*'Fuel & Inputs'!$C$21,100) -> 26300 | S37: =MROUND(M37*'Fuel & Inputs'!$C$20*'Fuel & Inputs'!$C$22,500) -> 318000 | T37: =MROUND(N37*'Fuel & Inputs'!$C$20*'Fuel & Inputs'!$C$22,500) -> 398000 | U37: =MROUND(O37*'Fuel & Inputs'!$C$20*'Fuel & Inputs'!$C$22,500) -> 707000
A38: 32 | B38: Wheel Loader | C38: CAT | D38: CAT910 | E38: 2010 | F38: LD-02 | G38: — | H38: Diesel | I38: 10 | J38: 1.112 | K38: =IF(I38=0,0,IF(L38="Rs./km",MROUND(IF(H38="Petrol",'Fuel & Inputs'!$C$5,'Fuel & Inputs'!$C$4)/I38*J38,1),MROUND(I38*J38*IF(H38="Petrol",'Fuel & Inputs'!$C$5,'Fuel & Inputs'!$C$4),10))) -> 4250 | L38: Rs./hr | M38: 3120 | N38: =MROUND(M38+'Fuel & Inputs'!$C$13,50) -> 3900 | O38: 6930 | P38: =MROUND(M38*'Fuel & Inputs'!$C$19*'Fuel & Inputs'!$C$21,100) -> 11900 | Q38: =MROUND(N38*'Fuel & Inputs'!$C$19*'Fuel & Inputs'!$C$21,100) -> 14800 | R38: =MROUND(O38*'Fuel & Inputs'!$C$19*'Fuel & Inputs'!$C$21,100) -> 26300 | S38: =MROUND(M38*'Fuel & Inputs'!$C$20*'Fuel & Inputs'!$C$22,500) -> 318000 | T38: =MROUND(N38*'Fuel & Inputs'!$C$20*'Fuel & Inputs'!$C$22,500) -> 398000 | U38: =MROUND(O38*'Fuel & Inputs'!$C$20*'Fuel & Inputs'!$C$22,500) -> 707000
A39: 33 | B39: Wheel Loader | C39: CAT | D39: 910E | E39: 2009 | F39: LD-01 | G39: — | H39: Diesel | I39: 10 | J39: 1.119 | K39: =IF(I39=0,0,IF(L39="Rs./km",MROUND(IF(H39="Petrol",'Fuel & Inputs'!$C$5,'Fuel & Inputs'!$C$4)/I39*J39,1),MROUND(I39*J39*IF(H39="Petrol",'Fuel & Inputs'!$C$5,'Fuel & Inputs'!$C$4),10))) -> 4270 | L39: Rs./hr | M39: 2740 | N39: =MROUND(M39+'Fuel & Inputs'!$C$13,50) -> 3550 | O39: 6080 | P39: =MROUND(M39*'Fuel & Inputs'!$C$19*'Fuel & Inputs'!$C$21,100) -> 10400 | Q39: =MROUND(N39*'Fuel & Inputs'!$C$19*'Fuel & Inputs'!$C$21,100) -> 13500 | R39: =MROUND(O39*'Fuel & Inputs'!$C$19*'Fuel & Inputs'!$C$21,100) -> 23100 | S39: =MROUND(M39*'Fuel & Inputs'!$C$20*'Fuel & Inputs'!$C$22,500) -> 279500 | T39: =MROUND(N39*'Fuel & Inputs'!$C$20*'Fuel & Inputs'!$C$22,500) -> 362000 | U39: =MROUND(O39*'Fuel & Inputs'!$C$20*'Fuel & Inputs'!$C$22,500) -> 620000
A40: TRUCK MIXER
A41: 34 | B41: Truck Mixer | C41: TATA | D41: LPK 1618 | E41: 2017 | F41: TM-18 | G41: ZA-8511 | H41: Diesel | I41: 11 | J41: 1.063 | K41: =IF(I41=0,0,IF(L41="Rs./km",MROUND(IF(H41="Petrol",'Fuel & Inputs'!$C$5,'Fuel & Inputs'!$C$4)/I41*J41,1),MROUND(I41*J41*IF(H41="Petrol",'Fuel & Inputs'!$C$5,'Fuel & Inputs'!$C$4),10))) -> 4470 | L41: Rs./hr | M41: 2250 | N41: =MROUND(M41+'Fuel & Inputs'!$C$13,50) -> 3050 | O41: 4460 | P41: =MROUND(M41*'Fuel & Inputs'!$C$19*'Fuel & Inputs'!$C$21,100) -> 8600 | Q41: =MROUND(N41*'Fuel & Inputs'!$C$19*'Fuel & Inputs'!$C$21,100) -> 11600 | R41: =MROUND(O41*'Fuel & Inputs'!$C$19*'Fuel & Inputs'!$C$21,100) -> 16900 | S41: =MROUND(M41*'Fuel & Inputs'!$C$20*'Fuel & Inputs'!$C$22,500) -> 229500 | T41: =MROUND(N41*'Fuel & Inputs'!$C$20*'Fuel & Inputs'!$C$22,500) -> 311000 | U41: =MROUND(O41*'Fuel & Inputs'!$C$20*'Fuel & Inputs'!$C$22,500) -> 455000
A42: 35 | B42: Truck Mixer | C42: TATA | D42: LPK 2518 | E42: 2017 | F42: TM-19 | G42: ZA-8445 | H42: Diesel | I42: 13 | J42: 1.063 | K42: =IF(I42=0,0,IF(L42="Rs./km",MROUND(IF(H42="Petrol",'Fuel & Inputs'!$C$5,'Fuel & Inputs'!$C$4)/I42*J42,1),MROUND(I42*J42*IF(H42="Petrol",'Fuel & Inputs'!$C$5,'Fuel & Inputs'!$C$4),10))) -> 5280 | L42: Rs./hr | M42: 2250 | N42: =MROUND(M42+'Fuel & Inputs'!$C$13,50) -> 3050 | O42: 4460 | P42: =MROUND(M42*'Fuel & Inputs'!$C$19*'Fuel & Inputs'!$C$21,100) -> 8600 | Q42: =MROUND(N42*'Fuel & Inputs'!$C$19*'Fuel & Inputs'!$C$21,100) -> 11600 | R42: =MROUND(O42*'Fuel & Inputs'!$C$19*'Fuel & Inputs'!$C$21,100) -> 16900 | S42: =MROUND(M42*'Fuel & Inputs'!$C$20*'Fuel & Inputs'!$C$22,500) -> 229500 | T42: =MROUND(N42*'Fuel & Inputs'!$C$20*'Fuel & Inputs'!$C$22,500) -> 311000 | U42: =MROUND(O42*'Fuel & Inputs'!$C$20*'Fuel & Inputs'!$C$22,500) -> 455000
A43: 36 | B43: Truck Mixer | C43: TATA | D43: LPK 1618 | E43: 2016 | F43: TM-15 | G43: ZA-7925 | H43: Diesel | I43: 11 | J43: 1.07 | K43: =IF(I43=0,0,IF(L43="Rs./km",MROUND(IF(H43="Petrol",'Fuel & Inputs'!$C$5,'Fuel & Inputs'!$C$4)/I43*J43,1),MROUND(I43*J43*IF(H43="Petrol",'Fuel & Inputs'!$C$5,'Fuel & Inputs'!$C$4),10))) -> 4500 | L43: Rs./hr | M43: 2250 | N43: =MROUND(M43+'Fuel & Inputs'!$C$13,50) -> 3050 | O43: 4460 | P43: =MROUND(M43*'Fuel & Inputs'!$C$19*'Fuel & Inputs'!$C$21,100) -> 8600 | Q43: =MROUND(N43*'Fuel & Inputs'!$C$19*'Fuel & Inputs'!$C$21,100) -> 11600 | R43: =MROUND(O43*'Fuel & Inputs'!$C$19*'Fuel & Inputs'!$C$21,100) -> 16900 | S43: =MROUND(M43*'Fuel & Inputs'!$C$20*'Fuel & Inputs'!$C$22,500) -> 229500 | T43: =MROUND(N43*'Fuel & Inputs'!$C$20*'Fuel & Inputs'!$C$22,500) -> 311000 | U43: =MROUND(O43*'Fuel & Inputs'!$C$20*'Fuel & Inputs'!$C$22,500) -> 455000
A44: 37 | B44: Truck Mixer | C44: ELCHER | D44: TERRA 16 | E44: 2016 | F44: TM-11 | G44: ZA-7291 | H44: Diesel | I44: 11 | J44: 1.07 | K44: =IF(I44=0,0,IF(L44="Rs./km",MROUND(IF(H44="Petrol",'Fuel & Inputs'!$C$5,'Fuel & Inputs'!$C$4)/I44*J44,1),MROUND(I44*J44*IF(H44="Petrol",'Fuel & Inputs'!$C$5,'Fuel & Inputs'!$C$4),10))) -> 4500 | L44: Rs./hr | M44: 2250 | N44: =MROUND(M44+'Fuel & Inputs'!$C$13,50) -> 3050 | O44: 4460 | P44: =MROUND(M44*'Fuel & Inputs'!$C$19*'Fuel & Inputs'!$C$21,100) -> 8600 | Q44: =MROUND(N44*'Fuel & Inputs'!$C$19*'Fuel & Inputs'!$C$21,100) -> 11600 | R44: =MROUND(O44*'Fuel & Inputs'!$C$19*'Fuel & Inputs'!$C$21,100) -> 16900 | S44: =MROUND(M44*'Fuel & Inputs'!$C$20*'Fuel & Inputs'!$C$22,500) -> 229500 | T44: =MROUND(N44*'Fuel & Inputs'!$C$20*'Fuel & Inputs'!$C$22,500) -> 311000 | U44: =MROUND(O44*'Fuel & Inputs'!$C$20*'Fuel & Inputs'!$C$22,500) -> 455000
A45: 38 | B45: Truck Mixer | C45: ELCHER | D45: TERRA 16 | E45: 2016 | F45: TM-12 | G45: ZA-7290 | H45: Diesel | I45: 11 | J45: 1.07 | K45: =IF(I45=0,0,IF(L45="Rs./km",MROUND(IF(H45="Petrol",'Fuel & Inputs'!$C$5,'Fuel & Inputs'!$C$4)/I45*J45,1),MROUND(I45*J45*IF(H45="Petrol",'Fuel & Inputs'!$C$5,'Fuel & Inputs'!$C$4),10))) -> 4500 | L45: Rs./hr | M45: 2250 | N45: =MROUND(M45+'Fuel & Inputs'!$C$13,50) -> 3050 | O45: 4460 | P45: =MROUND(M45*'Fuel & Inputs'!$C$19*'Fuel & Inputs'!$C$21,100) -> 8600 | Q45: =MROUND(N45*'Fuel & Inputs'!$C$19*'Fuel & Inputs'!$C$21,100) -> 11600 | R45: =MROUND(O45*'Fuel & Inputs'!$C$19*'Fuel & Inputs'!$C$21,100) -> 16900 | S45: =MROUND(M45*'Fuel & Inputs'!$C$20*'Fuel & Inputs'!$C$22,500) -> 229500 | T45: =MROUND(N45*'Fuel & Inputs'!$C$20*'Fuel & Inputs'!$C$22,500) -> 311000 | U45: =MROUND(O45*'Fuel & Inputs'!$C$20*'Fuel & Inputs'!$C$22,500) -> 455000
A46: 39 | B46: Truck Mixer | C46: TATA | D46: LPK 2518 | E46: 2016 | F46: TM-14 | G46: ZA-7810 | H46: Diesel | I46: 13 | J46: 1.07 | K46: =IF(I46=0,0,IF(L46="Rs./km",MROUND(IF(H46="Petrol",'Fuel & Inputs'!$C$5,'Fuel & Inputs'!$C$4)/I46*J46,1),MROUND(I46*J46*IF(H46="Petrol",'Fuel & Inputs'!$C$5,'Fuel & Inputs'!$C$4),10))) -> 5310 | L46: Rs./hr | M46: 2250 | N46: =MROUND(M46+'Fuel & Inputs'!$C$13,50) -> 3050 | O46: 4460 | P46: =MROUND(M46*'Fuel & Inputs'!$C$19*'Fuel & Inputs'!$C$21,100) -> 8600 | Q46: =MROUND(N46*'Fuel & Inputs'!$C$19*'Fuel & Inputs'!$C$21,100) -> 11600 | R46: =MROUND(O46*'Fuel & Inputs'!$C$19*'Fuel & Inputs'!$C$21,100) -> 16900 | S46: =MROUND(M46*'Fuel & Inputs'!$C$20*'Fuel & Inputs'!$C$22,500) -> 229500 | T46: =MROUND(N46*'Fuel & Inputs'!$C$20*'Fuel & Inputs'!$C$22,500) -> 311000 | U46: =MROUND(O46*'Fuel & Inputs'!$C$20*'Fuel & Inputs'!$C$22,500) -> 455000
A47: 40 | B47: Truck Mixer | C47: TATA | D47: LPK 2518 | E47: 2016 | F47: TM-16 | G47: ZA-8033 | H47: Diesel | I47: 13 | J47: 1.07 | K47: =IF(I47=0,0,IF(L47="Rs./km",MROUND(IF(H47="Petrol",'Fuel & Inputs'!$C$5,'Fuel & Inputs'!$C$4)/I47*J47,1),MROUND(I47*J47*IF(H47="Petrol",'Fuel & Inputs'!$C$5,'Fuel & Inputs'!$C$4),10))) -> 5310 | L47: Rs./hr | M47: 2250 | N47: =MROUND(M47+'Fuel & Inputs'!$C$13,50) -> 3050 | O47: 4460 | P47: =MROUND(M47*'Fuel & Inputs'!$C$19*'Fuel & Inputs'!$C$21,100) -> 8600 | Q47: =MROUND(N47*'Fuel & Inputs'!$C$19*'Fuel & Inputs'!$C$21,100) -> 11600 | R47: =MROUND(O47*'Fuel & Inputs'!$C$19*'Fuel & Inputs'!$C$21,100) -> 16900 | S47: =MROUND(M47*'Fuel & Inputs'!$C$20*'Fuel & Inputs'!$C$22,500) -> 229500 | T47: =MROUND(N47*'Fuel & Inputs'!$C$20*'Fuel & Inputs'!$C$22,500) -> 311000 | U47: =MROUND(O47*'Fuel & Inputs'!$C$20*'Fuel & Inputs'!$C$22,500) -> 455000
A48: 41 | B48: Truck Mixer | C48: TATA | D48: LPK 2518 | E48: 2017 | F48: TM-21 | G48: ZA-0050 | H48: Diesel | I48: 13 | J48: 1.063 | K48: =IF(I48=0,0,IF(L48="Rs./km",MROUND(IF(H48="Petrol",'Fuel & Inputs'!$C$5,'Fuel & Inputs'!$C$4)/I48*J48,1),MROUND(I48*J48*IF(H48="Petrol",'Fuel & Inputs'!$C$5,'Fuel & Inputs'!$C$4),10))) -> 5280 | L48: Rs./hr | M48: 2250 | N48: =MROUND(M48+'Fuel & Inputs'!$C$13,50) -> 3050 | O48: 4460 | P48: =MROUND(M48*'Fuel & Inputs'!$C$19*'Fuel & Inputs'!$C$21,100) -> 8600 | Q48: =MROUND(N48*'Fuel & Inputs'!$C$19*'Fuel & Inputs'!$C$21,100) -> 11600 | R48: =MROUND(O48*'Fuel & Inputs'!$C$19*'Fuel & Inputs'!$C$21,100) -> 16900 | S48: =MROUND(M48*'Fuel & Inputs'!$C$20*'Fuel & Inputs'!$C$22,500) -> 229500 | T48: =MROUND(N48*'Fuel & Inputs'!$C$20*'Fuel & Inputs'!$C$22,500) -> 311000 | U48: =MROUND(O48*'Fuel & Inputs'!$C$20*'Fuel & Inputs'!$C$22,500) -> 455000
A49: 42 | B49: Truck Mixer | C49: ASHOK LEYLAND | D49: TUSKER SUPER 1613 | E49: 2015 | F49: TM-10 | G49: ZA-6395 | H49: Diesel | I49: 11 | J49: 1.077 | K49: =IF(I49=0,0,IF(L49="Rs./km",MROUND(IF(H49="Petrol",'Fuel & Inputs'!$C$5,'Fuel & Inputs'!$C$4)/I49*J49,1),MROUND(I49*J49*IF(H49="Petrol",'Fuel & Inputs'!$C$5,'Fuel & Inputs'!$C$4),10))) -> 4530 | L49: Rs./hr | M49: 2250 | N49: =MROUND(M49+'Fuel & Inputs'!$C$13,50) -> 3050 | O49: 4460 | P49: =MROUND(M49*'Fuel & Inputs'!$C$19*'Fuel & Inputs'!$C$21,100) -> 8600 | Q49: =MROUND(N49*'Fuel & Inputs'!$C$19*'Fuel & Inputs'!$C$21,100) -> 11600 | R49: =MROUND(O49*'Fuel & Inputs'!$C$19*'Fuel & Inputs'!$C$21,100) -> 16900 | S49: =MROUND(M49*'Fuel & Inputs'!$C$20*'Fuel & Inputs'!$C$22,500) -> 229500 | T49: =MROUND(N49*'Fuel & Inputs'!$C$20*'Fuel & Inputs'!$C$22,500) -> 311000 | U49: =MROUND(O49*'Fuel & Inputs'!$C$20*'Fuel & Inputs'!$C$22,500) -> 455000
A50: 43 | B50: Truck Mixer | C50: MITSUBISHI | D50: KK-FE73EB CANTER | E50: 2003 | F50: TM-09 | G50: ZA-6255 | H50: Diesel | I50: 8 | J50: 1.161 | K50: =IF(I50=0,0,IF(L50="Rs./km",MROUND(IF(H50="Petrol",'Fuel & Inputs'!$C$5,'Fuel & Inputs'!$C$4)/I50*J50,1),MROUND(I50*J50*IF(H50="Petrol",'Fuel & Inputs'!$C$5,'Fuel & Inputs'!$C$4),10))) -> 3550 | L50: Rs./hr | M50: 1590 | N50: =MROUND(M50+'Fuel & Inputs'!$C$13,50) -> 2400 | O50: 3150 | P50: =MROUND(M50*'Fuel & Inputs'!$C$19*'Fuel & Inputs'!$C$21,100) -> 6000 | Q50: =MROUND(N50*'Fuel & Inputs'!$C$19*'Fuel & Inputs'!$C$21,100) -> 9100 | R50: =MROUND(O50*'Fuel & Inputs'!$C$19*'Fuel & Inputs'!$C$21,100) -> 12000 | S50: =MROUND(M50*'Fuel & Inputs'!$C$20*'Fuel & Inputs'!$C$22,500) -> 162000 | T50: =MROUND(N50*'Fuel & Inputs'!$C$20*'Fuel & Inputs'!$C$22,500) -> 245000 | U50: =MROUND(O50*'Fuel & Inputs'!$C$20*'Fuel & Inputs'!$C$22,500) -> 321500
A51: 44 | B51: Truck Mixer | C51: ISUZU | D51: KK-NRR35C4 FORWARD | E51: 2000 | F51: TM-04 | G51: LL-0690 | H51: Diesel | I51: 8 | J51: 1.175 | K51: =IF(I51=0,0,IF(L51="Rs./km",MROUND(IF(H51="Petrol",'Fuel & Inputs'!$C$5,'Fuel & Inputs'!$C$4)/I51*J51,1),MROUND(I51*J51*IF(H51="Petrol",'Fuel & Inputs'!$C$5,'Fuel & Inputs'!$C$4),10))) -> 3590 | L51: Rs./hr | M51: 1590 | N51: =MROUND(M51+'Fuel & Inputs'!$C$13,50) -> 2400 | O51: 3150 | P51: =MROUND(M51*'Fuel & Inputs'!$C$19*'Fuel & Inputs'!$C$21,100) -> 6000 | Q51: =MROUND(N51*'Fuel & Inputs'!$C$19*'Fuel & Inputs'!$C$21,100) -> 9100 | R51: =MROUND(O51*'Fuel & Inputs'!$C$19*'Fuel & Inputs'!$C$21,100) -> 12000 | S51: =MROUND(M51*'Fuel & Inputs'!$C$20*'Fuel & Inputs'!$C$22,500) -> 162000 | T51: =MROUND(N51*'Fuel & Inputs'!$C$20*'Fuel & Inputs'!$C$22,500) -> 245000 | U51: =MROUND(O51*'Fuel & Inputs'!$C$20*'Fuel & Inputs'!$C$22,500) -> 321500
A52: 45 | B52: Truck Mixer | C52: ISUZU | D52: KC-NRR33C20 | E52: 1996 | F52: TM-03 | G52: LK-5047 | H52: Diesel | I52: 8 | J52: 1.175 | K52: =IF(I52=0,0,IF(L52="Rs./km",MROUND(IF(H52="Petrol",'Fuel & Inputs'!$C$5,'Fuel & Inputs'!$C$4)/I52*J52,1),MROUND(I52*J52*IF(H52="Petrol",'Fuel & Inputs'!$C$5,'Fuel & Inputs'!$C$4),10))) -> 3590 | L52: Rs./hr | M52: 1420 | N52: =MROUND(M52+'Fuel & Inputs'!$C$13,50) -> 2200 | O52: 2810 | P52: =MROUND(M52*'Fuel & Inputs'!$C$19*'Fuel & Inputs'!$C$21,100) -> 5400 | Q52: =MROUND(N52*'Fuel & Inputs'!$C$19*'Fuel & Inputs'!$C$21,100) -> 8400 | R52: =MROUND(O52*'Fuel & Inputs'!$C$19*'Fuel & Inputs'!$C$21,100) -> 10700 | S52: =MROUND(M52*'Fuel & Inputs'!$C$20*'Fuel & Inputs'!$C$22,500) -> 145000 | T52: =MROUND(N52*'Fuel & Inputs'!$C$20*'Fuel & Inputs'!$C$22,500) -> 224500 | U52: =MROUND(O52*'Fuel & Inputs'!$C$20*'Fuel & Inputs'!$C$22,500) -> 286500
...

Sheet Machinery Price Sheet
A1: MACHINERY / PORTABLE EQUIPMENT PRICE SHEET 2026 — DRY / DRY + OPERATOR / WET (Rs./day, excl. 18% VAT, min. 1 day)
A2: WET = DRY + operator + fuel for the stated duty hrs/day at CPC prices (Diesel Rs.382 / Petrol-92 Rs.414, eff. 29-Jun-2026). Electric items: power by client (fuel = 0) — if we supply a generator, add it as a separate line. Extra running hours billed at L/hr x CPC price. Operator Rs.3,500/day (skilled welder/cutter Rs.5,000/day). Diamond blades & core bits billed per use at cost + 15%.
A4: A — POWER & AIR (generators, air compressors, welding generators, gas cutting)
A5: # | B5: Equipment | C5: Capacity / Size | D5: Power / Fuel | E5: Output & Efficiency | F5: Cons. L/hr | G5: Duty hrs/day | H5: Fuel Rs./day | I5: DRY Rs./day | J5: Operator Rs./day | K5: DRY + OPERATOR Rs./day | L5: WET Rs./day | M5: Market reference (SL, 2026)
A6: 1 | B6: Generator | C6: 3–5 kVA (petrol, 1-ph) | D6: Petrol engine | E6: 2.4–4.0 kW prime, 230 V; ~0.35 L/kWh | F6: 1.4 | G6: 8 | H6: =MROUND(F6*G6*IF(ISNUMBER(SEARCH("Diesel",D6)),'Fuel & Inputs'!$C$4,IF(ISNUMBER(SEARCH("Petrol",D6)),'Fuel & Inputs'!$C$5,0)),10) -> 4640 | I6: 2500 | J6: ='Fuel & Inputs'!$C$14 -> 3500 | K6: =I6+J6 -> 6000 | L6: =MROUND(K6+H6,100) -> 10600 | M6: Peters 2–5 kVA Rs.4,000–5,000/day
A7: 2 | B7: Generator | C7: 10 kVA (diesel, 1-ph) | D7: Diesel engine | E7: 8 kW prime, 230 V; ~0.28 L/kWh | F7: 2.2 | G7: 8 | H7: =MROUND(F7*G7*IF(ISNUMBER(SEARCH("Diesel",D7)),'Fuel & Inputs'!$C$4,IF(ISNUMBER(SEARCH("Petrol",D7)),'Fuel & Inputs'!$C$5,0)),10) -> 6720 | I7: 3500 | J7: ='Fuel & Inputs'!$C$14 -> 3500 | K7: =I7+J7 -> 7000 | L7: =MROUND(K7+H7,100) -> 13700 | M7: Peters 10 kVA Rs.6,000/day
A8: 3 | B8: Generator | C8: 15 kVA (diesel, 3-ph) | D8: Diesel engine | E8: 12 kW prime, 400 V | F8: 2.9 | G8: 8 | H8: =MROUND(F8*G8*IF(ISNUMBER(SEARCH("Diesel",D8)),'Fuel & Inputs'!$C$4,IF(ISNUMBER(SEARCH("Petrol",D8)),'Fuel & Inputs'!$C$5,0)),10) -> 8860 | I8: 4800 | J8: ='Fuel & Inputs'!$C$14 -> 3500 | K8: =I8+J8 -> 8300 | L8: =MROUND(K8+H8,100) -> 17200 | M8: Interpolated SL band
A9: 4 | B9: Generator | C9: 20–25 kVA (diesel, 3-ph) | D9: Diesel engine | E9: 16–20 kW prime, 400 V | F9: 4 | G9: 8 | H9: =MROUND(F9*G9*IF(ISNUMBER(SEARCH("Diesel",D9)),'Fuel & Inputs'!$C$4,IF(ISNUMBER(SEARCH("Petrol",D9)),'Fuel & Inputs'!$C$5,0)),10) -> 12220 | I9: 6000 | J9: ='Fuel & Inputs'!$C$14 -> 3500 | K9: =I9+J9 -> 9500 | L9: =MROUND(K9+H9,100) -> 21700 | M9: Peters 25 kVA Rs.8,000/day
A10: 5 | B10: Generator | C10: 30–50 kVA (diesel, 3-ph) | D10: Diesel engine | E10: 24–40 kW prime | F10: 7.5 | G10: 8 | H10: =MROUND(F10*G10*IF(ISNUMBER(SEARCH("Diesel",D10)),'Fuel & Inputs'!$C$4,IF(ISNUMBER(SEARCH("Petrol",D10)),'Fuel & Inputs'!$C$5,0)),10) -> 22920 | I10: 10000 | J10: ='Fuel & Inputs'!$C$14 -> 3500 | K10: =I10+J10 -> 13500 | L10: =MROUND(K10+H10,100) -> 36400 | M10: Peters 50 kVA Rs.10–12,000/day
A11: 6 | B11: Generator | C11: 60–80 kVA (soundproof) | D11: Diesel engine | E11: 48–64 kW prime, <75 dB@7m | F11: 12 | G11: 8 | H11: =MROUND(F11*G11*IF(ISNUMBER(SEARCH("Diesel",D11)),'Fuel & Inputs'!$C$4,IF(ISNUMBER(SEARCH("Petrol",D11)),'Fuel & Inputs'!$C$5,0)),10) -> 36670 | I11: 15000 | J11: ='Fuel & Inputs'!$C$14 -> 3500 | K11: =I11+J11 -> 18500 | L11: =MROUND(K11+H11,100) -> 55200 | M11: Generators.lk/UTE band
A12: 7 | B12: Generator | C12: 100–125 kVA (soundproof) | D12: Diesel engine | E12: 80–100 kW prime | F12: 19 | G12: 8 | H12: =MROUND(F12*G12*IF(ISNUMBER(SEARCH("Diesel",D12)),'Fuel & Inputs'!$C$4,IF(ISNUMBER(SEARCH("Petrol",D12)),'Fuel & Inputs'!$C$5,0)),10) -> 58060 | I12: 22000 | J12: ='Fuel & Inputs'!$C$14 -> 3500 | K12: =I12+J12 -> 25500 | L12: =MROUND(K12+H12,100) -> 83600 | M12: Generators.lk/UTE band
A13: 8 | B13: Generator | C13: 150 kVA (soundproof) | D13: Diesel engine | E13: 120 kW prime | F13: 24 | G13: 8 | H13: =MROUND(F13*G13*IF(ISNUMBER(SEARCH("Diesel",D13)),'Fuel & Inputs'!$C$4,IF(ISNUMBER(SEARCH("Petrol",D13)),'Fuel & Inputs'!$C$5,0)),10) -> 73340 | I13: 28000 | J13: ='Fuel & Inputs'!$C$14 -> 3500 | K13: =I13+J13 -> 31500 | L13: =MROUND(K13+H13,100) -> 104800 | M13: Generators.lk upper band
A14: 9 | B14: Generator | C14: 250 kVA (soundproof) | D14: Diesel engine | E14: 200 kW prime | F14: 38 | G14: 8 | H14: =MROUND(F14*G14*IF(ISNUMBER(SEARCH("Diesel",D14)),'Fuel & Inputs'!$C$4,IF(ISNUMBER(SEARCH("Petrol",D14)),'Fuel & Inputs'!$C$5,0)),10) -> 116130 | I14: 40000 | J14: ='Fuel & Inputs'!$C$14 -> 3500 | K14: =I14+J14 -> 43500 | L14: =MROUND(K14+H14,100) -> 159600 | M14: Project/event band, Colombo
A15: 10 | B15: Air Compressor | C15: 2–3 HP (portable) | D15: Electric 1.5–2.2 kW | E15: 8–10 cfm @ 8 bar, 50 L tank | F15: 0 | G15: 8 | H15: =MROUND(F15*G15*IF(ISNUMBER(SEARCH("Diesel",D15)),'Fuel & Inputs'!$C$4,IF(ISNUMBER(SEARCH("Petrol",D15)),'Fuel & Inputs'!$C$5,0)),10) -> 0 | I15: 1300 | J15: ='Fuel & Inputs'!$C$14 -> 3500 | K15: =I15+J15 -> 4800 | L15: =MROUND(K15+H15,100) -> 4800 | M15: SL hire-shop day-rate
A16: 11 | B16: Air Compressor | C16: 5–7 HP (belt-drive) | D16: Petrol engine | E16: 16–21 cfm @ 8–10 bar | F16: 1.2 | G16: 6 | H16: =MROUND(F16*G16*IF(ISNUMBER(SEARCH("Diesel",D16)),'Fuel & Inputs'!$C$4,IF(ISNUMBER(SEARCH("Petrol",D16)),'Fuel & Inputs'!$C$5,0)),10) -> 2980 | I16: 2400 | J16: ='Fuel & Inputs'!$C$14 -> 3500 | K16: =I16+J16 -> 5900 | L16: =MROUND(K16+H16,100) -> 8900 | M16: Western-Province hire-shop
A17: 12 | B17: Air Compressor | C17: 10–15 HP (industrial) | D17: Electric 7.5–11 kW | E17: 35–50 cfm @ 10–12 bar | F17: 0 | G17: 8 | H17: =MROUND(F17*G17*IF(ISNUMBER(SEARCH("Diesel",D17)),'Fuel & Inputs'!$C$4,IF(ISNUMBER(SEARCH("Petrol",D17)),'Fuel & Inputs'!$C$5,0)),10) -> 0 | I17: 4500 | J17: ='Fuel & Inputs'!$C$14 -> 3500 | K17: =I17+J17 -> 8000 | L17: =MROUND(K17+H17,100) -> 8000 | M17: Western-Province hire-shop
... A20: 15 | B20: Pneumatic Jack Hammer | C20: 25–30 kg (w/ hoses, excl. compressor) | D20: Pneumatic (via compressor) | E20: ~1,250 bpm; pavement/rock breaking | F20: 0 | G20: 0 | H20: =MROUND(F20*G20*IF(ISNUMBER(SEARCH("Diesel",D20)),'Fuel & Inputs'!$C$4,IF(ISNUMBER(SEARCH("Petrol",D20)),'Fuel & Inputs'!$C$5,0)),10) -> 0 | I20: 4000 | J20: ='Fuel & Inputs'!$C$14 -> 3500 | K20: =I20+J20 -> 7500 | L20: =MROUND(K20+H20,100) -> 7500 | M20: Peters jackhammer pkg Rs.10,000/day (with compressor)
A21: 16 | B21: Welding Inverter | C21: 200 A (MMA/ARC) | D21: Electric 6–8 kVA | E21: 200 A @ 60% duty; rods up to 4.0 mm | F21: 0 | G21: 8 | H21: =MROUND(F21*G21*IF(ISNUMBER(SEARCH("Diesel",D21)),'Fuel & Inputs'!$C$4,IF(ISNUMBER(SEARCH("Petrol",D21)),'Fuel & Inputs'!$C$5,0)),10) -> 0 | I21: 1800 | J21: ='Fuel & Inputs'!$C$15 -> 5000 | K21: =I21+J21 -> 6800 | L21: =MROUND(K21+H21,100) -> 6800 | M21: SL hire-shop day-rate
A22: 17 | B22: Welding Generator | C22: 250 A (petrol) | D22: Petrol engine | E22: 250 A DC @ 60% duty + 3 kW aux power | F22: 1.8 | G22: 5 | H22: =MROUND(F22*G22*IF(ISNUMBER(SEARCH("Diesel",D22)),'Fuel & Inputs'!$C$4,IF(ISNUMBER(SEARCH("Petrol",D22)),'Fuel & Inputs'!$C$5,0)),10) -> 3730 | I22: 5500 | J22: ='Fuel & Inputs'!$C$15 -> 5000 | K22: =I22+J22 -> 10500 | L22: =MROUND(K22+H22,100) -> 14200 | M22: Engine-welder SL band
A23: 18 | B23: Welding Generator | C23: 300 A (diesel) | D23: Diesel engine | E23: 300 A DC @ 60% duty + 5 kW aux power | F23: 2.5 | G23: 5 | H23: =MROUND(F23*G23*IF(ISNUMBER(SEARCH("Diesel",D23)),'Fuel & Inputs'!$C$4,IF(ISNUMBER(SEARCH("Petrol",D23)),'Fuel & Inputs'!$C$5,0)),10) -> 4780 | I23: 6500 | J23: ='Fuel & Inputs'!$C$15 -> 5000 | K23: =I23+J23 -> 11500 | L23: =MROUND(K23+H23,100) -> 16300 | M23: Existing card; SL band
