Workbook

Sheet README
B2: FLEET RENTAL PRICING — 2026 RATE CARD
B3: Market: Sri Lanka | Currency: LKR | Fleet Size: 518 units
B5: Purpose | C5: Internal rate-card workbook used to quote customers for daily / hourly / monthly rental of our machinery fleet.
B6: Pricing strategy | C6: Competitive but not cheapest — positioned ~15–20% below SLLDC official government rates and in line with private operators in Colombo, Gampaha, Kandy, Kurunegala.
B7: Wet rate | C7: INCLUDES fuel + operator + normal maintenance. Recommended for clients without trained operators.
B8: Dry rate | C8: Machine ONLY. Fuel, operator, lubricants, toll and food paid by client. Recommended for contractors with own crew.
B9: Daily rate | C9: Minimum billable 4 working hours per day. Derived as Hourly × 4 × 0.95 (5% volume discount).
B10: Monthly rate | C10: Minimum billable 120 working hours per month. Derived as Hourly × 120 × 0.85 (15% volume discount). Extra hours billed at Hourly rate.
B11: Age adjustment | C11: Rate declines with age: 2020+ = 100%, 2015–19 = 92%, 2010–14 = 82%, 2005–09 = 72%, 2000–04 = 65%, pre-2000 = 58%. Applied on top of base rate.
B12: Excavator size | C12: Separate multiplier by model (e.g. PC30 = 0.55×, PC200 = 1.00×, R330 = 1.30×).
B13: Client extras | C13: Trailer one-way, toll, fines, operator meals & lodging charged at cost. 15-day advance payment standard.
B14: VAT | C14: Add 18% VAT on all rates (standard SL rate 2026).
B16: Workbook sheets
B17: 1. README | C17: This page.
B18: 2. Rate Card | C18: Base hourly Wet/Dry rate per category + age factors (editable inputs in blue).
B19: 3. Fleet Pricing | C19: Every single unit (518) with calculated 2026 Dry/Wet hourly, daily (min 4h), monthly (min 120h) rates.
B20: 4. Market Research | C20: Competitor prices gathered from Sri Lankan & Indian rental portals (SLLDC, wedabima, krearthmovers, petersequipment, ikman).
B21: 5. Summary by Category | C21: Fleet count & average monthly wet revenue potential per category.
B23: Prepared | C23: April 2026 — All prices in LKR, exclusive of VAT.
B25: NEW SHEETS (v2 — engineering)
B26: 6. Engineering Assumptions | C26: All inputs: diesel price, operator rate, fuel consumption per category, PM/repair base costs, new unit prices, service life, age multipliers, consumable prices.
B27: 7. Engineering Cost | C27: Per-unit hourly cost build-up: Fuel + Operator + PM + Major repair + Overhead + 20% profit = suggested WET rate. Compare against current Fleet Pricing.
B28: 8. Maintenance & Repair | C28: Monthly spend forecast per unit (120 hrs): fuel, operator, PM, major repair, totals with overhead.
B29: 9. Replacement Analysis | C29: Every unit scored KEEP / MONITOR / REPLACE based on age, repair-to-revenue ratio, estimated 2026 resale value, and brand-new 2026 price.
B30: 10. Replacement Summary | C30: Category rollup — how many to KEEP / MONITOR / REPLACE, total CAPEX for new equipment, total resale from retiring old units.
B32: Key inputs given (Apr 2026)
B33: Operator rate | C33: Rs. 650 / hour • Minimum monthly salary Rs. 78,000
B34: Gross profit target | C34: 20% on total cost
B35: Overhead | C35: 15% of direct cost (yard, admin, insurance, transport, depreciation recovery)
B36: Diesel (CPC Auto Diesel) | C36: Rs. 382 / litre (March 2026 CPC)
B37: Min working hours | C37: 120 / month • 4 / day
B39: CHANGELOG — v3 rate engineering
B40: Issue identified | C40: Previous rates (v2) sat below engineering cost floor — we were earning less than the 20% target profit on many units.
B41: Fix (v3) | C41: Rate Card now shows Market LOW / MID / HIGH for each category and derives the recommended rate via formula: MAX(Engineering Floor, LOW × 1.10) capped at HIGH × 0.88.
B42: Outcome | C42: New rates sit in the upper-mid of the market — above bottom-feeders, below SLLDC government ceiling. Typical increase +25–40%.
B43: If the cell in column G (Eng. Floor) on Rate Card turns red | C43: It means even the market HIGH price × 0.88 won't cover cost + 20% profit. Either we must run at lower margin for that category, or stop renting it out.
B45: CHANGELOG — v4 portable equipment
B46: New sheet added | C46: "Portable Equipment Rates" (sheet 3) — capacity-wise daily hire rates for generators, air compressors, poker/concrete vibrators, submersible pumps (1"–6"), engine water pumps (2"/3"/4"), rotary hammers, circular saws, angle grinders, plate compactor, power trowel and welding plant.
B47: Basis | C47: WET = fuel/operator/consumables included; DRY = bare hire. Per-day billing, minimum 1 day. 36 line items across 10 categories. Excludes 18% VAT & transport.
B48: Market sources | C48: Sri Lankan rental market, May–Jun 2026: Peters Equipment (petersequipment.lk) published day-rates; surplus.lk and wedabima.com availability. Generators Rs.4,000–12,000/day by kVA; Rotary Hammer SDS Rs.3,000; Demolition Breaker Rs.4,000; Tamping Rammer Rs.3,500; drills Rs.250–500.
...

Sheet Rate Card
A1: 2026 RATE CARD — Engineering-Derived Hourly Rates
A2: Each rate is computed from three drivers: Market LOW, Market HIGH, and Engineering Cost + 20% profit. Recommended Wet = MAX(Engineering Floor, Market LOW × 1.10) capped at Market HIGH × 0.88. Recommended Dry = Wet × Dry ratio (industry convention). Blue cells = editable inputs.
A4: # | B4: Category | C4: Market LOW (wet) | D4: Market MID (wet) | E4: Market HIGH (wet) | F4: Eng. Cost / h (age-5) | G4: Eng. Floor (+20% profit) | H4: Positioning rule | I4: Recommended WET (/h) | J4: Dry ratio (blue = editable) | K4: Recommended DRY (/h) | L4: Wet : Dry ratio | M4: % above LOW | N4: % below HIGH | O4: Source / note
A5: 1 | B5: Backhoe Loader | C5: 2500 | D5: 3500 | E5: 6050 | F5: ='Engineering Assumptions'!$C$18*'Engineering Assumptions'!$B$5+'Engineering Assumptions'!$B$8+'Engineering Assumptions'!$D$18*1+'Engineering Assumptions'!$E$18*0.3 -> 2997 | G5: =F5*(1+'Engineering Assumptions'!$B$10)*(1+'Engineering Assumptions'!$B$11) -> 4135.86 | H5: MAX(Eng. Floor, LOW×1.10) capped at HIGH×0.88 | I5: =MROUND(MIN(MAX(G5,C5*1.1),E5*0.88),50) -> 4150 | J5: 0.48 | K5: =MROUND(I5*J5,50) -> 2000 | L5: =K5/I5 -> 0.48192771 | M5: =(I5-C5)/C5 -> 0.66 | N5: =(E5-I5)/E5 -> 0.31404959 | O5: LOW: Small private, Wedabima • HIGH: SLLDC JCB 3CX wet
A6: 2 | B6: Wheel Loader | C6: 5000 | D6: 8500 | E6: 15760 | F6: ='Engineering Assumptions'!$C$19*'Engineering Assumptions'!$B$5+'Engineering Assumptions'!$B$8+'Engineering Assumptions'!$D$19*1+'Engineering Assumptions'!$E$19*0.3 -> 6110 | G6: =F6*(1+'Engineering Assumptions'!$B$10)*(1+'Engineering Assumptions'!$B$11) -> 8431.8 | H6: MAX(Eng. Floor, LOW×1.10) capped at HIGH×0.88 | I6: =MROUND(MIN(MAX(G6,C6*1.1),E6*0.88),50) -> 8450 | J6: 0.45 | K6: =MROUND(I6*J6,50) -> 3800 | L6: =K6/I6 -> 0.44970414 | M6: =(I6-C6)/C6 -> 0.69 | N6: =(E6-I6)/E6 -> 0.46383249 | O6: LOW: Used private • HIGH: SLLDC Doosan Mega 250
A7: 3 | B7: Truck Mixer | C7: 3500 | D7: 4500 | E7: 5500 | F7: ='Engineering Assumptions'!$C$20*'Engineering Assumptions'!$B$5+'Engineering Assumptions'!$B$8+'Engineering Assumptions'!$D$20*1+'Engineering Assumptions'!$E$20*0.3 -> 3628 | G7: =F7*(1+'Engineering Assumptions'!$B$10)*(1+'Engineering Assumptions'!$B$11) -> 5006.64 | H7: MAX(Eng. Floor, LOW×1.10) capped at HIGH×0.88 | I7: =MROUND(MIN(MAX(G7,C7*1.1),E7*0.88),50) -> 4850 | J7: 0.5 | K7: =MROUND(I7*J7,50) -> 2450 | L7: =K7/I7 -> 0.50515464 | M7: =(I7-C7)/C7 -> 0.38571429 | N7: =(E7-I7)/E7 -> 0.11818182 | O7: LOW: TATA mixer private • HIGH: Large private operators
A8: 4 | B8: Self Loader Mixer | C8: 4500 | D8: 5200 | E8: 6000 | F8: ='Engineering Assumptions'!$C$21*'Engineering Assumptions'!$B$5+'Engineering Assumptions'!$B$8+'Engineering Assumptions'!$D$21*1+'Engineering Assumptions'!$E$21*0.3 -> 4062 | G8: =F8*(1+'Engineering Assumptions'!$B$10)*(1+'Engineering Assumptions'!$B$11) -> 5605.56 | H8: MAX(Eng. Floor, LOW×1.10) capped at HIGH×0.88 | I8: =MROUND(MIN(MAX(G8,C8*1.1),E8*0.88),50) -> 5300 | J8: 0.5 | K8: =MROUND(I8*J8,50) -> 2650 | L8: =K8/I8 -> 0.5 | M8: =(I8-C8)/C8 -> 0.17777778 | N8: =(E8-I8)/E8 -> 0.11666667 | O8: LOW: FIORI/Ajax private • HIGH: Large operators
A9: 5 | B9: Static Roller | C9: 2500 | D9: 3500 | E9: 5230 | F9: ='Engineering Assumptions'!$C$22*'Engineering Assumptions'!$B$5+'Engineering Assumptions'!$B$8+'Engineering Assumptions'!$D$22*1+'Engineering Assumptions'!$E$22*0.3 -> 4029 | G9: =F9*(1+'Engineering Assumptions'!$B$10)*(1+'Engineering Assumptions'!$B$11) -> 5560.02 | H9: MAX(Eng. Floor, LOW×1.10) capped at HIGH×0.88 | I9: =MROUND(MIN(MAX(G9,C9*1.1),E9*0.88),50) -> 4600 | J9: 0.5 | K9: =MROUND(I9*J9,50) -> 2300 | L9: =K9/I9 -> 0.5 | M9: =(I9-C9)/C9 -> 0.84 | N9: =(E9-I9)/E9 -> 0.12045889 | O9: LOW: Private 10T • HIGH: SLLDC HAMM HD12vv
A10: 6 | B10: Vibrating Roller | C10: 3000 | D10: 4000 | E10: 5000 | F10: ='Engineering Assumptions'!$C$23*'Engineering Assumptions'!$B$5+'Engineering Assumptions'!$B$8+'Engineering Assumptions'!$D$23*1+'Engineering Assumptions'!$E$23*0.3 -> 2812 | G10: =F10*(1+'Engineering Assumptions'!$B$10)*(1+'Engineering Assumptions'!$B$11) -> 3880.56 | H10: MAX(Eng. Floor, LOW×1.10) capped at HIGH×0.88 | I10: =MROUND(MIN(MAX(G10,C10*1.1),E10*0.88),50) -> 3900 | J10: 0.5 | K10: =MROUND(I10*J10,50) -> 1950 | L10: =K10/I10 -> 0.5 | M10: =(I10-C10)/C10 -> 0.3 | N10: =(E10-I10)/E10 -> 0.22 | O10: LOW: BOMAG private • HIGH: Large private 10T
A11: 7 | B11: Pneumatic Roller | C11: 3000 | D11: 3800 | E11: 4500 | F11: ='Engineering Assumptions'!$C$24*'Engineering Assumptions'!$B$5+'Engineering Assumptions'!$B$8+'Engineering Assumptions'!$D$24*1+'Engineering Assumptions'!$E$24*0.3 -> 3605 | G11: =F11*(1+'Engineering Assumptions'!$B$10)*(1+'Engineering Assumptions'!$B$11) -> 4974.9 | H11: MAX(Eng. Floor, LOW×1.10) capped at HIGH×0.88 | I11: =MROUND(MIN(MAX(G11,C11*1.1),E11*0.88),50) -> 3950 | J11: 0.5 | K11: =MROUND(I11*J11,50) -> 2000 | L11: =K11/I11 -> 0.50632911 | M11: =(I11-C11)/C11 -> 0.31666667 | N11: =(E11-I11)/E11 -> 0.12222222 | O11: LOW: Private Sakai/Dynapac • HIGH: Premium operators
A12: 8 | B12: Motor Grader | C12: 7000 | D12: 8500 | E12: 11000 | F12: ='Engineering Assumptions'!$C$25*'Engineering Assumptions'!$B$5+'Engineering Assumptions'!$B$8+'Engineering Assumptions'!$D$25*1+'Engineering Assumptions'!$E$25*0.3 -> 6980 | G12: =F12*(1+'Engineering Assumptions'!$B$10)*(1+'Engineering Assumptions'!$B$11) -> 9632.4 | H12: MAX(Eng. Floor, LOW×1.10) capped at HIGH×0.88 | I12: =MROUND(MIN(MAX(G12,C12*1.1),E12*0.88),50) -> 9650 | J12: 0.45 | K12: =MROUND(I12*J12,50) -> 4350 | L12: =K12/I12 -> 0.4507772 | M12: =(I12-C12)/C12 -> 0.37857143 | N12: =(E12-I12)/E12 -> 0.12272727 | O12: LOW: Private used CAT • HIGH: Premium/SLLDC class
A13: 9 | B13: Skid Steer | C13: 2000 | D13: 2500 | E13: 3060 | F13: ='Engineering Assumptions'!$C$26*'Engineering Assumptions'!$B$5+'Engineering Assumptions'!$B$8+'Engineering Assumptions'!$D$26*1+'Engineering Assumptions'!$E$26*0.3 -> 2589 | G13: =F13*(1+'Engineering Assumptions'!$B$10)*(1+'Engineering Assumptions'!$B$11) -> 3572.82 | H13: MAX(Eng. Floor, LOW×1.10) capped at HIGH×0.88 | I13: =MROUND(MIN(MAX(G13,C13*1.1),E13*0.88),50) -> 2700 | J13: 0.5 | K13: =MROUND(I13*J13,50) -> 1350 | L13: =K13/I13 -> 0.5 | M13: =(I13-C13)/C13 -> 0.35 | N13: =(E13-I13)/E13 -> 0.11764706 | O13: LOW: Small private • HIGH: SLLDC Bobcat
A14: 10 | B14: Asphalt Paver | C14: 7000 | D14: 8500 | E14: 10000 | F14: ='Engineering Assumptions'!$C$27*'Engineering Assumptions'!$B$5+'Engineering Assumptions'!$B$8+'Engineering Assumptions'!$D$27*1+'Engineering Assumptions'!$E$27*0.3 -> 5822 | G14: =F14*(1+'Engineering Assumptions'!$B$10)*(1+'Engineering Assumptions'!$B$11) -> 8034.36 | H14: MAX(Eng. Floor, LOW×1.10) capped at HIGH×0.88 | I14: =MROUND(MIN(MAX(G14,C14*1.1),E14*0.88),50) -> 8050 | J14: 0.45 | K14: =MROUND(I14*J14,50) -> 3600 | L14: =K14/I14 -> 0.44720497 | M14: =(I14-C14)/C14 -> 0.15 | N14: =(E14-I14)/E14 -> 0.195 | O14: LOW: SUMITOMO private • HIGH: VOLVO premium
A15: 11 | B15: Bitumen Bowser | C15: 2500 | D15: 3200 | E15: 4000 | F15: ='Engineering Assumptions'!$C$28*'Engineering Assumptions'!$B$5+'Engineering Assumptions'!$B$8+'Engineering Assumptions'!$D$28*1+'Engineering Assumptions'!$E$28*0.3 -> 3366 | G15: =F15*(1+'Engineering Assumptions'!$B$10)*(1+'Engineering Assumptions'!$B$11) -> 4645.08 | H15: MAX(Eng. Floor, LOW×1.10) capped at HIGH×0.88 | I15: =MROUND(MIN(MAX(G15,C15*1.1),E15*0.88),50) -> 3500 | J15: 0.5 | K15: =MROUND(I15*J15,50) -> 1750 | L15: =K15/I15 -> 0.5 | M15: =(I15-C15)/C15 -> 0.4 | N15: =(E15-I15)/E15 -> 0.125 | O15: LOW: Private 4-cu • HIGH: Large insulated bowser
A16: 12 | B16: Mobile Crane | C16: 8000 | D16: 9500 | E16: 11660 | F16: ='Engineering Assumptions'!$C$29*'Engineering Assumptions'!$B$5+'Engineering Assumptions'!$B$8+'Engineering Assumptions'!$D$29*1+'Engineering Assumptions'!$E$29*0.3 -> 4954 | G16: =F16*(1+'Engineering Assumptions'!$B$10)*(1+'Engineering Assumptions'!$B$11) -> 6836.52 | H16: MAX(Eng. Floor, LOW×1.10) capped at HIGH×0.88 | I16: =MROUND(MIN(MAX(G16,C16*1.1),E16*0.88),50) -> 8800 | J16: 0.5 | K16: =MROUND(I16*J16,50) -> 4400 | L16: =K16/I16 -> 0.5 | M16: =(I16-C16)/C16 -> 0.1 | N16: =(E16-I16)/E16 -> 0.24528302 | O16: LOW: Private 25T • HIGH: SLLDC Kobelco RK250
A17: 13 | B17: Boom Truck | C17: 4000 | D17: 5000 | E17: 6610 | F17: ='Engineering Assumptions'!$C$30*'Engineering Assumptions'!$B$5+'Engineering Assumptions'!$B$8+'Engineering Assumptions'!$D$30*1+'Engineering Assumptions'!$E$30*0.3 -> 3628 | G17: =F17*(1+'Engineering Assumptions'!$B$10)*(1+'Engineering Assumptions'!$B$11) -> 5006.64 | H17: MAX(Eng. Floor, LOW×1.10) capped at HIGH×0.88 | I17: =MROUND(MIN(MAX(G17,C17*1.1),E17*0.88),50) -> 5000 | J17: 0.5 | K17: =MROUND(I17*J17,50) -> 2500 | L17: =K17/I17 -> 0.5 | M17: =(I17-C17)/C17 -> 0.25 | N17: =(E17-I17)/E17 -> 0.24357035 | O17: LOW: Califolink private • HIGH: SLLDC 17T 3T-crane
A18: 14 | B18: Prime Mover / Bed | C18: 3500 | D18: 4500 | E18: 5500 | F18: ='Engineering Assumptions'!$C$31*'Engineering Assumptions'!$B$5+'Engineering Assumptions'!$B$8+'Engineering Assumptions'!$D$31*1+'Engineering Assumptions'!$E$31*0.3 -> 6363 | G18: =F18*(1+'Engineering Assumptions'!$B$10)*(1+'Engineering Assumptions'!$B$11) -> 8780.94 | H18: MAX(Eng. Floor, LOW×1.10) capped at HIGH×0.88 | I18: =MROUND(MIN(MAX(G18,C18*1.1),E18*0.88),50) -> 4850 | J18: 0.5 | K18: =MROUND(I18*J18,50) -> 2450 | L18: =K18/I18 -> 0.50515464 | M18: =(I18-C18)/C18 -> 0.38571429 | N18: =(E18-I18)/E18 -> 0.11818182 | O18: LOW: Private HINO/TATA • HIGH: Premium lowbed operators
A19: 15 | B19: Pump Truck (Concrete) | C19: 8500 | D19: 10000 | E19: 11000 | F19: ='Engineering Assumptions'!$C$32*'Engineering Assumptions'!$B$5+'Engineering Assumptions'!$B$8+'Engineering Assumptions'!$D$32*1+'Engineering Assumptions'!$E$32*0.3 -> 6242 | G19: =F19*(1+'Engineering Assumptions'!$B$10)*(1+'Engineering Assumptions'!$B$11) -> 8613.96 | H19: MAX(Eng. Floor, LOW×1.10) capped at HIGH×0.88 | I19: =MROUND(MIN(MAX(G19,C19*1.1),E19*0.88),50) -> 9350 | J19: 0.45 | K19: =MROUND(I19*J19,50) -> 4200 | L19: =K19/I19 -> 0.44919786 | M19: =(I19-C19)/C19 -> 0.1 | N19: =(E19-I19)/E19 -> 0.15 | O19: LOW: Private Sany pump • HIGH: Premium operators
A20: 16 | B20: Double Cab (Pickup) | C20: 1200 | D20: 1500 | E20: 2000 | F20: ='Engineering Assumptions'!$C$33*'Engineering Assumptions'!$B$5+'Engineering Assumptions'!$B$8+'Engineering Assumptions'!$D$33*1+'Engineering Assumptions'!$E$33*0.3 -> 1919 | G20: =F20*(1+'Engineering Assumptions'!$B$10)*(1+'Engineering Assumptions'!$B$11) -> 2648.22 | H20: MAX(Eng. Floor, LOW×1.10) capped at HIGH×0.88 | I20: =MROUND(MIN(MAX(G20,C20*1.1),E20*0.88),50) -> 1750 | J20: 0.55 | K20: =MROUND(I20*J20,50) -> 950 | L20: =K20/I20 -> 0.54285714 | M20: =(I20-C20)/C20 -> 0.45833333 | N20: =(E20-I20)/E20 -> 0.125 | O20: LOW: Hilux long-term private • HIGH: Malkey/Lanka Rent premium
A21: 17 | B21: Van | C21: 950 | D21: 1300 | E21: 1800 | F21: ='Engineering Assumptions'!$C$34*'Engineering Assumptions'!$B$5+'Engineering Assumptions'!$B$8+'Engineering Assumptions'!$D$34*1+'Engineering Assumptions'!$E$34*0.3 -> 1702 | G21: =F21*(1+'Engineering Assumptions'!$B$10)*(1+'Engineering Assumptions'!$B$11) -> 2348.76 | H21: MAX(Eng. Floor, LOW×1.10) capped at HIGH×0.88 | I21: =MROUND(MIN(MAX(G21,C21*1.1),E21*0.88),50) -> 1600 | J21: 0.55 | K21: =MROUND(I21*J21,50) -> 900 | L21: =K21/I21 -> 0.5625 | M21: =(I21-C21)/C21 -> 0.68421053 | N21: =(E21-I21)/E21 -> 0.11111111 | O21: LOW: Liteace private • HIGH: KDH200 premium
A22: 18 | B22: Crew Cab | C22: 900 | D22: 1200 | E22: 1600 | F22: ='Engineering Assumptions'!$C$35*'Engineering Assumptions'!$B$5+'Engineering Assumptions'!$B$8+'Engineering Assumptions'!$D$35*1+'Engineering Assumptions'!$E$35*0.3 -> 1906 | G22: =F22*(1+'Engineering Assumptions'!$B$10)*(1+'Engineering Assumptions'!$B$11) -> 2630.28 | H22: MAX(Eng. Floor, LOW×1.10) capped at HIGH×0.88 | I22: =MROUND(MIN(MAX(G22,C22*1.1),E22*0.88),50) -> 1400 | J22: 0.55 | K22: =MROUND(I22*J22,50) -> 750 | L22: =K22/I22 -> 0.53571429 | M22: =(I22-C22)/C22 -> 0.55555556 | N22: =(E22-I22)/E22 -> 0.125 | O22: LOW: JMC private • HIGH: ISUZU premium
A23: 19 | B23: Single Cab | C23: 700 | D23: 1000 | E23: 1300 | F23: ='Engineering Assumptions'!$C$36*'Engineering Assumptions'!$B$5+'Engineering Assumptions'!$B$8+'Engineering Assumptions'!$D$36*1+'Engineering Assumptions'!$E$36*0.3 -> 1702 | G23: =F23*(1+'Engineering Assumptions'!$B$10)*(1+'Engineering Assumptions'!$B$11) -> 2348.76 | H23: MAX(Eng. Floor, LOW×1.10) capped at HIGH×0.88 | I23: =MROUND(MIN(MAX(G23,C23*1.1),E23*0.88),50) -> 1150 | J23: 0.55 | K23: =MROUND(I23*J23,50) -> 650 | L23: =K23/I23 -> 0.56521739 | M23: =(I23-C23)/C23 -> 0.64285714 | N23: =(E23-I23)/E23 -> 0.11538462 | O23: LOW: Tata Ace small • HIGH: Mahindra BMT premium
A24: 20 | B24: Dump Truck (Tipper) | C24: 2000 | D24: 2800 | E24: 3700 | F24: ='Engineering Assumptions'!$C$37*'Engineering Assumptions'!$B$5+'Engineering Assumptions'!$B$8+'Engineering Assumptions'!$D$37*1+'Engineering Assumptions'!$E$37*0.3 -> 3838 | G24: =F24*(1+'Engineering Assumptions'!$B$10)*(1+'Engineering Assumptions'!$B$11) -> 5296.44 | H24: MAX(Eng. Floor, LOW×1.10) capped at HIGH×0.88 | I24: =MROUND(MIN(MAX(G24,C24*1.1),E24*0.88),50) -> 3250 | J24: 0.48 | K24: =MROUND(I24*J24,50) -> 1550 | L24: =K24/I24 -> 0.47692308 | M24: =(I24-C24)/C24 -> 0.625 | N24: =(E24-I24)/E24 -> 0.12162162 | O24: LOW: Ikman monthly low • HIGH: Premium Tata LPK1618
A25: 21 | B25: Trailer | C25: 1200 | D25: 1700 | E25: 2200 | F25: ='Engineering Assumptions'!$C$38*'Engineering Assumptions'!$B$5+0+'Engineering Assumptions'!$D$38*1+'Engineering Assumptions'!$E$38*0.3 -> 71 | G25: =F25*(1+'Engineering Assumptions'!$B$10)*(1+'Engineering Assumptions'!$B$11) -> 97.98 | H25: MAX(Eng. Floor, LOW×1.10) capped at HIGH×0.88 | I25: =MROUND(MIN(MAX(G25,C25*1.1),E25*0.88),50) -> 1300 | J25: 0.95 | K25: =MROUND(I25*J25,50) -> 1250 | L25: =K25/I25 -> 0.96153846 | M25: =(I25-C25)/C25 -> 0.083333333 | N25: =(E25-I25)/E25 -> 0.40909091 | O25: LOW: Private tractor trailer • HIGH: Premium operators
A26: 22 | B26: Lorry Trailer | C26: 2000 | D26: 2600 | E26: 3200 | F26: ='Engineering Assumptions'!$C$39*'Engineering Assumptions'!$B$5+0+'Engineering Assumptions'!$D$39*1+'Engineering Assumptions'!$E$39*0.3 -> 84 | G26: =F26*(1+'Engineering Assumptions'!$B$10)*(1+'Engineering Assumptions'!$B$11) -> 115.92 | H26: MAX(Eng. Floor, LOW×1.10) capped at HIGH×0.88 | I26: =MROUND(MIN(MAX(G26,C26*1.1),E26*0.88),50) -> 2200 | J26: 0.95 | K26: =MROUND(I26*J26,50) -> 2100 | L26: =K26/I26 -> 0.95454545 | M26: =(I26-C26)/C26 -> 0.1 | N26: =(E26-I26)/E26 -> 0.3125 | O26: LOW: Private Tantri • HIGH: Premium Tantri TFB40
A27: 23 | B27: Diesel Bowser | C27: 1500 | D27: 2200 | E27: 2800 | F27: ='Engineering Assumptions'!$C$40*'Engineering Assumptions'!$B$5+'Engineering Assumptions'!$B$8+'Engineering Assumptions'!$D$40*1+'Engineering Assumptions'!$E$40*0.3 -> 2139 | G27: =F27*(1+'Engineering Assumptions'!$B$10)*(1+'Engineering Assumptions'!$B$11) -> 2951.82 | H27: MAX(Eng. Floor, LOW×1.10) capped at HIGH×0.88 | I27: =MROUND(MIN(MAX(G27,C27*1.1),E27*0.88),50) -> 2450 | J27: 0.55 | K27: =MROUND(I27*J27,50) -> 1350 | L27: =K27/I27 -> 0.55102041 | M27: =(I27-C27)/C27 -> 0.63333333 | N27: =(E27-I27)/E27 -> 0.125 | O27: LOW: Private fuel bowser • HIGH: Premium large bowser
A28: 24 | B28: Excavator | C28: 5500 | D28: 7500 | E28: 12100 | F28: ='Engineering Assumptions'!$C$41*'Engineering Assumptions'!$B$5+'Engineering Assumptions'!$B$8+'Engineering Assumptions'!$D$41*1+'Engineering Assumptions'!$E$41*0.3 -> 6916 | G28: =F28*(1+'Engineering Assumptions'!$B$10)*(1+'Engineering Assumptions'!$B$11) -> 9544.08 | H28: MAX(Eng. Floor, LOW×1.10) capped at HIGH×0.88 | I28: =MROUND(MIN(MAX(G28,C28*1.1),E28*0.88),50) -> 9550 | J28: 0.45 | K28: =MROUND(I28*J28,50) -> 4300 | L28: =K28/I28 -> 0.45026178 | M28: =(I28-C28)/C28 -> 0.73636364 | N28: =(E28-I28)/E28 -> 0.2107438 | O28: LOW: Private 20T Hyundai • HIGH: SLLDC Doosan DX200
A29: 25 | B29: Water Bowser | C29: 1800 | D29: 2300 | E29: 4940 | F29: ='Engineering Assumptions'!$C$42*'Engineering Assumptions'!$B$5+'Engineering Assumptions'!$B$8+'Engineering Assumptions'!$D$42*1+'Engineering Assumptions'!$E$42*0.3 -> 2152 | G29: =F29*(1+'Engineering Assumptions'!$B$10)*(1+'Engineering Assumptions'!$B$11) -> 2969.76 | H29: MAX(Eng. Floor, LOW×1.10) capped at HIGH×0.88 | I29: =MROUND(MIN(MAX(G29,C29*1.1),E29*0.88),50) -> 2950 | J29: 0.5 | K29: =MROUND(I29*J29,50) -> 1500 | L29: =K29/I29 -> 0.50847458 | M29: =(I29-C29)/C29 -> 0.63888889 | N29: =(E29-I29)/E29 -> 0.40283401 | O29: LOW: Private small • HIGH: SLLDC 6,000L equiv.
A30: 26 | B30: Farm Tractor | C30: 1200 | D30: 1800 | E30: 2400 | F30: ='Engineering Assumptions'!$C$43*'Engineering Assumptions'!$B$5+'Engineering Assumptions'!$B$8+'Engineering Assumptions'!$D$43*1+'Engineering Assumptions'!$E$43*0.3 -> 2330 | G30: =F30*(1+'Engineering Assumptions'!$B$10)*(1+'Engineering Assumptions'!$B$11) -> 3215.4 | H30: MAX(Eng. Floor, LOW×1.10) capped at HIGH×0.88 | I30: =MROUND(MIN(MAX(G30,C30*1.1),E30*0.88),50) -> 2100 | J30: 0.55 | K30: =MROUND(I30*J30,50) -> 1150 | L30: =K30/I30 -> 0.54761905 | M30: =(I30-C30)/C30 -> 0.75 | N30: =(E30-I30)/E30 -> 0.125 | O30: LOW: MASSEY/TAFE private • HIGH: MAHINDRA premium
A31: 27 | B31: Motor Bicycle | C31: 250 | D31: 350 | E31: 550 | F31: ='Engineering Assumptions'!$C$44*'Engineering Assumptions'!$B$5+0+'Engineering Assumptions'!$D$44*1+'Engineering Assumptions'!$E$44*0.3 -> 493.9 | G31: =F31*(1+'Engineering Assumptions'!$B$10)*(1+'Engineering Assumptions'!$B$11) -> 681.582 | H31: MAX(Eng. Floor, LOW×1.10) capped at HIGH×0.88 | I31: =MROUND(MIN(MAX(G31,C31*1.1),E31*0.88),50) -> 500 | J31: 0.6 | K31: =MROUND(I31*J31,50) -> 300 | L31: =K31/I31 -> 0.6 | M31: =(I31-C31)/C31 -> 1 | N31: =(E31-I31)/E31 -> 0.090909091 | O31: LOW: Staff rental private • HIGH: Daily hire
A32: 28 | B32: Tractor Bowser | C32: 1200 | D32: 1600 | E32: 2000 | F32: ='Engineering Assumptions'!$C$45*'Engineering Assumptions'!$B$5+'Engineering Assumptions'!$B$8+'Engineering Assumptions'!$D$45*1+'Engineering Assumptions'!$E$45*0.3 -> 2521 | G32: =F32*(1+'Engineering Assumptions'!$B$10)*(1+'Engineering Assumptions'!$B$11) -> 3478.98 | H32: MAX(Eng. Floor, LOW×1.10) capped at HIGH×0.88 | I32: =MROUND(MIN(MAX(G32,C32*1.1),E32*0.88),50) -> 1750 | J32: 0.55 | K32: =MROUND(I32*J32,50) -> 950 | L32: =K32/I32 -> 0.54285714 | M32: =(I32-C32)/C32 -> 0.45833333 | N32: =(E32-I32)/E32 -> 0.125 | O32: LOW: Private combo • HIGH: Premium combo
A33: 29 | B33: Forklift | C33: 2000 | D33: 3000 | E33: 3800 | F33: ='Engineering Assumptions'!$C$46*'Engineering Assumptions'!$B$5+'Engineering Assumptions'!$B$8+'Engineering Assumptions'!$D$46*1+'Engineering Assumptions'!$E$46*0.3 -> 2210 | G33: =F33*(1+'Engineering Assumptions'!$B$10)*(1+'Engineering Assumptions'!$B$11) -> 3049.8 | H33: MAX(Eng. Floor, LOW×1.10) capped at HIGH×0.88 | I33: =MROUND(MIN(MAX(G33,C33*1.1),E33*0.88),50) -> 3050 | J33: 0.5 | K33: =MROUND(I33*J33,50) -> 1550 | L33: =K33/I33 -> 0.50819672 | M33: =(I33-C33)/C33 -> 0.525 | N33: =(E33-I33)/E33 -> 0.19736842 | O33: LOW: Private 3T • HIGH: Premium insulated/specialist
A36: AGE DEPRECIATION APPLIED TO FLEET UNITS
A37: Year of manufacture | B37: Age factor | C37: % of base rate | D37: Rationale
A38: 2020 and newer | B38: 1 | C38: =B38 -> 1 | D38: Same as new — no discount
A39: 2015 – 2019 | B39: 0.92 | C39: =B39 -> 0.92 | D39: Light depreciation
A40: 2010 – 2014 | B40: 0.82 | C40: =B40 -> 0.82 | D40: Used but serviceable
A41: 2005 – 2009 | B41: 0.72 | C41: =B41 -> 0.72 | D41: Older unit — customer expects discount
A42: 2000 – 2004 | B42: 0.65 | C42: =B42 -> 0.65 | D42: Legacy — only for budget-sensitive clients
A43: Before 2000 / Unknown | B43: 0.58 | C43: =B43 -> 0.58 | D43: End-of-life — last resort only
...

Sheet Portable Equipment Rates
A1: 2026 PORTABLE EQUIPMENT RATES — Day-Hire, Sri Lankan Market
A2: Capacity-wise daily hire rates (Rs./day) for portable plant, surveyed from the Sri Lankan rental market (May–Jun 2026). WET = with fuel/operator/consumables; DRY = bare machine hire only. Min. billing 1 day. Rates exclude 18% VAT and transport.
A4: # | B4: Category | C4: Capacity / Size | D4: WET Rs./day | E4: DRY Rs./day | F4: Billing | G4: Min. | H4: Source / basis note
A5: 1 | B5: Generator | C5: 3–5 kVA (petrol, 1-ph) | D5: 5000 | E5: 2500 | F5: Per day | G5: 1 day | H5: Peters Equipment: 5kVA Rs.4,000 / 2-3kVA Rs.5,000 per day
A6: 2 | B6: Generator | C6: 10 kVA (diesel, 1-ph) | D6: 7000 | E6: 3500 | F6: Per day | G6: 1 day | H6: Peters Equipment 10kVA diesel Rs.6,000/day (op w/fuel basis)
A7: 3 | B7: Generator | C7: 20–25 kVA (diesel, 3-ph) | D7: 12000 | E7: 6000 | F7: Per day | G7: 1 day | H7: Peters Equipment 25kVA diesel Rs.8,000/day
A8: 4 | B8: Generator | C8: 30–50 kVA (diesel, 3-ph) | D8: 18000 | E8: 10000 | F8: Per day | G8: 1 day | H8: Peters Equipment 50kVA diesel Rs.10-12,000/day
A9: 5 | B9: Generator | C9: 60–80 kVA (soundproof) | D9: 26000 | E9: 15000 | F9: Per day | G9: 1 day | H9: Interpolated from 50kVA card + UTE/Generators.lk band
A10: 6 | B10: Generator | C10: 100–125 kVA (soundproof) | D10: 38000 | E10: 22000 | F10: Per day | G10: 1 day | H10: Generators.lk / UTE long-term construction band
A11: 7 | B11: Generator | C11: 150 kVA (soundproof) | D11: 48000 | E11: 28000 | F11: Per day | G11: 1 day | H11: Generators.lk 150kVA upper rental band
A12: 8 | B12: Air Compressor | C12: 2–3 HP (portable, electric) | D12: 2200 | E12: 1300 | F12: Per day | G12: 1 day | H12: SL hire-shop day-rate; surplus.lk "any capacity per day"
A13: 9 | B13: Air Compressor | C13: 5–7 HP (belt-drive, petrol) | D13: 3800 | E13: 2400 | F13: Per day | G13: 1 day | H13: Competitive Western-Province hire-shop day-rate
A14: 10 | B14: Air Compressor | C14: 10–15 HP (industrial) | D14: 6500 | E14: 4500 | F14: Per day | G14: 1 day | H14: Competitive Western-Province hire-shop day-rate
A15: 11 | B15: Air Compressor | C15: 185 cfm (towable diesel) | D15: 16000 | E15: 11000 | F15: Per day | G15: 1 day | H15: Towable jackhammer-feed compressor; project day-rate
A16: 12 | B16: Air Compressor | C16: 375 cfm (towable diesel) | D16: 26000 | E16: 18000 | F16: Per day | G16: 1 day | H16: Large towable diesel; project day-rate
... A40: 36 | B40: Welding Plant | C40: 300 A diesel (engine-driven) | D40: 9500 | E40: 6500 | F40: Per day | G40: 1 day | H40: Engine-driven welder day-hire
A42: Methodology & sources
A43: • WET rate = machine + fuel/power + operator + routine consumables (bits, oil, nozzles). DRY rate = bare equipment hire; customer supplies fuel, power and operator.
A44: • Anchored to published Sri Lankan rental day-rates from Peters Equipment (petersequipment.lk, 2026): generators Rs.4,000–12,000/day by kVA; Rotary Hammer SDS Rs.3,000; Jack Hammer Rs.10,000; Demolition Breaker Rs.4,000; Tamping Rammer Rs.3,500; drills Rs.250–500/day.
A45: • Air compressors, poker/concrete vibrators, submersible & engine water pumps, circular saws and angle grinders are confirmed available for daily hire in the Sri Lankan market (surplus.lk, wedabima.com); where a vendor lists "call for price", the rate shown is a competitive Colombo / Western-Province hire-shop day-rate.
A46: • Rates are indicative for quotation/proforma use and exclude 18% VAT, transport/mobilisation, and any operator overtime. Minimum billing is one (1) day unless agreed otherwise.
A47: • Review the WET/DRY cells (blue/green) each quarter against current market quotes; they are hardcoded inputs, not formulas.

Sheet Fuel Rates
A1: FLEET FUEL RATES — estimated by model size-class & manufacturing year (518 units)
A2: Per-unit fuel-cost rate at three duty scenarios (Lowest / Medium / Highest). Typical consumption is set from each machine's model size/engine class, then adjusted for age via the manufacturing year. Machinery Rs./hr, road vehicles Rs./km. Edit the blue cells (fuel prices, age factor, or any vehicle's consumption) and rates recalculate. SL prices, Jun 2026.
A4: FUEL PRICE & AGE INPUTS (edit to update every rate)
A5: Auto Diesel (Rs./litre) | D5: 478 | E5: ← Ceypetco/LIOC 01-Jun-2026
A6: Petrol 92 Octane (Rs./litre) | D6: 434
A8: Base year (new = no penalty) | D8: 2026
A9: Extra fuel % per year of age | D9: 0.007 | E9: ← older engines burn more (e.g. 0.7%/yr)
A10: Cap age (years) | D10: 25
A11: PER-VEHICLE FUEL RATES (518 units) — by model class & year
A12: # | B12: E&C No | C12: Reg No | D12: Category | E12: Model | F12: Year | G12: Fuel | H12: Basis | I12: Size / Engine Class | J12: Unit | K12: Cons Econ | L12: Cons Typ | M12: Cons Heavy | N12: Age × | O12: Lowest Rate | P12: Medium Rate | Q12: Highest Rate | R12: Rate Unit
A13: 1 | B13: AP-01 | C13: — | D13: Asphalt Paver | E13: Sumitomo Ha45C-2065 | F13: 2012 | G13: Diesel | H13: Hour | I13: Standard (class avg) | J13: L/hr | K13: 10.1 | L13: 14 | M13: 18.9 | N13: =1+MIN(MAX($D$8-F13,0),$D$10)*$D$9 -> 1.098 | O13: =IF(H13="None",0,IF(H13="KM",IF(G13="Petrol",$D$6,$D$5)*N13/K13,K13*N13*IF(G13="Petrol",$D$6,$D$5))) -> 5300.9244 | P13: =IF(H13="None",0,IF(H13="KM",IF(G13="Petrol",$D$6,$D$5)*N13/L13,L13*N13*IF(G13="Petrol",$D$6,$D$5))) -> 7347.816 | Q13: =IF(H13="None",0,IF(H13="KM",IF(G13="Petrol",$D$6,$D$5)*N13/M13,M13*N13*IF(G13="Petrol",$D$6,$D$5))) -> 9919.5516 | R13: =IF(H13="None","—",IF(H13="KM","Rs./km","Rs./hr")) -> Rs./hr
A14: 2 | B14: AP-02 | C14: — | D14: Asphalt Paver | E14: Mitsubishi Mf40Wh | F14: 2013 | G14: Diesel | H14: Hour | I14: Standard (class avg) | J14: L/hr | K14: 10.1 | L14: 14 | M14: 18.9 | N14: =1+MIN(MAX($D$8-F14,0),$D$10)*$D$9 -> 1.091 | O14: =IF(H14="None",0,IF(H14="KM",IF(G14="Petrol",$D$6,$D$5)*N14/K14,K14*N14*IF(G14="Petrol",$D$6,$D$5))) -> 5267.1298 | P14: =IF(H14="None",0,IF(H14="KM",IF(G14="Petrol",$D$6,$D$5)*N14/L14,L14*N14*IF(G14="Petrol",$D$6,$D$5))) -> 7300.972 | Q14: =IF(H14="None",0,IF(H14="KM",IF(G14="Petrol",$D$6,$D$5)*N14/M14,M14*N14*IF(G14="Petrol",$D$6,$D$5))) -> 9856.3122 | R14: =IF(H14="None","—",IF(H14="KM","Rs./km","Rs./hr")) -> Rs./hr
A15: 3 | B15: AP-03 | C15: — | D15: Asphalt Paver | E15: Mitsubishi Mf-55Wh | F15: 2014 | G15: Diesel | H15: Hour | I15: Standard (class avg) | J15: L/hr | K15: 10.1 | L15: 14 | M15: 18.9 | N15: =1+MIN(MAX($D$8-F15,0),$D$10)*$D$9 -> 1.084 | O15: =IF(H15="None",0,IF(H15="KM",IF(G15="Petrol",$D$6,$D$5)*N15/K15,K15*N15*IF(G15="Petrol",$D$6,$D$5))) -> 5233.3352 | P15: =IF(H15="None",0,IF(H15="KM",IF(G15="Petrol",$D$6,$D$5)*N15/L15,L15*N15*IF(G15="Petrol",$D$6,$D$5))) -> 7254.128 | Q15: =IF(H15="None",0,IF(H15="KM",IF(G15="Petrol",$D$6,$D$5)*N15/M15,M15*N15*IF(G15="Petrol",$D$6,$D$5))) -> 9793.0728 | R15: =IF(H15="None","—",IF(H15="KM","Rs./km","Rs./hr")) -> Rs./hr
A16: 4 | B16: AP-04 | C16: — | D16: Asphalt Paver | E16: Mitsubishi Mf60Wd | F16: 2014 | G16: Diesel | H16: Hour | I16: Standard (class avg) | J16: L/hr | K16: 10.1 | L16: 14 | M16: 18.9 | N16: =1+MIN(MAX($D$8-F16,0),$D$10)*$D$9 -> 1.084 | O16: =IF(H16="None",0,IF(H16="KM",IF(G16="Petrol",$D$6,$D$5)*N16/K16,K16*N16*IF(G16="Petrol",$D$6,$D$5))) -> 5233.3352 | P16: =IF(H16="None",0,IF(H16="KM",IF(G16="Petrol",$D$6,$D$5)*N16/L16,L16*N16*IF(G16="Petrol",$D$6,$D$5))) -> 7254.128 | Q16: =IF(H16="None",0,IF(H16="KM",IF(G16="Petrol",$D$6,$D$5)*N16/M16,M16*N16*IF(G16="Petrol",$D$6,$D$5))) -> 9793.0728 | R16: =IF(H16="None","—",IF(H16="KM","Rs./km","Rs./hr")) -> Rs./hr
A17: 5 | B17: AP-05 | C17: — | D17: Asphalt Paver | E17: Nigata — | F17: 2012 | G17: Diesel | H17: Hour | I17: Standard (class avg) | J17: L/hr | K17: 10.1 | L17: 14 | M17: 18.9 | N17: =1+MIN(MAX($D$8-F17,0),$D$10)*$D$9 -> 1.098 | O17: =IF(H17="None",0,IF(H17="KM",IF(G17="Petrol",$D$6,$D$5)*N17/K17,K17*N17*IF(G17="Petrol",$D$6,$D$5))) -> 5300.9244 | P17: =IF(H17="None",0,IF(H17="KM",IF(G17="Petrol",$D$6,$D$5)*N17/L17,L17*N17*IF(G17="Petrol",$D$6,$D$5))) -> 7347.816 | Q17: =IF(H17="None",0,IF(H17="KM",IF(G17="Petrol",$D$6,$D$5)*N17/M17,M17*N17*IF(G17="Petrol",$D$6,$D$5))) -> 9919.5516 | R17: =IF(H17="None","—",IF(H17="KM","Rs./km","Rs./hr")) -> Rs./hr
A18: 6 | B18: AP-06 | C18: — | D18: Asphalt Paver | E18: (Unknown) — | F18: — | G18: Diesel | H18: Hour | I18: Standard (class avg) | J18: L/hr | K18: 10.1 | L18: 14 | M18: 18.9 | N18: =1 -> 1 | O18: =IF(H18="None",0,IF(H18="KM",IF(G18="Petrol",$D$6,$D$5)*N18/K18,K18*N18*IF(G18="Petrol",$D$6,$D$5))) -> 4827.8 | P18: =IF(H18="None",0,IF(H18="KM",IF(G18="Petrol",$D$6,$D$5)*N18/L18,L18*N18*IF(G18="Petrol",$D$6,$D$5))) -> 6692 | Q18: =IF(H18="None",0,IF(H18="KM",IF(G18="Petrol",$D$6,$D$5)*N18/M18,M18*N18*IF(G18="Petrol",$D$6,$D$5))) -> 9034.2 | R18: =IF(H18="None","—",IF(H18="KM","Rs./km","Rs./hr")) -> Rs./hr
A19: 7 | B19: AP-07 | C19: — | D19: Asphalt Paver | E19: (Unknown) — | F19: — | G19: Diesel | H19: Hour | I19: Standard (class avg) | J19: L/hr | K19: 10.1 | L19: 14 | M19: 18.9 | N19: =1 -> 1 | O19: =IF(H19="None",0,IF(H19="KM",IF(G19="Petrol",$D$6,$D$5)*N19/K19,K19*N19*IF(G19="Petrol",$D$6,$D$5))) -> 4827.8 | P19: =IF(H19="None",0,IF(H19="KM",IF(G19="Petrol",$D$6,$D$5)*N19/L19,L19*N19*IF(G19="Petrol",$D$6,$D$5))) -> 6692 | Q19: =IF(H19="None",0,IF(H19="KM",IF(G19="Petrol",$D$6,$D$5)*N19/M19,M19*N19*IF(G19="Petrol",$D$6,$D$5))) -> 9034.2 | R19: =IF(H19="None","—",IF(H19="KM","Rs./km","Rs./hr")) -> Rs./hr
A20: 8 | B20: AP-08 | C20: — | D20: Asphalt Paver | E20: Volvo P6820C | F20: 2019 | G20: Diesel | H20: Hour | I20: Standard (class avg) | J20: L/hr | K20: 10.1 | L20: 14 | M20: 18.9 | N20: =1+MIN(MAX($D$8-F20,0),$D$10)*$D$9 -> 1.049 | O20: =IF(H20="None",0,IF(H20="KM",IF(G20="Petrol",$D$6,$D$5)*N20/K20,K20*N20*IF(G20="Petrol",$D$6,$D$5))) -> 5064.3622 | P20: =IF(H20="None",0,IF(H20="KM",IF(G20="Petrol",$D$6,$D$5)*N20/L20,L20*N20*IF(G20="Petrol",$D$6,$D$5))) -> 7019.908 | Q20: =IF(H20="None",0,IF(H20="KM",IF(G20="Petrol",$D$6,$D$5)*N20/M20,M20*N20*IF(G20="Petrol",$D$6,$D$5))) -> 9476.8758 | R20: =IF(H20="None","—",IF(H20="KM","Rs./km","Rs./hr")) -> Rs./hr
A21: 9 | B21: AP-09 | C21: — | D21: Asphalt Paver | E21: Sumitomo Ha60W-7 | F21: 2012 | G21: Diesel | H21: Hour | I21: Standard (class avg) | J21: L/hr | K21: 10.1 | L21: 14 | M21: 18.9 | N21: =1+MIN(MAX($D$8-F21,0),$D$10)*$D$9 -> 1.098 | O21: =IF(H21="None",0,IF(H21="KM",IF(G21="Petrol",$D$6,$D$5)*N21/K21,K21*N21*IF(G21="Petrol",$D$6,$D$5))) -> 5300.9244 | P21: =IF(H21="None",0,IF(H21="KM",IF(G21="Petrol",$D$6,$D$5)*N21/L21,L21*N21*IF(G21="Petrol",$D$6,$D$5))) -> 7347.816 | Q21: =IF(H21="None",0,IF(H21="KM",IF(G21="Petrol",$D$6,$D$5)*N21/M21,M21*N21*IF(G21="Petrol",$D$6,$D$5))) -> 9919.5516 | R21: =IF(H21="None","—",IF(H21="KM","Rs./km","Rs./hr")) -> Rs./hr
A22: 10 | B22: AP-10 | C22: — | D22: Asphalt Paver | E22: Dynapac Sd2500C | F22: 2020 | G22: Diesel | H22: Hour | I22: Standard (class avg) | J22: L/hr | K22: 10.1 | L22: 14 | M22: 18.9 | N22: =1+MIN(MAX($D$8-F22,0),$D$10)*$D$9 -> 1.042 | O22: =IF(H22="None",0,IF(H22="KM",IF(G22="Petrol",$D$6,$D$5)*N22/K22,K22*N22*IF(G22="Petrol",$D$6,$D$5))) -> 5030.5676 | P22: =IF(H22="None",0,IF(H22="KM",IF(G22="Petrol",$D$6,$D$5)*N22/L22,L22*N22*IF(G22="Petrol",$D$6,$D$5))) -> 6973.064 | Q22: =IF(H22="None",0,IF(H22="KM",IF(G22="Petrol",$D$6,$D$5)*N22/M22,M22*N22*IF(G22="Petrol",$D$6,$D$5))) -> 9413.6364 | R22: =IF(H22="None","—",IF(H22="KM","Rs./km","Rs./hr")) -> Rs./hr
A23: 11 | B23: AP-11 | C23: — | D23: Asphalt Paver | E23: Sumitomo Ha60W-5 | F23: 2006 | G23: Diesel | H23: Hour | I23: Standard (class avg) | J23: L/hr | K23: 10.1 | L23: 14 | M23: 18.9 | N23: =1+MIN(MAX($D$8-F23,0),$D$10)*$D$9 -> 1.14 | O23: =IF(H23="None",0,IF(H23="KM",IF(G23="Petrol",$D$6,$D$5)*N23/K23,K23*N23*IF(G23="Petrol",$D$6,$D$5))) -> 5503.692 | P23: =IF(H23="None",0,IF(H23="KM",IF(G23="Petrol",$D$6,$D$5)*N23/L23,L23*N23*IF(G23="Petrol",$D$6,$D$5))) -> 7628.88 | Q23: =IF(H23="None",0,IF(H23="KM",IF(G23="Petrol",$D$6,$D$5)*N23/M23,M23*N23*IF(G23="Petrol",$D$6,$D$5))) -> 10298.988 | R23: =IF(H23="None","—",IF(H23="KM","Rs./km","Rs./hr")) -> Rs./hr
A24: 12 | B24: LB-01 | C24: ZA-2609 | D24: Backhoe Loader | E24: Jcb 3Dx | F24: 2012 | G24: Diesel | H24: Hour | I24: Standard (class avg) | J24: L/hr | K24: 5 | L24: 7 | M24: 9.5 | N24: =1+MIN(MAX($D$8-F24,0),$D$10)*$D$9 -> 1.098 | O24: =IF(H24="None",0,IF(H24="KM",IF(G24="Petrol",$D$6,$D$5)*N24/K24,K24*N24*IF(G24="Petrol",$D$6,$D$5))) -> 2624.22 | P24: =IF(H24="None",0,IF(H24="KM",IF(G24="Petrol",$D$6,$D$5)*N24/L24,L24*N24*IF(G24="Petrol",$D$6,$D$5))) -> 3673.908 | Q24: =IF(H24="None",0,IF(H24="KM",IF(G24="Petrol",$D$6,$D$5)*N24/M24,M24*N24*IF(G24="Petrol",$D$6,$D$5))) -> 4986.018 | R24: =IF(H24="None","—",IF(H24="KM","Rs./km","Rs./hr")) -> Rs./hr
A25: 13 | B25: LB-02 | C25: ZA-2963 | D25: Backhoe Loader | E25: Jcb 3Dx | F25: 2012 | G25: Diesel | H25: Hour | I25: Standard (class avg) | J25: L/hr | K25: 5 | L25: 7 | M25: 9.5 | N25: =1+MIN(MAX($D$8-F25,0),$D$10)*$D$9 -> 1.098 | O25: =IF(H25="None",0,IF(H25="KM",IF(G25="Petrol",$D$6,$D$5)*N25/K25,K25*N25*IF(G25="Petrol",$D$6,$D$5))) -> 2624.22 | P25: =IF(H25="None",0,IF(H25="KM",IF(G25="Petrol",$D$6,$D$5)*N25/L25,L25*N25*IF(G25="Petrol",$D$6,$D$5))) -> 3673.908 | Q25: =IF(H25="None",0,IF(H25="KM",IF(G25="Petrol",$D$6,$D$5)*N25/M25,M25*N25*IF(G25="Petrol",$D$6,$D$5))) -> 4986.018 | R25: =IF(H25="None","—",IF(H25="KM","Rs./km","Rs./hr")) -> Rs./hr
A26: 14 | B26: LB-03 | C26: ZA-2964 | D26: Backhoe Loader | E26: Jcb 3Dx | F26: 2012 | G26: Diesel | H26: Hour | I26: Standard (class avg) | J26: L/hr | K26: 5 | L26: 7 | M26: 9.5 | N26: =1+MIN(MAX($D$8-F26,0),$D$10)*$D$9 -> 1.098 | O26: =IF(H26="None",0,IF(H26="KM",IF(G26="Petrol",$D$6,$D$5)*N26/K26,K26*N26*IF(G26="Petrol",$D$6,$D$5))) -> 2624.22 | P26: =IF(H26="None",0,IF(H26="KM",IF(G26="Petrol",$D$6,$D$5)*N26/L26,L26*N26*IF(G26="Petrol",$D$6,$D$5))) -> 3673.908 | Q26: =IF(H26="None",0,IF(H26="KM",IF(G26="Petrol",$D$6,$D$5)*N26/M26,M26*N26*IF(G26="Petrol",$D$6,$D$5))) -> 4986.018 | R26: =IF(H26="None","—",IF(H26="KM","Rs./km","Rs./hr")) -> Rs./hr
A27: 15 | B27: LB-04 | C27: RS-0401 | D27: Backhoe Loader | E27: Jcb Slp3Cx | F27: 1999 | G27: Diesel | H27: Hour | I27: Standard (class avg) | J27: L/hr | K27: 5 | L27: 7 | M27: 9.5 | N27: =1+MIN(MAX($D$8-F27,0),$D$10)*$D$9 -> 1.175 | O27: =IF(H27="None",0,IF(H27="KM",IF(G27="Petrol",$D$6,$D$5)*N27/K27,K27*N27*IF(G27="Petrol",$D$6,$D$5))) -> 2808.25 | P27: =IF(H27="None",0,IF(H27="KM",IF(G27="Petrol",$D$6,$D$5)*N27/L27,L27*N27*IF(G27="Petrol",$D$6,$D$5))) -> 3931.55 | Q27: =IF(H27="None",0,IF(H27="KM",IF(G27="Petrol",$D$6,$D$5)*N27/M27,M27*N27*IF(G27="Petrol",$D$6,$D$5))) -> 5335.675 | R27: =IF(H27="None","—",IF(H27="KM","Rs./km","Rs./hr")) -> Rs./hr
A28: 16 | B28: LB-05 | C28: RS-0483 | D28: Backhoe Loader | E28: Jcb 3Dx | F28: 2006 | G28: Diesel | H28: Hour | I28: Standard (class avg) | J28: L/hr | K28: 5 | L28: 7 | M28: 9.5 | N28: =1+MIN(MAX($D$8-F28,0),$D$10)*$D$9 -> 1.14 | O28: =IF(H28="None",0,IF(H28="KM",IF(G28="Petrol",$D$6,$D$5)*N28/K28,K28*N28*IF(G28="Petrol",$D$6,$D$5))) -> 2724.6 | P28: =IF(H28="None",0,IF(H28="KM",IF(G28="Petrol",$D$6,$D$5)*N28/L28,L28*N28*IF(G28="Petrol",$D$6,$D$5))) -> 3814.44 | Q28: =IF(H28="None",0,IF(H28="KM",IF(G28="Petrol",$D$6,$D$5)*N28/M28,M28*N28*IF(G28="Petrol",$D$6,$D$5))) -> 5176.74 | R28: =IF(H28="None","—",IF(H28="KM","Rs./km","Rs./hr")) -> Rs./hr
A29: 17 | B29: LB-06 | C29: ZA-0447 | D29: Backhoe Loader | E29: Jcb 3Cx | F29: 2002 | G29: Diesel | H29: Hour | I29: Standard (class avg) | J29: L/hr | K29: 5 | L29: 7 | M29: 9.5 | N29: =1+MIN(MAX($D$8-F29,0),$D$10)*$D$9 -> 1.168 | O29: =IF(H29="None",0,IF(H29="KM",IF(G29="Petrol",$D$6,$D$5)*N29/K29,K29*N29*IF(G29="Petrol",$D$6,$D$5))) -> 2791.52 | P29: =IF(H29="None",0,IF(H29="KM",IF(G29="Petrol",$D$6,$D$5)*N29/L29,L29*N29*IF(G29="Petrol",$D$6,$D$5))) -> 3908.128 | Q29: =IF(H29="None",0,IF(H29="KM",IF(G29="Petrol",$D$6,$D$5)*N29/M29,M29*N29*IF(G29="Petrol",$D$6,$D$5))) -> 5303.888 | R29: =IF(H29="None","—",IF(H29="KM","Rs./km","Rs./hr")) -> Rs./hr
A30: 18 | B30: LB-07 | C30: ZA-2608 | D30: Backhoe Loader | E30: Jcb Jcb 3Cx | F30: 2004 | G30: Diesel | H30: Hour | I30: Standard (class avg) | J30: L/hr | K30: 5 | L30: 7 | M30: 9.5 | N30: =1+MIN(MAX($D$8-F30,0),$D$10)*$D$9 -> 1.154 | O30: =IF(H30="None",0,IF(H30="KM",IF(G30="Petrol",$D$6,$D$5)*N30/K30,K30*N30*IF(G30="Petrol",$D$6,$D$5))) -> 2758.06 | P30: =IF(H30="None",0,IF(H30="KM",IF(G30="Petrol",$D$6,$D$5)*N30/L30,L30*N30*IF(G30="Petrol",$D$6,$D$5))) -> 3861.284 | Q30: =IF(H30="None",0,IF(H30="KM",IF(G30="Petrol",$D$6,$D$5)*N30/M30,M30*N30*IF(G30="Petrol",$D$6,$D$5))) -> 5240.314 | R30: =IF(H30="None","—",IF(H30="KM","Rs./km","Rs./hr")) -> Rs./hr
A31: 19 | B31: LB-08 | C31: ZA-6068 | D31: Backhoe Loader | E31: Jcb Jcb 3Dx | F31: 2015 | G31: Diesel | H31: Hour | I31: Standard (class avg) | J31: L/hr | K31: 5 | L31: 7 | M31: 9.5 | N31: =1+MIN(MAX($D$8-F31,0),$D$10)*$D$9 -> 1.077 | O31: =IF(H31="None",0,IF(H31="KM",IF(G31="Petrol",$D$6,$D$5)*N31/K31,K31*N31*IF(G31="Petrol",$D$6,$D$5))) -> 2574.03 | P31: =IF(H31="None",0,IF(H31="KM",IF(G31="Petrol",$D$6,$D$5)*N31/L31,L31*N31*IF(G31="Petrol",$D$6,$D$5))) -> 3603.642 | Q31: =IF(H31="None",0,IF(H31="KM",IF(G31="Petrol",$D$6,$D$5)*N31/M31,M31*N31*IF(G31="Petrol",$D$6,$D$5))) -> 4890.657 | R31: =IF(H31="None","—",IF(H31="KM","Rs./km","Rs./hr")) -> Rs./hr
... A68: 56 | B68: DB-02 | C68: 68-5115 | D68: Diesel Bowser | E68: Isuzu 207 Di | F68: 1990 | G68: Diesel | H68: Hour | I68: Standard (class avg) | J68: L/hr | K68: 5 | L68: 7 | M68: 9.5 | N68: =1+MIN(MAX($D$8-F68,0),$D$10)*$D$9 -> 1.175 | O68: =IF(H68="None",0,IF(H68="KM",IF(G68="Petrol",$D$6,$D$5)*N68/K68,K68*N68*IF(G68="Petrol",$D$6,$D$5))) -> 2808.25 | P68: =IF(H68="None",0,IF(H68="KM",IF(G68="Petrol",$D$6,$D$5)*N68/L68,L68*N68*IF(G68="Petrol",$D$6,$D$5))) -> 3931.55 | Q68: =IF(H68="None",0,IF(H68="KM",IF(G68="Petrol",$D$6,$D$5)*N68/M68,M68*N68*IF(G68="Petrol",$D$6,$D$5))) -> 5335.675 | R68: =IF(H68="None","—",IF(H68="KM","Rs./km","Rs./hr")) -> Rs./hr
A69: 57 | B69: DB-03 | C69: 40-2955 | D69: Diesel Bowser | E69: Nissan Atlas | F69: — | G69: Diesel | H69: Hour | I69: Standard (class avg) | J69: L/hr | K69: 5 | L69: 7 | M69: 9.5 | N69: =1 -> 1 | O69: =IF(H69="None",0,IF(H69="KM",IF(G69="Petrol",$D$6,$D$5)*N69/K69,K69*N69*IF(G69="Petrol",$D$6,$D$5))) -> 2390 | P69: =IF(H69="None",0,IF(H69="KM",IF(G69="Petrol",$D$6,$D$5)*N69/L69,L69*N69*IF(G69="Petrol",$D$6,$D$5))) -> 3346 | Q69: =IF(H69="None",0,IF(H69="KM",IF(G69="Petrol",$D$6,$D$5)*N69/M69,M69*N69*IF(G69="Petrol",$D$6,$D$5))) -> 4541 | R69: =IF(H69="None","—",IF(H69="KM","Rs./km","Rs./hr")) -> Rs./hr
A70: 58 | B70: DB-04 | C70: 41-1130 | D70: Diesel Bowser | E70: Isuzu — | F70: 2005 | G70: Diesel | H70: Hour | I70: Standard (class avg) | J70: L/hr | K70: 5 | L70: 7 | M70: 9.5 | N70: =1+MIN(MAX($D$8-F70,0),$D$10)*$D$9 -> 1.147 | O70: =IF(H70="None",0,IF(H70="KM",IF(G70="Petrol",$D$6,$D$5)*N70/K70,K70*N70*IF(G70="Petrol",$D$6,$D$5))) -> 2741.33 | P70: =IF(H70="None",0,IF(H70="KM",IF(G70="Petrol",$D$6,$D$5)*N70/L70,L70*N70*IF(G70="Petrol",$D$6,$D$5))) -> 3837.862 | Q70: =IF(H70="None",0,IF(H70="KM",IF(G70="Petrol",$D$6,$D$5)*N70/M70,M70*N70*IF(G70="Petrol",$D$6,$D$5))) -> 5208.527 | R70: =IF(H70="None","—",IF(H70="KM","Rs./km","Rs./hr")) -> Rs./hr
A71: 59 | B71: DB-05 | C71: LA-1359 | D71: Diesel Bowser | E71: Tata — | F71: 1990 | G71: Diesel | H71: Hour | I71: Standard (class avg) | J71: L/hr | K71: 5 | L71: 7 | M71: 9.5 | N71: =1+MIN(MAX($D$8-F71,0),$D$10)*$D$9 -> 1.175 | O71: =IF(H71="None",0,IF(H71="KM",IF(G71="Petrol",$D$6,$D$5)*N71/K71,K71*N71*IF(G71="Petrol",$D$6,$D$5))) -> 2808.25 | P71: =IF(H71="None",0,IF(H71="KM",IF(G71="Petrol",$D$6,$D$5)*N71/L71,L71*N71*IF(G71="Petrol",$D$6,$D$5))) -> 3931.55 | Q71: =IF(H71="None",0,IF(H71="KM",IF(G71="Petrol",$D$6,$D$5)*N71/M71,M71*N71*IF(G71="Petrol",$D$6,$D$5))) -> 5335.675 | R71: =IF(H71="None","—",IF(H71="KM","Rs./km","Rs./hr")) -> Rs./hr
A72: 60 | B72: — | C72: — | D72: Diesel Bowser | E72: Tata — | F72: — | G72: Diesel | H72: Hour | I72: Standard (class avg) | J72: L/hr | K72: 5 | L72: 7 | M72: 9.5 | N72: =1 -> 1 | O72: =IF(H72="None",0,IF(H72="KM",IF(G72="Petrol",$D$6,$D$5)*N72/K72,K72*N72*IF(G72="Petrol",$D$6,$D$5))) -> 2390 | P72: =IF(H72="None",0,IF(H72="KM",IF(G72="Petrol",$D$6,$D$5)*N72/L72,L72*N72*IF(G72="Petrol",$D$6,$D$5))) -> 3346 | Q72: =IF(H72="None",0,IF(H72="KM",IF(G72="Petrol",$D$6,$D$5)*N72/M72,M72*N72*IF(G72="Petrol",$D$6,$D$5))) -> 4541 | R72: =IF(H72="None","—",IF(H72="KM","Rs./km","Rs./hr")) -> Rs./hr
A73: 61 | B73: DC-06 | C73: PA-4193 | D73: Double Cab (Pickup) | E73: Toyota Hilux | F73: 2005 | G73: Diesel | H73: KM | I73: Standard (class avg) | J73: km/L | K73: 12.8 | L73: 10 | M73: 8 | N73: =1+MIN(MAX($D$8-F73,0),$D$10)*$D$9 -> 1.147 | O73: =IF(H73="None",0,IF(H73="KM",IF(G73="Petrol",$D$6,$D$5)*N73/K73,K73*N73*IF(G73="Petrol",$D$6,$D$5))) -> 42.833281 | P73: =IF(H73="None",0,IF(H73="KM",IF(G73="Petrol",$D$6,$D$5)*N73/L73,L73*N73*IF(G73="Petrol",$D$6,$D$5))) -> 54.8266 | Q73: =IF(H73="None",0,IF(H73="KM",IF(G73="Petrol",$D$6,$D$5)*N73/M73,M73*N73*IF(G73="Petrol",$D$6,$D$5))) -> 68.53325 | R73: =IF(H73="None","—",IF(H73="KM","Rs./km","Rs./hr")) -> Rs./km
A74: 62 | B74: DC-07 | C74: 51-8083 | D74: Double Cab (Pickup) | E74: Datzen Motor Pic-Up | F74: — | G74: Diesel | H74: KM | I74: Standard (class avg) | J74: km/L | K74: 12.8 | L74: 10 | M74: 8 | N74: =1 -> 1 | O74: =IF(H74="None",0,IF(H74="KM",IF(G74="Petrol",$D$6,$D$5)*N74/K74,K74*N74*IF(G74="Petrol",$D$6,$D$5))) -> 37.34375 | P74: =IF(H74="None",0,IF(H74="KM",IF(G74="Petrol",$D$6,$D$5)*N74/L74,L74*N74*IF(G74="Petrol",$D$6,$D$5))) -> 47.8 | Q74: =IF(H74="None",0,IF(H74="KM",IF(G74="Petrol",$D$6,$D$5)*N74/M74,M74*N74*IF(G74="Petrol",$D$6,$D$5))) -> 59.75 | R74: =IF(H74="None","—",IF(H74="KM","Rs./km","Rs./hr")) -> Rs./km
A75: 63 | B75: DC-08 | C75: 59-5421 | D75: Double Cab (Pickup) | E75: Isuzu Motor Pic-Up | F75: 1997 | G75: Diesel | H75: KM | I75: Standard (class avg) | J75: km/L | K75: 12.8 | L75: 10 | M75: 8 | N75: =1+MIN(MAX($D$8-F75,0),$D$10)*$D$9 -> 1.175 | O75: =IF(H75="None",0,IF(H75="KM",IF(G75="Petrol",$D$6,$D$5)*N75/K75,K75*N75*IF(G75="Petrol",$D$6,$D$5))) -> 43.878906 | P75: =IF(H75="None",0,IF(H75="KM",IF(G75="Petrol",$D$6,$D$5)*N75/L75,L75*N75*IF(G75="Petrol",$D$6,$D$5))) -> 56.165 | Q75: =IF(H75="None",0,IF(H75="KM",IF(G75="Petrol",$D$6,$D$5)*N75/M75,M75*N75*IF(G75="Petrol",$D$6,$D$5))) -> 70.20625 | R75: =IF(H75="None","—",IF(H75="KM","Rs./km","Rs./hr")) -> Rs./km
A76: 64 | B76: DC-10 | C76: 28-4314 | D76: Double Cab (Pickup) | E76: Datzen Motor Pic-Up | F76: 1985 | G76: Diesel | H76: KM | I76: Standard (class avg) | J76: km/L | K76: 12.8 | L76: 10 | M76: 8 | N76: =1+MIN(MAX($D$8-F76,0),$D$10)*$D$9 -> 1.175 | O76: =IF(H76="None",0,IF(H76="KM",IF(G76="Petrol",$D$6,$D$5)*N76/K76,K76*N76*IF(G76="Petrol",$D$6,$D$5))) -> 43.878906 | P76: =IF(H76="None",0,IF(H76="KM",IF(G76="Petrol",$D$6,$D$5)*N76/L76,L76*N76*IF(G76="Petrol",$D$6,$D$5))) -> 56.165 | Q76: =IF(H76="None",0,IF(H76="KM",IF(G76="Petrol",$D$6,$D$5)*N76/M76,M76*N76*IF(G76="Petrol",$D$6,$D$5))) -> 70.20625 | R76: =IF(H76="None","—",IF(H76="KM","Rs./km","Rs./hr")) -> Rs./km
A77: 65 | B77: DC-11 | C77: HU-5097 | D77: Double Cab (Pickup) | E77: Mitsubishi L 200 | F77: 2003 | G77: Diesel | H77: KM | I77: Standard (class avg) | J77: km/L | K77: 12.8 | L77: 10 | M77: 8 | N77: =1+MIN(MAX($D$8-F77,0),$D$10)*$D$9 -> 1.161 | O77: =IF(H77="None",0,IF(H77="KM",IF(G77="Petrol",$D$6,$D$5)*N77/K77,K77*N77*IF(G77="Petrol",$D$6,$D$5))) -> 43.356094 | P77: =IF(H77="None",0,IF(H77="KM",IF(G77="Petrol",$D$6,$D$5)*N77/L77,L77*N77*IF(G77="Petrol",$D$6,$D$5))) -> 55.4958 | Q77: =IF(H77="None",0,IF(H77="KM",IF(G77="Petrol",$D$6,$D$5)*N77/M77,M77*N77*IF(G77="Petrol",$D$6,$D$5))) -> 69.36975 | R77: =IF(H77="None","—",IF(H77="KM","Rs./km","Rs./hr")) -> Rs./km
A78: 66 | B78: DC-12 | C78: 253-2574 | D78: Double Cab (Pickup) | E78: Mitsubishi Motor Pic-Up | F78: 1999 | G78: Diesel | H78: KM | I78: Standard (class avg) | J78: km/L | K78: 12.8 | L78: 10 | M78: 8 | N78: =1+MIN(MAX($D$8-F78,0),$D$10)*$D$9 -> 1.175 | O78: =IF(H78="None",0,IF(H78="KM",IF(G78="Petrol",$D$6,$D$5)*N78/K78,K78*N78*IF(G78="Petrol",$D$6,$D$5))) -> 43.878906 | P78: =IF(H78="None",0,IF(H78="KM",IF(G78="Petrol",$D$6,$D$5)*N78/L78,L78*N78*IF(G78="Petrol",$D$6,$D$5))) -> 56.165 | Q78: =IF(H78="None",0,IF(H78="KM",IF(G78="Petrol",$D$6,$D$5)*N78/M78,M78*N78*IF(G78="Petrol",$D$6,$D$5))) -> 70.20625 | R78: =IF(H78="None","—",IF(H78="KM","Rs./km","Rs./hr")) -> Rs./km
...

Sheet Summary
A1: FLEET SUMMARY — Counts & Monthly Revenue Potential
A2: Monthly potential = unit count × average monthly WET rate (120 hrs, 85% volume discount) if every machine deployed 1 full month.
A4: # | B4: Category | C4: Unit count | D4: Avg. Hourly WET | E4: Avg. Monthly WET (120h) | F4: Category Monthly Revenue Potential
A5: 1 | B5: Backhoe Loader | C5: 24 | D5: =IFERROR(AVERAGEIF('Fleet Pricing'!B:B,B5,'Fleet Pricing'!H:H),0) -> 3704.5833 | E5: =IFERROR(AVERAGEIF('Fleet Pricing'!B:B,B5,'Fleet Pricing'!L:L),0) -> 377937.5 | F5: =C5*E5 -> 9070500
A6: 2 | B6: Wheel Loader | C6: 9 | D6: =IFERROR(AVERAGEIF('Fleet Pricing'!B:B,B6,'Fleet Pricing'!H:H),0) -> 7097.7778 | E6: =IFERROR(AVERAGEIF('Fleet Pricing'!B:B,B6,'Fleet Pricing'!L:L),0) -> 724055.56 | F6: =C6*E6 -> 6516500
A7: 3 | B7: Truck Mixer | C7: 16 | D7: =IFERROR(AVERAGEIF('Fleet Pricing'!B:B,B7,'Fleet Pricing'!H:H),0) -> 3780.625 | E7: =IFERROR(AVERAGEIF('Fleet Pricing'!B:B,B7,'Fleet Pricing'!L:L),0) -> 385656.25 | F7: =C7*E7 -> 6170500
A8: 4 | B8: Self Loader Mixer | C8: 3 | D8: =IFERROR(AVERAGEIF('Fleet Pricing'!B:B,B8,'Fleet Pricing'!H:H),0) -> 4880 | E8: =IFERROR(AVERAGEIF('Fleet Pricing'!B:B,B8,'Fleet Pricing'!L:L),0) -> 498000 | F8: =C8*E8 -> 1494000
A9: 5 | B9: Static Roller | C9: 19 | D9: =IFERROR(AVERAGEIF('Fleet Pricing'!B:B,B9,'Fleet Pricing'!H:H),0) -> 3602.1053 | E9: =IFERROR(AVERAGEIF('Fleet Pricing'!B:B,B9,'Fleet Pricing'!L:L),0) -> 367421.05 | F9: =C9*E9 -> 6981000
A10: 6 | B10: Vibrating Roller | C10: 72 | D10: =IFERROR(AVERAGEIF('Fleet Pricing'!B:B,B10,'Fleet Pricing'!H:H),0) -> 2716.6667 | E10: =IFERROR(AVERAGEIF('Fleet Pricing'!B:B,B10,'Fleet Pricing'!L:L),0) -> 277083.33 | F10: =C10*E10 -> 19950000
A11: 7 | B11: Pneumatic Roller | C11: 10 | D11: =IFERROR(AVERAGEIF('Fleet Pricing'!B:B,B11,'Fleet Pricing'!H:H),0) -> 2983 | E11: =IFERROR(AVERAGEIF('Fleet Pricing'!B:B,B11,'Fleet Pricing'!L:L),0) -> 304250 | F11: =C11*E11 -> 3042500
A12: 8 | B12: Motor Grader | C12: 16 | D12: =IFERROR(AVERAGEIF('Fleet Pricing'!B:B,B12,'Fleet Pricing'!H:H),0) -> 7094.375 | E12: =IFERROR(AVERAGEIF('Fleet Pricing'!B:B,B12,'Fleet Pricing'!L:L),0) -> 723593.75 | F12: =C12*E12 -> 11577500
A13: 9 | B13: Skid Steer | C13: 25 | D13: =IFERROR(AVERAGEIF('Fleet Pricing'!B:B,B13,'Fleet Pricing'!H:H),0) -> 2489.6 | E13: =IFERROR(AVERAGEIF('Fleet Pricing'!B:B,B13,'Fleet Pricing'!L:L),0) -> 254000 | F13: =C13*E13 -> 6350000
A14: 10 | B14: Asphalt Paver | C14: 11 | D14: =IFERROR(AVERAGEIF('Fleet Pricing'!B:B,B14,'Fleet Pricing'!H:H),0) -> 6381.8182 | E14: =IFERROR(AVERAGEIF('Fleet Pricing'!B:B,B14,'Fleet Pricing'!L:L),0) -> 650863.64 | F14: =C14*E14 -> 7159500
A15: 11 | B15: Bitumen Bowser | C15: 4 | D15: =IFERROR(AVERAGEIF('Fleet Pricing'!B:B,B15,'Fleet Pricing'!H:H),0) -> 2747.5 | E15: =IFERROR(AVERAGEIF('Fleet Pricing'!B:B,B15,'Fleet Pricing'!L:L),0) -> 280125 | F15: =C15*E15 -> 1120500
A16: 12 | B16: Mobile Crane | C16: 2 | D16: =IFERROR(AVERAGEIF('Fleet Pricing'!B:B,B16,'Fleet Pricing'!H:H),0) -> 5100 | E16: =IFERROR(AVERAGEIF('Fleet Pricing'!B:B,B16,'Fleet Pricing'!L:L),0) -> 520000 | F16: =C16*E16 -> 1040000
... A33: 29 | B33: Forklift | C33: 3 | D33: =IFERROR(AVERAGEIF('Fleet Pricing'!B:B,B33,'Fleet Pricing'!H:H),0) -> 1770 | E33: =IFERROR(AVERAGEIF('Fleet Pricing'!B:B,B33,'Fleet Pricing'!L:L),0) -> 180500 | F33: =C33*E33 -> 541500
B34: TOTAL FLEET | C34: =SUM(C5:C33) -> 518 | F34: =SUM(F5:F33) -> 159293500

Sheet Fleet Pricing
A1: FLEET PRICING 2026 — ALL 518 UNITS (engineered rates)
A2: Rates in LKR, excluding 18% VAT. Daily min. 4 hrs • Monthly min. 120 hrs. Driven by Rate Card sheet.
A4: # | B4: Category | C4: Brand | D4: E&C No. | E4: Model | F4: Year | G4: Registration No. | H4: Hourly WET | I4: Hourly DRY | J4: Daily WET (4h) | K4: Daily DRY (4h) | L4: Monthly WET (120h) | M4: Monthly DRY (120h) | N4: Remarks | O4: age_f | P4: size_m
A5: BACKHOE LOADER
A6: 1 | B6: Backhoe Loader | C6: BOB CAT | D6: LB-22 | E6: B760 | F6: 2021 | G6: ZB-2586 | H6: =MROUND('Rate Card'!$I$5*O6*P6,10) -> 4150 | I6: =MROUND('Rate Card'!$K$5*O6*P6,10) -> 2000 | J6: =MROUND(H6*4*'Rate Card'!$B$47,100) -> 15800 | K6: =MROUND(I6*4*'Rate Card'!$B$47,100) -> 7600 | L6: =MROUND(H6*120*'Rate Card'!$B$48,500) -> 423500 | M6: =MROUND(I6*120*'Rate Card'!$B$48,500) -> 204000 | O6: 1 | P6: 1
A7: 2 | B7: Backhoe Loader | C7: BOB CAT | D7: LB-23 | E7: B760 | F7: 2021 | G7: ZB-2587 | H7: =MROUND('Rate Card'!$I$5*O7*P7,10) -> 4150 | I7: =MROUND('Rate Card'!$K$5*O7*P7,10) -> 2000 | J7: =MROUND(H7*4*'Rate Card'!$B$47,100) -> 15800 | K7: =MROUND(I7*4*'Rate Card'!$B$47,100) -> 7600 | L7: =MROUND(H7*120*'Rate Card'!$B$48,500) -> 423500 | M7: =MROUND(I7*120*'Rate Card'!$B$48,500) -> 204000 | O7: 1 | P7: 1
A8: 3 | B8: Backhoe Loader | C8: BOB CAT | D8: LB-24 | E8: B760 | F8: 2021 | G8: ZB-2583 | H8: =MROUND('Rate Card'!$I$5*O8*P8,10) -> 4150 | I8: =MROUND('Rate Card'!$K$5*O8*P8,10) -> 2000 | J8: =MROUND(H8*4*'Rate Card'!$B$47,100) -> 15800 | K8: =MROUND(I8*4*'Rate Card'!$B$47,100) -> 7600 | L8: =MROUND(H8*120*'Rate Card'!$B$48,500) -> 423500 | M8: =MROUND(I8*120*'Rate Card'!$B$48,500) -> 204000 | O8: 1 | P8: 1
A9: 4 | B9: Backhoe Loader | C9: J.C.B | D9: LB-16 | E9: 3DX | F9: 2020 | G9: ZB-1547 | H9: =MROUND('Rate Card'!$I$5*O9*P9,10) -> 4150 | I9: =MROUND('Rate Card'!$K$5*O9*P9,10) -> 2000 | J9: =MROUND(H9*4*'Rate Card'!$B$47,100) -> 15800 | K9: =MROUND(I9*4*'Rate Card'!$B$47,100) -> 7600 | L9: =MROUND(H9*120*'Rate Card'!$B$48,500) -> 423500 | M9: =MROUND(I9*120*'Rate Card'!$B$48,500) -> 204000 | O9: 1 | P9: 1
A10: 5 | B10: Backhoe Loader | C10: JCB | D10: LB-02 | E10: 3DX | F10: 2012 | G10: ZA-2963 | H10: =MROUND('Rate Card'!$I$5*O10*P10,10) -> 4150 | I10: =MROUND('Rate Card'!$K$5*O10*P10,10) -> 2000 | J10: =MROUND(H10*4*'Rate Card'!$B$47,100) -> 15800 | K10: =MROUND(I10*4*'Rate Card'!$B$47,100) -> 7600 | L10: =MROUND(H10*120*'Rate Card'!$B$48,500) -> 423500 | M10: =MROUND(I10*120*'Rate Card'!$B$48,500) -> 204000 | O10: 1 | P10: 1
A11: 6 | B11: Backhoe Loader | C11: JCB | D11: LB-03 | E11: 3DX | F11: 2012 | G11: ZA-2964 | H11: =MROUND('Rate Card'!$I$5*O11*P11,10) -> 4150 | I11: =MROUND('Rate Card'!$K$5*O11*P11,10) -> 2000 | J11: =MROUND(H11*4*'Rate Card'!$B$47,100) -> 15800 | K11: =MROUND(I11*4*'Rate Card'!$B$47,100) -> 7600 | L11: =MROUND(H11*120*'Rate Card'!$B$48,500) -> 423500 | M11: =MROUND(I11*120*'Rate Card'!$B$48,500) -> 204000 | O11: 1 | P11: 1
A12: 7 | B12: Backhoe Loader | C12: JCB | D12: LB-09 | E12: 3DX | F12: 2015 | G12: ZA-6069 | H12: =MROUND('Rate Card'!$I$5*O12*P12,10) -> 4150 | I12: =MROUND('Rate Card'!$K$5*O12*P12,10) -> 2000 | J12: =MROUND(H12*4*'Rate Card'!$B$47,100) -> 15800 | K12: =MROUND(I12*4*'Rate Card'!$B$47,100) -> 7600 | L12: =MROUND(H12*120*'Rate Card'!$B$48,500) -> 423500 | M12: =MROUND(I12*120*'Rate Card'!$B$48,500) -> 204000 | O12: 1 | P12: 1
A13: 8 | B13: Backhoe Loader | C13: JCB | D13: LB-11 | E13: 3DX | F13: 2016 | G13: ZA-7092 | H13: =MROUND('Rate Card'!$I$5*O13*P13,10) -> 4150 | I13: =MROUND('Rate Card'!$K$5*O13*P13,10) -> 2000 | J13: =MROUND(H13*4*'Rate Card'!$B$47,100) -> 15800 | K13: =MROUND(I13*4*'Rate Card'!$B$47,100) -> 7600 | L13: =MROUND(H13*120*'Rate Card'!$B$48,500) -> 423500 | M13: =MROUND(I13*120*'Rate Card'!$B$48,500) -> 204000 | O13: 1 | P13: 1
A14: 9 | B14: Backhoe Loader | C14: JCB | D14: LB-13 | E14: 3DX | F14: 2016 | G14: ZA-7965 | H14: =MROUND('Rate Card'!$I$5*O14*P14,10) -> 4150 | I14: =MROUND('Rate Card'!$K$5*O14*P14,10) -> 2000 | J14: =MROUND(H14*4*'Rate Card'!$B$47,100) -> 15800 | K14: =MROUND(I14*4*'Rate Card'!$B$47,100) -> 7600 | L14: =MROUND(H14*120*'Rate Card'!$B$48,500) -> 423500 | M14: =MROUND(I14*120*'Rate Card'!$B$48,500) -> 204000 | O14: 1 | P14: 1
A15: 10 | B15: Backhoe Loader | C15: J.C.B | D15: LB-15 | E15: 570ST | F15: 2019 | G15: ZB-1047 | H15: =MROUND('Rate Card'!$I$5*O15*P15,10) -> 3820 | I15: =MROUND('Rate Card'!$K$5*O15*P15,10) -> 1840 | J15: =MROUND(H15*4*'Rate Card'!$B$47,100) -> 14500 | K15: =MROUND(I15*4*'Rate Card'!$B$47,100) -> 7000 | L15: =MROUND(H15*120*'Rate Card'!$B$48,500) -> 389500 | M15: =MROUND(I15*120*'Rate Card'!$B$48,500) -> 187500 | O15: 0.92 | P15: 1
A16: 11 | B16: Backhoe Loader | C16: JCB | D16: LB-10 | E16: JCB 3DX | F16: 2016 | G16: ZA-7034 | H16: =MROUND('Rate Card'!$I$5*O16*P16,10) -> 3820 | I16: =MROUND('Rate Card'!$K$5*O16*P16,10) -> 1840 | J16: =MROUND(H16*4*'Rate Card'!$B$47,100) -> 14500 | K16: =MROUND(I16*4*'Rate Card'!$B$47,100) -> 7000 | L16: =MROUND(H16*120*'Rate Card'!$B$48,500) -> 389500 | M16: =MROUND(I16*120*'Rate Card'!$B$48,500) -> 187500 | O16: 0.92 | P16: 1
A17: 12 | B17: Backhoe Loader | C17: JCB | D17: LB-14 | E17: JCB 3DX | F17: 2016 | G17: ZA-7968 | H17: =MROUND('Rate Card'!$I$5*O17*P17,10) -> 3820 | I17: =MROUND('Rate Card'!$K$5*O17*P17,10) -> 1840 | J17: =MROUND(H17*4*'Rate Card'!$B$47,100) -> 14500 | K17: =MROUND(I17*4*'Rate Card'!$B$47,100) -> 7000 | L17: =MROUND(H17*120*'Rate Card'!$B$48,500) -> 389500 | M17: =MROUND(I17*120*'Rate Card'!$B$48,500) -> 187500 | O17: 0.92 | P17: 1
... A25: 20 | B25: Backhoe Loader | C25: J.C.B | D25: LB-21 | E25: 3DX | F25: 2020 | G25: ZB-1980 | H25: =MROUND('Rate Card'!$I$5*O25*P25,10) -> 3400 | I25: =MROUND('Rate Card'!$K$5*O25*P25,10) -> 1640 | J25: =MROUND(H25*4*'Rate Card'!$B$47,100) -> 12900 | K25: =MROUND(I25*4*'Rate Card'!$B$47,100) -> 6200 | L25: =MROUND(H25*120*'Rate Card'!$B$48,500) -> 347000 | M25: =MROUND(I25*120*'Rate Card'!$B$48,500) -> 167500 | O25: 0.82 | P25: 1
A26: 21 | B26: Backhoe Loader | C26: JCB | D26: LB-05 | E26: 3DX | F26: 2006 | G26: RS-0483 | H26: =MROUND('Rate Card'!$I$5*O26*P26,10) -> 2990 | I26: =MROUND('Rate Card'!$K$5*O26*P26,10) -> 1440 | J26: =MROUND(H26*4*'Rate Card'!$B$47,100) -> 11400 | K26: =MROUND(I26*4*'Rate Card'!$B$47,100) -> 5500 | L26: =MROUND(H26*120*'Rate Card'!$B$48,500) -> 305000 | M26: =MROUND(I26*120*'Rate Card'!$B$48,500) -> 147000 | N26: age factor 72% | O26: 0.72 | P26: 1
A27: 22 | B27: Backhoe Loader | C27: JCB | D27: LB-07 | E27: JCB 3CX | F27: 2004 | G27: ZA-2608 | H27: =MROUND('Rate Card'!$I$5*O27*P27,10) -> 2700 | I27: =MROUND('Rate Card'!$K$5*O27*P27,10) -> 1300 | J27: =MROUND(H27*4*'Rate Card'!$B$47,100) -> 10300 | K27: =MROUND(I27*4*'Rate Card'!$B$47,100) -> 4900 | L27: =MROUND(H27*120*'Rate Card'!$B$48,500) -> 275500 | M27: =MROUND(I27*120*'Rate Card'!$B$48,500) -> 132500 | N27: age factor 65% | O27: 0.65 | P27: 1
