Workbook

Sheet Fuel Log
A1: BATTICALOA ICDP LOT-02 | E&C DAILY FUEL ISSUING SHEET
A3: Date | B3: Sheet Row No | C3: Vehicle No | D3: Vehicle Category | E3: 1st Fuel Qty (L) | F3: 2nd Fuel Qty (L) | G3: Total Issued (L) | H3: 1st Meter Reading | I3: 2nd Meter Reading | J3: Previous Meter | K3: Driver Name | L3: Remarks
A4: 46235 | B4: 1 | C4: 226-3944 | D4: 1 Cub (Hire) | E4: 10 | F4: 5 | G4: =SUM(E4:F4) -> 15 | H4: 252089 | I4: 252075 | K4: Sabe | L4: 2nd meter reads lower than 1st meter as written
A5: 46235 | B5: 2 | C5: LO-4821 | D5: Tipper | E5: 10 | F5: 5 | G5: =SUM(E5:F5) -> 15 | H5: N/W | K5: Athapaththu
A6: 46235 | B6: 3 | C6: LL-0936 | D6: 1 Cub | E6: 10 | G6: =SUM(E6:F6) -> 10 | H6: N/W | K6: Samith
A7: 46235 | B7: 4 | C7: PD-6917 | D7: Bolero | E7: 10 | G7: =SUM(E7:F7) -> 10 | H7: 217050 | I7: 217139 | K7: Lahiru | L7: Vehicle no. overwritten on sheet
A8: 46235 | B8: 5 | C8: LO-1059 | D8: W/B | F8: 20 | G8: =SUM(E8:F8) -> 20 | H8: 72623 | K8: Gangoda | L8: 1st qty struck out; 20 L entered under 2nd qty. Vehicle written as LO-4821 then corrected to 1059
A9: 46235 | B9: 6 | C9: LC-6767 | D9: W/B | E9: 10 | G9: =SUM(E9:F9) -> 10 | H9: N/W | K9: Sirithunga
A10: 46235 | B10: 7 | C10: ZA-7968 | D10: JCB | E10: 15 | G10: =SUM(E10:F10) -> 15 | H10: 954.8 | K10: Chamod
A11: 46235 | B11: 8 | C11: SL-13 | D11: Bob Cat | E11: 10 | G11: =SUM(E11:F11) -> 10 | H11: 6855.4 | K11: Mihiranga
A12: 46235 | B12: 9 | C12: ZB-1979 | D12: JCB | E12: 15 | F12: 10 | G12: =SUM(E12:F12) -> 25 | H12: 7113.8 | I12: 7117 | K12: Sugath
A13: 46235 | B13: 10 | C13: SR-19 | D13: 10 Ton | E13: 15 | G13: =SUM(E13:F13) -> 15 | H13: 2546.3 | K13: Dushan
A14: 46235 | B14: 11 | C14: VP-60 | D14: 4 Ton | E14: 5 | G14: =SUM(E14:F14) -> 5 | H14: 1629 | K14: Sadaruwan | L14: Meter figure overwritten
A15: 46235 | B15: 12 | C15: MG-14 | D15: MG | E15: 15 | G15: =SUM(E15:F15) -> 15 | H15: 6723 | K15: Athapaththu
A16: 46235 | B16: 13 | C16: GE-102 | D16: Generator | E16: 10 | G16: =SUM(E16:F16) -> 10 | H16: - | K16: Janith | L16: Generator, no meter recorded
A17: 46235 | B17: 14 | C17: HEX-43 | D17: Excavator | E17: 20 | G17: =SUM(E17:F17) -> 20 | H17: 5314.5 | K17: Disanayaka | L17: Category blank on sheet; taken from 03/08 sheet
A18: 46235 | B18: 15 | C18: LD-1718 | D18: Tipper | E18: 25 | G18: =SUM(E18:F18) -> 25 | H18: 142906 | K18: Sameera
A19: 46236 | B19: 1 | C19: 226-3944 | D19: 1 Cub (Cub) | E19: 15 | G19: =SUM(E19:F19) -> 15 | H19: 252110 | K19: Sabe
A20: 46236 | B20: 2 | C20: PD-6917 | D20: Bolero | E20: 10 | F20: 10 | G20: =SUM(E20:F20) -> 20 | H20: 217213 | I20: 217299 | K20: Lahiru
A21: 46236 | B21: 3 | C21: LK-0936 | D21: 1 Cub | E21: 10 | F21: 5 | G21: =SUM(E21:F21) -> 15 | H21: N/W | K21: Samith | L21: Written LK-0936; same unit as LL-0936 on 01/08 and 03/08
A22: 46236 | B22: 4 | C22: LO-4821 | D22: Tipper | E22: 20 | F22: 5 | G22: =SUM(E22:F22) -> 25 | H22: N/W | K22: Athapaththu
A23: 46236 | B23: 5 | C23: ZB-1979 | D23: JCB | E23: 20 | F23: 10 | G23: =SUM(E23:F23) -> 30 | H23: 7118.9 | I23: 7123.1 | K23: Sugath
A24: 46236 | B24: 6 | C24: LC-6767 | D24: W/B | E24: 10 | G24: =SUM(E24:F24) -> 10 | H24: N/W | K24: Sirithunga | L24: Written as LO-1059 then struck out and corrected to C-6767
A25: 46236 | B25: 7 | C25: ZA-7968 | D25: JCB | E25: 10 | G25: =SUM(E25:F25) -> 10 | H25: 958.8 | K25: Chamod
A26: 46236 | B26: 8 | C26: LO-1059 | D26: W/B | E26: 15 | G26: =SUM(E26:F26) -> 15 | H26: 72643 | K26: Gangoda
A27: 46236 | B27: 9 | C27: GE-84 | D27: Generator | E27: 10 | G27: =SUM(E27:F27) -> 10 | H27: - | K27: Dinu | L27: 2nd qty entry struck out; category blank on sheet
A28: 46236 | B28: 10 | C28: HEX-43 | D28: Excavator | E28: 40 | F28: 10 | G28: =SUM(E28:F28) -> 50 | H28: 5316.1 | I28: 5319.8 | K28: Disanayaka | L28: Category blank on sheet
A29: 46236 | B29: 11 | C29: SR-19 | D29: 10 Ton | E29: 15 | G29: =SUM(E29:F29) -> 15 | H29: 2548.8 | K29: Sadaruwan
A30: 46236 | B30: 12 | C30: VP-60 | D30: 4 Ton | E30: 5 | G30: =SUM(E30:F30) -> 5 | H30: 1630 | K30: Sadaruwan
A31: 46236 | B31: 13 | C31: KF-3700 | D31: DM Cab | E31: 25 | G31: =SUM(E31:F31) -> 25 | H31: 32143 | K31: Kanishka | L31: Leading digit unclear, may be 82143
A32: 46236 | B32: 14 | C32: ZA-7969 | D32: JCB | E32: 5 | G32: =SUM(E32:F32) -> 5 | H32: 15665 | K32: Thusitha
A33: 46236 | B33: 15 | C33: ZA-7291 | E33: 20 | G33: =SUM(E33:F33) -> 20 | H33: 15 | K33: Samith | L33: Meter entry incomplete on sheet
A34: 46236 | B34: 16 | C34: TM-13 | D34: Fiori | E34: 15 | G34: =SUM(E34:F34) -> 15 | K34: Saman | L34: No meter recorded; no signature
A35: 46236 | B35: 17 | C35: LN-1867 | E35: 20 | G35: =SUM(E35:F35) -> 20 | H35: N/W | K35: Chanaka
A36: 46236 | B36: 18 | C36: LD-1718 | D36: Tipper | E36: 25 | G36: =SUM(E36:F36) -> 25 | H36: 143140 | K36: Sameera
A37: 46237 | B37: 1 | C37: 226-3944 | D37: 1 Cub (Hire) | E37: 15 | G37: =SUM(E37:F37) -> 15 | H37: 252231 | J37: 252284 | K37: Sabe | L37: 2nd meter entry struck out; previous meter 252284 recorded
A38: 46237 | B38: 2 | C38: PD-6917 | D38: Bolero | E38: 10 | G38: =SUM(E38:F38) -> 10 | H38: 217381 | I38: 217463 | K38: Lahiru
A39: 46237 | B39: 3 | C39: LO-4821 | D39: Tipper | E39: 20 | F39: 5 | G39: =SUM(E39:F39) -> 25 | H39: N/W | K39: Athapaththu
A40: 46237 | B40: 4 | C40: LL-0936 | D40: 1 Cub | E40: 10 | F40: 10 | G40: =SUM(E40:F40) -> 20 | H40: N/W | K40: Samith
A41: 46237 | B41: 5 | C41: LC-6767 | D41: W/B | E41: 15 | G41: =SUM(E41:F41) -> 15 | H41: N/W | K41: Sirithunga
...

Sheet Daily Summary
A1: DAILY FUEL ISSUE SUMMARY
A3: Date | B3: Day | C3: Entries on Sheet | D3: 1st Fuel Qty (L) | E3: 2nd Fuel Qty (L) | F3: Total Issued (L)
A4: 46235 | B4: =TEXT(A4,"DDDD") -> Saturday | C4: =COUNTIFS('Fuel Log'!$A$4:$A$52,A4) -> 15 | D4: =SUMIFS('Fuel Log'!$E$4:$E$52,'Fuel Log'!$A$4:$A$52,A4) -> 180 | E4: =SUMIFS('Fuel Log'!$F$4:$F$52,'Fuel Log'!$A$4:$A$52,A4) -> 40 | F4: =SUMIFS('Fuel Log'!$G$4:$G$52,'Fuel Log'!$A$4:$A$52,A4) -> 220
A5: 46236 | B5: =TEXT(A5,"DDDD") -> Sunday | C5: =COUNTIFS('Fuel Log'!$A$4:$A$52,A5) -> 18 | D5: =SUMIFS('Fuel Log'!$E$4:$E$52,'Fuel Log'!$A$4:$A$52,A5) -> 290 | E5: =SUMIFS('Fuel Log'!$F$4:$F$52,'Fuel Log'!$A$4:$A$52,A5) -> 40 | F5: =SUMIFS('Fuel Log'!$G$4:$G$52,'Fuel Log'!$A$4:$A$52,A5) -> 330
A6: 46237 | B6: =TEXT(A6,"DDDD") -> Monday | C6: =COUNTIFS('Fuel Log'!$A$4:$A$52,A6) -> 16 | D6: =SUMIFS('Fuel Log'!$E$4:$E$52,'Fuel Log'!$A$4:$A$52,A6) -> 255 | E6: =SUMIFS('Fuel Log'!$F$4:$F$52,'Fuel Log'!$A$4:$A$52,A6) -> 30 | F6: =SUMIFS('Fuel Log'!$G$4:$G$52,'Fuel Log'!$A$4:$A$52,A6) -> 285
A7: TOTAL | C7: =SUM(C4:C6) -> 49 | D7: =SUM(D4:D6) -> 725 | E7: =SUM(E4:E6) -> 110 | F7: =SUM(F4:F6) -> 835
A9: Note: The 'Today Diesel Received Qty', 'Today Issue Qty' and 'Today Balance' footer boxes
A10: were left blank on all three original sheets, so opening and closing stock cannot be reconciled.

Sheet Vehicle Summary
A1: VEHICLE-WISE FUEL ISSUE SUMMARY
A3: Vehicle No | B3: Vehicle Category | C3: 46235 | D3: 46236 | E3: 46237 | F3: Total Issued (L) | G3: No. of Fills
A4: 226-3944 | B4: 1 Cub (Hire) | C4: =SUMIFS('Fuel Log'!$G$4:$G$52,'Fuel Log'!$C$4:$C$52,$A4,'Fuel Log'!$A$4:$A$52,C$3) -> 15 | D4: =SUMIFS('Fuel Log'!$G$4:$G$52,'Fuel Log'!$C$4:$C$52,$A4,'Fuel Log'!$A$4:$A$52,D$3) -> 15 | E4: =SUMIFS('Fuel Log'!$G$4:$G$52,'Fuel Log'!$C$4:$C$52,$A4,'Fuel Log'!$A$4:$A$52,E$3) -> 15 | F4: =SUM(C4:E4) -> 45 | G4: =COUNTIFS('Fuel Log'!$C$4:$C$52,$A4) -> 3
A5: 40-8060 | B5: Crew Cab | C5: =SUMIFS('Fuel Log'!$G$4:$G$52,'Fuel Log'!$C$4:$C$52,$A5,'Fuel Log'!$A$4:$A$52,C$3) -> 0 | D5: =SUMIFS('Fuel Log'!$G$4:$G$52,'Fuel Log'!$C$4:$C$52,$A5,'Fuel Log'!$A$4:$A$52,D$3) -> 0 | E5: =SUMIFS('Fuel Log'!$G$4:$G$52,'Fuel Log'!$C$4:$C$52,$A5,'Fuel Log'!$A$4:$A$52,E$3) -> 10 | F5: =SUM(C5:E5) -> 10 | G5: =COUNTIFS('Fuel Log'!$C$4:$C$52,$A5) -> 1
A6: 43-3416 | B6: Prime Bowser | C6: =SUMIFS('Fuel Log'!$G$4:$G$52,'Fuel Log'!$C$4:$C$52,$A6,'Fuel Log'!$A$4:$A$52,C$3) -> 0 | D6: =SUMIFS('Fuel Log'!$G$4:$G$52,'Fuel Log'!$C$4:$C$52,$A6,'Fuel Log'!$A$4:$A$52,D$3) -> 0 | E6: =SUMIFS('Fuel Log'!$G$4:$G$52,'Fuel Log'!$C$4:$C$52,$A6,'Fuel Log'!$A$4:$A$52,E$3) -> 20 | F6: =SUM(C6:E6) -> 20 | G6: =COUNTIFS('Fuel Log'!$C$4:$C$52,$A6) -> 1
A7: 525-03 | B7: 10 Ton | C7: =SUMIFS('Fuel Log'!$G$4:$G$52,'Fuel Log'!$C$4:$C$52,$A7,'Fuel Log'!$A$4:$A$52,C$3) -> 0 | D7: =SUMIFS('Fuel Log'!$G$4:$G$52,'Fuel Log'!$C$4:$C$52,$A7,'Fuel Log'!$A$4:$A$52,D$3) -> 0 | E7: =SUMIFS('Fuel Log'!$G$4:$G$52,'Fuel Log'!$C$4:$C$52,$A7,'Fuel Log'!$A$4:$A$52,E$3) -> 15 | F7: =SUM(C7:E7) -> 15 | G7: =COUNTIFS('Fuel Log'!$C$4:$C$52,$A7) -> 1
A8: AC-23 | B8: Compressor | C8: =SUMIFS('Fuel Log'!$G$4:$G$52,'Fuel Log'!$C$4:$C$52,$A8,'Fuel Log'!$A$4:$A$52,C$3) -> 0 | D8: =SUMIFS('Fuel Log'!$G$4:$G$52,'Fuel Log'!$C$4:$C$52,$A8,'Fuel Log'!$A$4:$A$52,D$3) -> 0 | E8: =SUMIFS('Fuel Log'!$G$4:$G$52,'Fuel Log'!$C$4:$C$52,$A8,'Fuel Log'!$A$4:$A$52,E$3) -> 10 | F8: =SUM(C8:E8) -> 10 | G8: =COUNTIFS('Fuel Log'!$C$4:$C$52,$A8) -> 1
A9: DAF-7979 | B9: Bolero | C9: =SUMIFS('Fuel Log'!$G$4:$G$52,'Fuel Log'!$C$4:$C$52,$A9,'Fuel Log'!$A$4:$A$52,C$3) -> 0 | D9: =SUMIFS('Fuel Log'!$G$4:$G$52,'Fuel Log'!$C$4:$C$52,$A9,'Fuel Log'!$A$4:$A$52,D$3) -> 0 | E9: =SUMIFS('Fuel Log'!$G$4:$G$52,'Fuel Log'!$C$4:$C$52,$A9,'Fuel Log'!$A$4:$A$52,E$3) -> 20 | F9: =SUM(C9:E9) -> 20 | G9: =COUNTIFS('Fuel Log'!$C$4:$C$52,$A9) -> 1
A10: GE-102 | B10: Generator | C10: =SUMIFS('Fuel Log'!$G$4:$G$52,'Fuel Log'!$C$4:$C$52,$A10,'Fuel Log'!$A$4:$A$52,C$3) -> 10 | D10: =SUMIFS('Fuel Log'!$G$4:$G$52,'Fuel Log'!$C$4:$C$52,$A10,'Fuel Log'!$A$4:$A$52,D$3) -> 0 | E10: =SUMIFS('Fuel Log'!$G$4:$G$52,'Fuel Log'!$C$4:$C$52,$A10,'Fuel Log'!$A$4:$A$52,E$3) -> 5 | F10: =SUM(C10:E10) -> 15 | G10: =COUNTIFS('Fuel Log'!$C$4:$C$52,$A10) -> 2
A11: GE-84 | B11: Generator | C11: =SUMIFS('Fuel Log'!$G$4:$G$52,'Fuel Log'!$C$4:$C$52,$A11,'Fuel Log'!$A$4:$A$52,C$3) -> 0 | D11: =SUMIFS('Fuel Log'!$G$4:$G$52,'Fuel Log'!$C$4:$C$52,$A11,'Fuel Log'!$A$4:$A$52,D$3) -> 10 | E11: =SUMIFS('Fuel Log'!$G$4:$G$52,'Fuel Log'!$C$4:$C$52,$A11,'Fuel Log'!$A$4:$A$52,E$3) -> 10 | F11: =SUM(C11:E11) -> 20 | G11: =COUNTIFS('Fuel Log'!$C$4:$C$52,$A11) -> 2
A12: HEX-43 | B12: Excavator | C12: =SUMIFS('Fuel Log'!$G$4:$G$52,'Fuel Log'!$C$4:$C$52,$A12,'Fuel Log'!$A$4:$A$52,C$3) -> 20 | D12: =SUMIFS('Fuel Log'!$G$4:$G$52,'Fuel Log'!$C$4:$C$52,$A12,'Fuel Log'!$A$4:$A$52,D$3) -> 50 | E12: =SUMIFS('Fuel Log'!$G$4:$G$52,'Fuel Log'!$C$4:$C$52,$A12,'Fuel Log'!$A$4:$A$52,E$3) -> 40 | F12: =SUM(C12:E12) -> 110 | G12: =COUNTIFS('Fuel Log'!$C$4:$C$52,$A12) -> 3
A13: KF-3700 | B13: DM Cab | C13: =SUMIFS('Fuel Log'!$G$4:$G$52,'Fuel Log'!$C$4:$C$52,$A13,'Fuel Log'!$A$4:$A$52,C$3) -> 0 | D13: =SUMIFS('Fuel Log'!$G$4:$G$52,'Fuel Log'!$C$4:$C$52,$A13,'Fuel Log'!$A$4:$A$52,D$3) -> 25 | E13: =SUMIFS('Fuel Log'!$G$4:$G$52,'Fuel Log'!$C$4:$C$52,$A13,'Fuel Log'!$A$4:$A$52,E$3) -> 0 | F13: =SUM(C13:E13) -> 25 | G13: =COUNTIFS('Fuel Log'!$C$4:$C$52,$A13) -> 1
A14: LC-6767 | B14: W/B | C14: =SUMIFS('Fuel Log'!$G$4:$G$52,'Fuel Log'!$C$4:$C$52,$A14,'Fuel Log'!$A$4:$A$52,C$3) -> 10 | D14: =SUMIFS('Fuel Log'!$G$4:$G$52,'Fuel Log'!$C$4:$C$52,$A14,'Fuel Log'!$A$4:$A$52,D$3) -> 10 | E14: =SUMIFS('Fuel Log'!$G$4:$G$52,'Fuel Log'!$C$4:$C$52,$A14,'Fuel Log'!$A$4:$A$52,E$3) -> 15 | F14: =SUM(C14:E14) -> 35 | G14: =COUNTIFS('Fuel Log'!$C$4:$C$52,$A14) -> 3
A15: LD-1718 | B15: Tipper | C15: =SUMIFS('Fuel Log'!$G$4:$G$52,'Fuel Log'!$C$4:$C$52,$A15,'Fuel Log'!$A$4:$A$52,C$3) -> 25 | D15: =SUMIFS('Fuel Log'!$G$4:$G$52,'Fuel Log'!$C$4:$C$52,$A15,'Fuel Log'!$A$4:$A$52,D$3) -> 25 | E15: =SUMIFS('Fuel Log'!$G$4:$G$52,'Fuel Log'!$C$4:$C$52,$A15,'Fuel Log'!$A$4:$A$52,E$3) -> 0 | F15: =SUM(C15:E15) -> 50 | G15: =COUNTIFS('Fuel Log'!$C$4:$C$52,$A15) -> 2
... A17: LL-0936 | B17: 1 Cub | C17: =SUMIFS('Fuel Log'!$G$4:$G$52,'Fuel Log'!$C$4:$C$52,$A17,'Fuel Log'!$A$4:$A$52,C$3) -> 10 | D17: =SUMIFS('Fuel Log'!$G$4:$G$52,'Fuel Log'!$C$4:$C$52,$A17,'Fuel Log'!$A$4:$A$52,D$3) -> 0 | E17: =SUMIFS('Fuel Log'!$G$4:$G$52,'Fuel Log'!$C$4:$C$52,$A17,'Fuel Log'!$A$4:$A$52,E$3) -> 20 | F17: =SUM(C17:E17) -> 30 | G17: =COUNTIFS('Fuel Log'!$C$4:$C$52,$A17) -> 2
A18: LN-1867 | C18: =SUMIFS('Fuel Log'!$G$4:$G$52,'Fuel Log'!$C$4:$C$52,$A18,'Fuel Log'!$A$4:$A$52,C$3) -> 0 | D18: =SUMIFS('Fuel Log'!$G$4:$G$52,'Fuel Log'!$C$4:$C$52,$A18,'Fuel Log'!$A$4:$A$52,D$3) -> 20 | E18: =SUMIFS('Fuel Log'!$G$4:$G$52,'Fuel Log'!$C$4:$C$52,$A18,'Fuel Log'!$A$4:$A$52,E$3) -> 0 | F18: =SUM(C18:E18) -> 20 | G18: =COUNTIFS('Fuel Log'!$C$4:$C$52,$A18) -> 1
A19: LO-1059 | B19: W/B | C19: =SUMIFS('Fuel Log'!$G$4:$G$52,'Fuel Log'!$C$4:$C$52,$A19,'Fuel Log'!$A$4:$A$52,C$3) -> 20 | D19: =SUMIFS('Fuel Log'!$G$4:$G$52,'Fuel Log'!$C$4:$C$52,$A19,'Fuel Log'!$A$4:$A$52,D$3) -> 15 | E19: =SUMIFS('Fuel Log'!$G$4:$G$52,'Fuel Log'!$C$4:$C$52,$A19,'Fuel Log'!$A$4:$A$52,E$3) -> 0 | F19: =SUM(C19:E19) -> 35 | G19: =COUNTIFS('Fuel Log'!$C$4:$C$52,$A19) -> 2
A20: LO-4821 | B20: Tipper | C20: =SUMIFS('Fuel Log'!$G$4:$G$52,'Fuel Log'!$C$4:$C$52,$A20,'Fuel Log'!$A$4:$A$52,C$3) -> 15 | D20: =SUMIFS('Fuel Log'!$G$4:$G$52,'Fuel Log'!$C$4:$C$52,$A20,'Fuel Log'!$A$4:$A$52,D$3) -> 25 | E20: =SUMIFS('Fuel Log'!$G$4:$G$52,'Fuel Log'!$C$4:$C$52,$A20,'Fuel Log'!$A$4:$A$52,E$3) -> 25 | F20: =SUM(C20:E20) -> 65 | G20: =COUNTIFS('Fuel Log'!$C$4:$C$52,$A20) -> 3
A21: MG-14 | B21: MG | C21: =SUMIFS('Fuel Log'!$G$4:$G$52,'Fuel Log'!$C$4:$C$52,$A21,'Fuel Log'!$A$4:$A$52,C$3) -> 15 | D21: =SUMIFS('Fuel Log'!$G$4:$G$52,'Fuel Log'!$C$4:$C$52,$A21,'Fuel Log'!$A$4:$A$52,D$3) -> 0 | E21: =SUMIFS('Fuel Log'!$G$4:$G$52,'Fuel Log'!$C$4:$C$52,$A21,'Fuel Log'!$A$4:$A$52,E$3) -> 0 | F21: =SUM(C21:E21) -> 15 | G21: =COUNTIFS('Fuel Log'!$C$4:$C$52,$A21) -> 1
A22: PD-6917 | B22: Bolero | C22: =SUMIFS('Fuel Log'!$G$4:$G$52,'Fuel Log'!$C$4:$C$52,$A22,'Fuel Log'!$A$4:$A$52,C$3) -> 10 | D22: =SUMIFS('Fuel Log'!$G$4:$G$52,'Fuel Log'!$C$4:$C$52,$A22,'Fuel Log'!$A$4:$A$52,D$3) -> 20 | E22: =SUMIFS('Fuel Log'!$G$4:$G$52,'Fuel Log'!$C$4:$C$52,$A22,'Fuel Log'!$A$4:$A$52,E$3) -> 10 | F22: =SUM(C22:E22) -> 40 | G22: =COUNTIFS('Fuel Log'!$C$4:$C$52,$A22) -> 3
A23: SL-13 | B23: Bob Cat | C23: =SUMIFS('Fuel Log'!$G$4:$G$52,'Fuel Log'!$C$4:$C$52,$A23,'Fuel Log'!$A$4:$A$52,C$3) -> 10 | D23: =SUMIFS('Fuel Log'!$G$4:$G$52,'Fuel Log'!$C$4:$C$52,$A23,'Fuel Log'!$A$4:$A$52,D$3) -> 0 | E23: =SUMIFS('Fuel Log'!$G$4:$G$52,'Fuel Log'!$C$4:$C$52,$A23,'Fuel Log'!$A$4:$A$52,E$3) -> 0 | F23: =SUM(C23:E23) -> 10 | G23: =COUNTIFS('Fuel Log'!$C$4:$C$52,$A23) -> 1
A24: SL-16 | B24: Bob Cat | C24: =SUMIFS('Fuel Log'!$G$4:$G$52,'Fuel Log'!$C$4:$C$52,$A24,'Fuel Log'!$A$4:$A$52,C$3) -> 0 | D24: =SUMIFS('Fuel Log'!$G$4:$G$52,'Fuel Log'!$C$4:$C$52,$A24,'Fuel Log'!$A$4:$A$52,D$3) -> 0 | E24: =SUMIFS('Fuel Log'!$G$4:$G$52,'Fuel Log'!$C$4:$C$52,$A24,'Fuel Log'!$A$4:$A$52,E$3) -> 20 | F24: =SUM(C24:E24) -> 20 | G24: =COUNTIFS('Fuel Log'!$C$4:$C$52,$A24) -> 1
A25: SR-19 | B25: 10 Ton | C25: =SUMIFS('Fuel Log'!$G$4:$G$52,'Fuel Log'!$C$4:$C$52,$A25,'Fuel Log'!$A$4:$A$52,C$3) -> 15 | D25: =SUMIFS('Fuel Log'!$G$4:$G$52,'Fuel Log'!$C$4:$C$52,$A25,'Fuel Log'!$A$4:$A$52,D$3) -> 15 | E25: =SUMIFS('Fuel Log'!$G$4:$G$52,'Fuel Log'!$C$4:$C$52,$A25,'Fuel Log'!$A$4:$A$52,E$3) -> 0 | F25: =SUM(C25:E25) -> 30 | G25: =COUNTIFS('Fuel Log'!$C$4:$C$52,$A25) -> 2
A26: TM-13 | B26: Fiori | C26: =SUMIFS('Fuel Log'!$G$4:$G$52,'Fuel Log'!$C$4:$C$52,$A26,'Fuel Log'!$A$4:$A$52,C$3) -> 0 | D26: =SUMIFS('Fuel Log'!$G$4:$G$52,'Fuel Log'!$C$4:$C$52,$A26,'Fuel Log'!$A$4:$A$52,D$3) -> 15 | E26: =SUMIFS('Fuel Log'!$G$4:$G$52,'Fuel Log'!$C$4:$C$52,$A26,'Fuel Log'!$A$4:$A$52,E$3) -> 0 | F26: =SUM(C26:E26) -> 15 | G26: =COUNTIFS('Fuel Log'!$C$4:$C$52,$A26) -> 1
A27: VP-60 | B27: 4 Ton | C27: =SUMIFS('Fuel Log'!$G$4:$G$52,'Fuel Log'!$C$4:$C$52,$A27,'Fuel Log'!$A$4:$A$52,C$3) -> 5 | D27: =SUMIFS('Fuel Log'!$G$4:$G$52,'Fuel Log'!$C$4:$C$52,$A27,'Fuel Log'!$A$4:$A$52,D$3) -> 5 | E27: =SUMIFS('Fuel Log'!$G$4:$G$52,'Fuel Log'!$C$4:$C$52,$A27,'Fuel Log'!$A$4:$A$52,E$3) -> 0 | F27: =SUM(C27:E27) -> 10 | G27: =COUNTIFS('Fuel Log'!$C$4:$C$52,$A27) -> 2
A28: ZA-7291 | C28: =SUMIFS('Fuel Log'!$G$4:$G$52,'Fuel Log'!$C$4:$C$52,$A28,'Fuel Log'!$A$4:$A$52,C$3) -> 0 | D28: =SUMIFS('Fuel Log'!$G$4:$G$52,'Fuel Log'!$C$4:$C$52,$A28,'Fuel Log'!$A$4:$A$52,D$3) -> 20 | E28: =SUMIFS('Fuel Log'!$G$4:$G$52,'Fuel Log'!$C$4:$C$52,$A28,'Fuel Log'!$A$4:$A$52,E$3) -> 0 | F28: =SUM(C28:E28) -> 20 | G28: =COUNTIFS('Fuel Log'!$C$4:$C$52,$A28) -> 1
A29: ZA-7965 | B29: JCB | C29: =SUMIFS('Fuel Log'!$G$4:$G$52,'Fuel Log'!$C$4:$C$52,$A29,'Fuel Log'!$A$4:$A$52,C$3) -> 0 | D29: =SUMIFS('Fuel Log'!$G$4:$G$52,'Fuel Log'!$C$4:$C$52,$A29,'Fuel Log'!$A$4:$A$52,D$3) -> 0 | E29: =SUMIFS('Fuel Log'!$G$4:$G$52,'Fuel Log'!$C$4:$C$52,$A29,'Fuel Log'!$A$4:$A$52,E$3) -> 30 | F29: =SUM(C29:E29) -> 30 | G29: =COUNTIFS('Fuel Log'!$C$4:$C$52,$A29) -> 1
A30: ZA-7968 | B30: JCB | C30: =SUMIFS('Fuel Log'!$G$4:$G$52,'Fuel Log'!$C$4:$C$52,$A30,'Fuel Log'!$A$4:$A$52,C$3) -> 15 | D30: =SUMIFS('Fuel Log'!$G$4:$G$52,'Fuel Log'!$C$4:$C$52,$A30,'Fuel Log'!$A$4:$A$52,D$3) -> 10 | E30: =SUMIFS('Fuel Log'!$G$4:$G$52,'Fuel Log'!$C$4:$C$52,$A30,'Fuel Log'!$A$4:$A$52,E$3) -> 0 | F30: =SUM(C30:E30) -> 25 | G30: =COUNTIFS('Fuel Log'!$C$4:$C$52,$A30) -> 2
A31: ZA-7969 | B31: JCB | C31: =SUMIFS('Fuel Log'!$G$4:$G$52,'Fuel Log'!$C$4:$C$52,$A31,'Fuel Log'!$A$4:$A$52,C$3) -> 0 | D31: =SUMIFS('Fuel Log'!$G$4:$G$52,'Fuel Log'!$C$4:$C$52,$A31,'Fuel Log'!$A$4:$A$52,D$3) -> 5 | E31: =SUMIFS('Fuel Log'!$G$4:$G$52,'Fuel Log'!$C$4:$C$52,$A31,'Fuel Log'!$A$4:$A$52,E$3) -> 0 | F31: =SUM(C31:E31) -> 5 | G31: =COUNTIFS('Fuel Log'!$C$4:$C$52,$A31) -> 1
A32: ZB-1979 | B32: JCB | C32: =SUMIFS('Fuel Log'!$G$4:$G$52,'Fuel Log'!$C$4:$C$52,$A32,'Fuel Log'!$A$4:$A$52,C$3) -> 25 | D32: =SUMIFS('Fuel Log'!$G$4:$G$52,'Fuel Log'!$C$4:$C$52,$A32,'Fuel Log'!$A$4:$A$52,D$3) -> 30 | E32: =SUMIFS('Fuel Log'!$G$4:$G$52,'Fuel Log'!$C$4:$C$52,$A32,'Fuel Log'!$A$4:$A$52,E$3) -> 20 | F32: =SUM(C32:E32) -> 75 | G32: =COUNTIFS('Fuel Log'!$C$4:$C$52,$A32) -> 3
A33: TOTAL | C33: =SUM(C4:C32) -> 220 | D33: =SUM(D4:D32) -> 330 | E33: =SUM(E4:E32) -> 285 | F33: =SUM(F4:F32) -> 835 | G33: =SUM(G4:G32) -> 49

Sheet Transcription Notes
A1: TRANSCRIPTION NOTES AND DATA QUALITY FLAGS
A3: Item | B3: Note
A4: Source files | B4: Four images supplied. The first two are byte-identical copies of the same sheet dated 01/08/2026, so three distinct daily sheets were transcribed.
A5: Meter codes | B5: N/W is reproduced as written on the sheet and means the meter is not working. A dash means no meter is fitted, which applies to generators, the compressor and the prime bowser. A blank cell means the issuing officer wrote nothing.
A6: Footer boxes | B6: Today Diesel Received Qty, Today Issue Qty and Today Balance are blank on all three sheets. Tank stock cannot be reconciled against issues from this data.
A7: Approve Officer column | B7: Blank on all three sheets. No approval signature was captured against any issue.
A8: Fuel Issued column | B8: Blank on all three sheets. Only the 1st and 2nd Fuel Qty columns carry quantities.
A9: 226-3944 on 01/08 | B9: 1st meter 252089 and 2nd meter 252075. The second reading is lower than the first, which is not possible on a forward-running odometer. Needs checking with the site.
A10: 226-3944 on 03/08 | B10: The 2nd meter entry is struck out and 252284 is written in the Previous Meter column instead. Recorded as shown.
A11: LL-0936 and LK-0936 | B11: Almost certainly the same 1 Cub. Written LL on 01/08 and 03/08 and LK on 02/08. Kept as written; confirm the correct registration.
A12: SL-13 and SL-16 | B12: Bob Cat recorded as SL-13 on 01/08 and SL-16 on 03/08. Kept as written; confirm which is correct.
A13: ZA-7968, ZA-7969, ZA-7965 | B13: Three JCB registrations appear across the three sheets and the third digit is unclear in each case. Kept as written.
A14: LO-1059 on 01/08 | B14: Vehicle written as LO-4821 then corrected to 1059. The 1st Fuel Qty entry is struck out and 20 litres is written under 2nd Fuel Qty.
... A21: Totals | B21: All totals in this workbook are live formulas. Correcting any quantity in the Fuel Log tab updates the Daily Summary and Vehicle Summary automatically.
