Workbook

Sheet Fuel Issue Register
A1: EDWARD & CHRISTIE (PVT) LTD - CEP/3 WADAKADA
A2: DAILY FUEL & LUBRICANT ISSUE - TRANSACTION REGISTER
A3: Transcribed from six handwritten daily issue notes, 01 Aug 2026 to 06 Aug 2026. Diesel only - no petrol, kerosene, oil or grease was issued on any of the six days. Store Keeper on all sheets: Darshana.
A5: Date | B5: Day | C5: Line No | D5: Vehicle No (as written) | E5: Vehicle No (normalised) | F5: Diesel Qty (L) | G5: Current Meter (as read) | H5: Meter Read Confidence | I5: Driver / Operator | J5: Source Image | K5: Remarks / Legibility Note
A6: 2026-08-01 | B6: Saturday | C6: 1 | D6: ZA-8395 | E6: ZA-8395 | F6: 30 | G6: 3275 | H6: Medium | I6: Chathuranga | J6: IMG-2 (09_32_45)
A7: 2026-08-01 | B7: Saturday | C7: 2 | D7: DAB-5905 | E7: DAB-5905 | F7: 10 | G7: 68608.4 | H7: Medium | I7: Kasun | J7: IMG-2 (09_32_45) | K7: Reading shown with leading zero as 068608.4
A8: 2026-08-01 | B8: Saturday | C8: 3 | D8: LP-7183 | E8: LP-7183 | F8: 20 | G8: 151402 | H8: Medium | I8: Kalinda | J8: IMG-2 (09_32_45)
A9: 2026-08-01 | B9: Saturday | C9: 4 | D9: LP-1577 | E9: LP-1577 | F9: 20 | G9: 81920 | H9: High | I9: Danushka | J9: IMG-2 (09_32_45)
A10: 2026-08-01 | B10: Saturday | C10: 5 | D10: ZB-8395 | E10: ZB-8395 | F10: 10 | G10: 9278 | H10: Low | I10: Chathuranga | J10: IMG-2 (09_32_45) | K10: Same numeric as line 1 but different prefix - confirm whether ZA or ZB
A11: 2026-08-01 | B11: Saturday | C11: 6 | D11: LP-1575 | E11: LP-1575 | F11: 20 | G11: 28976 | H11: Medium | I11: Sahiraj | J11: IMG-2 (09_32_45)
A12: 2026-08-01 | B12: Saturday | C12: 7 | D12: CL-0980 | E12: CL-0980 | F12: 12 | I12: Jayasekara | J12: IMG-2 (09_32_45) | K12: Meter column left blank
A13: Sub-total issued 2026-08-01 | F13: =SUM(F6:F12) -> 122 | G13: 7 issue lines
A14: 2026-08-02 | B14: Sunday | C14: 1 | D14: NP-19 | E14: NP-19 | F14: 30 | G14: 12969.9 | H14: Low | I14: Ananda | J14: IMG-5 (09_32_46) | K14: Plate/machine ID poorly legible - reads NP-19 or NF-19
A15: 2026-08-02 | B15: Sunday | C15: 2 | D15: DAB-5905 | E15: DAB-5905 | F15: 10 | G15: 68688 | H15: High | I15: Kasun | J15: IMG-5 (09_32_46)
A16: 2026-08-02 | B16: Sunday | C16: 3 | D16: DAB-5905 | E16: DAB-5905 | F16: 10 | I16: Kasun | J16: IMG-5 (09_32_46) | K16: Second issue to same vehicle on same day, no meter recorded
A17: Sub-total issued 2026-08-02 | F17: =SUM(F14:F16) -> 50 | G17: 3 issue lines
A18: 2026-08-03 | B18: Monday | C18: 1 | D18: LD-09 | E18: LD-09 | F18: 30 | G18: 20060.8 | H18: Medium | I18: Asantha | J18: IMG-6 (09_32_47)
A19: 2026-08-03 | B19: Monday | C19: 2 | D19: ZA-0050 | E19: ZA-0050 | F19: 20 | I19: Kaushalya | J19: IMG-6 (09_32_47) | K19: Meter column left blank
A20: 2026-08-03 | B20: Monday | C20: 3 | D20: ZA-7083 | E20: ZA-7083 | F20: 30 | I20: Thusara | J20: IMG-6 (09_32_47) | K20: Meter column left blank
A21: 2026-08-03 | B21: Monday | C21: 4 | D21: ZA-2612 | E21: ZA-2612 | F21: 30 | I21: Manjula | J21: IMG-6 (09_32_47) | K21: Meter column left blank
A22: 2026-08-03 | B22: Monday | C22: 5 | D22: GE-60 | E22: GE-60 | F22: 20 | G22: 251.4 | H22: Low | J22: IMG-6 (09_32_47) | K22: Only trailing digits legible - likely 20251.4, verify against book
A23: Sub-total issued 2026-08-03 | F23: =SUM(F18:F22) -> 130 | G23: 5 issue lines
A24: 2026-08-04 | B24: Tuesday | C24: 1 | D24: DAB-5905 | E24: DAB-5905 | F24: 10 | G24: 68909 | H24: High | I24: Kasun | J24: IMG-4 (09_32_46_2)
A25: 2026-08-04 | B25: Tuesday | C25: 2 | D25: ZA-2999 | E25: ZA-2999 | F25: 30 | I25: Thusara | J25: IMG-4 (09_32_46_2) | K25: Plate reads ZA-2999 or ZA-2900
A26: 2026-08-04 | B26: Tuesday | C26: 3 | D26: ZB-0050 | E26: ZA-0050 | F26: 25 | I26: Kaushalya | J26: IMG-4 (09_32_46_2) | K26: Written ZB-0050; fleet elsewhere shows ZA-0050 - confirm
A27: 2026-08-04 | B27: Tuesday | C27: 4 | D27: ZA-8511 | E27: ZA-8511 | F27: 25 | I27: Sanjeewa | J27: IMG-4 (09_32_46_2) | K27: Meter column left blank
A28: 2026-08-04 | B28: Tuesday | C28: 5 | D28: DAB-5905 | E28: DAB-5905 | F28: 10 | G28: 69009 | H28: High | I28: Kosal | J28: IMG-4 (09_32_46_2) | K28: Second issue to same vehicle on same day
A29: Sub-total issued 2026-08-04 | F29: =SUM(F24:F28) -> 100 | G29: 5 issue lines
A30: 2026-08-05 | B30: Wednesday | C30: 1 | D30: ZA-8929 | E30: ZA-8929 | F30: 30 | G30: 5295 | H30: Low | I30: Chathuranga | J30: IMG-3 (09_32_46_1) | K30: Plate reads ZA-8929 or ZA-8399; meter reads 5295 or 3295
A31: 2026-08-05 | B31: Wednesday | C31: 2 | D31: LP-1577 | E31: LP-1577 | F31: 5 | G31: 82066 | H31: Medium | I31: Danushka | J31: IMG-3 (09_32_46_1)
A32: 2026-08-05 | B32: Wednesday | C32: 3 | D32: DAB-5905 | E32: DAB-5905 | F32: 10 | G32: 69125 | H32: High | I32: Kasun | J32: IMG-3 (09_32_46_1)
A33: 2026-08-05 | B33: Wednesday | C33: 4 | D33: ZA-7083 | E33: ZA-7083 | F33: 15 | I33: Thusara | J33: IMG-3 (09_32_46_1) | K33: Meter column left blank
A34: 2026-08-05 | B34: Wednesday | C34: 5 | D34: GE-60 | E34: GE-60 | F34: 20 | G34: 20253.3 | H34: Medium | I34: Gopal | J34: IMG-3 (09_32_46_1)
A35: Sub-total issued 2026-08-05 | F35: =SUM(F30:F34) -> 80 | G35: 5 issue lines
A36: 2026-08-06 | B36: Thursday | C36: 1 | D36: ZA-0050 | E36: ZA-0050 | F36: 25 | I36: Thusara/Thrisankaran | J36: IMG-1 (08_47_38) | K36: Meter column left blank
A37: 2026-08-06 | B37: Thursday | C37: 2 | D37: ZA-8931 | E37: ZA-8931 | F37: 30 | I37: Thisara | J37: IMG-1 (08_47_38) | K37: Plate reads ZA-8931 or ZA-8934
A38: 2026-08-06 | B38: Thursday | C38: 3 | D38: LD-09 | E38: LD-09 | F38: 30 | G38: 688 | H38: Low | I38: Ashith | J38: IMG-1 (08_47_38) | K38: Only trailing digits legible - likely 20068.8, verify against book
A39: 2026-08-06 | B39: Thursday | C39: 4 | D39: ZA-2612 | E39: ZA-2612 | F39: 30 | I39: Manjula | J39: IMG-1 (08_47_38) | K39: Meter column left blank
A40: 2026-08-06 | B40: Thursday | C40: 5 | D40: LN-8288 | E40: LN-8288 | F40: 2 | I40: Nalin | J40: IMG-1 (08_47_38) | K40: 2 L only - small engine / generator / hand tool
A41: 2026-08-06 | B41: Thursday | C41: 6 | D41: PA-8511 | E41: ZA-8511 | F41: 25 | I41: Danushka | J41: IMG-1 (08_47_38) | K41: Written PA-8511; fleet elsewhere shows ZA-8511 - confirm
...

Sheet Daily Stock Reconciliation
A1: EDWARD & CHRISTIE (PVT) LTD - CEP/3 WADAKADA
A2: DAILY DIESEL STOCK RECONCILIATION
A3: Balance Forward + Received - Issued = Closing Stock. Every daily total on the sheet is re-added from the individual issue lines and compared against the figure written by the store keeper.
A5: Date | B5: Day | C5: Balance Forward (L) | D5: Received (L) | E5: Total Available (L) | F5: Issued - as written (L) | G5: Issued - sum of lines (L) | H5: Variance (L) | I5: Closing Stock - as written (L) | J5: Closing Stock - computed (L) | K5: Reconciles? | L5: Note
A6: 2026-08-01 | B6: Saturday | C6: 234 | D6: 0 | E6: =C6+D6 -> 234 | F6: 122 | G6: ='Fuel Issue Register'!F13 -> 122 | H6: =F6-G6 -> 0 | I6: 112 | J6: =E6-G6 -> 112 | K6: =IF(AND(H6=0,I6=J6),"OK","CHECK") -> OK | L6: Balance Forward on the sheet is faint. 234 L is the only value consistent with 122 L issued and 112 L closing.
A7: 2026-08-02 | B7: Sunday | C7: 112 | D7: 400 | E7: =C7+D7 -> 512 | F7: 50 | G7: ='Fuel Issue Register'!F17 -> 50 | H7: =F7-G7 -> 0 | I7: 462 | J7: =E7-G7 -> 462 | K7: =IF(AND(H7=0,I7=J7),"OK","CHECK") -> OK | L7: Bowser / barrel receipt of 400 L recorded.
A8: 2026-08-03 | B8: Monday | C8: 462 | D8: 0 | E8: =C8+D8 -> 462 | F8: 130 | G8: ='Fuel Issue Register'!F23 -> 130 | H8: =F8-G8 -> 0 | I8: 332 | J8: =E8-G8 -> 332 | K8: =IF(AND(H8=0,I8=J8),"OK","CHECK") -> OK | L8: No receipt. Closing figure on the sheet is smudged; 332 L is the arithmetic result.
A9: 2026-08-04 | B9: Tuesday | C9: 332 | D9: 0 | E9: =C9+D9 -> 332 | F9: 100 | G9: ='Fuel Issue Register'!F29 -> 100 | H9: =F9-G9 -> 0 | I9: 232 | J9: =E9-G9 -> 232 | K9: =IF(AND(H9=0,I9=J9),"OK","CHECK") -> OK | L9: No receipt.
A10: 2026-08-05 | B10: Wednesday | C10: 232 | D10: 400 | E10: =C10+D10 -> 632 | F10: 80 | G10: ='Fuel Issue Register'!F35 -> 80 | H10: =F10-G10 -> 0 | I10: 552 | J10: =E10-G10 -> 552 | K10: =IF(AND(H10=0,I10=J10),"OK","CHECK") -> OK | L10: Second receipt of 400 L recorded.
A11: 2026-08-06 | B11: Thursday | C11: 552 | D11: 0 | E11: =C11+D11 -> 552 | F11: 152 | G11: ='Fuel Issue Register'!F43 -> 152 | H11: =F11-G11 -> 0 | I11: 400 | J11: =E11-G11 -> 400 | K11: =IF(AND(H11=0,I11=J11),"OK","CHECK") -> OK | L11: No receipt. Only sheet carrying a site name (CEP/3 Wadakada).
A12: PERIOD TOTAL | C12: =C6 -> 234 | D12: =SUM(D6:D11) -> 800 | F12: =SUM(F6:F11) -> 634 | G12: =SUM(G6:G11) -> 634 | H12: =SUM(H6:H11) -> 0 | I12: =I11 -> 400
A14: PERIOD PROOF
A15: Opening balance carried into 01 Aug 2026 (L) | D15: =C6 -> 234
A16: Total diesel received 01-06 Aug 2026 (L) | D16: =SUM(D6:D11) -> 800
A17: Total diesel issued 01-06 Aug 2026 (L) | D17: =SUM(G6:G11) -> 634
A18: Expected closing stock at 06 Aug 2026 (L) | D18: =D15+D16-D17 -> 400
A19: Closing stock written on 06 Aug sheet (L) | D19: =I11 -> 400
A20: Difference (L) | D20: =D19-D18 -> 0

Sheet Vehicle Summary
A1: EDWARD & CHRISTIE (PVT) LTD - CEP/3 WADAKADA
A2: VEHICLE / MACHINE CONSUMPTION SUMMARY
A3: 18 distinct units drew diesel over the six days, ranked by total litres issued. First / Last Meter use only fully written readings. Partial readings are counted separately and excluded from the movement calculation.
A5: Rank | B5: Vehicle No | C5: Issue Lines | D5: Days Drawn | E5: Total Diesel Issued (L) | F5: Average per Issue (L) | G5: Largest Single Issue (L) | H5: % of Period Total | I5: Usable Meter Readings | J5: Partial / Unusable | K5: First Meter | L5: Last Meter | M5: Meter Movement | N5: Driver(s) / Operator(s) Recorded
A6: 1 | B6: DAB-5905 | C6: 7 | D6: 5 | E6: 70 | F6: =IF(C6=0,0,E6/C6) -> 10 | G6: 10 | H6: =E6/$E$24 -> 0.11041009 | I6: 6 | J6: 0 | K6: 68608.4 | L6: 69350 | M6: =L6-K6 -> 741.6 | N6: Kasun, Kosal
A7: 2 | B7: ZA-0050 | C7: 3 | D7: 3 | E7: 70 | F7: =IF(C7=0,0,E7/C7) -> 23.333333 | G7: 25 | H7: =E7/$E$24 -> 0.11041009 | I7: 0 | J7: 0 | N7: Kaushalya, Thusara/Thrisankaran
A8: 3 | B8: LD-09 | C8: 2 | D8: 2 | E8: 60 | F8: =IF(C8=0,0,E8/C8) -> 30 | G8: 30 | H8: =E8/$E$24 -> 0.094637224 | I8: 1 | J8: 1 | K8: 20060.8 | N8: Asantha, Ashith
A9: 4 | B9: ZA-2612 | C9: 2 | D9: 2 | E9: 60 | F9: =IF(C9=0,0,E9/C9) -> 30 | G9: 30 | H9: =E9/$E$24 -> 0.094637224 | I9: 0 | J9: 0 | N9: Manjula
A10: 5 | B10: ZA-8511 | C10: 2 | D10: 2 | E10: 50 | F10: =IF(C10=0,0,E10/C10) -> 25 | G10: 25 | H10: =E10/$E$24 -> 0.078864353 | I10: 0 | J10: 0 | N10: Danushka, Sanjeewa
A11: 6 | B11: ZA-7083 | C11: 2 | D11: 2 | E11: 45 | F11: =IF(C11=0,0,E11/C11) -> 22.5 | G11: 30 | H11: =E11/$E$24 -> 0.070977918 | I11: 0 | J11: 0 | N11: Thusara
A12: 7 | B12: GE-60 | C12: 2 | D12: 2 | E12: 40 | F12: =IF(C12=0,0,E12/C12) -> 20 | G12: 20 | H12: =E12/$E$24 -> 0.063091483 | I12: 1 | J12: 1 | K12: 20253.3 | N12: Gopal
A13: 8 | B13: NP-19 | C13: 1 | D13: 1 | E13: 30 | F13: =IF(C13=0,0,E13/C13) -> 30 | G13: 30 | H13: =E13/$E$24 -> 0.047318612 | I13: 1 | J13: 0 | K13: 12969.9 | N13: Ananda
A14: 9 | B14: ZA-2999 | C14: 1 | D14: 1 | E14: 30 | F14: =IF(C14=0,0,E14/C14) -> 30 | G14: 30 | H14: =E14/$E$24 -> 0.047318612 | I14: 0 | J14: 0 | N14: Thusara
A15: 10 | B15: ZA-8395 | C15: 1 | D15: 1 | E15: 30 | F15: =IF(C15=0,0,E15/C15) -> 30 | G15: 30 | H15: =E15/$E$24 -> 0.047318612 | I15: 1 | J15: 0 | K15: 3275 | N15: Chathuranga
A16: 11 | B16: ZA-8929 | C16: 1 | D16: 1 | E16: 30 | F16: =IF(C16=0,0,E16/C16) -> 30 | G16: 30 | H16: =E16/$E$24 -> 0.047318612 | I16: 1 | J16: 0 | K16: 5295 | N16: Chathuranga
A17: 12 | B17: ZA-8931 | C17: 1 | D17: 1 | E17: 30 | F17: =IF(C17=0,0,E17/C17) -> 30 | G17: 30 | H17: =E17/$E$24 -> 0.047318612 | I17: 0 | J17: 0 | N17: Thisara
A18: 13 | B18: LP-1577 | C18: 2 | D18: 2 | E18: 25 | F18: =IF(C18=0,0,E18/C18) -> 12.5 | G18: 20 | H18: =E18/$E$24 -> 0.039432177 | I18: 2 | J18: 0 | K18: 81920 | L18: 82066 | M18: =L18-K18 -> 146 | N18: Danushka
A19: 14 | B19: LP-1575 | C19: 1 | D19: 1 | E19: 20 | F19: =IF(C19=0,0,E19/C19) -> 20 | G19: 20 | H19: =E19/$E$24 -> 0.031545741 | I19: 1 | J19: 0 | K19: 28976 | N19: Sahiraj
A20: 15 | B20: LP-7183 | C20: 1 | D20: 1 | E20: 20 | F20: =IF(C20=0,0,E20/C20) -> 20 | G20: 20 | H20: =E20/$E$24 -> 0.031545741 | I20: 1 | J20: 0 | K20: 151402 | N20: Kalinda
A21: 16 | B21: CL-0980 | C21: 1 | D21: 1 | E21: 12 | F21: =IF(C21=0,0,E21/C21) -> 12 | G21: 12 | H21: =E21/$E$24 -> 0.018927445 | I21: 0 | J21: 0 | N21: Jayasekara
A22: 17 | B22: ZB-8395 | C22: 1 | D22: 1 | E22: 10 | F22: =IF(C22=0,0,E22/C22) -> 10 | G22: 10 | H22: =E22/$E$24 -> 0.015772871 | I22: 1 | J22: 0 | K22: 9278 | N22: Chathuranga
A23: 18 | B23: LN-8288 | C23: 1 | D23: 1 | E23: 2 | F23: =IF(C23=0,0,E23/C23) -> 2 | G23: 2 | H23: =E23/$E$24 -> 0.0031545741 | I23: 0 | J23: 0 | N23: Nalin
A24: TOTAL - ALL UNITS | C24: =SUM(C6:C23) -> 32 | E24: =SUM(E6:E23) -> 634 | H24: =SUM(H6:H23) -> 1

Sheet Meter & Fuel Rate
A1: EDWARD & CHRISTIE (PVT) LTD - CEP/3 WADAKADA
A2: METER MOVEMENT AND DIESEL RATE (WHERE TWO OR MORE READINGS EXIST)
A3: Only 5 of 18 units have two or more legible meter readings in the period. Unit = km for road vehicles and hours for machines - confirm per unit before using these rates commercially.
A5: Vehicle No | B5: From Date | C5: To Date | D5: Opening Meter | E5: Closing Meter | F5: Meter Movement | G5: Diesel Issued in Window (L) | H5: Units per Litre | I5: Litres per 100 Units | J5: Confidence | K5: Comment
A6: DAB-5905 | B6: 2026-08-01 | C6: 2026-08-02 | D6: 68608.4 | E6: 68688 | F6: =E6-D6 -> 79.6 | G6: 10 | H6: =IFERROR(F6/G6,"") -> 7.96 | I6: =IFERROR(G6/F6*100,"") -> 12.562814 | J6: Medium
A7: DAB-5905 | B7: 2026-08-02 | C7: 2026-08-04 | D7: 68688 | E7: 68909 | F7: =E7-D7 -> 221 | G7: 20 | H7: =IFERROR(F7/G7,"") -> 11.05 | I7: =IFERROR(G7/F7*100,"") -> 9.0497738 | J7: High | K7: 1 intervening issue(s) had no meter recorded - litres shown are the tank-to-tank total for the window.
A8: DAB-5905 | B8: 2026-08-04 | C8: 2026-08-04 | D8: 68909 | E8: 69009 | F8: =E8-D8 -> 100 | G8: 10 | H8: =IFERROR(F8/G8,"") -> 10 | I8: =IFERROR(G8/F8*100,"") -> 10 | J8: High | K8: Two issues to the same unit on the same day.
A9: DAB-5905 | B9: 2026-08-04 | C9: 2026-08-05 | D9: 69009 | E9: 69125 | F9: =E9-D9 -> 116 | G9: 10 | H9: =IFERROR(F9/G9,"") -> 11.6 | I9: =IFERROR(G9/F9*100,"") -> 8.6206897 | J9: High
A10: DAB-5905 | B10: 2026-08-05 | C10: 2026-08-06 | D10: 69125 | E10: 69350 | F10: =E10-D10 -> 225 | G10: 10 | H10: =IFERROR(F10/G10,"") -> 22.5 | I10: =IFERROR(G10/F10*100,"") -> 4.4444444 | J10: Medium
A11: DAB-5905 - period | B11: 2026-08-01 | C11: 2026-08-06 | D11: 68608.4 | E11: 69350 | F11: =E11-D11 -> 741.6 | G11: 60 | H11: =IFERROR(F11/G11,"") -> 12.36 | I11: =IFERROR(G11/F11*100,"") -> 8.0906149 | K11: Whole-period average across all fills between the first and last usable reading.
A12: LP-1577 | B12: 2026-08-01 | C12: 2026-08-05 | D12: 81920 | E12: 82066 | F12: =E12-D12 -> 146 | G12: 20 | H12: =IFERROR(F12/G12,"") -> 7.3 | I12: =IFERROR(G12/F12*100,"") -> 13.69863 | J12: Medium
A14: Only ONE usable meter reading, so no rate can be calculated: LD-09, GE-60, NP-19, ZA-8395, ZA-8929, LP-1575, LP-7183, ZB-8395. NO meter reading at all on any line: ZA-0050, ZA-2612, ZA-8511, ZA-7083, ZA-2999, ZA-8931, CL-0980, LN-8288. GE-60 (03 Aug) and LD-09 (06 Aug) each have a second reading on the sheet, but only the trailing digits were written, so both are excluded here. Readings carrying a decimal (DAB-5905, GE-60, LD-09, NP-19) are most likely hour meters; readings without one are most likely odometers. Confirm per unit before using any rate for billing.

Sheet Control Findings
A1: EDWARD & CHRISTIE (PVT) LTD - CEP/3 WADAKADA
A2: DATA QUALITY AND CONTROL FINDINGS
A3: Observations arising from transcription of the 01-06 Aug 2026 issue notes.
A5: No | B5: Finding | C5: Category | D5: Severity | E5: Evidence in the six sheets | F5: Recommended action
A6: 1 | B6: Current Meter left blank on most lines | C6: Recording discipline | D6: High | E6: 17 of 32 issue lines (53%) carry no meter reading. On 03 Aug four of five lines are blank; on 06 Aug five of seven are blank. | F6: Make the meter reading a mandatory field. No meter, no issue. Store keeper to refuse the line if the operator cannot state a reading.
A7: 2 | B7: Previous Meter and Consumption columns never used | C7: Form design / control | D7: High | E7: Both columns are printed on the form and are empty on all six sheets. Consumption is therefore never computed at the point of issue. | F7: Either enforce use of the columns or drop them and compute consumption in the fuel system. An unused control column signals to staff that the control is optional.
A8: 3 | B8: Issue Note No. never filled | C8: Traceability | D8: Medium | E8: The Issue Note No. field is blank on all six sheets. Sheets are identifiable only by date. | F8: Pre-print sequential issue note numbers on the pad so a missing sheet becomes visible.
A9: 4 | B9: Officer name and signature column blank | C9: Segregation of duties | D9: High | E9: The Officer / Name / Signature block is empty on all six sheets. Only the driver signs and only the store keeper certifies. | F9: Require a site officer counter-signature on the daily total, independent of the store keeper.
A10: 5 | B10: Site not stated on five of six sheets | C10: Traceability | D10: Medium | E10: Only the 06 Aug sheet carries CEP/3 Wadakada, handwritten above the letterhead. The other five sheets carry no site. | F10: Pre-print or rubber-stamp the site code on every pad issued to a site.
A11: 6 | B11: Same vehicle drawing twice in one day with no meter on the second issue | C11: Fraud exposure | D11: High | E11: DAB-5905 drew 10 L twice on 02 Aug (second issue no meter) and 10 L twice on 04 Aug. Seven separate issues in six days, 70 L total, the highest line count in the period. | F11: Flag repeat same-day issues for the same unit. Require the second issue to carry a meter reading and a written reason.
A12: 7 | B12: Plate numbers written inconsistently | C12: Master data | D12: Medium | E12: ZA-0050 appears as ZB-0050 on 04 Aug. ZA-8511 appears as PA-8511 on 06 Aug. ZA-8395 and ZB-8395 both appear on 01 Aug with different meters. | F12: Issue a printed fleet list to each site store. Store keeper to copy the plate from the list, not from the driver.
A13: 8 | B13: Balance Forward on 01 Aug not legible | C13: Recording discipline | D13: Low | E13: The opening figure is faint. 234 L is inferred from 122 L issued and 112 L closing, and is confirmed by the six-day chain balancing exactly. | F13: Store keeper to overwrite faint figures clearly rather than leave them.
A14: 9 | B14: Meter readings partially written | C14: Recording discipline | D14: Medium | E14: GE-60 on 03 Aug shows only 251.4 against 20253.3 two days later. LD-09 on 06 Aug shows only 688 against 20060.8 on 03 Aug. | F14: Require the full meter reading including all leading digits, not just the digits that changed.
A15: 10 | B15: Driver names only, no employee number | C15: Traceability | D15: Medium | E15: Drivers are recorded by first name only. Kasun, Thusara, Danushka, Chathuranga and Manjula each appear on several days with no unique identifier. | F15: Add an EPF or employee number column so the issue ties to a payroll record.
A16: 11 | B16: Positive finding - stock chain reconciles exactly | C16: Stock control | D16: Positive | E16: 234 L opening plus 800 L received less 634 L issued equals 400 L closing, and every daily line total re-adds to the written daily total with zero variance across all six days. | F16: No action. Confirm the two 400 L receipts against the supplier delivery notes to close the loop.

Sheet Source Sheet Log
A1: EDWARD & CHRISTIE (PVT) LTD - CEP/3 WADAKADA
A2: SOURCE DOCUMENT LOG
A3: One row per scanned sheet, for audit trail back to the original book.
A5: Date on sheet | B5: Source image file | C5: Site written on sheet | D5: Issue Note No. | E5: Issue lines | F5: Diesel issued (L) | G5: Received (L) | H5: Closing stock (L) | I5: Certified by | J5: Designation | K5: Date signed
A6: 2026-08-01 | B6: WhatsApp_Image_2026-08-07_at_09_32_45.jpeg | C6: (not stated on sheet) | D6: (blank on sheet) | E6: 7 | F6: ='Fuel Issue Register'!F13 -> 122 | G6: 0 | H6: 112 | I6: Darshana | J6: SK (Store Keeper) | K6: 2026-08-01
A7: 2026-08-02 | B7: WhatsApp_Image_2026-08-07_at_09_32_46.jpeg | C7: (not stated on sheet) | D7: (blank on sheet) | E7: 3 | F7: ='Fuel Issue Register'!F17 -> 50 | G7: 400 | H7: 462 | I7: Darshana | J7: SK (Store Keeper) | K7: 2026-08-02
A8: 2026-08-03 | B8: WhatsApp_Image_2026-08-07_at_09_32_47.jpeg | C8: (not stated on sheet) | D8: (blank on sheet) | E8: 5 | F8: ='Fuel Issue Register'!F23 -> 130 | G8: 0 | H8: 332 | I8: Darshana | J8: SK (Store Keeper) | K8: 2026-08-03
A9: 2026-08-04 | B9: WhatsApp_Image_2026-08-07_at_09_32_46__2_.jpeg | C9: (not stated on sheet) | D9: (blank on sheet) | E9: 5 | F9: ='Fuel Issue Register'!F29 -> 100 | G9: 0 | H9: 232 | I9: Darshana | J9: SK (Store Keeper) | K9: 2026-08-04
A10: 2026-08-05 | B10: WhatsApp_Image_2026-08-07_at_09_32_46__1_.jpeg | C10: (not stated on sheet) | D10: (blank on sheet) | E10: 5 | F10: ='Fuel Issue Register'!F35 -> 80 | G10: 400 | H10: 552 | I10: Darshana | J10: SK (Store Keeper) | K10: 2026-08-05
A11: 2026-08-06 | B11: WhatsApp_Image_2026-08-07_at_08_47_38.jpeg | C11: CEP/3 Wadakada | D11: (blank on sheet) | E11: 7 | F11: ='Fuel Issue Register'!F43 -> 152 | G11: 0 | H11: 400 | I11: Darshana | J11: SK (Store Keeper) | K11: 2026-08-06
A12: TOTAL | E12: =SUM(E6:E11) -> 32 | F12: =SUM(F6:F11) -> 634 | G12: =SUM(G6:G11) -> 800

Sheet Driver Summary
A1: EDWARD & CHRISTIE (PVT) LTD - CEP/3 WADAKADA
A2: DRIVER AND OPERATOR SUMMARY
A3: Names are transcribed from handwritten signatures and first names only, with no employee number on the form. Treat every name here as provisional until matched against the site attendance register.
A5: Rank | B5: Driver / Operator (as read from handwriting) | C5: Issue Lines | D5: Days Appearing | E5: Total Diesel Drawn (L) | F5: % of Period Total | G5: Units Driven | H5: Vehicles / machines signed for
A6: 1 | B6: Thusara | C6: 3 | D6: 3 | E6: 75 | F6: =E6/$E$25 -> 0.11829653 | G6: 2 | H6: ZA-2999, ZA-7083
A7: 2 | B7: Chathuranga | C7: 3 | D7: 2 | E7: 70 | F7: =E7/$E$25 -> 0.11041009 | G7: 3 | H7: ZA-8395, ZA-8929, ZB-8395
A8: 3 | B8: Kasun | C8: 6 | D8: 5 | E8: 60 | F8: =E8/$E$25 -> 0.094637224 | G8: 1 | H8: DAB-5905
A9: 4 | B9: Manjula | C9: 2 | D9: 2 | E9: 60 | F9: =E9/$E$25 -> 0.094637224 | G9: 1 | H9: ZA-2612
A10: 5 | B10: Danushka | C10: 3 | D10: 3 | E10: 50 | F10: =E10/$E$25 -> 0.078864353 | G10: 2 | H10: LP-1577, ZA-8511
A11: 6 | B11: Kaushalya | C11: 2 | D11: 2 | E11: 45 | F11: =E11/$E$25 -> 0.070977918 | G11: 1 | H11: ZA-0050
A12: 7 | B12: Ananda | C12: 1 | D12: 1 | E12: 30 | F12: =E12/$E$25 -> 0.047318612 | G12: 1 | H12: NP-19
A13: 8 | B13: Asantha | C13: 1 | D13: 1 | E13: 30 | F13: =E13/$E$25 -> 0.047318612 | G13: 1 | H13: LD-09
A14: 9 | B14: Ashith | C14: 1 | D14: 1 | E14: 30 | F14: =E14/$E$25 -> 0.047318612 | G14: 1 | H14: LD-09
A15: 10 | B15: Thisara | C15: 1 | D15: 1 | E15: 30 | F15: =E15/$E$25 -> 0.047318612 | G15: 1 | H15: ZA-8931
A16: 11 | B16: Sanjeewa | C16: 1 | D16: 1 | E16: 25 | F16: =E16/$E$25 -> 0.039432177 | G16: 1 | H16: ZA-8511
A17: 12 | B17: Thusara/Thrisankaran | C17: 1 | D17: 1 | E17: 25 | F17: =E17/$E$25 -> 0.039432177 | G17: 1 | H17: ZA-0050
... A24: 19 | B24: Nalin | C24: 1 | D24: 1 | E24: 2 | F24: =E24/$E$25 -> 0.0031545741 | G24: 1 | H24: LN-8288
A25: TOTAL | C25: =SUM(C6:C24) -> 32 | E25: =SUM(E6:E24) -> 634 | F25: =SUM(F6:F24) -> 1
