Workbook

Sheet Fuel Issues
A1: All Diesel Issues - Galagedara Site
A2: Every issue from the first day on site to yesterday. Three sources combined; 26/07 taken from the stock book only, to avoid double counting.
A4: Date | B4: Month | C4: Vehicle / Unit | D4: As Written on Record | E4: Qty (L) | F4: Source Record
A5: 46153 | B5: =DATE(YEAR(A5),MONTH(A5),1) -> 46143 | C5: 2B-1980 | D5: ZB-1980 | E5: 20 | F5: Stock book
A6: 46156 | B6: =DATE(YEAR(A6),MONTH(A6),1) -> 46143 | C6: 2B-1980 | D6: ZB-1980 | E6: 60 | F6: Stock book
A7: 46162 | B7: =DATE(YEAR(A7),MONTH(A7),1) -> 46143 | C7: 2B-1980 | D7: ZB-1980 | E7: 60 | F7: Stock book
A8: 46165 | B8: =DATE(YEAR(A8),MONTH(A8),1) -> 46143 | C8: 2B-1980 | D8: ZB-1980 | E8: 40 | F8: Stock book
A9: 46166 | B9: =DATE(YEAR(A9),MONTH(A9),1) -> 46143 | C9: 2B-1980 | D9: ZB-1980 | E9: 60 | F9: Stock book
A10: 46177 | B10: =DATE(YEAR(A10),MONTH(A10),1) -> 46174 | C10: 2B-1980 | D10: ZB-1980 | E10: 20 | F10: Stock book
A11: 46177 | B11: =DATE(YEAR(A11),MONTH(A11),1) -> 46174 | C11: D4D-01 | D11: D4D1 | E11: 40 | F11: Stock book
A12: 46178 | B12: =DATE(YEAR(A12),MONTH(A12),1) -> 46174 | C12: 2B-1980 | D12: ZB-1980 | E12: 20 | F12: Stock book
A13: 46178 | B13: =DATE(YEAR(A13),MONTH(A13),1) -> 46174 | C13: D4D-01 | D13: D4D1 | E13: 40 | F13: Stock book
A14: 46179 | B14: =DATE(YEAR(A14),MONTH(A14),1) -> 46174 | C14: 59-5421 | D14: 59-5421 | E14: 5 | F14: Stock book
A15: 46181 | B15: =DATE(YEAR(A15),MONTH(A15),1) -> 46174 | C15: 59-5421 | D15: 59-5421 | E15: 10 | F15: Stock book
A16: 46181 | B16: =DATE(YEAR(A16),MONTH(A16),1) -> 46174 | C16: D4D-02 | D16: D4D2 | E16: 60 | F16: Stock book
... A440: 46239 | B440: =DATE(YEAR(A440),MONTH(A440),1) -> 46235 | C440: SR-12 | D440: SR-12 | E440: 50 | F440: Aug photo sheets
D441: Total | E441: =SUM(E5:E440) -> 18403

Sheet Receipts
A1: Diesel Received on Site
A2: From the stock book and the issue log. No receipt figures were recorded on the 02/08 to 05/08 sheets, so August is understated.
A4: Date | B4: Month | C4: Description | D4: Qty (L) | E4: Source Record
A5: 46153 | B5: =DATE(YEAR(A5),MONTH(A5),1) -> 46143 | C5: Received cep-03 site | D5: 20 | E5: Stock book
A6: 46156 | B6: =DATE(YEAR(A6),MONTH(A6),1) -> 46143 | C6: Received Filling station | D6: 60 | E6: Stock book
A7: 46162 | B7: =DATE(YEAR(A7),MONTH(A7),1) -> 46143 | C7: Received Filling station | D7: 60 | E7: Stock book
A8: 46165 | B8: =DATE(YEAR(A8),MONTH(A8),1) -> 46143 | C8: Received Filling station | D8: 40 | E8: Stock book
A9: 46166 | B9: =DATE(YEAR(A9),MONTH(A9),1) -> 46143 | C9: Received Filling station | D9: 60 | E9: Stock book
A10: 46177 | B10: =DATE(YEAR(A10),MONTH(A10),1) -> 46174 | C10: Received Filling station | D10: 120 | E10: Stock book
A11: 46179 | B11: =DATE(YEAR(A11),MONTH(A11),1) -> 46174 | C11: Received cep-03 site | D11: 200 | E11: Stock book
A12: 46179 | B12: =DATE(YEAR(A12),MONTH(A12),1) -> 46174 | C12: Received Filling station | D12: 5 | E12: Stock book
A13: 46181 | B13: =DATE(YEAR(A13),MONTH(A13),1) -> 46174 | C13: Received cep-03 site | D13: 200 | E13: Stock book
A14: 46185 | B14: =DATE(YEAR(A14),MONTH(A14),1) -> 46174 | C14: Received cep-03 site | D14: 200 | E14: Stock book
A15: 46188 | B15: =DATE(YEAR(A15),MONTH(A15),1) -> 46174 | C15: Received cep-03 site | D15: 200 | E15: Stock book
A16: 46189 | B16: =DATE(YEAR(A16),MONTH(A16),1) -> 46174 | C16: Received cep-03 site | D16: 200 | E16: Stock book
... A37: 46234 | B37: =DATE(YEAR(A37),MONTH(A37),1) -> 46204 | C37: Received (issue log) | D37: 1250 | E37: Issue log
C38: Total | D38: =SUM(D5:D37) -> 16836

Sheet Allocation Register
A1: Vehicle Allocation Register
A2: Position as at | B2: 46239
A4: # | B4: Vehicle / Unit | C4: Allocation Date (1st Fuel Issue) | D4: Allocation Month | E4: Last Fuel Issue | F4: Days on Site | G4: Days Since Last Issue | H4: Status | I4: Total Diesel (L) | J4: No. of Issues | K4: Avg L per Issue | L4: Recorded As
A5: 1 | B5: 2B-1980 | C5: =_xlfn.MINIFS('Fuel Issues'!$A$5:$A$440,'Fuel Issues'!$C$5:$C$440,$B5) -> 46153 | D5: =DATE(YEAR(C5),MONTH(C5),1) -> 46143 | E5: =_xlfn.MAXIFS('Fuel Issues'!$A$5:$A$440,'Fuel Issues'!$C$5:$C$440,$B5) -> 46239 | F5: =$E5-$C5+1 -> 87 | G5: =$B$2-$E5 -> 0 | H5: =IF($G5<=7,"On site","No issue "&$G5&" days") -> On site | I5: =SUMIFS('Fuel Issues'!$E$5:$E$440,'Fuel Issues'!$C$5:$C$440,$B5) -> 576 | J5: =COUNTIFS('Fuel Issues'!$C$5:$C$440,$B5) -> 20 | K5: =IFERROR($I5/$J5,"") -> 28.8 | L5: 2B-1980, LB-21, LB-21REPAIR, ZB-1980
A6: 2 | B6: D4D-01 | C6: =_xlfn.MINIFS('Fuel Issues'!$A$5:$A$440,'Fuel Issues'!$C$5:$C$440,$B6) -> 46177 | D6: =DATE(YEAR(C6),MONTH(C6),1) -> 46174 | E6: =_xlfn.MAXIFS('Fuel Issues'!$A$5:$A$440,'Fuel Issues'!$C$5:$C$440,$B6) -> 46178 | F6: =$E6-$C6+1 -> 2 | G6: =$B$2-$E6 -> 61 | H6: =IF($G6<=7,"On site","No issue "&$G6&" days") -> No issue 61 days | I6: =SUMIFS('Fuel Issues'!$E$5:$E$440,'Fuel Issues'!$C$5:$C$440,$B6) -> 80 | J6: =COUNTIFS('Fuel Issues'!$C$5:$C$440,$B6) -> 2 | K6: =IFERROR($I6/$J6,"") -> 40 | L6: D4D1
A7: 3 | B7: 59-5421 | C7: =_xlfn.MINIFS('Fuel Issues'!$A$5:$A$440,'Fuel Issues'!$C$5:$C$440,$B7) -> 46179 | D7: =DATE(YEAR(C7),MONTH(C7),1) -> 46174 | E7: =_xlfn.MAXIFS('Fuel Issues'!$A$5:$A$440,'Fuel Issues'!$C$5:$C$440,$B7) -> 46239 | F7: =$E7-$C7+1 -> 61 | G7: =$B$2-$E7 -> 0 | H7: =IF($G7<=7,"On site","No issue "&$G7&" days") -> On site | I7: =SUMIFS('Fuel Issues'!$E$5:$E$440,'Fuel Issues'!$C$5:$C$440,$B7) -> 393 | J7: =COUNTIFS('Fuel Issues'!$C$5:$C$440,$B7) -> 34 | K7: =IFERROR($I7/$J7,"") -> 11.558824 | L7: 59-5421
A8: 4 | B8: D4D-02 | C8: =_xlfn.MINIFS('Fuel Issues'!$A$5:$A$440,'Fuel Issues'!$C$5:$C$440,$B8) -> 46181 | D8: =DATE(YEAR(C8),MONTH(C8),1) -> 46174 | E8: =_xlfn.MAXIFS('Fuel Issues'!$A$5:$A$440,'Fuel Issues'!$C$5:$C$440,$B8) -> 46239 | F8: =$E8-$C8+1 -> 59 | G8: =$B$2-$E8 -> 0 | H8: =IF($G8<=7,"On site","No issue "&$G8&" days") -> On site | I8: =SUMIFS('Fuel Issues'!$E$5:$E$440,'Fuel Issues'!$C$5:$C$440,$B8) -> 1455 | J8: =COUNTIFS('Fuel Issues'!$C$5:$C$440,$B8) -> 38 | K8: =IFERROR($I8/$J8,"") -> 38.289474 | L8: D2D-02, D4D-02, D4D-2, D4D-II, D4D-TJ, D4D2
A9: 5 | B9: HEX-45 | C9: =_xlfn.MINIFS('Fuel Issues'!$A$5:$A$440,'Fuel Issues'!$C$5:$C$440,$B9) -> 46182 | D9: =DATE(YEAR(C9),MONTH(C9),1) -> 46174 | E9: =_xlfn.MAXIFS('Fuel Issues'!$A$5:$A$440,'Fuel Issues'!$C$5:$C$440,$B9) -> 46239 | F9: =$E9-$C9+1 -> 58 | G9: =$B$2-$E9 -> 0 | H9: =IF($G9<=7,"On site","No issue "&$G9&" days") -> On site | I9: =SUMIFS('Fuel Issues'!$E$5:$E$440,'Fuel Issues'!$C$5:$C$440,$B9) -> 2920 | J9: =COUNTIFS('Fuel Issues'!$C$5:$C$440,$B9) -> 44 | K9: =IFERROR($I9/$J9,"") -> 66.363636 | L9: EXCAVETORHEX-45, HEX-45, HEX-46
A10: 6 | B10: D4D-03 | C10: =_xlfn.MINIFS('Fuel Issues'!$A$5:$A$440,'Fuel Issues'!$C$5:$C$440,$B10) -> 46187 | D10: =DATE(YEAR(C10),MONTH(C10),1) -> 46174 | E10: =_xlfn.MAXIFS('Fuel Issues'!$A$5:$A$440,'Fuel Issues'!$C$5:$C$440,$B10) -> 46210 | F10: =$E10-$C10+1 -> 24 | G10: =$B$2-$E10 -> 29 | H10: =IF($G10<=7,"On site","No issue "&$G10&" days") -> No issue 29 days | I10: =SUMIFS('Fuel Issues'!$E$5:$E$440,'Fuel Issues'!$C$5:$C$440,$B10) -> 330 | J10: =COUNTIFS('Fuel Issues'!$C$5:$C$440,$B10) -> 10 | K10: =IFERROR($I10/$J10,"") -> 33 | L10: D4D-03, D4D-3
A11: 7 | B11: HEX-01 | C11: =_xlfn.MINIFS('Fuel Issues'!$A$5:$A$440,'Fuel Issues'!$C$5:$C$440,$B11) -> 46190 | D11: =DATE(YEAR(C11),MONTH(C11),1) -> 46174 | E11: =_xlfn.MAXIFS('Fuel Issues'!$A$5:$A$440,'Fuel Issues'!$C$5:$C$440,$B11) -> 46212 | F11: =$E11-$C11+1 -> 23 | G11: =$B$2-$E11 -> 27 | H11: =IF($G11<=7,"On site","No issue "&$G11&" days") -> No issue 27 days | I11: =SUMIFS('Fuel Issues'!$E$5:$E$440,'Fuel Issues'!$C$5:$C$440,$B11) -> 890 | J11: =COUNTIFS('Fuel Issues'!$C$5:$C$440,$B11) -> 14 | K11: =IFERROR($I11/$J11,"") -> 63.571429 | L11: HEX-01
A12: 8 | B12: PJ-6376 | C12: =_xlfn.MINIFS('Fuel Issues'!$A$5:$A$440,'Fuel Issues'!$C$5:$C$440,$B12) -> 46193 | D12: =DATE(YEAR(C12),MONTH(C12),1) -> 46174 | E12: =_xlfn.MAXIFS('Fuel Issues'!$A$5:$A$440,'Fuel Issues'!$C$5:$C$440,$B12) -> 46238 | F12: =$E12-$C12+1 -> 46 | G12: =$B$2-$E12 -> 1 | H12: =IF($G12<=7,"On site","No issue "&$G12&" days") -> On site | I12: =SUMIFS('Fuel Issues'!$E$5:$E$440,'Fuel Issues'!$C$5:$C$440,$B12) -> 533 | J12: =COUNTIFS('Fuel Issues'!$C$5:$C$440,$B12) -> 25 | K12: =IFERROR($I12/$J12,"") -> 21.32 | L12: PJ-6376
A13: 9 | B13: SR-13 | C13: =_xlfn.MINIFS('Fuel Issues'!$A$5:$A$440,'Fuel Issues'!$C$5:$C$440,$B13) -> 46195 | D13: =DATE(YEAR(C13),MONTH(C13),1) -> 46174 | E13: =_xlfn.MAXIFS('Fuel Issues'!$A$5:$A$440,'Fuel Issues'!$C$5:$C$440,$B13) -> 46237 | F13: =$E13-$C13+1 -> 43 | G13: =$B$2-$E13 -> 2 | H13: =IF($G13<=7,"On site","No issue "&$G13&" days") -> On site | I13: =SUMIFS('Fuel Issues'!$E$5:$E$440,'Fuel Issues'!$C$5:$C$440,$B13) -> 350 | J13: =COUNTIFS('Fuel Issues'!$C$5:$C$440,$B13) -> 14 | K13: =IFERROR($I13/$J13,"") -> 25 | L13: SR-13
A14: 10 | B14: MG-07 | C14: =_xlfn.MINIFS('Fuel Issues'!$A$5:$A$440,'Fuel Issues'!$C$5:$C$440,$B14) -> 46197 | D14: =DATE(YEAR(C14),MONTH(C14),1) -> 46174 | E14: =_xlfn.MAXIFS('Fuel Issues'!$A$5:$A$440,'Fuel Issues'!$C$5:$C$440,$B14) -> 46238 | F14: =$E14-$C14+1 -> 42 | G14: =$B$2-$E14 -> 1 | H14: =IF($G14<=7,"On site","No issue "&$G14&" days") -> On site | I14: =SUMIFS('Fuel Issues'!$E$5:$E$440,'Fuel Issues'!$C$5:$C$440,$B14) -> 780 | J14: =COUNTIFS('Fuel Issues'!$C$5:$C$440,$B14) -> 24 | K14: =IFERROR($I14/$J14,"") -> 32.5 | L14: MG-07, ZA-4344
A15: 11 | B15: PE-3723 | C15: =_xlfn.MINIFS('Fuel Issues'!$A$5:$A$440,'Fuel Issues'!$C$5:$C$440,$B15) -> 46200 | D15: =DATE(YEAR(C15),MONTH(C15),1) -> 46174 | E15: =_xlfn.MAXIFS('Fuel Issues'!$A$5:$A$440,'Fuel Issues'!$C$5:$C$440,$B15) -> 46234 | F15: =$E15-$C15+1 -> 35 | G15: =$B$2-$E15 -> 5 | H15: =IF($G15<=7,"On site","No issue "&$G15&" days") -> On site | I15: =SUMIFS('Fuel Issues'!$E$5:$E$440,'Fuel Issues'!$C$5:$C$440,$B15) -> 110 | J15: =COUNTIFS('Fuel Issues'!$C$5:$C$440,$B15) -> 6 | K15: =IFERROR($I15/$J15,"") -> 18.333333 | L15: PE-3723, PE-3723(MRCHINTHAKASURVEYOROFFICER), PE-3729
A16: 12 | B16: LO-7181 | C16: =_xlfn.MINIFS('Fuel Issues'!$A$5:$A$440,'Fuel Issues'!$C$5:$C$440,$B16) -> 46205 | D16: =DATE(YEAR(C16),MONTH(C16),1) -> 46204 | E16: =_xlfn.MAXIFS('Fuel Issues'!$A$5:$A$440,'Fuel Issues'!$C$5:$C$440,$B16) -> 46227 | F16: =$E16-$C16+1 -> 23 | G16: =$B$2-$E16 -> 12 | H16: =IF($G16<=7,"On site","No issue "&$G16&" days") -> No issue 12 days | I16: =SUMIFS('Fuel Issues'!$E$5:$E$440,'Fuel Issues'!$C$5:$C$440,$B16) -> 130 | J16: =COUNTIFS('Fuel Issues'!$C$5:$C$440,$B16) -> 7 | K16: =IFERROR($I16/$J16,"") -> 18.571429 | L16: LO-7181
... A42: 38 | B42: LK-5041 | C42: =_xlfn.MINIFS('Fuel Issues'!$A$5:$A$440,'Fuel Issues'!$C$5:$C$440,$B42) -> 46239 | D42: =DATE(YEAR(C42),MONTH(C42),1) -> 46235 | E42: =_xlfn.MAXIFS('Fuel Issues'!$A$5:$A$440,'Fuel Issues'!$C$5:$C$440,$B42) -> 46239 | F42: =$E42-$C42+1 -> 1 | G42: =$B$2-$E42 -> 0 | H42: =IF($G42<=7,"On site","No issue "&$G42&" days") -> On site | I42: =SUMIFS('Fuel Issues'!$E$5:$E$440,'Fuel Issues'!$C$5:$C$440,$B42) -> 30 | J42: =COUNTIFS('Fuel Issues'!$C$5:$C$440,$B42) -> 1 | K42: =IFERROR($I42/$J42,"") -> 30 | L42: LK-5041
B43: Total | I43: =SUM(I5:I42) -> 18403 | J43: =SUM(J5:J42) -> 436

Sheet Monthly Issues
A1: Month-wise Diesel Issues and Fleet Build-up
A2: August 2026 covers 01 to 05 August only.
A4: Month | B4: Diesel Received (L) | C4: Diesel Issued (L) | D4: No. of Issues | E4: Days with Issues | F4: Units Fuelled in Month | G4: New Units Allocated | H4: Cumulative Fleet on Site | I4: Avg L per Issue | J4: Share of Total Issued
A5: 46143 | B5: =SUMIFS(Receipts!$D$5:$D$37,Receipts!$A$5:$A$37,">="&$A5,Receipts!$A$5:$A$37,"<"&DATE(YEAR($A5),MONTH($A5)+1,1)) -> 240 | C5: =SUMIFS('Fuel Issues'!$E$5:$E$440,'Fuel Issues'!$A$5:$A$440,">="&$A5,'Fuel Issues'!$A$5:$A$440,"<"&DATE(YEAR($A5),MONTH($A5)+1,1)) -> 240 | D5: =COUNTIFS('Fuel Issues'!$A$5:$A$440,">="&$A5,'Fuel Issues'!$A$5:$A$440,"<"&DATE(YEAR($A5),MONTH($A5)+1,1)) -> 5 | E5: 5 | F5: 1 | G5: =COUNTIFS('Allocation Register'!$D$5:$D$42,$A5) -> 1 | H5: =SUM($G$5:$G5) -> 1 | I5: =IFERROR($C5/$D5,"") -> 48 | J5: =IFERROR($C5/SUM($C$5:$C$8),"") -> 0.013041352
A6: 46174 | B6: =SUMIFS(Receipts!$D$5:$D$37,Receipts!$A$5:$A$37,">="&$A6,Receipts!$A$5:$A$37,"<"&DATE(YEAR($A6),MONTH($A6)+1,1)) -> 2925 | C6: =SUMIFS('Fuel Issues'!$E$5:$E$440,'Fuel Issues'!$A$5:$A$440,">="&$A6,'Fuel Issues'!$A$5:$A$440,"<"&DATE(YEAR($A6),MONTH($A6)+1,1)) -> 2455 | D6: =COUNTIFS('Fuel Issues'!$A$5:$A$440,">="&$A6,'Fuel Issues'!$A$5:$A$440,"<"&DATE(YEAR($A6),MONTH($A6)+1,1)) -> 72 | E6: 22 | F6: 11 | G6: =COUNTIFS('Allocation Register'!$D$5:$D$42,$A6) -> 10 | H6: =SUM($G$5:$G6) -> 11 | I6: =IFERROR($C6/$D6,"") -> 34.097222 | J6: =IFERROR($C6/SUM($C$5:$C$8),"") -> 0.13340216
A7: 46204 | B7: =SUMIFS(Receipts!$D$5:$D$37,Receipts!$A$5:$A$37,">="&$A7,Receipts!$A$5:$A$37,"<"&DATE(YEAR($A7),MONTH($A7)+1,1)) -> 13671 | C7: =SUMIFS('Fuel Issues'!$E$5:$E$440,'Fuel Issues'!$A$5:$A$440,">="&$A7,'Fuel Issues'!$A$5:$A$440,"<"&DATE(YEAR($A7),MONTH($A7)+1,1)) -> 13053 | D7: =COUNTIFS('Fuel Issues'!$A$5:$A$440,">="&$A7,'Fuel Issues'!$A$5:$A$440,"<"&DATE(YEAR($A7),MONTH($A7)+1,1)) -> 312 | E7: 30 | F7: 34 | G7: =COUNTIFS('Allocation Register'!$D$5:$D$42,$A7) -> 24 | H7: =SUM($G$5:$G7) -> 35 | I7: =IFERROR($C7/$D7,"") -> 41.836538 | J7: =IFERROR($C7/SUM($C$5:$C$8),"") -> 0.70928653
A8: 46235 | B8: =SUMIFS(Receipts!$D$5:$D$37,Receipts!$A$5:$A$37,">="&$A8,Receipts!$A$5:$A$37,"<"&DATE(YEAR($A8),MONTH($A8)+1,1)) -> 0 | C8: =SUMIFS('Fuel Issues'!$E$5:$E$440,'Fuel Issues'!$A$5:$A$440,">="&$A8,'Fuel Issues'!$A$5:$A$440,"<"&DATE(YEAR($A8),MONTH($A8)+1,1)) -> 2655 | D8: =COUNTIFS('Fuel Issues'!$A$5:$A$440,">="&$A8,'Fuel Issues'!$A$5:$A$440,"<"&DATE(YEAR($A8),MONTH($A8)+1,1)) -> 47 | E8: 5 | F8: 21 | G8: =COUNTIFS('Allocation Register'!$D$5:$D$42,$A8) -> 3 | H8: =SUM($G$5:$G8) -> 38 | I8: =IFERROR($C8/$D8,"") -> 56.489362 | J8: =IFERROR($C8/SUM($C$5:$C$8),"") -> 0.14426996
A9: Total | B9: =SUM(B5:B8) -> 16836 | C9: =SUM(C5:C8) -> 18403 | D9: =SUM(D5:D8) -> 436 | E9: =SUM(E5:E8) -> 62 | G9: =SUM(G5:G8) -> 38 | J9: =SUM(J5:J8) -> 1

Sheet Monthly Allocations
A1: Vehicles Allocated to Site, by Month
A2: A unit is listed in the month of its first diesel issue. Each unit appears once only.
A4: May 2026 - 1 unit(s) allocated
A5: # | B5: Vehicle / Unit | C5: Allocation Date | D5: Day | E5: Diesel in That Month (L) | F5: Total Diesel to Date (L)
A6: 1 | B6: 2B-1980 | C6: 46153 | D6: =TEXT($C6,"DDD") -> Mon | E6: =SUMIFS('Fuel Issues'!$E$5:$E$440,'Fuel Issues'!$C$5:$C$440,$B6,'Fuel Issues'!$A$5:$A$440,">="&DATE(YEAR($C6),MONTH($C6),1),'Fuel Issues'!$A$5:$A$440,"<"&DATE(YEAR($C6),MONTH($C6)+1,1)) -> 240 | F6: =SUMIFS('Fuel Issues'!$E$5:$E$440,'Fuel Issues'!$C$5:$C$440,$B6) -> 576
B7: Month subtotal | E7: =SUM(E6:E6) -> 240 | F7: =SUM(F6:F6) -> 576
A10: Jun 2026 - 10 unit(s) allocated
A11: # | B11: Vehicle / Unit | C11: Allocation Date | D11: Day | E11: Diesel in That Month (L) | F11: Total Diesel to Date (L)
A12: 1 | B12: D4D-01 | C12: 46177 | D12: =TEXT($C12,"DDD") -> Thu | E12: =SUMIFS('Fuel Issues'!$E$5:$E$440,'Fuel Issues'!$C$5:$C$440,$B12,'Fuel Issues'!$A$5:$A$440,">="&DATE(YEAR($C12),MONTH($C12),1),'Fuel Issues'!$A$5:$A$440,"<"&DATE(YEAR($C12),MONTH($C12)+1,1)) -> 80 | F12: =SUMIFS('Fuel Issues'!$E$5:$E$440,'Fuel Issues'!$C$5:$C$440,$B12) -> 80
A13: 2 | B13: 59-5421 | C13: 46179 | D13: =TEXT($C13,"DDD") -> Sat | E13: =SUMIFS('Fuel Issues'!$E$5:$E$440,'Fuel Issues'!$C$5:$C$440,$B13,'Fuel Issues'!$A$5:$A$440,">="&DATE(YEAR($C13),MONTH($C13),1),'Fuel Issues'!$A$5:$A$440,"<"&DATE(YEAR($C13),MONTH($C13)+1,1)) -> 125 | F13: =SUMIFS('Fuel Issues'!$E$5:$E$440,'Fuel Issues'!$C$5:$C$440,$B13) -> 393
A14: 3 | B14: D4D-02 | C14: 46181 | D14: =TEXT($C14,"DDD") -> Mon | E14: =SUMIFS('Fuel Issues'!$E$5:$E$440,'Fuel Issues'!$C$5:$C$440,$B14,'Fuel Issues'!$A$5:$A$440,">="&DATE(YEAR($C14),MONTH($C14),1),'Fuel Issues'!$A$5:$A$440,"<"&DATE(YEAR($C14),MONTH($C14)+1,1)) -> 380 | F14: =SUMIFS('Fuel Issues'!$E$5:$E$440,'Fuel Issues'!$C$5:$C$440,$B14) -> 1455
A15: 4 | B15: HEX-45 | C15: 46182 | D15: =TEXT($C15,"DDD") -> Tue | E15: =SUMIFS('Fuel Issues'!$E$5:$E$440,'Fuel Issues'!$C$5:$C$440,$B15,'Fuel Issues'!$A$5:$A$440,">="&DATE(YEAR($C15),MONTH($C15),1),'Fuel Issues'!$A$5:$A$440,"<"&DATE(YEAR($C15),MONTH($C15)+1,1)) -> 800 | F15: =SUMIFS('Fuel Issues'!$E$5:$E$440,'Fuel Issues'!$C$5:$C$440,$B15) -> 2920
A16: 5 | B16: D4D-03 | C16: 46187 | D16: =TEXT($C16,"DDD") -> Sun | E16: =SUMIFS('Fuel Issues'!$E$5:$E$440,'Fuel Issues'!$C$5:$C$440,$B16,'Fuel Issues'!$A$5:$A$440,">="&DATE(YEAR($C16),MONTH($C16),1),'Fuel Issues'!$A$5:$A$440,"<"&DATE(YEAR($C16),MONTH($C16)+1,1)) -> 200 | F16: =SUMIFS('Fuel Issues'!$E$5:$E$440,'Fuel Issues'!$C$5:$C$440,$B16) -> 330
A17: 6 | B17: HEX-01 | C17: 46190 | D17: =TEXT($C17,"DDD") -> Wed | E17: =SUMIFS('Fuel Issues'!$E$5:$E$440,'Fuel Issues'!$C$5:$C$440,$B17,'Fuel Issues'!$A$5:$A$440,">="&DATE(YEAR($C17),MONTH($C17),1),'Fuel Issues'!$A$5:$A$440,"<"&DATE(YEAR($C17),MONTH($C17)+1,1)) -> 500 | F17: =SUMIFS('Fuel Issues'!$E$5:$E$440,'Fuel Issues'!$C$5:$C$440,$B17) -> 890
A18: 7 | B18: PJ-6376 | C18: 46193 | D18: =TEXT($C18,"DDD") -> Sat | E18: =SUMIFS('Fuel Issues'!$E$5:$E$440,'Fuel Issues'!$C$5:$C$440,$B18,'Fuel Issues'!$A$5:$A$440,">="&DATE(YEAR($C18),MONTH($C18),1),'Fuel Issues'!$A$5:$A$440,"<"&DATE(YEAR($C18),MONTH($C18)+1,1)) -> 110 | F18: =SUMIFS('Fuel Issues'!$E$5:$E$440,'Fuel Issues'!$C$5:$C$440,$B18) -> 533
A19: 8 | B19: SR-13 | C19: 46195 | D19: =TEXT($C19,"DDD") -> Mon | E19: =SUMIFS('Fuel Issues'!$E$5:$E$440,'Fuel Issues'!$C$5:$C$440,$B19,'Fuel Issues'!$A$5:$A$440,">="&DATE(YEAR($C19),MONTH($C19),1),'Fuel Issues'!$A$5:$A$440,"<"&DATE(YEAR($C19),MONTH($C19)+1,1)) -> 50 | F19: =SUMIFS('Fuel Issues'!$E$5:$E$440,'Fuel Issues'!$C$5:$C$440,$B19) -> 350
A20: 9 | B20: MG-07 | C20: 46197 | D20: =TEXT($C20,"DDD") -> Wed | E20: =SUMIFS('Fuel Issues'!$E$5:$E$440,'Fuel Issues'!$C$5:$C$440,$B20,'Fuel Issues'!$A$5:$A$440,">="&DATE(YEAR($C20),MONTH($C20),1),'Fuel Issues'!$A$5:$A$440,"<"&DATE(YEAR($C20),MONTH($C20)+1,1)) -> 60 | F20: =SUMIFS('Fuel Issues'!$E$5:$E$440,'Fuel Issues'!$C$5:$C$440,$B20) -> 780
A21: 10 | B21: PE-3723 | C21: 46200 | D21: =TEXT($C21,"DDD") -> Sat | E21: =SUMIFS('Fuel Issues'!$E$5:$E$440,'Fuel Issues'!$C$5:$C$440,$B21,'Fuel Issues'!$A$5:$A$440,">="&DATE(YEAR($C21),MONTH($C21),1),'Fuel Issues'!$A$5:$A$440,"<"&DATE(YEAR($C21),MONTH($C21)+1,1)) -> 20 | F21: =SUMIFS('Fuel Issues'!$E$5:$E$440,'Fuel Issues'!$C$5:$C$440,$B21) -> 110
B22: Month subtotal | E22: =SUM(E12:E21) -> 2325 | F22: =SUM(F12:F21) -> 7841
A25: Jul 2026 - 24 unit(s) allocated
A26: # | B26: Vehicle / Unit | C26: Allocation Date | D26: Day | E26: Diesel in That Month (L) | F26: Total Diesel to Date (L)
A27: 1 | B27: LO-7181 | C27: 46205 | D27: =TEXT($C27,"DDD") -> Thu | E27: =SUMIFS('Fuel Issues'!$E$5:$E$440,'Fuel Issues'!$C$5:$C$440,$B27,'Fuel Issues'!$A$5:$A$440,">="&DATE(YEAR($C27),MONTH($C27),1),'Fuel Issues'!$A$5:$A$440,"<"&DATE(YEAR($C27),MONTH($C27)+1,1)) -> 130 | F27: =SUMIFS('Fuel Issues'!$E$5:$E$440,'Fuel Issues'!$C$5:$C$440,$B27) -> 130
A28: 2 | B28: HEX-26 | C28: 46208 | D28: =TEXT($C28,"DDD") -> Sun | E28: =SUMIFS('Fuel Issues'!$E$5:$E$440,'Fuel Issues'!$C$5:$C$440,$B28,'Fuel Issues'!$A$5:$A$440,">="&DATE(YEAR($C28),MONTH($C28),1),'Fuel Issues'!$A$5:$A$440,"<"&DATE(YEAR($C28),MONTH($C28)+1,1)) -> 1740 | F28: =SUMIFS('Fuel Issues'!$E$5:$E$440,'Fuel Issues'!$C$5:$C$440,$B28) -> 2090
A29: 3 | B29: LB-25 | C29: 46208 | D29: =TEXT($C29,"DDD") -> Sun | E29: =SUMIFS('Fuel Issues'!$E$5:$E$440,'Fuel Issues'!$C$5:$C$440,$B29,'Fuel Issues'!$A$5:$A$440,">="&DATE(YEAR($C29),MONTH($C29),1),'Fuel Issues'!$A$5:$A$440,"<"&DATE(YEAR($C29),MONTH($C29)+1,1)) -> 526 | F29: =SUMIFS('Fuel Issues'!$E$5:$E$440,'Fuel Issues'!$C$5:$C$440,$B29) -> 526
A30: 4 | B30: DAH-2491 | C30: 46209 | D30: =TEXT($C30,"DDD") -> Mon | E30: =SUMIFS('Fuel Issues'!$E$5:$E$440,'Fuel Issues'!$C$5:$C$440,$B30,'Fuel Issues'!$A$5:$A$440,">="&DATE(YEAR($C30),MONTH($C30),1),'Fuel Issues'!$A$5:$A$440,"<"&DATE(YEAR($C30),MONTH($C30)+1,1)) -> 191 | F30: =SUMIFS('Fuel Issues'!$E$5:$E$440,'Fuel Issues'!$C$5:$C$440,$B30) -> 191
A31: 5 | B31: LA-1359 | C31: 46209 | D31: =TEXT($C31,"DDD") -> Mon | E31: =SUMIFS('Fuel Issues'!$E$5:$E$440,'Fuel Issues'!$C$5:$C$440,$B31,'Fuel Issues'!$A$5:$A$440,">="&DATE(YEAR($C31),MONTH($C31),1),'Fuel Issues'!$A$5:$A$440,"<"&DATE(YEAR($C31),MONTH($C31)+1,1)) -> 162 | F31: =SUMIFS('Fuel Issues'!$E$5:$E$440,'Fuel Issues'!$C$5:$C$440,$B31) -> 162
A32: 6 | B32: LP-1709 | C32: 46209 | D32: =TEXT($C32,"DDD") -> Mon | E32: =SUMIFS('Fuel Issues'!$E$5:$E$440,'Fuel Issues'!$C$5:$C$440,$B32,'Fuel Issues'!$A$5:$A$440,">="&DATE(YEAR($C32),MONTH($C32),1),'Fuel Issues'!$A$5:$A$440,"<"&DATE(YEAR($C32),MONTH($C32)+1,1)) -> 30 | F32: =SUMIFS('Fuel Issues'!$E$5:$E$440,'Fuel Issues'!$C$5:$C$440,$B32) -> 30
A33: 7 | B33: PH-9072 | C33: 46209 | D33: =TEXT($C33,"DDD") -> Mon | E33: =SUMIFS('Fuel Issues'!$E$5:$E$440,'Fuel Issues'!$C$5:$C$440,$B33,'Fuel Issues'!$A$5:$A$440,">="&DATE(YEAR($C33),MONTH($C33),1),'Fuel Issues'!$A$5:$A$440,"<"&DATE(YEAR($C33),MONTH($C33)+1,1)) -> 384 | F33: =SUMIFS('Fuel Issues'!$E$5:$E$440,'Fuel Issues'!$C$5:$C$440,$B33) -> 485
A34: 8 | B34: DAG-4969 | C34: 46210 | D34: =TEXT($C34,"DDD") -> Tue | E34: =SUMIFS('Fuel Issues'!$E$5:$E$440,'Fuel Issues'!$C$5:$C$440,$B34,'Fuel Issues'!$A$5:$A$440,">="&DATE(YEAR($C34),MONTH($C34),1),'Fuel Issues'!$A$5:$A$440,"<"&DATE(YEAR($C34),MONTH($C34)+1,1)) -> 150 | F34: =SUMIFS('Fuel Issues'!$E$5:$E$440,'Fuel Issues'!$C$5:$C$440,$B34) -> 170
A35: 9 | B35: VR-59 | C35: 46210 | D35: =TEXT($C35,"DDD") -> Tue | E35: =SUMIFS('Fuel Issues'!$E$5:$E$440,'Fuel Issues'!$C$5:$C$440,$B35,'Fuel Issues'!$A$5:$A$440,">="&DATE(YEAR($C35),MONTH($C35),1),'Fuel Issues'!$A$5:$A$440,"<"&DATE(YEAR($C35),MONTH($C35)+1,1)) -> 45 | F35: =SUMIFS('Fuel Issues'!$E$5:$E$440,'Fuel Issues'!$C$5:$C$440,$B35) -> 45
A36: 10 | B36: 325-1030 | C36: 46211 | D36: =TEXT($C36,"DDD") -> Wed | E36: =SUMIFS('Fuel Issues'!$E$5:$E$440,'Fuel Issues'!$C$5:$C$440,$B36,'Fuel Issues'!$A$5:$A$440,">="&DATE(YEAR($C36),MONTH($C36),1),'Fuel Issues'!$A$5:$A$440,"<"&DATE(YEAR($C36),MONTH($C36)+1,1)) -> 241 | F36: =SUMIFS('Fuel Issues'!$E$5:$E$440,'Fuel Issues'!$C$5:$C$440,$B36) -> 281
A37: 11 | B37: HEX-33 | C37: 46211 | D37: =TEXT($C37,"DDD") -> Wed | E37: =SUMIFS('Fuel Issues'!$E$5:$E$440,'Fuel Issues'!$C$5:$C$440,$B37,'Fuel Issues'!$A$5:$A$440,">="&DATE(YEAR($C37),MONTH($C37),1),'Fuel Issues'!$A$5:$A$440,"<"&DATE(YEAR($C37),MONTH($C37)+1,1)) -> 1620 | F37: =SUMIFS('Fuel Issues'!$E$5:$E$440,'Fuel Issues'!$C$5:$C$440,$B37) -> 1940
A38: 12 | B38: LO-4925 | C38: 46212 | D38: =TEXT($C38,"DDD") -> Thu | E38: =SUMIFS('Fuel Issues'!$E$5:$E$440,'Fuel Issues'!$C$5:$C$440,$B38,'Fuel Issues'!$A$5:$A$440,">="&DATE(YEAR($C38),MONTH($C38),1),'Fuel Issues'!$A$5:$A$440,"<"&DATE(YEAR($C38),MONTH($C38)+1,1)) -> 195 | F38: =SUMIFS('Fuel Issues'!$E$5:$E$440,'Fuel Issues'!$C$5:$C$440,$B38) -> 195
... A50: 24 | B50: 2B-4606 | C50: 46230 | D50: =TEXT($C50,"DDD") -> Mon | E50: =SUMIFS('Fuel Issues'!$E$5:$E$440,'Fuel Issues'!$C$5:$C$440,$B50,'Fuel Issues'!$A$5:$A$440,">="&DATE(YEAR($C50),MONTH($C50),1),'Fuel Issues'!$A$5:$A$440,"<"&DATE(YEAR($C50),MONTH($C50)+1,1)) -> 30 | F50: =SUMIFS('Fuel Issues'!$E$5:$E$440,'Fuel Issues'!$C$5:$C$440,$B50) -> 150
B51: Month subtotal | E51: =SUM(E27:E50) -> 8040 | F51: =SUM(F27:F50) -> 9704
A54: Aug 2026 - 3 unit(s) allocated
A55: # | B55: Vehicle / Unit | C55: Allocation Date | D55: Day | E55: Diesel in That Month (L) | F55: Total Diesel to Date (L)
A56: 1 | B56: HEX-42 | C56: 46238 | D56: =TEXT($C56,"DDD") -> Tue | E56: =SUMIFS('Fuel Issues'!$E$5:$E$440,'Fuel Issues'!$C$5:$C$440,$B56,'Fuel Issues'!$A$5:$A$440,">="&DATE(YEAR($C56),MONTH($C56),1),'Fuel Issues'!$A$5:$A$440,"<"&DATE(YEAR($C56),MONTH($C56)+1,1)) -> 80 | F56: =SUMIFS('Fuel Issues'!$E$5:$E$440,'Fuel Issues'!$C$5:$C$440,$B56) -> 80
A57: 2 | B57: GE-M47 | C57: 46239 | D57: =TEXT($C57,"DDD") -> Wed | E57: =SUMIFS('Fuel Issues'!$E$5:$E$440,'Fuel Issues'!$C$5:$C$440,$B57,'Fuel Issues'!$A$5:$A$440,">="&DATE(YEAR($C57),MONTH($C57),1),'Fuel Issues'!$A$5:$A$440,"<"&DATE(YEAR($C57),MONTH($C57)+1,1)) -> 172 | F57: =SUMIFS('Fuel Issues'!$E$5:$E$440,'Fuel Issues'!$C$5:$C$440,$B57) -> 172
A58: 3 | B58: LK-5041 | C58: 46239 | D58: =TEXT($C58,"DDD") -> Wed | E58: =SUMIFS('Fuel Issues'!$E$5:$E$440,'Fuel Issues'!$C$5:$C$440,$B58,'Fuel Issues'!$A$5:$A$440,">="&DATE(YEAR($C58),MONTH($C58),1),'Fuel Issues'!$A$5:$A$440,"<"&DATE(YEAR($C58),MONTH($C58)+1,1)) -> 30 | F58: =SUMIFS('Fuel Issues'!$E$5:$E$440,'Fuel Issues'!$C$5:$C$440,$B58) -> 30
...

Sheet Vehicle x Month
A1: Diesel Issued by Unit and Month (L)
A2: Sorted by total issued. A blank month means the unit drew no fuel that month.
A4: Vehicle / Unit | B4: May 2026 | C4: Jun 2026 | D4: Jul 2026 | E4: Aug 2026 | F4: Total (L) | G4: No. of Issues | H4: Allocation Date | I4: Share
A5: HEX-45 | B5: =IF(SUMIFS('Fuel Issues'!$E$5:$E$440,'Fuel Issues'!$C$5:$C$440,$A5,'Fuel Issues'!$A$5:$A$440,">="&DATE(2026,5,1),'Fuel Issues'!$A$5:$A$440,"<"&DATE(2026,6,1))=0,"",SUMIFS('Fuel Issues'!$E$5:$E$440,'Fuel Issues'!$C$5:$C$440,$A5,'Fuel Issues'!$A$5:$A$440,">="&DATE(2026,5,1),'Fuel Issues'!$A$5:$A$440,"<"&DATE(2026,6,1))) | C5: =IF(SUMIFS('Fuel Issues'!$E$5:$E$440,'Fuel Issues'!$C$5:$C$440,$A5,'Fuel Issues'!$A$5:$A$440,">="&DATE(2026,6,1),'Fuel Issues'!$A$5:$A$440,"<"&DATE(2026,7,1))=0,"",SUMIFS('Fuel Issues'!$E$5:$E$440,'Fuel Issues'!$C$5:$C$440,$A5,'Fuel Issues'!$A$5:$A$440,">="&DATE(2026,6,1),'Fuel Issues'!$A$5:$A$440,"<"&DATE(2026,7,1))) -> 800 | D5: =IF(SUMIFS('Fuel Issues'!$E$5:$E$440,'Fuel Issues'!$C$5:$C$440,$A5,'Fuel Issues'!$A$5:$A$440,">="&DATE(2026,7,1),'Fuel Issues'!$A$5:$A$440,"<"&DATE(2026,8,1))=0,"",SUMIFS('Fuel Issues'!$E$5:$E$440,'Fuel Issues'!$C$5:$C$440,$A5,'Fuel Issues'!$A$5:$A$440,">="&DATE(2026,7,1),'Fuel Issues'!$A$5:$A$440,"<"&DATE(2026,8,1))) -> 1870 | E5: =IF(SUMIFS('Fuel Issues'!$E$5:$E$440,'Fuel Issues'!$C$5:$C$440,$A5,'Fuel Issues'!$A$5:$A$440,">="&DATE(2026,8,1),'Fuel Issues'!$A$5:$A$440,"<"&DATE(2026,9,1))=0,"",SUMIFS('Fuel Issues'!$E$5:$E$440,'Fuel Issues'!$C$5:$C$440,$A5,'Fuel Issues'!$A$5:$A$440,">="&DATE(2026,8,1),'Fuel Issues'!$A$5:$A$440,"<"&DATE(2026,9,1))) -> 250 | F5: =SUMIFS('Fuel Issues'!$E$5:$E$440,'Fuel Issues'!$C$5:$C$440,$A5) -> 2920 | G5: =COUNTIFS('Fuel Issues'!$C$5:$C$440,$A5) -> 44 | H5: =_xlfn.MINIFS('Fuel Issues'!$A$5:$A$440,'Fuel Issues'!$C$5:$C$440,$A5) -> 46182 | I5: =IFERROR($F5/SUM($F$5:$F$42),"") -> 0.15866978
A6: HEX-26 | B6: =IF(SUMIFS('Fuel Issues'!$E$5:$E$440,'Fuel Issues'!$C$5:$C$440,$A6,'Fuel Issues'!$A$5:$A$440,">="&DATE(2026,5,1),'Fuel Issues'!$A$5:$A$440,"<"&DATE(2026,6,1))=0,"",SUMIFS('Fuel Issues'!$E$5:$E$440,'Fuel Issues'!$C$5:$C$440,$A6,'Fuel Issues'!$A$5:$A$440,">="&DATE(2026,5,1),'Fuel Issues'!$A$5:$A$440,"<"&DATE(2026,6,1))) | C6: =IF(SUMIFS('Fuel Issues'!$E$5:$E$440,'Fuel Issues'!$C$5:$C$440,$A6,'Fuel Issues'!$A$5:$A$440,">="&DATE(2026,6,1),'Fuel Issues'!$A$5:$A$440,"<"&DATE(2026,7,1))=0,"",SUMIFS('Fuel Issues'!$E$5:$E$440,'Fuel Issues'!$C$5:$C$440,$A6,'Fuel Issues'!$A$5:$A$440,">="&DATE(2026,6,1),'Fuel Issues'!$A$5:$A$440,"<"&DATE(2026,7,1))) | D6: =IF(SUMIFS('Fuel Issues'!$E$5:$E$440,'Fuel Issues'!$C$5:$C$440,$A6,'Fuel Issues'!$A$5:$A$440,">="&DATE(2026,7,1),'Fuel Issues'!$A$5:$A$440,"<"&DATE(2026,8,1))=0,"",SUMIFS('Fuel Issues'!$E$5:$E$440,'Fuel Issues'!$C$5:$C$440,$A6,'Fuel Issues'!$A$5:$A$440,">="&DATE(2026,7,1),'Fuel Issues'!$A$5:$A$440,"<"&DATE(2026,8,1))) -> 1740 | E6: =IF(SUMIFS('Fuel Issues'!$E$5:$E$440,'Fuel Issues'!$C$5:$C$440,$A6,'Fuel Issues'!$A$5:$A$440,">="&DATE(2026,8,1),'Fuel Issues'!$A$5:$A$440,"<"&DATE(2026,9,1))=0,"",SUMIFS('Fuel Issues'!$E$5:$E$440,'Fuel Issues'!$C$5:$C$440,$A6,'Fuel Issues'!$A$5:$A$440,">="&DATE(2026,8,1),'Fuel Issues'!$A$5:$A$440,"<"&DATE(2026,9,1))) -> 350 | F6: =SUMIFS('Fuel Issues'!$E$5:$E$440,'Fuel Issues'!$C$5:$C$440,$A6) -> 2090 | G6: =COUNTIFS('Fuel Issues'!$C$5:$C$440,$A6) -> 31 | H6: =_xlfn.MINIFS('Fuel Issues'!$A$5:$A$440,'Fuel Issues'!$C$5:$C$440,$A6) -> 46208 | I6: =IFERROR($F6/SUM($F$5:$F$42),"") -> 0.11356844
A7: HEX-33 | B7: =IF(SUMIFS('Fuel Issues'!$E$5:$E$440,'Fuel Issues'!$C$5:$C$440,$A7,'Fuel Issues'!$A$5:$A$440,">="&DATE(2026,5,1),'Fuel Issues'!$A$5:$A$440,"<"&DATE(2026,6,1))=0,"",SUMIFS('Fuel Issues'!$E$5:$E$440,'Fuel Issues'!$C$5:$C$440,$A7,'Fuel Issues'!$A$5:$A$440,">="&DATE(2026,5,1),'Fuel Issues'!$A$5:$A$440,"<"&DATE(2026,6,1))) | C7: =IF(SUMIFS('Fuel Issues'!$E$5:$E$440,'Fuel Issues'!$C$5:$C$440,$A7,'Fuel Issues'!$A$5:$A$440,">="&DATE(2026,6,1),'Fuel Issues'!$A$5:$A$440,"<"&DATE(2026,7,1))=0,"",SUMIFS('Fuel Issues'!$E$5:$E$440,'Fuel Issues'!$C$5:$C$440,$A7,'Fuel Issues'!$A$5:$A$440,">="&DATE(2026,6,1),'Fuel Issues'!$A$5:$A$440,"<"&DATE(2026,7,1))) | D7: =IF(SUMIFS('Fuel Issues'!$E$5:$E$440,'Fuel Issues'!$C$5:$C$440,$A7,'Fuel Issues'!$A$5:$A$440,">="&DATE(2026,7,1),'Fuel Issues'!$A$5:$A$440,"<"&DATE(2026,8,1))=0,"",SUMIFS('Fuel Issues'!$E$5:$E$440,'Fuel Issues'!$C$5:$C$440,$A7,'Fuel Issues'!$A$5:$A$440,">="&DATE(2026,7,1),'Fuel Issues'!$A$5:$A$440,"<"&DATE(2026,8,1))) -> 1620 | E7: =IF(SUMIFS('Fuel Issues'!$E$5:$E$440,'Fuel Issues'!$C$5:$C$440,$A7,'Fuel Issues'!$A$5:$A$440,">="&DATE(2026,8,1),'Fuel Issues'!$A$5:$A$440,"<"&DATE(2026,9,1))=0,"",SUMIFS('Fuel Issues'!$E$5:$E$440,'Fuel Issues'!$C$5:$C$440,$A7,'Fuel Issues'!$A$5:$A$440,">="&DATE(2026,8,1),'Fuel Issues'!$A$5:$A$440,"<"&DATE(2026,9,1))) -> 320 | F7: =SUMIFS('Fuel Issues'!$E$5:$E$440,'Fuel Issues'!$C$5:$C$440,$A7) -> 1940 | G7: =COUNTIFS('Fuel Issues'!$C$5:$C$440,$A7) -> 26 | H7: =_xlfn.MINIFS('Fuel Issues'!$A$5:$A$440,'Fuel Issues'!$C$5:$C$440,$A7) -> 46211 | I7: =IFERROR($F7/SUM($F$5:$F$42),"") -> 0.10541759
A8: HEX-37 | B8: =IF(SUMIFS('Fuel Issues'!$E$5:$E$440,'Fuel Issues'!$C$5:$C$440,$A8,'Fuel Issues'!$A$5:$A$440,">="&DATE(2026,5,1),'Fuel Issues'!$A$5:$A$440,"<"&DATE(2026,6,1))=0,"",SUMIFS('Fuel Issues'!$E$5:$E$440,'Fuel Issues'!$C$5:$C$440,$A8,'Fuel Issues'!$A$5:$A$440,">="&DATE(2026,5,1),'Fuel Issues'!$A$5:$A$440,"<"&DATE(2026,6,1))) | C8: =IF(SUMIFS('Fuel Issues'!$E$5:$E$440,'Fuel Issues'!$C$5:$C$440,$A8,'Fuel Issues'!$A$5:$A$440,">="&DATE(2026,6,1),'Fuel Issues'!$A$5:$A$440,"<"&DATE(2026,7,1))=0,"",SUMIFS('Fuel Issues'!$E$5:$E$440,'Fuel Issues'!$C$5:$C$440,$A8,'Fuel Issues'!$A$5:$A$440,">="&DATE(2026,6,1),'Fuel Issues'!$A$5:$A$440,"<"&DATE(2026,7,1))) | D8: =IF(SUMIFS('Fuel Issues'!$E$5:$E$440,'Fuel Issues'!$C$5:$C$440,$A8,'Fuel Issues'!$A$5:$A$440,">="&DATE(2026,7,1),'Fuel Issues'!$A$5:$A$440,"<"&DATE(2026,8,1))=0,"",SUMIFS('Fuel Issues'!$E$5:$E$440,'Fuel Issues'!$C$5:$C$440,$A8,'Fuel Issues'!$A$5:$A$440,">="&DATE(2026,7,1),'Fuel Issues'!$A$5:$A$440,"<"&DATE(2026,8,1))) -> 1140 | E8: =IF(SUMIFS('Fuel Issues'!$E$5:$E$440,'Fuel Issues'!$C$5:$C$440,$A8,'Fuel Issues'!$A$5:$A$440,">="&DATE(2026,8,1),'Fuel Issues'!$A$5:$A$440,"<"&DATE(2026,9,1))=0,"",SUMIFS('Fuel Issues'!$E$5:$E$440,'Fuel Issues'!$C$5:$C$440,$A8,'Fuel Issues'!$A$5:$A$440,">="&DATE(2026,8,1),'Fuel Issues'!$A$5:$A$440,"<"&DATE(2026,9,1))) -> 520 | F8: =SUMIFS('Fuel Issues'!$E$5:$E$440,'Fuel Issues'!$C$5:$C$440,$A8) -> 1660 | G8: =COUNTIFS('Fuel Issues'!$C$5:$C$440,$A8) -> 15 | H8: =_xlfn.MINIFS('Fuel Issues'!$A$5:$A$440,'Fuel Issues'!$C$5:$C$440,$A8) -> 46223 | I8: =IFERROR($F8/SUM($F$5:$F$42),"") -> 0.090202684
A9: D4D-02 | B9: =IF(SUMIFS('Fuel Issues'!$E$5:$E$440,'Fuel Issues'!$C$5:$C$440,$A9,'Fuel Issues'!$A$5:$A$440,">="&DATE(2026,5,1),'Fuel Issues'!$A$5:$A$440,"<"&DATE(2026,6,1))=0,"",SUMIFS('Fuel Issues'!$E$5:$E$440,'Fuel Issues'!$C$5:$C$440,$A9,'Fuel Issues'!$A$5:$A$440,">="&DATE(2026,5,1),'Fuel Issues'!$A$5:$A$440,"<"&DATE(2026,6,1))) | C9: =IF(SUMIFS('Fuel Issues'!$E$5:$E$440,'Fuel Issues'!$C$5:$C$440,$A9,'Fuel Issues'!$A$5:$A$440,">="&DATE(2026,6,1),'Fuel Issues'!$A$5:$A$440,"<"&DATE(2026,7,1))=0,"",SUMIFS('Fuel Issues'!$E$5:$E$440,'Fuel Issues'!$C$5:$C$440,$A9,'Fuel Issues'!$A$5:$A$440,">="&DATE(2026,6,1),'Fuel Issues'!$A$5:$A$440,"<"&DATE(2026,7,1))) -> 380 | D9: =IF(SUMIFS('Fuel Issues'!$E$5:$E$440,'Fuel Issues'!$C$5:$C$440,$A9,'Fuel Issues'!$A$5:$A$440,">="&DATE(2026,7,1),'Fuel Issues'!$A$5:$A$440,"<"&DATE(2026,8,1))=0,"",SUMIFS('Fuel Issues'!$E$5:$E$440,'Fuel Issues'!$C$5:$C$440,$A9,'Fuel Issues'!$A$5:$A$440,">="&DATE(2026,7,1),'Fuel Issues'!$A$5:$A$440,"<"&DATE(2026,8,1))) -> 940 | E9: =IF(SUMIFS('Fuel Issues'!$E$5:$E$440,'Fuel Issues'!$C$5:$C$440,$A9,'Fuel Issues'!$A$5:$A$440,">="&DATE(2026,8,1),'Fuel Issues'!$A$5:$A$440,"<"&DATE(2026,9,1))=0,"",SUMIFS('Fuel Issues'!$E$5:$E$440,'Fuel Issues'!$C$5:$C$440,$A9,'Fuel Issues'!$A$5:$A$440,">="&DATE(2026,8,1),'Fuel Issues'!$A$5:$A$440,"<"&DATE(2026,9,1))) -> 135 | F9: =SUMIFS('Fuel Issues'!$E$5:$E$440,'Fuel Issues'!$C$5:$C$440,$A9) -> 1455 | G9: =COUNTIFS('Fuel Issues'!$C$5:$C$440,$A9) -> 38 | H9: =_xlfn.MINIFS('Fuel Issues'!$A$5:$A$440,'Fuel Issues'!$C$5:$C$440,$A9) -> 46181 | I9: =IFERROR($F9/SUM($F$5:$F$42),"") -> 0.079063196
A10: HEX-01 | B10: =IF(SUMIFS('Fuel Issues'!$E$5:$E$440,'Fuel Issues'!$C$5:$C$440,$A10,'Fuel Issues'!$A$5:$A$440,">="&DATE(2026,5,1),'Fuel Issues'!$A$5:$A$440,"<"&DATE(2026,6,1))=0,"",SUMIFS('Fuel Issues'!$E$5:$E$440,'Fuel Issues'!$C$5:$C$440,$A10,'Fuel Issues'!$A$5:$A$440,">="&DATE(2026,5,1),'Fuel Issues'!$A$5:$A$440,"<"&DATE(2026,6,1))) | C10: =IF(SUMIFS('Fuel Issues'!$E$5:$E$440,'Fuel Issues'!$C$5:$C$440,$A10,'Fuel Issues'!$A$5:$A$440,">="&DATE(2026,6,1),'Fuel Issues'!$A$5:$A$440,"<"&DATE(2026,7,1))=0,"",SUMIFS('Fuel Issues'!$E$5:$E$440,'Fuel Issues'!$C$5:$C$440,$A10,'Fuel Issues'!$A$5:$A$440,">="&DATE(2026,6,1),'Fuel Issues'!$A$5:$A$440,"<"&DATE(2026,7,1))) -> 500 | D10: =IF(SUMIFS('Fuel Issues'!$E$5:$E$440,'Fuel Issues'!$C$5:$C$440,$A10,'Fuel Issues'!$A$5:$A$440,">="&DATE(2026,7,1),'Fuel Issues'!$A$5:$A$440,"<"&DATE(2026,8,1))=0,"",SUMIFS('Fuel Issues'!$E$5:$E$440,'Fuel Issues'!$C$5:$C$440,$A10,'Fuel Issues'!$A$5:$A$440,">="&DATE(2026,7,1),'Fuel Issues'!$A$5:$A$440,"<"&DATE(2026,8,1))) -> 390 | E10: =IF(SUMIFS('Fuel Issues'!$E$5:$E$440,'Fuel Issues'!$C$5:$C$440,$A10,'Fuel Issues'!$A$5:$A$440,">="&DATE(2026,8,1),'Fuel Issues'!$A$5:$A$440,"<"&DATE(2026,9,1))=0,"",SUMIFS('Fuel Issues'!$E$5:$E$440,'Fuel Issues'!$C$5:$C$440,$A10,'Fuel Issues'!$A$5:$A$440,">="&DATE(2026,8,1),'Fuel Issues'!$A$5:$A$440,"<"&DATE(2026,9,1))) | F10: =SUMIFS('Fuel Issues'!$E$5:$E$440,'Fuel Issues'!$C$5:$C$440,$A10) -> 890 | G10: =COUNTIFS('Fuel Issues'!$C$5:$C$440,$A10) -> 14 | H10: =_xlfn.MINIFS('Fuel Issues'!$A$5:$A$440,'Fuel Issues'!$C$5:$C$440,$A10) -> 46190 | I10: =IFERROR($F10/SUM($F$5:$F$42),"") -> 0.04836168
A11: HEX-23 | B11: =IF(SUMIFS('Fuel Issues'!$E$5:$E$440,'Fuel Issues'!$C$5:$C$440,$A11,'Fuel Issues'!$A$5:$A$440,">="&DATE(2026,5,1),'Fuel Issues'!$A$5:$A$440,"<"&DATE(2026,6,1))=0,"",SUMIFS('Fuel Issues'!$E$5:$E$440,'Fuel Issues'!$C$5:$C$440,$A11,'Fuel Issues'!$A$5:$A$440,">="&DATE(2026,5,1),'Fuel Issues'!$A$5:$A$440,"<"&DATE(2026,6,1))) | C11: =IF(SUMIFS('Fuel Issues'!$E$5:$E$440,'Fuel Issues'!$C$5:$C$440,$A11,'Fuel Issues'!$A$5:$A$440,">="&DATE(2026,6,1),'Fuel Issues'!$A$5:$A$440,"<"&DATE(2026,7,1))=0,"",SUMIFS('Fuel Issues'!$E$5:$E$440,'Fuel Issues'!$C$5:$C$440,$A11,'Fuel Issues'!$A$5:$A$440,">="&DATE(2026,6,1),'Fuel Issues'!$A$5:$A$440,"<"&DATE(2026,7,1))) | D11: =IF(SUMIFS('Fuel Issues'!$E$5:$E$440,'Fuel Issues'!$C$5:$C$440,$A11,'Fuel Issues'!$A$5:$A$440,">="&DATE(2026,7,1),'Fuel Issues'!$A$5:$A$440,"<"&DATE(2026,8,1))=0,"",SUMIFS('Fuel Issues'!$E$5:$E$440,'Fuel Issues'!$C$5:$C$440,$A11,'Fuel Issues'!$A$5:$A$440,">="&DATE(2026,7,1),'Fuel Issues'!$A$5:$A$440,"<"&DATE(2026,8,1))) -> 810 | E11: =IF(SUMIFS('Fuel Issues'!$E$5:$E$440,'Fuel Issues'!$C$5:$C$440,$A11,'Fuel Issues'!$A$5:$A$440,">="&DATE(2026,8,1),'Fuel Issues'!$A$5:$A$440,"<"&DATE(2026,9,1))=0,"",SUMIFS('Fuel Issues'!$E$5:$E$440,'Fuel Issues'!$C$5:$C$440,$A11,'Fuel Issues'!$A$5:$A$440,">="&DATE(2026,8,1),'Fuel Issues'!$A$5:$A$440,"<"&DATE(2026,9,1))) | F11: =SUMIFS('Fuel Issues'!$E$5:$E$440,'Fuel Issues'!$C$5:$C$440,$A11) -> 810 | G11: =COUNTIFS('Fuel Issues'!$C$5:$C$440,$A11) -> 12 | H11: =_xlfn.MINIFS('Fuel Issues'!$A$5:$A$440,'Fuel Issues'!$C$5:$C$440,$A11) -> 46215 | I11: =IFERROR($F11/SUM($F$5:$F$42),"") -> 0.044014563
A12: MG-07 | B12: =IF(SUMIFS('Fuel Issues'!$E$5:$E$440,'Fuel Issues'!$C$5:$C$440,$A12,'Fuel Issues'!$A$5:$A$440,">="&DATE(2026,5,1),'Fuel Issues'!$A$5:$A$440,"<"&DATE(2026,6,1))=0,"",SUMIFS('Fuel Issues'!$E$5:$E$440,'Fuel Issues'!$C$5:$C$440,$A12,'Fuel Issues'!$A$5:$A$440,">="&DATE(2026,5,1),'Fuel Issues'!$A$5:$A$440,"<"&DATE(2026,6,1))) | C12: =IF(SUMIFS('Fuel Issues'!$E$5:$E$440,'Fuel Issues'!$C$5:$C$440,$A12,'Fuel Issues'!$A$5:$A$440,">="&DATE(2026,6,1),'Fuel Issues'!$A$5:$A$440,"<"&DATE(2026,7,1))=0,"",SUMIFS('Fuel Issues'!$E$5:$E$440,'Fuel Issues'!$C$5:$C$440,$A12,'Fuel Issues'!$A$5:$A$440,">="&DATE(2026,6,1),'Fuel Issues'!$A$5:$A$440,"<"&DATE(2026,7,1))) -> 60 | D12: =IF(SUMIFS('Fuel Issues'!$E$5:$E$440,'Fuel Issues'!$C$5:$C$440,$A12,'Fuel Issues'!$A$5:$A$440,">="&DATE(2026,7,1),'Fuel Issues'!$A$5:$A$440,"<"&DATE(2026,8,1))=0,"",SUMIFS('Fuel Issues'!$E$5:$E$440,'Fuel Issues'!$C$5:$C$440,$A12,'Fuel Issues'!$A$5:$A$440,">="&DATE(2026,7,1),'Fuel Issues'!$A$5:$A$440,"<"&DATE(2026,8,1))) -> 620 | E12: =IF(SUMIFS('Fuel Issues'!$E$5:$E$440,'Fuel Issues'!$C$5:$C$440,$A12,'Fuel Issues'!$A$5:$A$440,">="&DATE(2026,8,1),'Fuel Issues'!$A$5:$A$440,"<"&DATE(2026,9,1))=0,"",SUMIFS('Fuel Issues'!$E$5:$E$440,'Fuel Issues'!$C$5:$C$440,$A12,'Fuel Issues'!$A$5:$A$440,">="&DATE(2026,8,1),'Fuel Issues'!$A$5:$A$440,"<"&DATE(2026,9,1))) -> 100 | F12: =SUMIFS('Fuel Issues'!$E$5:$E$440,'Fuel Issues'!$C$5:$C$440,$A12) -> 780 | G12: =COUNTIFS('Fuel Issues'!$C$5:$C$440,$A12) -> 24 | H12: =_xlfn.MINIFS('Fuel Issues'!$A$5:$A$440,'Fuel Issues'!$C$5:$C$440,$A12) -> 46197 | I12: =IFERROR($F12/SUM($F$5:$F$42),"") -> 0.042384394
A13: 2B-1980 | B13: =IF(SUMIFS('Fuel Issues'!$E$5:$E$440,'Fuel Issues'!$C$5:$C$440,$A13,'Fuel Issues'!$A$5:$A$440,">="&DATE(2026,5,1),'Fuel Issues'!$A$5:$A$440,"<"&DATE(2026,6,1))=0,"",SUMIFS('Fuel Issues'!$E$5:$E$440,'Fuel Issues'!$C$5:$C$440,$A13,'Fuel Issues'!$A$5:$A$440,">="&DATE(2026,5,1),'Fuel Issues'!$A$5:$A$440,"<"&DATE(2026,6,1))) -> 240 | C13: =IF(SUMIFS('Fuel Issues'!$E$5:$E$440,'Fuel Issues'!$C$5:$C$440,$A13,'Fuel Issues'!$A$5:$A$440,">="&DATE(2026,6,1),'Fuel Issues'!$A$5:$A$440,"<"&DATE(2026,7,1))=0,"",SUMIFS('Fuel Issues'!$E$5:$E$440,'Fuel Issues'!$C$5:$C$440,$A13,'Fuel Issues'!$A$5:$A$440,">="&DATE(2026,6,1),'Fuel Issues'!$A$5:$A$440,"<"&DATE(2026,7,1))) -> 130 | D13: =IF(SUMIFS('Fuel Issues'!$E$5:$E$440,'Fuel Issues'!$C$5:$C$440,$A13,'Fuel Issues'!$A$5:$A$440,">="&DATE(2026,7,1),'Fuel Issues'!$A$5:$A$440,"<"&DATE(2026,8,1))=0,"",SUMIFS('Fuel Issues'!$E$5:$E$440,'Fuel Issues'!$C$5:$C$440,$A13,'Fuel Issues'!$A$5:$A$440,">="&DATE(2026,7,1),'Fuel Issues'!$A$5:$A$440,"<"&DATE(2026,8,1))) -> 131 | E13: =IF(SUMIFS('Fuel Issues'!$E$5:$E$440,'Fuel Issues'!$C$5:$C$440,$A13,'Fuel Issues'!$A$5:$A$440,">="&DATE(2026,8,1),'Fuel Issues'!$A$5:$A$440,"<"&DATE(2026,9,1))=0,"",SUMIFS('Fuel Issues'!$E$5:$E$440,'Fuel Issues'!$C$5:$C$440,$A13,'Fuel Issues'!$A$5:$A$440,">="&DATE(2026,8,1),'Fuel Issues'!$A$5:$A$440,"<"&DATE(2026,9,1))) -> 75 | F13: =SUMIFS('Fuel Issues'!$E$5:$E$440,'Fuel Issues'!$C$5:$C$440,$A13) -> 576 | G13: =COUNTIFS('Fuel Issues'!$C$5:$C$440,$A13) -> 20 | H13: =_xlfn.MINIFS('Fuel Issues'!$A$5:$A$440,'Fuel Issues'!$C$5:$C$440,$A13) -> 46153 | I13: =IFERROR($F13/SUM($F$5:$F$42),"") -> 0.031299245
A14: PJ-6376 | B14: =IF(SUMIFS('Fuel Issues'!$E$5:$E$440,'Fuel Issues'!$C$5:$C$440,$A14,'Fuel Issues'!$A$5:$A$440,">="&DATE(2026,5,1),'Fuel Issues'!$A$5:$A$440,"<"&DATE(2026,6,1))=0,"",SUMIFS('Fuel Issues'!$E$5:$E$440,'Fuel Issues'!$C$5:$C$440,$A14,'Fuel Issues'!$A$5:$A$440,">="&DATE(2026,5,1),'Fuel Issues'!$A$5:$A$440,"<"&DATE(2026,6,1))) | C14: =IF(SUMIFS('Fuel Issues'!$E$5:$E$440,'Fuel Issues'!$C$5:$C$440,$A14,'Fuel Issues'!$A$5:$A$440,">="&DATE(2026,6,1),'Fuel Issues'!$A$5:$A$440,"<"&DATE(2026,7,1))=0,"",SUMIFS('Fuel Issues'!$E$5:$E$440,'Fuel Issues'!$C$5:$C$440,$A14,'Fuel Issues'!$A$5:$A$440,">="&DATE(2026,6,1),'Fuel Issues'!$A$5:$A$440,"<"&DATE(2026,7,1))) -> 110 | D14: =IF(SUMIFS('Fuel Issues'!$E$5:$E$440,'Fuel Issues'!$C$5:$C$440,$A14,'Fuel Issues'!$A$5:$A$440,">="&DATE(2026,7,1),'Fuel Issues'!$A$5:$A$440,"<"&DATE(2026,8,1))=0,"",SUMIFS('Fuel Issues'!$E$5:$E$440,'Fuel Issues'!$C$5:$C$440,$A14,'Fuel Issues'!$A$5:$A$440,">="&DATE(2026,7,1),'Fuel Issues'!$A$5:$A$440,"<"&DATE(2026,8,1))) -> 358 | E14: =IF(SUMIFS('Fuel Issues'!$E$5:$E$440,'Fuel Issues'!$C$5:$C$440,$A14,'Fuel Issues'!$A$5:$A$440,">="&DATE(2026,8,1),'Fuel Issues'!$A$5:$A$440,"<"&DATE(2026,9,1))=0,"",SUMIFS('Fuel Issues'!$E$5:$E$440,'Fuel Issues'!$C$5:$C$440,$A14,'Fuel Issues'!$A$5:$A$440,">="&DATE(2026,8,1),'Fuel Issues'!$A$5:$A$440,"<"&DATE(2026,9,1))) -> 65 | F14: =SUMIFS('Fuel Issues'!$E$5:$E$440,'Fuel Issues'!$C$5:$C$440,$A14) -> 533 | G14: =COUNTIFS('Fuel Issues'!$C$5:$C$440,$A14) -> 25 | H14: =_xlfn.MINIFS('Fuel Issues'!$A$5:$A$440,'Fuel Issues'!$C$5:$C$440,$A14) -> 46193 | I14: =IFERROR($F14/SUM($F$5:$F$42),"") -> 0.028962669
A15: LB-25 | B15: =IF(SUMIFS('Fuel Issues'!$E$5:$E$440,'Fuel Issues'!$C$5:$C$440,$A15,'Fuel Issues'!$A$5:$A$440,">="&DATE(2026,5,1),'Fuel Issues'!$A$5:$A$440,"<"&DATE(2026,6,1))=0,"",SUMIFS('Fuel Issues'!$E$5:$E$440,'Fuel Issues'!$C$5:$C$440,$A15,'Fuel Issues'!$A$5:$A$440,">="&DATE(2026,5,1),'Fuel Issues'!$A$5:$A$440,"<"&DATE(2026,6,1))) | C15: =IF(SUMIFS('Fuel Issues'!$E$5:$E$440,'Fuel Issues'!$C$5:$C$440,$A15,'Fuel Issues'!$A$5:$A$440,">="&DATE(2026,6,1),'Fuel Issues'!$A$5:$A$440,"<"&DATE(2026,7,1))=0,"",SUMIFS('Fuel Issues'!$E$5:$E$440,'Fuel Issues'!$C$5:$C$440,$A15,'Fuel Issues'!$A$5:$A$440,">="&DATE(2026,6,1),'Fuel Issues'!$A$5:$A$440,"<"&DATE(2026,7,1))) | D15: =IF(SUMIFS('Fuel Issues'!$E$5:$E$440,'Fuel Issues'!$C$5:$C$440,$A15,'Fuel Issues'!$A$5:$A$440,">="&DATE(2026,7,1),'Fuel Issues'!$A$5:$A$440,"<"&DATE(2026,8,1))=0,"",SUMIFS('Fuel Issues'!$E$5:$E$440,'Fuel Issues'!$C$5:$C$440,$A15,'Fuel Issues'!$A$5:$A$440,">="&DATE(2026,7,1),'Fuel Issues'!$A$5:$A$440,"<"&DATE(2026,8,1))) -> 526 | E15: =IF(SUMIFS('Fuel Issues'!$E$5:$E$440,'Fuel Issues'!$C$5:$C$440,$A15,'Fuel Issues'!$A$5:$A$440,">="&DATE(2026,8,1),'Fuel Issues'!$A$5:$A$440,"<"&DATE(2026,9,1))=0,"",SUMIFS('Fuel Issues'!$E$5:$E$440,'Fuel Issues'!$C$5:$C$440,$A15,'Fuel Issues'!$A$5:$A$440,">="&DATE(2026,8,1),'Fuel Issues'!$A$5:$A$440,"<"&DATE(2026,9,1))) | F15: =SUMIFS('Fuel Issues'!$E$5:$E$440,'Fuel Issues'!$C$5:$C$440,$A15) -> 526 | G15: =COUNTIFS('Fuel Issues'!$C$5:$C$440,$A15) -> 19 | H15: =_xlfn.MINIFS('Fuel Issues'!$A$5:$A$440,'Fuel Issues'!$C$5:$C$440,$A15) -> 46208 | I15: =IFERROR($F15/SUM($F$5:$F$42),"") -> 0.028582296
A16: PH-9072 | B16: =IF(SUMIFS('Fuel Issues'!$E$5:$E$440,'Fuel Issues'!$C$5:$C$440,$A16,'Fuel Issues'!$A$5:$A$440,">="&DATE(2026,5,1),'Fuel Issues'!$A$5:$A$440,"<"&DATE(2026,6,1))=0,"",SUMIFS('Fuel Issues'!$E$5:$E$440,'Fuel Issues'!$C$5:$C$440,$A16,'Fuel Issues'!$A$5:$A$440,">="&DATE(2026,5,1),'Fuel Issues'!$A$5:$A$440,"<"&DATE(2026,6,1))) | C16: =IF(SUMIFS('Fuel Issues'!$E$5:$E$440,'Fuel Issues'!$C$5:$C$440,$A16,'Fuel Issues'!$A$5:$A$440,">="&DATE(2026,6,1),'Fuel Issues'!$A$5:$A$440,"<"&DATE(2026,7,1))=0,"",SUMIFS('Fuel Issues'!$E$5:$E$440,'Fuel Issues'!$C$5:$C$440,$A16,'Fuel Issues'!$A$5:$A$440,">="&DATE(2026,6,1),'Fuel Issues'!$A$5:$A$440,"<"&DATE(2026,7,1))) | D16: =IF(SUMIFS('Fuel Issues'!$E$5:$E$440,'Fuel Issues'!$C$5:$C$440,$A16,'Fuel Issues'!$A$5:$A$440,">="&DATE(2026,7,1),'Fuel Issues'!$A$5:$A$440,"<"&DATE(2026,8,1))=0,"",SUMIFS('Fuel Issues'!$E$5:$E$440,'Fuel Issues'!$C$5:$C$440,$A16,'Fuel Issues'!$A$5:$A$440,">="&DATE(2026,7,1),'Fuel Issues'!$A$5:$A$440,"<"&DATE(2026,8,1))) -> 384 | E16: =IF(SUMIFS('Fuel Issues'!$E$5:$E$440,'Fuel Issues'!$C$5:$C$440,$A16,'Fuel Issues'!$A$5:$A$440,">="&DATE(2026,8,1),'Fuel Issues'!$A$5:$A$440,"<"&DATE(2026,9,1))=0,"",SUMIFS('Fuel Issues'!$E$5:$E$440,'Fuel Issues'!$C$5:$C$440,$A16,'Fuel Issues'!$A$5:$A$440,">="&DATE(2026,8,1),'Fuel Issues'!$A$5:$A$440,"<"&DATE(2026,9,1))) -> 101 | F16: =SUMIFS('Fuel Issues'!$E$5:$E$440,'Fuel Issues'!$C$5:$C$440,$A16) -> 485 | G16: =COUNTIFS('Fuel Issues'!$C$5:$C$440,$A16) -> 11 | H16: =_xlfn.MINIFS('Fuel Issues'!$A$5:$A$440,'Fuel Issues'!$C$5:$C$440,$A16) -> 46209 | I16: =IFERROR($F16/SUM($F$5:$F$42),"") -> 0.026354399
... A42: WG-13 | B42: =IF(SUMIFS('Fuel Issues'!$E$5:$E$440,'Fuel Issues'!$C$5:$C$440,$A42,'Fuel Issues'!$A$5:$A$440,">="&DATE(2026,5,1),'Fuel Issues'!$A$5:$A$440,"<"&DATE(2026,6,1))=0,"",SUMIFS('Fuel Issues'!$E$5:$E$440,'Fuel Issues'!$C$5:$C$440,$A42,'Fuel Issues'!$A$5:$A$440,">="&DATE(2026,5,1),'Fuel Issues'!$A$5:$A$440,"<"&DATE(2026,6,1))) | C42: =IF(SUMIFS('Fuel Issues'!$E$5:$E$440,'Fuel Issues'!$C$5:$C$440,$A42,'Fuel Issues'!$A$5:$A$440,">="&DATE(2026,6,1),'Fuel Issues'!$A$5:$A$440,"<"&DATE(2026,7,1))=0,"",SUMIFS('Fuel Issues'!$E$5:$E$440,'Fuel Issues'!$C$5:$C$440,$A42,'Fuel Issues'!$A$5:$A$440,">="&DATE(2026,6,1),'Fuel Issues'!$A$5:$A$440,"<"&DATE(2026,7,1))) | D42: =IF(SUMIFS('Fuel Issues'!$E$5:$E$440,'Fuel Issues'!$C$5:$C$440,$A42,'Fuel Issues'!$A$5:$A$440,">="&DATE(2026,7,1),'Fuel Issues'!$A$5:$A$440,"<"&DATE(2026,8,1))=0,"",SUMIFS('Fuel Issues'!$E$5:$E$440,'Fuel Issues'!$C$5:$C$440,$A42,'Fuel Issues'!$A$5:$A$440,">="&DATE(2026,7,1),'Fuel Issues'!$A$5:$A$440,"<"&DATE(2026,8,1))) -> 10 | E42: =IF(SUMIFS('Fuel Issues'!$E$5:$E$440,'Fuel Issues'!$C$5:$C$440,$A42,'Fuel Issues'!$A$5:$A$440,">="&DATE(2026,8,1),'Fuel Issues'!$A$5:$A$440,"<"&DATE(2026,9,1))=0,"",SUMIFS('Fuel Issues'!$E$5:$E$440,'Fuel Issues'!$C$5:$C$440,$A42,'Fuel Issues'!$A$5:$A$440,">="&DATE(2026,8,1),'Fuel Issues'!$A$5:$A$440,"<"&DATE(2026,9,1))) | F42: =SUMIFS('Fuel Issues'!$E$5:$E$440,'Fuel Issues'!$C$5:$C$440,$A42) -> 10 | G42: =COUNTIFS('Fuel Issues'!$C$5:$C$440,$A42) -> 1 | H42: =_xlfn.MINIFS('Fuel Issues'!$A$5:$A$440,'Fuel Issues'!$C$5:$C$440,$A42) -> 46229 | I42: =IFERROR($F42/SUM($F$5:$F$42),"") -> 0.00054338966
A43: Total | B43: =SUM(B5:B42) -> 240 | C43: =SUM(C5:C42) -> 2455 | D43: =SUM(D5:D42) -> 13053 | E43: =SUM(E5:E42) -> 2655 | F43: =SUM(F5:F42) -> 18403 | G43: =SUM(G5:G42) -> 436 | I43: =SUM(I5:I42) -> 1

Sheet Summary
A1: Galagedara Site - Diesel and Fleet Summary
A2: Period covered: 11 May 2026 to 05 Aug 2026
A4: Period
A5: First issue on site | B5: =_xlfn.MINIFS('Fuel Issues'!$A$5:$A$440,'Fuel Issues'!$E$5:$E$440,">0") -> 46153
A6: Latest issue recorded | B6: =_xlfn.MAXIFS('Fuel Issues'!$A$5:$A$440,'Fuel Issues'!$E$5:$E$440,">0") -> 46239
A7: Calendar days covered | B7: =B6-B5+1 -> 87
A8: Fuel
A9: Total diesel received (L) | B9: =SUM(Receipts!$D$5:$D$37) -> 16836
A10: Total diesel issued (L) | B10: =SUM('Fuel Issues'!$E$5:$E$440) -> 18403
A11: Difference, received less issued (L) | B11: =B9-B10 -> -1567
A12: Number of issue transactions | B12: =COUNT('Fuel Issues'!$E$5:$E$440) -> 436
A13: Average issue size (L) | B13: =B10/B12 -> 42.208716
A14: Average issued per calendar day (L) | B14: =B10/B7 -> 211.52874
A15: Fleet
A16: Distinct units fuelled on site | B16: =COUNTA('Allocation Register'!$B$5:$B$42) -> 38
A17: Units with an issue in the last 7 days | B17: =COUNTIFS('Allocation Register'!$G$5:$G$42,"<=7") -> 24
A18: Units idle more than 7 days | B18: =COUNTIFS('Allocation Register'!$G$5:$G$42,">7") -> 14
A19: Largest single consumer (L) | B19: =MAX('Allocation Register'!$I$5:$I$42) -> 2920
A20: Largest single consumer | B20: =INDEX('Allocation Register'!$B$5:$B$42,MATCH($B$19,'Allocation Register'!$I$5:$I$42,0)) -> HEX-45
A22: Fleet build-up by month
A23: Month | B23: New Units Allocated | C23: Cumulative Fleet | D23: Diesel Issued (L)
A24: 46143 | B24: ='Monthly Issues'!G5 -> 1 | C24: ='Monthly Issues'!H5 -> 1 | D24: ='Monthly Issues'!C5 -> 240
A25: 46174 | B25: ='Monthly Issues'!G6 -> 10 | C25: ='Monthly Issues'!H6 -> 11 | D25: ='Monthly Issues'!C6 -> 2455
A26: 46204 | B26: ='Monthly Issues'!G7 -> 24 | C26: ='Monthly Issues'!H7 -> 35 | D26: ='Monthly Issues'!C7 -> 13053
A27: 46235 | B27: ='Monthly Issues'!G8 -> 3 | C27: ='Monthly Issues'!H8 -> 38 | D27: ='Monthly Issues'!C8 -> 2655
A29: Top 10 units by diesel drawn
A30: Rank | B30: Vehicle / Unit | C30: Total Diesel (L) | D30: Allocation Date | E30: Share of Total
A31: 1 | B31: HEX-45 | C31: =SUMIFS('Fuel Issues'!$E$5:$E$440,'Fuel Issues'!$C$5:$C$440,$B31) -> 2920 | D31: =_xlfn.MINIFS('Fuel Issues'!$A$5:$A$440,'Fuel Issues'!$C$5:$C$440,$B31) -> 46182 | E31: =IFERROR($C31/$B$10,"") -> 0.15866978
A32: 2 | B32: HEX-26 | C32: =SUMIFS('Fuel Issues'!$E$5:$E$440,'Fuel Issues'!$C$5:$C$440,$B32) -> 2090 | D32: =_xlfn.MINIFS('Fuel Issues'!$A$5:$A$440,'Fuel Issues'!$C$5:$C$440,$B32) -> 46208 | E32: =IFERROR($C32/$B$10,"") -> 0.11356844
A33: 3 | B33: HEX-33 | C33: =SUMIFS('Fuel Issues'!$E$5:$E$440,'Fuel Issues'!$C$5:$C$440,$B33) -> 1940 | D33: =_xlfn.MINIFS('Fuel Issues'!$A$5:$A$440,'Fuel Issues'!$C$5:$C$440,$B33) -> 46211 | E33: =IFERROR($C33/$B$10,"") -> 0.10541759
A34: 4 | B34: HEX-37 | C34: =SUMIFS('Fuel Issues'!$E$5:$E$440,'Fuel Issues'!$C$5:$C$440,$B34) -> 1660 | D34: =_xlfn.MINIFS('Fuel Issues'!$A$5:$A$440,'Fuel Issues'!$C$5:$C$440,$B34) -> 46223 | E34: =IFERROR($C34/$B$10,"") -> 0.090202684
A35: 5 | B35: D4D-02 | C35: =SUMIFS('Fuel Issues'!$E$5:$E$440,'Fuel Issues'!$C$5:$C$440,$B35) -> 1455 | D35: =_xlfn.MINIFS('Fuel Issues'!$A$5:$A$440,'Fuel Issues'!$C$5:$C$440,$B35) -> 46181 | E35: =IFERROR($C35/$B$10,"") -> 0.079063196
A36: 6 | B36: HEX-01 | C36: =SUMIFS('Fuel Issues'!$E$5:$E$440,'Fuel Issues'!$C$5:$C$440,$B36) -> 890 | D36: =_xlfn.MINIFS('Fuel Issues'!$A$5:$A$440,'Fuel Issues'!$C$5:$C$440,$B36) -> 46190 | E36: =IFERROR($C36/$B$10,"") -> 0.04836168
A37: 7 | B37: HEX-23 | C37: =SUMIFS('Fuel Issues'!$E$5:$E$440,'Fuel Issues'!$C$5:$C$440,$B37) -> 810 | D37: =_xlfn.MINIFS('Fuel Issues'!$A$5:$A$440,'Fuel Issues'!$C$5:$C$440,$B37) -> 46215 | E37: =IFERROR($C37/$B$10,"") -> 0.044014563
A38: 8 | B38: MG-07 | C38: =SUMIFS('Fuel Issues'!$E$5:$E$440,'Fuel Issues'!$C$5:$C$440,$B38) -> 780 | D38: =_xlfn.MINIFS('Fuel Issues'!$A$5:$A$440,'Fuel Issues'!$C$5:$C$440,$B38) -> 46197 | E38: =IFERROR($C38/$B$10,"") -> 0.042384394
A39: 9 | B39: 2B-1980 | C39: =SUMIFS('Fuel Issues'!$E$5:$E$440,'Fuel Issues'!$C$5:$C$440,$B39) -> 576 | D39: =_xlfn.MINIFS('Fuel Issues'!$A$5:$A$440,'Fuel Issues'!$C$5:$C$440,$B39) -> 46153 | E39: =IFERROR($C39/$B$10,"") -> 0.031299245
A40: 10 | B40: PJ-6376 | C40: =SUMIFS('Fuel Issues'!$E$5:$E$440,'Fuel Issues'!$C$5:$C$440,$B40) -> 533 | D40: =_xlfn.MINIFS('Fuel Issues'!$A$5:$A$440,'Fuel Issues'!$C$5:$C$440,$B40) -> 46193 | E40: =IFERROR($C40/$B$10,"") -> 0.028962669

Sheet Sources & Name Map
A1: Sources, Method and Vehicle Name Decisions
A3: Sources combined
B4: Diesel stock book, 11 May 2026 to 26 Jul 2026. 347 issue rows, 13,817 L. This is the site's own stock book and is the only source for May and June.
B5: Fuel & Lubricant issue log (Galagedara), 26 Jul 2026 to 01 Aug 2026. The 26 Jul entries in this log are the same twelve issues already in the stock book, so 26 Jul has been taken from the stock book only. 51 rows kept, 2,483 L.
B6: Daily Fuel & Lubricant Issue sheets, 02 Aug to 05 Aug 2026, transcribed from photographs earlier today. 39 rows, 2,163 L. These carry the site forward to yesterday.
B7: The three sources join cleanly. Meter readings chain across the joins: HEX-26 10409.7, HEX-33 8966.7, PJ-6376 309005, 59-5421 247404 and LO-8349 92638 all carry from 01 Aug into the 02 Aug sheet, which confirms the August photographs are from this same site.
A8: Allocation date
B9: Allocation date is the unit's first diesel issue on this site, as you instructed. It is a good proxy but it will read late for any machine that arrived and sat idle before its first fill, and it cannot see a unit that was on site and never fuelled here.
B10: Days on Site counts from the first issue to the last issue inclusive. Days Since Last Issue is measured against the date in cell B2 of the Allocation Register, which you can change to re-date the whole sheet.
A11: Vehicle names merged
B12: The same machine is written differently across the three records. Before any counting, names were normalised. A merge was only applied where the two spellings never appear on the same day, since a unit cannot draw fuel twice under two names in one day. Merges applied:
B13: HEX-39 to HEX-37. The meter runs 7364.5, 7371.8, 7378.9, 7384.7, 7394.9 without a break, so the 02 to 05 Aug sheets were reading 37 as 39.
B14: HEX-46 to HEX-45, one row on 03 Aug. EXCAVETOR HEX-45 to HEX-45.
B15: ZB-1980, LB-21 and LB-21 Repair to 2B-1980. Meter 2315.9 on 26 Jul carries to 2320.5 on 29 Jul across the LB-21 and ZB-1980 spellings.
B16: ZB-4606 to 2B-4606. ZA-4344 to MG-07, which the 27 Jul sheet itself notes in a circle. NC-1094 to PC-1094. LO-4025 to LO-4925. LO-8360 to LO-8350. LA-0920 to LL-0920. WCA-13 to WG-13.
B17: D 4 D 2, D 4 D -2, D4D-II, D2D-02 and D4D-TJ all to D4D-02. The meter runs 5228.5, 5237.5, 5243.1, 5247, 5250.7, 5257.7, 5262.5 unbroken across every one of those spellings. D 4 D 1 to D4D-01 and D 4 D -3 to D4D-03.
B18: PE-3729 and PE-3723 (Mr Chinthaka Surveyor Officer) to PE-3723. DAG-4929 and DAC-4967 to DAG-4969.
A19: Names deliberately kept apart
B20: HEX-23 and HEX-33 both drew fuel on the same day twelve times, so they are two different excavators despite the similar number.
B21: LA-1359 and PH-9072 both drew fuel on 06 Jul, so they are two different units, even though the issue log noted a matching meter chain between them on 28 Jul and 01 Aug. That meter note looks like an entry error rather than an alias.
B22: SR-12 and SR-13 never clash on a date, but two clearly different meter ranges appear under the SR-12 name: about 2,730 hours and about 3,880 hours. That means the plate is being written inconsistently in both directions. They have been left as two units. This one is worth settling from the machine plates.
B23: GE-M47 and LK-5041 appear once each, on 05 Aug, and match nothing else in the records. Both plates were unclear in the photograph. They show as August allocations, which may be wrong.
A24: What is missing
B25: Receipts are complete only to 01 Aug. The 02 to 05 Aug sheets left the balance forward, issued and stock lines blank, so August receipts are understated and the received less issued figure on the Summary tab should not be read as a stock position.
B26: The 03 Aug sheet does not reconcile: rows total 365 L, the written issued figure reads 305 L, and the stock movement implies 344 L. HEX-37 at 120 L that day is the likely cause and is the one figure worth checking against the original.
